Workbook

Sheet LEADERBOARD
A1: 2013 WANNABE CUP
A2: TO PAR | B2: POS | C2: PLAYER | D2: SCORE | E2: =SETUP!C1 -> BLACK FOREST | F2: =SETUP!D1 -> LOCHENHEATH | G2: =SETUP!E1 -> THE LEGEND | H2: =SETUP!F1 -> FOREST DUNES
A3: {=index('Score Calcuations'!$N$3:$N$14,match(C3,'Score Calcuations'!$A$3:$A$14))} -> N/A | B3: =IFERROR(__xludf.DUMMYFUNCTION("query(index('Score Calcuations'!A3:N14&""""),""select Col3,Col1,Col14,Col5,Col7,Col9,Col11 ORDER BY Col13"",0)"),"") | C3: =IFERROR(__xludf.DUMMYFUNCTION("""COMPUTED_VALUE"""),"N/A") -> N/A | D3: =IFERROR(__xludf.DUMMYFUNCTION("""COMPUTED_VALUE"""),"N/A") -> N/A
A4: {=index('Score Calcuations'!$N$3:$N$14,match(C4,'Score Calcuations'!$A$3:$A$14))} -> N/A | C4: =IFERROR(__xludf.DUMMYFUNCTION("""COMPUTED_VALUE"""),"N/A") -> N/A | D4: =IFERROR(__xludf.DUMMYFUNCTION("""COMPUTED_VALUE"""),"N/A") -> N/A
A5: {=index('Score Calcuations'!$N$3:$N$14,match(C5,'Score Calcuations'!$A$3:$A$14))} -> N/A | C5: =IFERROR(__xludf.DUMMYFUNCTION("""COMPUTED_VALUE"""),"N/A") -> N/A | D5: =IFERROR(__xludf.DUMMYFUNCTION("""COMPUTED_VALUE"""),"N/A") -> N/A
A6: {=index('Score Calcuations'!$N$3:$N$14,match(C6,'Score Calcuations'!$A$3:$A$14))} -> N/A | C6: =IFERROR(__xludf.DUMMYFUNCTION("""COMPUTED_VALUE"""),"N/A") -> N/A | D6: =IFERROR(__xludf.DUMMYFUNCTION("""COMPUTED_VALUE"""),"N/A") -> N/A
A7: {=index('Score Calcuations'!$N$3:$N$14,match(C7,'Score Calcuations'!$A$3:$A$14))} -> N/A | C7: =IFERROR(__xludf.DUMMYFUNCTION("""COMPUTED_VALUE"""),"N/A") -> N/A | D7: =IFERROR(__xludf.DUMMYFUNCTION("""COMPUTED_VALUE"""),"N/A") -> N/A
A8: {=index('Score Calcuations'!$N$3:$N$14,match(C8,'Score Calcuations'!$A$3:$A$14))} -> N/A | C8: =IFERROR(__xludf.DUMMYFUNCTION("""COMPUTED_VALUE"""),"N/A") -> N/A | D8: =IFERROR(__xludf.DUMMYFUNCTION("""COMPUTED_VALUE"""),"N/A") -> N/A
A9: {=index('Score Calcuations'!$N$3:$N$14,match(C9,'Score Calcuations'!$A$3:$A$14))} -> N/A | B9: =IFERROR(__xludf.DUMMYFUNCTION("""COMPUTED_VALUE"""),"1") -> 1 | C9: =IFERROR(__xludf.DUMMYFUNCTION("""COMPUTED_VALUE"""),"Scott R") -> Scott R | D9: =IFERROR(__xludf.DUMMYFUNCTION("""COMPUTED_VALUE"""),"28") -> 28 | E9: =IFERROR(__xludf.DUMMYFUNCTION("""COMPUTED_VALUE"""),"82") -> 82 | F9: =IFERROR(__xludf.DUMMYFUNCTION("""COMPUTED_VALUE"""),"79") -> 79 | G9: =IFERROR(__xludf.DUMMYFUNCTION("""COMPUTED_VALUE"""),"76") -> 76 | H9: =IFERROR(__xludf.DUMMYFUNCTION("""COMPUTED_VALUE"""),"80") -> 80
A10: {=index('Score Calcuations'!$N$3:$N$14,match(C10,'Score Calcuations'!$A$3:$A$14))} -> 33 | B10: =IFERROR(__xludf.DUMMYFUNCTION("""COMPUTED_VALUE"""),"2") -> 2 | C10: =IFERROR(__xludf.DUMMYFUNCTION("""COMPUTED_VALUE"""),"Aaron J") -> Aaron J | D10: =IFERROR(__xludf.DUMMYFUNCTION("""COMPUTED_VALUE"""),"33") -> 33 | E10: =IFERROR(__xludf.DUMMYFUNCTION("""COMPUTED_VALUE"""),"82") -> 82 | F10: =IFERROR(__xludf.DUMMYFUNCTION("""COMPUTED_VALUE"""),"83") -> 83 | G10: =IFERROR(__xludf.DUMMYFUNCTION("""COMPUTED_VALUE"""),"76") -> 76 | H10: =IFERROR(__xludf.DUMMYFUNCTION("""COMPUTED_VALUE"""),"81") -> 81
A11: {=index('Score Calcuations'!$N$3:$N$14,match(C11,'Score Calcuations'!$A$3:$A$14))} -> 35 | B11: =IFERROR(__xludf.DUMMYFUNCTION("""COMPUTED_VALUE"""),"3") -> 3 | C11: =IFERROR(__xludf.DUMMYFUNCTION("""COMPUTED_VALUE"""),"Eric O") -> Eric O | D11: =IFERROR(__xludf.DUMMYFUNCTION("""COMPUTED_VALUE"""),"35") -> 35 | E11: =IFERROR(__xludf.DUMMYFUNCTION("""COMPUTED_VALUE"""),"91") -> 91 | F11: =IFERROR(__xludf.DUMMYFUNCTION("""COMPUTED_VALUE"""),"84") -> 84 | G11: =IFERROR(__xludf.DUMMYFUNCTION("""COMPUTED_VALUE"""),"73") -> 73 | H11: =IFERROR(__xludf.DUMMYFUNCTION("""COMPUTED_VALUE"""),"76") -> 76
A12: {=index('Score Calcuations'!$N$3:$N$14,match(C12,'Score Calcuations'!$A$3:$A$14))} -> 37 | B12: =IFERROR(__xludf.DUMMYFUNCTION("""COMPUTED_VALUE"""),"4") -> 4 | C12: =IFERROR(__xludf.DUMMYFUNCTION("""COMPUTED_VALUE"""),"Brian K") -> Brian K | D12: =IFERROR(__xludf.DUMMYFUNCTION("""COMPUTED_VALUE"""),"37") -> 37 | E12: =IFERROR(__xludf.DUMMYFUNCTION("""COMPUTED_VALUE"""),"84") -> 84 | F12: =IFERROR(__xludf.DUMMYFUNCTION("""COMPUTED_VALUE"""),"84") -> 84 | G12: =IFERROR(__xludf.DUMMYFUNCTION("""COMPUTED_VALUE"""),"77") -> 77 | H12: =IFERROR(__xludf.DUMMYFUNCTION("""COMPUTED_VALUE"""),"81") -> 81
A13: {=index('Score Calcuations'!$N$3:$N$14,match(C13,'Score Calcuations'!$A$3:$A$14))} -> 39 | B13: =IFERROR(__xludf.DUMMYFUNCTION("""COMPUTED_VALUE"""),"5") -> 5 | C13: =IFERROR(__xludf.DUMMYFUNCTION("""COMPUTED_VALUE"""),"Bob B") -> Bob B | D13: =IFERROR(__xludf.DUMMYFUNCTION("""COMPUTED_VALUE"""),"39") -> 39 | E13: =IFERROR(__xludf.DUMMYFUNCTION("""COMPUTED_VALUE"""),"88") -> 88 | F13: =IFERROR(__xludf.DUMMYFUNCTION("""COMPUTED_VALUE"""),"79") -> 79 | G13: =IFERROR(__xludf.DUMMYFUNCTION("""COMPUTED_VALUE"""),"83") -> 83 | H13: =IFERROR(__xludf.DUMMYFUNCTION("""COMPUTED_VALUE"""),"78") -> 78
A14: {=index('Score Calcuations'!$N$3:$N$14,match(C14,'Score Calcuations'!$A$3:$A$14))} -> 40 | B14: =IFERROR(__xludf.DUMMYFUNCTION("""COMPUTED_VALUE"""),"6") -> 6 | C14: =IFERROR(__xludf.DUMMYFUNCTION("""COMPUTED_VALUE"""),"Matt V") -> Matt V | D14: =IFERROR(__xludf.DUMMYFUNCTION("""COMPUTED_VALUE"""),"40") -> 40 | E14: =IFERROR(__xludf.DUMMYFUNCTION("""COMPUTED_VALUE"""),"87") -> 87 | F14: =IFERROR(__xludf.DUMMYFUNCTION("""COMPUTED_VALUE"""),"81") -> 81 | G14: =IFERROR(__xludf.DUMMYFUNCTION("""COMPUTED_VALUE"""),"81") -> 81 | H14: =IFERROR(__xludf.DUMMYFUNCTION("""COMPUTED_VALUE"""),"80") -> 80

Sheet Scorecards
C1: =SETUP!C1 -> BLACK FOREST | X1: =SETUP!C2 -> 72.8 | Y1: =SETUP!C3 -> 143
C2: Hole | D2: 1 | E2: 2 | F2: 3 | G2: 4 | H2: 5 | I2: 6 | J2: 7 | K2: 8 | L2: 9 | M2: 10 | N2: 11 | O2: 12 | P2: 13 | Q2: 14 | R2: 15 | S2: 16 | T2: 17 | U2: 18 | V2: OUT | W2: IN | X2: TOTAL | Y2: NET
A3: =SETUP!A4 -> Player | B3: Handi | C3: Par | D3: 5 | E3: 4 | F3: 4 | G3: 4 | H3: 3 | I3: 4 | J3: 5 | K3: 3 | L3: 4 | M3: 5 | N3: 4 | O3: 3 | P3: 4 | Q3: 4 | R3: 3 | S3: 5 | T3: 4 | U3: 5 | V3: =SUM(D3:L3) -> 36 | W3: =SUM(M3:U3) -> 37 | X3: =V3+W3 -> 73
A4: =SETUP!A5 -> Aaron J | B4: {=if(A4="","",index(SETUP!C:C,match(A4,SETUP!A:A,0)))} -> 13 | D4: 5 | E4: 8 | F4: 6 | G4: 5 | H4: 4 | I4: 5 | J4: 4 | K4: 3 | L4: 5 | M4: 8 | N4: 7 | O4: 3 | P4: 4 | Q4: 7 | R4: 3 | S4: 7 | T4: 4 | U4: 7 | V4: =SUM(D4:L4) -> 45 | W4: =SUM(M4:U4) -> 50 | X4: =IF(W4>0,V4+W4,"") -> 95 | Y4: =IF(W4=0,"",X4-B4) -> 82
A5: =SETUP!A6 -> Bob B | B5: {=if(A5="","",index(SETUP!C:C,match(A5,SETUP!A:A,0)))} -> 17 | D5: 7 | E5: 8 | F5: 4 | G5: 6 | H5: 5 | I5: 6 | J5: 5 | K5: 3 | L5: 6 | M5: 5 | N5: 5 | O5: 6 | P5: 5 | Q5: 6 | R5: 6 | S5: 8 | T5: 7 | U5: 7 | V5: =SUM(D5:L5) -> 50 | W5: =SUM(M5:U5) -> 55 | X5: =IF(W5>0,V5+W5,"") -> 105 | Y5: =IF(W5=0,"",X5-B5) -> 88
A6: =SETUP!A7 -> Brian K | B6: {=if(A6="","",index(SETUP!C:C,match(A6,SETUP!A:A,0)))} -> 17 | D6: 7 | E6: 6 | F6: 5 | G6: 6 | H6: 7 | I6: 7 | J6: 6 | K6: 4 | L6: 6 | M6: 6 | N6: 4 | O6: 5 | P6: 4 | Q6: 6 | R6: 3 | S6: 7 | T6: 5 | U6: 7 | V6: =SUM(D6:L6) -> 54 | W6: =SUM(M6:U6) -> 47 | X6: =IF(W6>0,V6+W6,"") -> 101 | Y6: =IF(W6=0,"",X6-B6) -> 84
A7: =SETUP!A8 -> Eric O | B7: {=if(A7="","",index(SETUP!C:C,match(A7,SETUP!A:A,0)))} -> 19 | D7: 7 | E7: 6 | F7: 6 | G7: 7 | H7: 4 | I7: 7 | J7: 5 | K7: 5 | L7: 7 | M7: 7 | N7: 7 | O7: 4 | P7: 5 | Q7: 8 | R7: 6 | S7: 8 | T7: 6 | U7: 5 | V7: =SUM(D7:L7) -> 54 | W7: =SUM(M7:U7) -> 56 | X7: =IF(W7>0,V7+W7,"") -> 110 | Y7: =IF(W7=0,"",X7-B7) -> 91
A8: =SETUP!A9 -> Matt V | B8: {=if(A8="","",index(SETUP!C:C,match(A8,SETUP!A:A,0)))} -> 16 | D8: 7 | E8: 7 | F8: 5 | G8: 5 | H8: 5 | I8: 5 | J8: 5 | K8: 4 | L8: 4 | M8: 8 | N8: 5 | O8: 4 | P8: 4 | Q8: 8 | R8: 4 | S8: 8 | T8: 7 | U8: 8 | V8: =SUM(D8:L8) -> 47 | W8: =SUM(M8:U8) -> 56 | X8: =IF(W8>0,V8+W8,"") -> 103 | Y8: =IF(W8=0,"",X8-B8) -> 87
A9: =SETUP!A10 -> Scott R | B9: {=if(A9="","",index(SETUP!C:C,match(A9,SETUP!A:A,0)))} -> 10 | D9: 6 | E9: 6 | F9: 6 | G9: 4 | H9: 4 | I9: 4 | J9: 6 | K9: 3 | L9: 5 | M9: 8 | N9: 5 | O9: 4 | P9: 5 | Q9: 7 | R9: 3 | S9: 4 | T9: 5 | U9: 7 | V9: =SUM(D9:L9) -> 44 | W9: =SUM(M9:U9) -> 48 | X9: =IF(W9>0,V9+W9,"") -> 92 | Y9: =IF(W9=0,"",X9-B9) -> 82
A10: =SETUP!A11 -> N/A | B10: {=if(A10="","",index(SETUP!C:C,match(A10,SETUP!A:A,0)))} | V10: =SUM(D10:L10) -> 0 | W10: =SUM(M10:U10) -> 0 | X10: =IF(W10>0,V10+W10,"") | Y10: =IF(W10=0,"",X10-B10)
A11: =SETUP!A12 -> N/A | B11: {=if(A11="","",index(SETUP!C:C,match(A11,SETUP!A:A,0)))} | V11: =SUM(D11:L11) -> 0 | W11: =SUM(M11:U11) -> 0 | X11: =IF(W11>0,V11+W11,"") | Y11: =IF(W11=0,"",X11-B11)
A12: =SETUP!A13 -> N/A | B12: {=if(A12="","",index(SETUP!C:C,match(A12,SETUP!A:A,0)))} | V12: =SUM(D12:L12) -> 0 | W12: =SUM(M12:U12) -> 0 | X12: =IF(W12>0,V12+W12,"") | Y12: =IF(W12=0,"",X12-B12)
A13: =SETUP!A14 -> N/A | B13: {=if(A13="","",index(SETUP!C:C,match(A13,SETUP!A:A,0)))} | V13: =SUM(D13:L13) -> 0 | W13: =SUM(M13:U13) -> 0 | X13: =IF(W13>0,V13+W13,"") | Y13: =IF(W13=0,"",X13-B13)
A14: =SETUP!A15 -> N/A | B14: {=if(A14="","",index(SETUP!C:C,match(A14,SETUP!A:A,0)))} | V14: =SUM(D14:L14) -> 0 | W14: =SUM(M14:U14) -> 0 | X14: =IF(W14>0,V14+W14,"") | Y14: =IF(W14=0,"",X14-B14)
A15: =SETUP!A16 -> N/A | B15: {=if(A15="","",index(SETUP!C:C,match(A15,SETUP!A:A,0)))} | V15: =SUM(D15:L15) -> 0 | W15: =SUM(M15:U15) -> 0 | X15: =IF(W15>0,V15+W15,"") | Y15: =IF(W15=0,"",X15-B15)
C16: SKIN | D16: {=IF(SUM(IF(IF('Betting SETUP'!$D$5:$D$16="Y", D4:D15, 10)=MIN(IF('Betting SETUP'!$D$5:$D$16="Y", D4:D15, 10)), 1, 0)) > 1, "", INDEX('Betting SETUP'!$A$5:$A$16,MATCH(MIN(IF('Betting SETUP'!$D$5:$D$16="Y",D4:D15,10)),IF('Betting SETUP'!$D$5:$D$16="Y",D4:D15,10),0)))} -> Aaron J | E16: {=IF(SUM(IF(IF('Betting SETUP'!$D$5:$D$16="Y", E4:E15, 10)=MIN(IF('Betting SETUP'!$D$5:$D$16="Y", E4:E15, 10)), 1, 0)) > 1, "", INDEX('Betting SETUP'!$A$5:$A$16,MATCH(MIN(IF('Betting SETUP'!$D$5:$D$16="Y",E4:E15,10)),IF('Betting SETUP'!$D$5:$D$16="Y",E4:E15,10),0)))} | F16: {=IF(SUM(IF(IF('Betting SETUP'!$D$5:$D$16="Y", F4:F15, 10)=MIN(IF('Betting SETUP'!$D$5:$D$16="Y", F4:F15, 10)), 1, 0)) > 1, "", INDEX('Betting SETUP'!$A$5:$A$16,MATCH(MIN(IF('Betting SETUP'!$D$5:$D$16="Y",F4:F15,10)),IF('Betting SETUP'!$D$5:$D$16="Y",F4:F15,10),0)))} -> Bob B | G16: {=IF(SUM(IF(IF('Betting SETUP'!$D$5:$D$16="Y", G4:G15, 10)=MIN(IF('Betting SETUP'!$D$5:$D$16="Y", G4:G15, 10)), 1, 0)) > 1, "", INDEX('Betting SETUP'!$A$5:$A$16,MATCH(MIN(IF('Betting SETUP'!$D$5:$D$16="Y",G4:G15,10)),IF('Betting SETUP'!$D$5:$D$16="Y",G4:G15,10),0)))} -> Scott R | H16: {=IF(SUM(IF(IF('Betting SETUP'!$D$5:$D$16="Y", H4:H15, 10)=MIN(IF('Betting SETUP'!$D$5:$D$16="Y", H4:H15, 10)), 1, 0)) > 1, "", INDEX('Betting SETUP'!$A$5:$A$16,MATCH(MIN(IF('Betting SETUP'!$D$5:$D$16="Y",H4:H15,10)),IF('Betting SETUP'!$D$5:$D$16="Y",H4:H15,10),0)))} | I16: {=IF(SUM(IF(IF('Betting SETUP'!$D$5:$D$16="Y", I4:I15, 10)=MIN(IF('Betting SETUP'!$D$5:$D$16="Y", I4:I15, 10)), 1, 0)) > 1, "", INDEX('Betting SETUP'!$A$5:$A$16,MATCH(MIN(IF('Betting SETUP'!$D$5:$D$16="Y",I4:I15,10)),IF('Betting SETUP'!$D$5:$D$16="Y",I4:I15,10),0)))} -> Scott R | J16: {=IF(SUM(IF(IF('Betting SETUP'!$D$5:$D$16="Y", J4:J15, 10)=MIN(IF('Betting SETUP'!$D$5:$D$16="Y", J4:J15, 10)), 1, 0)) > 1, "", INDEX('Betting SETUP'!$A$5:$A$16,MATCH(MIN(IF('Betting SETUP'!$D$5:$D$16="Y",J4:J15,10)),IF('Betting SETUP'!$D$5:$D$16="Y",J4:J15,10),0)))} -> Aaron J | K16: {=IF(SUM(IF(IF('Betting SETUP'!$D$5:$D$16="Y", K4:K15, 10)=MIN(IF('Betting SETUP'!$D$5:$D$16="Y", K4:K15, 10)), 1, 0)) > 1, "", INDEX('Betting SETUP'!$A$5:$A$16,MATCH(MIN(IF('Betting SETUP'!$D$5:$D$16="Y",K4:K15,10)),IF('Betting SETUP'!$D$5:$D$16="Y",K4:K15,10),0)))} | ... U16: {=IF(SUM(IF(IF('Betting SETUP'!$D$5:$D$16="Y", U4:U15, 10)=MIN(IF('Betting SETUP'!$D$5:$D$16="Y", U4:U15, 10)), 1, 0)) > 1, "", INDEX('Betting SETUP'!$A$5:$A$16,MATCH(MIN(IF('Betting SETUP'!$D$5:$D$16="Y",U4:U15,10)),IF('Betting SETUP'!$D$5:$D$16="Y",U4:U15,10),0)))} -> Eric O | X16: =18-COUNTBLANK(D16:U16) -> 12
C17: CTP | X17: =COUNTA(D17:U17) -> 0
C19: =SETUP!D1 -> LOCHENHEATH | X19: =SETUP!D2 -> 74.4 | Y19: =SETUP!D3 -> 144
C20: Hole | D20: 1 | E20: 2 | F20: 3 | G20: 4 | H20: 5 | I20: 6 | J20: 7 | K20: 8 | L20: 9 | M20: 10 | N20: 11 | O20: 12 | P20: 13 | Q20: 14 | R20: 15 | S20: 16 | T20: 17 | U20: 18 | V20: OUT | W20: IN | X20: TOTAL | Y20: NET
A21: Player | B21: Handi | C21: Par | D21: 4 | E21: 5 | F21: 3 | G21: 4 | H21: 4 | I21: 4 | J21: 5 | K21: 3 | L21: 4 | M21: 5 | N21: 3 | O21: 4 | P21: 4 | Q21: 4 | R21: 3 | S21: 4 | T21: 4 | U21: 5 | V21: =SUM(D21:L21) -> 36 | W21: =SUM(M21:U21) -> 36 | X21: =V21+W21 -> 72
A22: =SETUP!A5 -> Aaron J | B22: {=if(A22="","",index(SETUP!C:C,match(A22,SETUP!A:A,0)))} -> 13 | D22: 5 | E22: 8 | F22: 4 | G22: 4 | H22: 6 | I22: 4 | J22: 7 | K22: 2 | L22: 5 | M22: 6 | N22: 4 | O22: 4 | P22: 4 | Q22: 6 | R22: 4 | S22: 6 | T22: 7 | U22: 10 | V22: =SUM(D22:L22) -> 45 | W22: =SUM(M22:U22) -> 51 | X22: =IF(W22>0,V22+W22,"") -> 96 | Y22: =IF(W22=0,"",X22-B22) -> 83
A23: =SETUP!A6 -> Bob B | B23: {=if(A23="","",index(SETUP!C:C,match(A23,SETUP!A:A,0)))} -> 17 | D23: 6 | E23: 7 | F23: 5 | G23: 5 | H23: 6 | I23: 5 | J23: 7 | K23: 3 | L23: 6 | M23: 6 | N23: 5 | O23: 5 | P23: 6 | Q23: 5 | R23: 4 | S23: 4 | T23: 5 | U23: 6 | V23: =SUM(D23:L23) -> 50 | W23: =SUM(M23:U23) -> 46 | X23: =IF(W23>0,V23+W23,"") -> 96 | Y23: =IF(W23=0,"",X23-B23) -> 79
A24: =SETUP!A7 -> Brian K | B24: {=if(A24="","",index(SETUP!C:C,match(A24,SETUP!A:A,0)))} -> 17 | D24: 7 | E24: 8 | F24: 5 | G24: 7 | H24: 5 | I24: 4 | J24: 8 | K24: 4 | L24: 5 | M24: 7 | N24: 6 | O24: 4 | P24: 7 | Q24: 6 | R24: 4 | S24: 3 | T24: 5 | U24: 6 | V24: =SUM(D24:L24) -> 53 | W24: =SUM(M24:U24) -> 48 | X24: =IF(W24>0,V24+W24,"") -> 101 | Y24: =IF(W24=0,"",X24-B24) -> 84
A25: =SETUP!A8 -> Eric O | B25: {=if(A25="","",index(SETUP!C:C,match(A25,SETUP!A:A,0)))} -> 19 | D25: 7 | E25: 8 | F25: 4 | G25: 4 | H25: 5 | I25: 5 | J25: 7 | K25: 4 | L25: 8 | M25: 5 | N25: 5 | O25: 7 | P25: 6 | Q25: 6 | R25: 4 | S25: 5 | T25: 8 | U25: 5 | V25: =SUM(D25:L25) -> 52 | W25: =SUM(M25:U25) -> 51 | X25: =IF(W25>0,V25+W25,"") -> 103 | Y25: =IF(W25=0,"",X25-B25) -> 84
A26: =SETUP!A9 -> Matt V | B26: {=if(A26="","",index(SETUP!C:C,match(A26,SETUP!A:A,0)))} -> 16 | D26: 6 | E26: 9 | F26: 7 | G26: 5 | H26: 5 | I26: 6 | J26: 5 | K26: 4 | L26: 6 | M26: 6 | N26: 2 | O26: 4 | P26: 5 | Q26: 5 | R26: 5 | S26: 4 | T26: 8 | U26: 5 | V26: =SUM(D26:L26) -> 53 | W26: =SUM(M26:U26) -> 44 | X26: =IF(W26>0,V26+W26,"") -> 97 | Y26: =IF(W26=0,"",X26-B26) -> 81
A27: =SETUP!A10 -> Scott R | B27: {=if(A27="","",index(SETUP!C:C,match(A27,SETUP!A:A,0)))} -> 10 | D27: 4 | E27: 5 | F27: 4 | G27: 4 | H27: 5 | I27: 5 | J27: 7 | K27: 3 | L27: 6 | M27: 6 | N27: 6 | O27: 3 | P27: 6 | Q27: 5 | R27: 5 | S27: 4 | T27: 5 | U27: 6 | V27: =SUM(D27:L27) -> 43 | W27: =SUM(M27:U27) -> 46 | X27: =IF(W27>0,V27+W27,"") -> 89 | Y27: =IF(W27=0,"",X27-B27) -> 79
A28: =SETUP!A11 -> N/A | B28: {=if(A28="","",index(SETUP!C:C,match(A28,SETUP!A:A,0)))} | V28: =SUM(D28:L28) -> 0 | W28: =SUM(M28:U28) -> 0 | X28: =IF(W28>0,V28+W28,"") | Y28: =IF(W28=0,"",X28-B28)
A29: =SETUP!A12 -> N/A | B29: {=if(A29="","",index(SETUP!C:C,match(A29,SETUP!A:A,0)))} | V29: =SUM(D29:L29) -> 0 | W29: =SUM(M29:U29) -> 0 | X29: =IF(W29>0,V29+W29,"") | Y29: =IF(W29=0,"",X29-B29)
A30: =SETUP!A13 -> N/A | B30: {=if(A30="","",index(SETUP!C:C,match(A30,SETUP!A:A,0)))} | V30: =SUM(D30:L30) -> 0 | W30: =SUM(M30:U30) -> 0 | X30: =IF(W30>0,V30+W30,"") | Y30: =IF(W30=0,"",X30-B30)
A31: =SETUP!A14 -> N/A | B31: {=if(A31="","",index(SETUP!C:C,match(A31,SETUP!A:A,0)))} | V31: =SUM(D31:L31) -> 0 | W31: =SUM(M31:U31) -> 0 | X31: =IF(W31>0,V31+W31,"") | Y31: =IF(W31=0,"",X31-B31)
A32: =SETUP!A15 -> N/A | B32: {=if(A32="","",index(SETUP!C:C,match(A32,SETUP!A:A,0)))} | V32: =SUM(D32:L32) -> 0 | W32: =SUM(M32:U32) -> 0 | X32: =IF(W32>0,V32+W32,"") | Y32: =IF(W32=0,"",X32-B32)
A33: =SETUP!A16 -> N/A | B33: {=if(A33="","",index(SETUP!C:C,match(A33,SETUP!A:A,0)))} | V33: =SUM(D33:L33) -> 0 | W33: =SUM(M33:U33) -> 0 | X33: =IF(W33>0,V33+W33,"") | Y33: =IF(W33=0,"",X33-B33)
C34: SKIN | D34: {=IF(SUM(IF(IF('Betting SETUP'!$D$5:$D$16="Y", D22:D33, 10)=MIN(IF('Betting SETUP'!$D$5:$D$16="Y", D22:D33, 10)), 1, 0)) > 1, "", INDEX('Betting SETUP'!$A$5:$A$16,MATCH(MIN(IF('Betting SETUP'!$D$5:$D$16="Y",D22:D33,10)),IF('Betting SETUP'!$D$5:$D$16="Y",D22:D33,10),0)))} -> Scott R | E34: {=IF(SUM(IF(IF('Betting SETUP'!$D$5:$D$16="Y", E22:E33, 10)=MIN(IF('Betting SETUP'!$D$5:$D$16="Y", E22:E33, 10)), 1, 0)) > 1, "", INDEX('Betting SETUP'!$A$5:$A$16,MATCH(MIN(IF('Betting SETUP'!$D$5:$D$16="Y",E22:E33,10)),IF('Betting SETUP'!$D$5:$D$16="Y",E22:E33,10),0)))} -> Scott R | F34: {=IF(SUM(IF(IF('Betting SETUP'!$D$5:$D$16="Y", F22:F33, 10)=MIN(IF('Betting SETUP'!$D$5:$D$16="Y", F22:F33, 10)), 1, 0)) > 1, "", INDEX('Betting SETUP'!$A$5:$A$16,MATCH(MIN(IF('Betting SETUP'!$D$5:$D$16="Y",F22:F33,10)),IF('Betting SETUP'!$D$5:$D$16="Y",F22:F33,10),0)))} | G34: {=IF(SUM(IF(IF('Betting SETUP'!$D$5:$D$16="Y", G22:G33, 10)=MIN(IF('Betting SETUP'!$D$5:$D$16="Y", G22:G33, 10)), 1, 0)) > 1, "", INDEX('Betting SETUP'!$A$5:$A$16,MATCH(MIN(IF('Betting SETUP'!$D$5:$D$16="Y",G22:G33,10)),IF('Betting SETUP'!$D$5:$D$16="Y",G22:G33,10),0)))} | H34: {=IF(SUM(IF(IF('Betting SETUP'!$D$5:$D$16="Y", H22:H33, 10)=MIN(IF('Betting SETUP'!$D$5:$D$16="Y", H22:H33, 10)), 1, 0)) > 1, "", INDEX('Betting SETUP'!$A$5:$A$16,MATCH(MIN(IF('Betting SETUP'!$D$5:$D$16="Y",H22:H33,10)),IF('Betting SETUP'!$D$5:$D$16="Y",H22:H33,10),0)))} | I34: {=IF(SUM(IF(IF('Betting SETUP'!$D$5:$D$16="Y", I22:I33, 10)=MIN(IF('Betting SETUP'!$D$5:$D$16="Y", I22:I33, 10)), 1, 0)) > 1, "", INDEX('Betting SETUP'!$A$5:$A$16,MATCH(MIN(IF('Betting SETUP'!$D$5:$D$16="Y",I22:I33,10)),IF('Betting SETUP'!$D$5:$D$16="Y",I22:I33,10),0)))} | J34: {=IF(SUM(IF(IF('Betting SETUP'!$D$5:$D$16="Y", J22:J33, 10)=MIN(IF('Betting SETUP'!$D$5:$D$16="Y", J22:J33, 10)), 1, 0)) > 1, "", INDEX('Betting SETUP'!$A$5:$A$16,MATCH(MIN(IF('Betting SETUP'!$D$5:$D$16="Y",J22:J33,10)),IF('Betting SETUP'!$D$5:$D$16="Y",J22:J33,10),0)))} -> Matt V | K34: {=IF(SUM(IF(IF('Betting SETUP'!$D$5:$D$16="Y", K22:K33, 10)=MIN(IF('Betting SETUP'!$D$5:$D$16="Y", K22:K33, 10)), 1, 0)) > 1, "", INDEX('Betting SETUP'!$A$5:$A$16,MATCH(MIN(IF('Betting SETUP'!$D$5:$D$16="Y",K22:K33,10)),IF('Betting SETUP'!$D$5:$D$16="Y",K22:K33,10),0)))} -> Aaron J | ... U34: {=IF(SUM(IF(IF('Betting SETUP'!$D$5:$D$16="Y", U22:U33, 10)=MIN(IF('Betting SETUP'!$D$5:$D$16="Y", U22:U33, 10)), 1, 0)) > 1, "", INDEX('Betting SETUP'!$A$5:$A$16,MATCH(MIN(IF('Betting SETUP'!$D$5:$D$16="Y",U22:U33,10)),IF('Betting SETUP'!$D$5:$D$16="Y",U22:U33,10),0)))} | X34: =18-COUNTBLANK(D34:U34) -> 9
C35: CTP | X35: =COUNTA(D35:U35) -> 0
C37: =SETUP!E1 -> THE LEGEND | X37: =SETUP!E2 -> 71.4 | Y37: =SETUP!E3 -> 130
C38: Hole | D38: 1 | E38: 2 | F38: 3 | G38: 4 | H38: 5 | I38: 6 | J38: 7 | K38: 8 | L38: 9 | M38: 10 | N38: 11 | O38: 12 | P38: 13 | Q38: 14 | R38: 15 | S38: 16 | T38: 17 | U38: 18 | V38: OUT | W38: IN | X38: TOTAL | Y38: NET
A39: Player | B39: Handi | C39: Par | D39: 5 | E39: 4 | F39: 4 | G39: 3 | H39: 4 | I39: 4 | J39: 5 | K39: 4 | L39: 3 | M39: 4 | N39: 4 | O39: 3 | P39: 5 | Q39: 4 | R39: 3 | S39: 4 | T39: 4 | U39: 5 | V39: =SUM(D39:L39) -> 36 | W39: =SUM(M39:U39) -> 36 | X39: =V39+W39 -> 72
A40: =SETUP!A5 -> Aaron J | B40: {=if(A40="","",index(SETUP!C:C,match(A40,SETUP!A:A,0)))} -> 13 | D40: 4 | E40: 4 | F40: 5 | G40: 3 | H40: 9 | I40: 5 | J40: 5 | K40: 5 | L40: 3 | M40: 7 | N40: 5 | O40: 3 | P40: 6 | Q40: 4 | R40: 6 | S40: 5 | T40: 5 | U40: 5 | V40: =SUM(D40:L40) -> 43 | W40: =SUM(M40:U40) -> 46 | X40: =IF(W40>0,V40+W40,"") -> 89 | Y40: =IF(W40=0,"",X40-B40) -> 76
A41: =SETUP!A6 -> Bob B | B41: {=if(A41="","",index(SETUP!C:C,match(A41,SETUP!A:A,0)))} -> 17 | D41: 7 | E41: 6 | F41: 5 | G41: 4 | H41: 5 | I41: 6 | J41: 9 | K41: 8 | L41: 3 | M41: 4 | N41: 6 | O41: 3 | P41: 7 | Q41: 5 | R41: 3 | S41: 6 | T41: 6 | U41: 7 | V41: =SUM(D41:L41) -> 53 | W41: =SUM(M41:U41) -> 47 | X41: =IF(W41>0,V41+W41,"") -> 100 | Y41: =IF(W41=0,"",X41-B41) -> 83
A42: =SETUP!A7 -> Brian K | B42: {=if(A42="","",index(SETUP!C:C,match(A42,SETUP!A:A,0)))} -> 17 | D42: 6 | E42: 5 | F42: 5 | G42: 4 | H42: 4 | I42: 7 | J42: 7 | K42: 5 | L42: 3 | M42: 5 | N42: 5 | O42: 4 | P42: 7 | Q42: 4 | R42: 5 | S42: 5 | T42: 6 | U42: 7 | V42: =SUM(D42:L42) -> 46 | W42: =SUM(M42:U42) -> 48 | X42: =IF(W42>0,V42+W42,"") -> 94 | Y42: =IF(W42=0,"",X42-B42) -> 77
...

Sheet BettingScoreboard
A1: Low Net Per Round | B1: =SETUP!C1 -> BLACK FOREST | C1: =SETUP!D1 -> LOCHENHEATH | D1: =SETUP!E1 -> THE LEGEND | E1: =SETUP!F1 -> FOREST DUNES | G1: Player | H1: Skins | I1: Skin $ | K1: Player | L1: CTP | M1: CTP $
A2: =SETUP!$A5 -> Aaron J | B2: {=IF(index('Betting SETUP'!$C:$C,match($A2,'Betting SETUP'!$A:$A,0))="Y",(index('Score Calcuations'!E:E,match($A2,'Score Calcuations'!A:A))), "out")} -> 82 | C2: {=IF(index('Betting SETUP'!$C:$C,match($A2,'Betting SETUP'!$A:$A,0))="Y",(index('Score Calcuations'!G:G,match($A2,'Score Calcuations'!A:A))), "out")} -> 83 | D2: {=IF(index('Betting SETUP'!$C:$C,match($A2,'Betting SETUP'!$A:$A,0))="Y",(index('Score Calcuations'!I:I,match($A2,'Score Calcuations'!A:A))), "out")} -> 76 | E2: {=IF(index('Betting SETUP'!$C:$C,match($A2,'Betting SETUP'!$A:$A,0))="Y",(index('Score Calcuations'!K:K,match($A2,'Score Calcuations'!A:A))), "out")} -> 81 | G2: =SETUP!$A5 -> Aaron J | H2: =SUM(COUNTIF(Scorecards!$D$16:$U$16,BettingScoreboard!$G2),COUNTIF(Scorecards!$D$34:$U$34,BettingScoreboard!$G2),COUNTIF(Scorecards!$D$52:$U$52,BettingScoreboard!$G2),COUNTIF(Scorecards!$D$70:$U$70,BettingScoreboard!$G2)) -> 11 | I2: =H2*'Betting SETUP'!$D$3/(sum($H$2:$H$13)) -> 4.4132407 | K2: =SETUP!$A5 -> Aaron J | L2: =SUM(COUNTIF(Scorecards!$D$17:$U$17,BettingScoreboard!$K2),COUNTIF(Scorecards!$D$35:$U$35,BettingScoreboard!$K2),COUNTIF(Scorecards!$D$53:$U$53,BettingScoreboard!$K2),COUNTIF(Scorecards!$D$71:$U$71,BettingScoreboard!$K2)) -> 0 | M2: =L2*'Betting SETUP'!$E$3 -> 0
A3: =SETUP!$A6 -> Bob B | B3: {=IF(index('Betting SETUP'!$C:$C,match($A3,'Betting SETUP'!$A:$A,0))="Y",(index('Score Calcuations'!E:E,match($A3,'Score Calcuations'!A:A))), "out")} -> 88 | C3: {=IF(index('Betting SETUP'!$C:$C,match($A3,'Betting SETUP'!$A:$A,0))="Y",(index('Score Calcuations'!G:G,match($A3,'Score Calcuations'!A:A))), "out")} -> 79 | D3: {=IF(index('Betting SETUP'!$C:$C,match($A3,'Betting SETUP'!$A:$A,0))="Y",(index('Score Calcuations'!I:I,match($A3,'Score Calcuations'!A:A))), "out")} -> 83 | E3: {=IF(index('Betting SETUP'!$C:$C,match($A3,'Betting SETUP'!$A:$A,0))="Y",(index('Score Calcuations'!K:K,match($A3,'Score Calcuations'!A:A))), "out")} -> 78 | G3: =SETUP!$A6 -> Bob B | H3: =SUM(COUNTIF(Scorecards!$D$16:$U$16,BettingScoreboard!$G3),COUNTIF(Scorecards!$D$34:$U$34,BettingScoreboard!$G3),COUNTIF(Scorecards!$D$52:$U$52,BettingScoreboard!$G3),COUNTIF(Scorecards!$D$70:$U$70,BettingScoreboard!$G3)) -> 3 | I3: =H3*'Betting SETUP'!$D$3/(sum($H$2:$H$13)) -> 1.2036111 | K3: =SETUP!$A6 -> Bob B | L3: =SUM(COUNTIF(Scorecards!$D$17:$U$17,BettingScoreboard!$K3),COUNTIF(Scorecards!$D$35:$U$35,BettingScoreboard!$K3),COUNTIF(Scorecards!$D$53:$U$53,BettingScoreboard!$K3),COUNTIF(Scorecards!$D$71:$U$71,BettingScoreboard!$K3)) -> 0 | M3: =L3*'Betting SETUP'!$E$3 -> 0
A4: =SETUP!$A7 -> Brian K | B4: {=IF(index('Betting SETUP'!$C:$C,match($A4,'Betting SETUP'!$A:$A,0))="Y",(index('Score Calcuations'!E:E,match($A4,'Score Calcuations'!A:A))), "out")} -> 84 | C4: {=IF(index('Betting SETUP'!$C:$C,match($A4,'Betting SETUP'!$A:$A,0))="Y",(index('Score Calcuations'!G:G,match($A4,'Score Calcuations'!A:A))), "out")} -> 84 | D4: {=IF(index('Betting SETUP'!$C:$C,match($A4,'Betting SETUP'!$A:$A,0))="Y",(index('Score Calcuations'!I:I,match($A4,'Score Calcuations'!A:A))), "out")} -> 77 | E4: {=IF(index('Betting SETUP'!$C:$C,match($A4,'Betting SETUP'!$A:$A,0))="Y",(index('Score Calcuations'!K:K,match($A4,'Score Calcuations'!A:A))), "out")} -> 81 | G4: =SETUP!$A7 -> Brian K | H4: =SUM(COUNTIF(Scorecards!$D$16:$U$16,BettingScoreboard!$G4),COUNTIF(Scorecards!$D$34:$U$34,BettingScoreboard!$G4),COUNTIF(Scorecards!$D$52:$U$52,BettingScoreboard!$G4),COUNTIF(Scorecards!$D$70:$U$70,BettingScoreboard!$G4)) -> 4 | I4: =H4*'Betting SETUP'!$D$3/(sum($H$2:$H$13)) -> 1.6048148 | K4: =SETUP!$A7 -> Brian K | L4: =SUM(COUNTIF(Scorecards!$D$17:$U$17,BettingScoreboard!$K4),COUNTIF(Scorecards!$D$35:$U$35,BettingScoreboard!$K4),COUNTIF(Scorecards!$D$53:$U$53,BettingScoreboard!$K4),COUNTIF(Scorecards!$D$71:$U$71,BettingScoreboard!$K4)) -> 0 | M4: =L4*'Betting SETUP'!$E$3 -> 0
A5: =SETUP!$A8 -> Eric O | B5: {=IF(index('Betting SETUP'!$C:$C,match($A5,'Betting SETUP'!$A:$A,0))="Y",(index('Score Calcuations'!E:E,match($A5,'Score Calcuations'!A:A))), "out")} -> 91 | C5: {=IF(index('Betting SETUP'!$C:$C,match($A5,'Betting SETUP'!$A:$A,0))="Y",(index('Score Calcuations'!G:G,match($A5,'Score Calcuations'!A:A))), "out")} -> 84 | D5: {=IF(index('Betting SETUP'!$C:$C,match($A5,'Betting SETUP'!$A:$A,0))="Y",(index('Score Calcuations'!I:I,match($A5,'Score Calcuations'!A:A))), "out")} -> 73 | E5: {=IF(index('Betting SETUP'!$C:$C,match($A5,'Betting SETUP'!$A:$A,0))="Y",(index('Score Calcuations'!K:K,match($A5,'Score Calcuations'!A:A))), "out")} -> 76 | G5: =SETUP!$A8 -> Eric O | H5: =SUM(COUNTIF(Scorecards!$D$16:$U$16,BettingScoreboard!$G5),COUNTIF(Scorecards!$D$34:$U$34,BettingScoreboard!$G5),COUNTIF(Scorecards!$D$52:$U$52,BettingScoreboard!$G5),COUNTIF(Scorecards!$D$70:$U$70,BettingScoreboard!$G5)) -> 5 | I5: =H5*'Betting SETUP'!$D$3/(sum($H$2:$H$13)) -> 2.0060185 | K5: =SETUP!$A8 -> Eric O | L5: =SUM(COUNTIF(Scorecards!$D$17:$U$17,BettingScoreboard!$K5),COUNTIF(Scorecards!$D$35:$U$35,BettingScoreboard!$K5),COUNTIF(Scorecards!$D$53:$U$53,BettingScoreboard!$K5),COUNTIF(Scorecards!$D$71:$U$71,BettingScoreboard!$K5)) -> 0 | M5: =L5*'Betting SETUP'!$E$3 -> 0
A6: =SETUP!$A9 -> Matt V | B6: {=IF(index('Betting SETUP'!$C:$C,match($A6,'Betting SETUP'!$A:$A,0))="Y",(index('Score Calcuations'!E:E,match($A6,'Score Calcuations'!A:A))), "out")} -> 87 | C6: {=IF(index('Betting SETUP'!$C:$C,match($A6,'Betting SETUP'!$A:$A,0))="Y",(index('Score Calcuations'!G:G,match($A6,'Score Calcuations'!A:A))), "out")} -> 81 | D6: {=IF(index('Betting SETUP'!$C:$C,match($A6,'Betting SETUP'!$A:$A,0))="Y",(index('Score Calcuations'!I:I,match($A6,'Score Calcuations'!A:A))), "out")} -> 81 | E6: {=IF(index('Betting SETUP'!$C:$C,match($A6,'Betting SETUP'!$A:$A,0))="Y",(index('Score Calcuations'!K:K,match($A6,'Score Calcuations'!A:A))), "out")} -> 80 | G6: =SETUP!$A9 -> Matt V | H6: =SUM(COUNTIF(Scorecards!$D$16:$U$16,BettingScoreboard!$G6),COUNTIF(Scorecards!$D$34:$U$34,BettingScoreboard!$G6),COUNTIF(Scorecards!$D$52:$U$52,BettingScoreboard!$G6),COUNTIF(Scorecards!$D$70:$U$70,BettingScoreboard!$G6)) -> 5 | I6: =H6*'Betting SETUP'!$D$3/(sum($H$2:$H$13)) -> 2.0060185 | K6: =SETUP!$A9 -> Matt V | L6: =SUM(COUNTIF(Scorecards!$D$17:$U$17,BettingScoreboard!$K6),COUNTIF(Scorecards!$D$35:$U$35,BettingScoreboard!$K6),COUNTIF(Scorecards!$D$53:$U$53,BettingScoreboard!$K6),COUNTIF(Scorecards!$D$71:$U$71,BettingScoreboard!$K6)) -> 0 | M6: =L6*'Betting SETUP'!$E$3 -> 0
A7: =SETUP!$A10 -> Scott R | B7: {=IF(index('Betting SETUP'!$C:$C,match($A7,'Betting SETUP'!$A:$A,0))="Y",(index('Score Calcuations'!E:E,match($A7,'Score Calcuations'!A:A))), "out")} | C7: {=IF(index('Betting SETUP'!$C:$C,match($A7,'Betting SETUP'!$A:$A,0))="Y",(index('Score Calcuations'!G:G,match($A7,'Score Calcuations'!A:A))), "out")} | D7: {=IF(index('Betting SETUP'!$C:$C,match($A7,'Betting SETUP'!$A:$A,0))="Y",(index('Score Calcuations'!I:I,match($A7,'Score Calcuations'!A:A))), "out")} | E7: {=IF(index('Betting SETUP'!$C:$C,match($A7,'Betting SETUP'!$A:$A,0))="Y",(index('Score Calcuations'!K:K,match($A7,'Score Calcuations'!A:A))), "out")} | G7: =SETUP!$A10 -> Scott R | H7: =SUM(COUNTIF(Scorecards!$D$16:$U$16,BettingScoreboard!$G7),COUNTIF(Scorecards!$D$34:$U$34,BettingScoreboard!$G7),COUNTIF(Scorecards!$D$52:$U$52,BettingScoreboard!$G7),COUNTIF(Scorecards!$D$70:$U$70,BettingScoreboard!$G7)) -> 8 | I7: =H7*'Betting SETUP'!$D$3/(sum($H$2:$H$13)) -> 3.2096296 | K7: =SETUP!$A10 -> Scott R | L7: =SUM(COUNTIF(Scorecards!$D$17:$U$17,BettingScoreboard!$K7),COUNTIF(Scorecards!$D$35:$U$35,BettingScoreboard!$K7),COUNTIF(Scorecards!$D$53:$U$53,BettingScoreboard!$K7),COUNTIF(Scorecards!$D$71:$U$71,BettingScoreboard!$K7)) -> 0 | M7: =L7*'Betting SETUP'!$E$3 -> 0
A8: =SETUP!$A11 -> N/A | B8: {=IF(index('Betting SETUP'!$C:$C,match($A8,'Betting SETUP'!$A:$A,0))="Y",(index('Score Calcuations'!E:E,match($A8,'Score Calcuations'!A:A))), "out")} -> 87 | C8: {=IF(index('Betting SETUP'!$C:$C,match($A8,'Betting SETUP'!$A:$A,0))="Y",(index('Score Calcuations'!G:G,match($A8,'Score Calcuations'!A:A))), "out")} -> 81 | D8: {=IF(index('Betting SETUP'!$C:$C,match($A8,'Betting SETUP'!$A:$A,0))="Y",(index('Score Calcuations'!I:I,match($A8,'Score Calcuations'!A:A))), "out")} -> 81 | E8: {=IF(index('Betting SETUP'!$C:$C,match($A8,'Betting SETUP'!$A:$A,0))="Y",(index('Score Calcuations'!K:K,match($A8,'Score Calcuations'!A:A))), "out")} -> 80 | G8: =SETUP!$A11 -> N/A | H8: =SUM(COUNTIF(Scorecards!$D$16:$U$16,BettingScoreboard!$G8),COUNTIF(Scorecards!$D$34:$U$34,BettingScoreboard!$G8),COUNTIF(Scorecards!$D$52:$U$52,BettingScoreboard!$G8),COUNTIF(Scorecards!$D$70:$U$70,BettingScoreboard!$G8)) -> 0 | I8: =H8*'Betting SETUP'!$D$3/(sum($H$2:$H$13)) -> 0 | K8: =SETUP!$A11 -> N/A | L8: =SUM(COUNTIF(Scorecards!$D$17:$U$17,BettingScoreboard!$K8),COUNTIF(Scorecards!$D$35:$U$35,BettingScoreboard!$K8),COUNTIF(Scorecards!$D$53:$U$53,BettingScoreboard!$K8),COUNTIF(Scorecards!$D$71:$U$71,BettingScoreboard!$K8)) -> 0 | M8: =L8*'Betting SETUP'!$E$3 -> 0
A9: =SETUP!$A12 -> N/A | B9: {=IF(index('Betting SETUP'!$C:$C,match($A9,'Betting SETUP'!$A:$A,0))="Y",(index('Score Calcuations'!E:E,match($A9,'Score Calcuations'!A:A))), "out")} -> 87 | C9: {=IF(index('Betting SETUP'!$C:$C,match($A9,'Betting SETUP'!$A:$A,0))="Y",(index('Score Calcuations'!G:G,match($A9,'Score Calcuations'!A:A))), "out")} -> 81 | D9: {=IF(index('Betting SETUP'!$C:$C,match($A9,'Betting SETUP'!$A:$A,0))="Y",(index('Score Calcuations'!I:I,match($A9,'Score Calcuations'!A:A))), "out")} -> 81 | E9: {=IF(index('Betting SETUP'!$C:$C,match($A9,'Betting SETUP'!$A:$A,0))="Y",(index('Score Calcuations'!K:K,match($A9,'Score Calcuations'!A:A))), "out")} -> 80 | G9: =SETUP!$A12 -> N/A | H9: =SUM(COUNTIF(Scorecards!$D$16:$U$16,BettingScoreboard!$G9),COUNTIF(Scorecards!$D$34:$U$34,BettingScoreboard!$G9),COUNTIF(Scorecards!$D$52:$U$52,BettingScoreboard!$G9),COUNTIF(Scorecards!$D$70:$U$70,BettingScoreboard!$G9)) -> 0 | I9: =H9*'Betting SETUP'!$D$3/(sum($H$2:$H$13)) -> 0 | K9: =SETUP!$A12 -> N/A | L9: =SUM(COUNTIF(Scorecards!$D$17:$U$17,BettingScoreboard!$K9),COUNTIF(Scorecards!$D$35:$U$35,BettingScoreboard!$K9),COUNTIF(Scorecards!$D$53:$U$53,BettingScoreboard!$K9),COUNTIF(Scorecards!$D$71:$U$71,BettingScoreboard!$K9)) -> 0 | M9: =L9*'Betting SETUP'!$E$3 -> 0
A10: =SETUP!$A13 -> N/A | B10: {=IF(index('Betting SETUP'!$C:$C,match($A10,'Betting SETUP'!$A:$A,0))="Y",(index('Score Calcuations'!E:E,match($A10,'Score Calcuations'!A:A))), "out")} -> 87 | C10: {=IF(index('Betting SETUP'!$C:$C,match($A10,'Betting SETUP'!$A:$A,0))="Y",(index('Score Calcuations'!G:G,match($A10,'Score Calcuations'!A:A))), "out")} -> 81 | D10: {=IF(index('Betting SETUP'!$C:$C,match($A10,'Betting SETUP'!$A:$A,0))="Y",(index('Score Calcuations'!I:I,match($A10,'Score Calcuations'!A:A))), "out")} -> 81 | E10: {=IF(index('Betting SETUP'!$C:$C,match($A10,'Betting SETUP'!$A:$A,0))="Y",(index('Score Calcuations'!K:K,match($A10,'Score Calcuations'!A:A))), "out")} -> 80 | G10: =SETUP!$A13 -> N/A | H10: =SUM(COUNTIF(Scorecards!$D$16:$U$16,BettingScoreboard!$G10),COUNTIF(Scorecards!$D$34:$U$34,BettingScoreboard!$G10),COUNTIF(Scorecards!$D$52:$U$52,BettingScoreboard!$G10),COUNTIF(Scorecards!$D$70:$U$70,BettingScoreboard!$G10)) -> 0 | I10: =H10*'Betting SETUP'!$D$3/(sum($H$2:$H$13)) -> 0 | K10: =SETUP!$A13 -> N/A | L10: =SUM(COUNTIF(Scorecards!$D$17:$U$17,BettingScoreboard!$K10),COUNTIF(Scorecards!$D$35:$U$35,BettingScoreboard!$K10),COUNTIF(Scorecards!$D$53:$U$53,BettingScoreboard!$K10),COUNTIF(Scorecards!$D$71:$U$71,BettingScoreboard!$K10)) -> 0 | M10: =L10*'Betting SETUP'!$E$3 -> 0
A11: =SETUP!$A14 -> N/A | B11: {=IF(index('Betting SETUP'!$C:$C,match($A11,'Betting SETUP'!$A:$A,0))="Y",(index('Score Calcuations'!E:E,match($A11,'Score Calcuations'!A:A))), "out")} -> 87 | C11: {=IF(index('Betting SETUP'!$C:$C,match($A11,'Betting SETUP'!$A:$A,0))="Y",(index('Score Calcuations'!G:G,match($A11,'Score Calcuations'!A:A))), "out")} -> 81 | D11: {=IF(index('Betting SETUP'!$C:$C,match($A11,'Betting SETUP'!$A:$A,0))="Y",(index('Score Calcuations'!I:I,match($A11,'Score Calcuations'!A:A))), "out")} -> 81 | E11: {=IF(index('Betting SETUP'!$C:$C,match($A11,'Betting SETUP'!$A:$A,0))="Y",(index('Score Calcuations'!K:K,match($A11,'Score Calcuations'!A:A))), "out")} -> 80 | G11: =SETUP!$A14 -> N/A | H11: =SUM(COUNTIF(Scorecards!$D$16:$U$16,BettingScoreboard!$G11),COUNTIF(Scorecards!$D$34:$U$34,BettingScoreboard!$G11),COUNTIF(Scorecards!$D$52:$U$52,BettingScoreboard!$G11),COUNTIF(Scorecards!$D$70:$U$70,BettingScoreboard!$G11)) -> 0 | I11: =H11*'Betting SETUP'!$D$3/(sum($H$2:$H$13)) -> 0 | K11: =SETUP!$A14 -> N/A | L11: =SUM(COUNTIF(Scorecards!$D$17:$U$17,BettingScoreboard!$K11),COUNTIF(Scorecards!$D$35:$U$35,BettingScoreboard!$K11),COUNTIF(Scorecards!$D$53:$U$53,BettingScoreboard!$K11),COUNTIF(Scorecards!$D$71:$U$71,BettingScoreboard!$K11)) -> 0 | M11: =L11*'Betting SETUP'!$E$3 -> 0
A12: =SETUP!$A15 -> N/A | B12: {=IF(index('Betting SETUP'!$C:$C,match($A12,'Betting SETUP'!$A:$A,0))="Y",(index('Score Calcuations'!E:E,match($A12,'Score Calcuations'!A:A))), "out")} -> 87 | C12: {=IF(index('Betting SETUP'!$C:$C,match($A12,'Betting SETUP'!$A:$A,0))="Y",(index('Score Calcuations'!G:G,match($A12,'Score Calcuations'!A:A))), "out")} -> 81 | D12: {=IF(index('Betting SETUP'!$C:$C,match($A12,'Betting SETUP'!$A:$A,0))="Y",(index('Score Calcuations'!I:I,match($A12,'Score Calcuations'!A:A))), "out")} -> 81 | E12: {=IF(index('Betting SETUP'!$C:$C,match($A12,'Betting SETUP'!$A:$A,0))="Y",(index('Score Calcuations'!K:K,match($A12,'Score Calcuations'!A:A))), "out")} -> 80 | G12: =SETUP!$A15 -> N/A | H12: =SUM(COUNTIF(Scorecards!$D$16:$U$16,BettingScoreboard!$G12),COUNTIF(Scorecards!$D$34:$U$34,BettingScoreboard!$G12),COUNTIF(Scorecards!$D$52:$U$52,BettingScoreboard!$G12),COUNTIF(Scorecards!$D$70:$U$70,BettingScoreboard!$G12)) -> 0 | I12: =H12*'Betting SETUP'!$D$3/(sum($H$2:$H$13)) -> 0 | K12: =SETUP!$A15 -> N/A | L12: =SUM(COUNTIF(Scorecards!$D$17:$U$17,BettingScoreboard!$K12),COUNTIF(Scorecards!$D$35:$U$35,BettingScoreboard!$K12),COUNTIF(Scorecards!$D$53:$U$53,BettingScoreboard!$K12),COUNTIF(Scorecards!$D$71:$U$71,BettingScoreboard!$K12)) -> 0 | M12: =L12*'Betting SETUP'!$E$3 -> 0
A13: =SETUP!$A16 -> N/A | B13: {=IF(index('Betting SETUP'!$C:$C,match($A13,'Betting SETUP'!$A:$A,0))="Y",(index('Score Calcuations'!E:E,match($A13,'Score Calcuations'!A:A))), "out")} -> 87 | C13: {=IF(index('Betting SETUP'!$C:$C,match($A13,'Betting SETUP'!$A:$A,0))="Y",(index('Score Calcuations'!G:G,match($A13,'Score Calcuations'!A:A))), "out")} -> 81 | D13: {=IF(index('Betting SETUP'!$C:$C,match($A13,'Betting SETUP'!$A:$A,0))="Y",(index('Score Calcuations'!I:I,match($A13,'Score Calcuations'!A:A))), "out")} -> 81 | E13: {=IF(index('Betting SETUP'!$C:$C,match($A13,'Betting SETUP'!$A:$A,0))="Y",(index('Score Calcuations'!K:K,match($A13,'Score Calcuations'!A:A))), "out")} -> 80 | G13: =SETUP!$A16 -> N/A | H13: =SUM(COUNTIF(Scorecards!$D$16:$U$16,BettingScoreboard!$G13),COUNTIF(Scorecards!$D$34:$U$34,BettingScoreboard!$G13),COUNTIF(Scorecards!$D$52:$U$52,BettingScoreboard!$G13),COUNTIF(Scorecards!$D$70:$U$70,BettingScoreboard!$G13)) -> 0 | I13: =H13*'Betting SETUP'!$D$3/(sum($H$2:$H$13)) -> 0 | K13: =SETUP!$A16 -> N/A | L13: =SUM(COUNTIF(Scorecards!$D$17:$U$17,BettingScoreboard!$K13),COUNTIF(Scorecards!$D$35:$U$35,BettingScoreboard!$K13),COUNTIF(Scorecards!$D$53:$U$53,BettingScoreboard!$K13),COUNTIF(Scorecards!$D$71:$U$71,BettingScoreboard!$K13)) -> 0 | M13: =L13*'Betting SETUP'!$E$3 -> 0
A14: # of Winners | B14: =COUNTIF(BettingScoreboard!$B$2:$B$13,MIN(BettingScoreboard!$B$2:$B$13)) -> 1 | C14: =COUNTIF(BettingScoreboard!$C$2:$C$13,MIN(BettingScoreboard!$C$2:$C$13)) -> 1 | D14: =COUNTIF(BettingScoreboard!$D$2:$D$13,MIN(BettingScoreboard!$D$2:$D$13)) -> 1 | E14: =COUNTIF(BettingScoreboard!$E$2:$E$13,MIN(BettingScoreboard!$E$2:$E$13)) -> 1 | G14: Total | H14: =sum(H2:H13) -> 36 | K14: Total | L14: =sum(L2:L13) -> 0
A15: Payout | B15: ='Betting SETUP'!$C$3/B14 -> 20.01 | C15: ='Betting SETUP'!$C$3/C14 -> 20.01 | D15: ='Betting SETUP'!$C$3/D14 -> 20.01 | E15: ='Betting SETUP'!$C$3/E14 -> 20.01 | G15: Each Skin | H15: ='Betting SETUP'!$D$3/sum(Scorecards!X16,Scorecards!X34,Scorecards!X52,Scorecards!X70) -> 0.4012037 | K15: Each CTP | L15: ='Betting SETUP'!E3 -> 15

Sheet Stock Market
B1: 1 | C1: Shares | N1: =sum(N3:N14) -> 240
B2: {=transpose(A3:A14)} -> Aaron J | C2: Bob B | D2: Brian K | E2: Eric O | F2: Matt V | G2: Scott R | H2: N/A | I2: N/A | J2: N/A | K2: N/A | L2: N/A | M2: N/A | N2: TOTAL | P2: FINAL | Q2: PAYOUT | R2: 420 | S2: =R2/25 -> 16.8
A3: =SETUP!A5 -> Aaron J | B3: 5 | C3: 3 | D3: 4 | G3: 1 | I3: 3 | L3: 2 | M3: 2 | N3: =sum(B3:M3)*$B$1 -> 20 | P3: =SETUP!A5 -> Aaron J | Q3: =if($Q$31="TBD","TBD",if($Q$31=0,((R19/$R$31)*($N$1+$N$17)),if($R$31=0,((Q19/$Q$31)*($N$1+$N$17)),($Q$19*$Q$18)+(R19*$R$18)))) -> 75 | R3: 5 | S3: =R3*$S$2 -> 84
A4: =SETUP!A6 -> Bob B | C4: 5 | D4: 5 | G4: 5 | J4: 5 | N4: =sum(B4:M4)*$B$1 -> 20 | P4: =SETUP!A6 -> Bob B | Q4: =if($Q$31="TBD","TBD",if($Q$31=0,((R20/$R$31)*($N$1+$N$17)),if($R$31=0,((Q20/$Q$31)*($N$1+$N$17)),($Q$19*$Q$18)+(R20*$R$18)))) -> 75 | R4: 0 | S4: =R4*$S$2 -> 0
A5: =SETUP!A7 -> Brian K | B5: 2 | C5: 2 | D5: 6 | G5: 2 | H5: 2 | I5: 2 | J5: 2 | M5: 2 | N5: =sum(B5:M5)*$B$1 -> 20 | P5: =SETUP!A7 -> Brian K | Q5: =if($Q$31="TBD","TBD",if($Q$31=0,((R21/$R$31)*($N$1+$N$17)),if($R$31=0,((Q21/$Q$31)*($N$1+$N$17)),($Q$19*$Q$18)+(R21*$R$18)))) -> 115 | R5: 4 | S5: =R5*$S$2 -> 67.2
A6: =SETUP!A8 -> Eric O | B6: 5 | C6: 2 | E6: 5 | H6: 2 | I6: 2 | L6: 2 | M6: 2 | N6: =sum(B6:M6)*$B$1 -> 20 | P6: =SETUP!A8 -> Eric O | Q6: =if($Q$31="TBD","TBD",if($Q$31=0,((R22/$R$31)*($N$1+$N$17)),if($R$31=0,((Q22/$Q$31)*($N$1+$N$17)),($Q$19*$Q$18)+(R22*$R$18)))) -> 75 | R6: 5 | S6: =R6*$S$2 -> 84
A7: =SETUP!A9 -> Matt V | B7: 2 | D7: 1 | F7: 10 | I7: 5 | M7: 2 | N7: =sum(B7:M7)*$B$1 -> 20 | P7: =SETUP!A9 -> Matt V | Q7: =if($Q$31="TBD","TBD",if($Q$31=0,((R23/$R$31)*($N$1+$N$17)),if($R$31=0,((Q23/$Q$31)*($N$1+$N$17)),($Q$19*$Q$18)+(R23*$R$18)))) -> 75 | R7: 2 | S7: =R7*$S$2 -> 33.6
A8: =SETUP!A10 -> Scott R | D8: 4 | G8: 6 | H8: 4 | J8: 3 | K8: 3 | N8: =sum(B8:M8)*$B$1 -> 20 | P8: =SETUP!A10 -> Scott R | Q8: =if($Q$31="TBD","TBD",if($Q$31=0,((R24/$R$31)*($N$1+$N$17)),if($R$31=0,((Q24/$Q$31)*($N$1+$N$17)),($Q$19*$Q$18)+(R24*$R$18)))) -> 75 | R8: 0 | S8: =R8*$S$2 -> 0
A9: =SETUP!A11 -> N/A | C9: 1 | F9: 2 | H9: 15 | I9: 1 | K9: 1 | N9: =sum(B9:M9)*$B$1 -> 20 | P9: =SETUP!A11 -> N/A | Q9: =if($Q$31="TBD","TBD",if($Q$31=0,((R25/$R$31)*($N$1+$N$17)),if($R$31=0,((Q25/$Q$31)*($N$1+$N$17)),($Q$19*$Q$18)+(R25*$R$18)))) -> 135 | R9: 3 | S9: =R9*$S$2 -> 50.4
A10: =SETUP!A12 -> N/A | B10: 2 | C10: 2 | D10: 3 | E10: 2 | G10: 3 | H10: 5 | I10: 1 | L10: 2 | N10: =sum(B10:M10)*$B$1 -> 20 | P10: =SETUP!A12 -> N/A | Q10: =if($Q$31="TBD","TBD",if($Q$31=0,((R26/$R$31)*($N$1+$N$17)),if($R$31=0,((Q26/$Q$31)*($N$1+$N$17)),($Q$19*$Q$18)+(R26*$R$18)))) -> 135 | R10: 2 | S10: =R10*$S$2 -> 33.6
A11: =SETUP!A13 -> N/A | J11: 20 | N11: =sum(B11:M11)*$B$1 -> 20 | P11: =SETUP!A13 -> N/A | Q11: =if($Q$31="TBD","TBD",if($Q$31=0,((R27/$R$31)*($N$1+$N$17)),if($R$31=0,((Q27/$Q$31)*($N$1+$N$17)),($Q$19*$Q$18)+(R27*$R$18)))) -> 135 | R11: 0 | S11: =R11*$S$2 -> 0
A12: =SETUP!A14 -> N/A | E12: 5 | G12: 5 | H12: 5 | K12: 5 | N12: =sum(B12:M12)*$B$1 -> 20 | P12: =SETUP!A14 -> N/A | Q12: =if($Q$31="TBD","TBD",if($Q$31=0,((R28/$R$31)*($N$1+$N$17)),if($R$31=0,((Q28/$Q$31)*($N$1+$N$17)),($Q$19*$Q$18)+(R28*$R$18)))) -> 135 | R12: 0 | S12: =R12*$S$2 -> 0
A13: =SETUP!A15 -> N/A | L13: 20 | N13: =sum(B13:M13)*$B$1 -> 20 | P13: =SETUP!A15 -> N/A | Q13: =if($Q$31="TBD","TBD",if($Q$31=0,((R29/$R$31)*($N$1+$N$17)),if($R$31=0,((Q29/$Q$31)*($N$1+$N$17)),($Q$19*$Q$18)+(R29*$R$18)))) -> 135 | R13: 0 | S13: =R13*$S$2 -> 0
A14: =SETUP!A16 -> N/A | M14: 20 | N14: =sum(B14:M14)*$B$1 -> 20 | P14: =SETUP!A16 -> N/A | Q14: =if($Q$31="TBD","TBD",if($Q$31=0,((R30/$R$31)*($N$1+$N$17)),if($R$31=0,((Q30/$Q$31)*($N$1+$N$17)),($Q$19*$Q$18)+(R30*$R$18)))) -> 135 | R14: 4 | S14: =R14*$S$2 -> 67.2
B15: =SUM(B3:B14) -> 16 | C15: =SUM(C3:C14) -> 15 | D15: =SUM(D3:D14) -> 23 | E15: =SUM(E3:E14) -> 12 | F15: =SUM(F3:F14) -> 12 | G15: =SUM(G3:G14) -> 22 | H15: =SUM(H3:H14) -> 33 | I15: =SUM(I3:I14) -> 14 | ... M15: =SUM(M3:M14) -> 28 | N15: =sum(B15:M15) -> 240
B17: 2 | C17: Shares | N17: =sum(N19:N30) -> 180 | P17: WBC Winner | Q17: initial | R17: rebuy
B18: {=transpose(A19:A30)} -> Aaron J | C18: Bob B | D18: Brian K | E18: Eric O | F18: Matt V | G18: Scott R | H18: N/A | I18: N/A | J18: N/A | K18: N/A | L18: N/A | M18: N/A | N18: TOTAL | P18: Aaron J | Q18: =if(P18="","TBD",if(Q31=0,0,N1/Q31)) -> 15 | R18: =if(R31="TBD","TBD",if($R$31=0,0,(N17/R31))) -> 20
A19: =SETUP!A5 -> Aaron J | C19: 3 | D19: 2 | J19: 5 | N19: =sum(B19:M19)*$B$17 -> 20 | P19: =SETUP!A5 -> Aaron J | Q19: =if($P$18="","",if($P$18=B$2,(vlookup(P19,$A$3:$I$14,2,FALSE)),if($P$18=C$2,(vlookup(P19,$A$3:$I$14,3,FALSE)),if($P$18=D$2,(vlookup(P19,$A$3:$I$14,4,FALSE)),if($P$18=E$2,(vlookup(P19,$A$3:$I$14,5,FALSE)),if($P$18=F$2,(vlookup(P19,$A$3:$I$14,6,FALSE)),if($P$18=G$2,(vlookup(P19,$A$3:$I$14,7,FALSE)),if($P$18=H$2,(vlookup(P19,$A$3:$I$14,8,FALSE)),if($P$18=I$2,(vlookup(P19,$A$3:$I$14,9,FALSE)),if($P$18=J$2,(vlookup(P19,$A$3:$I$14,10,FALSE)),if($P$18=K$2,(vlookup(P19,$A$3:$I$14,11,FALSE)),if($P$18=L$2,(vlookup(P19,$A$3:$I$14,12,FALSE)),if($P$18=M$2,(vlookup(P19,$A$3:$I$14,13,FALSE)),0))))))))))))) -> 5 | R19: =if($P$18="","",if($P$18=B$18,(vlookup($P19,$A$19:$I$30,2,FALSE)),if($P$18=C$18,(vlookup($P19,$A$19:$I$30,3,FALSE)),if($P$18=D$18,(vlookup($P19,$A$19:$I$30,4,FALSE)),if($P$18=E$18,(vlookup($P19,$A$19:$I$30,5,FALSE)),if($P$18=F$18,(vlookup($P19,$A$19:$I$30,6,FALSE)),if($P$18=G$18,(vlookup($P19,$A$19:$I$30,7,FALSE)),if($P$18=H$18,(vlookup($P19,$A$19:$I$30,8,FALSE)), if($P$18=I$18,(vlookup($P19,$A$19:$I$30,9,FALSE)),if($P$18=J$18,(vlookup($P19,$A$19:$I$30,10,FALSE)),if($P$18=K$18,(vlookup($P19,$A$19:$I$30,11,FALSE)), if($P$18=L$18,(vlookup($P19,$A$19:$I$30,12,FALSE)), if($P$18=M$18,(vlookup($P19,$A$19:$I$30,13,FALSE)))))))))))))))
A20: =SETUP!A6 -> Bob B | C20: 10 | N20: =sum(B20:M20)*$B$17 -> 20 | P20: =SETUP!A6 -> Bob B | Q20: =if($P$18="","",if($P$18=B$2,(vlookup(P20,$A$3:$I$14,2,FALSE)),if($P$18=C$2,(vlookup(P20,$A$3:$I$14,3,FALSE)),if($P$18=D$2,(vlookup(P20,$A$3:$I$14,4,FALSE)),if($P$18=E$2,(vlookup(P20,$A$3:$I$14,5,FALSE)),if($P$18=F$2,(vlookup(P20,$A$3:$I$14,6,FALSE)),if($P$18=G$2,(vlookup(P20,$A$3:$I$14,7,FALSE)),if($P$18=H$2,(vlookup(P20,$A$3:$I$14,8,FALSE)),if($P$18=I$2,(vlookup(P20,$A$3:$I$14,9,FALSE)),if($P$18=J$2,(vlookup(P20,$A$3:$I$14,10,FALSE)),if($P$18=K$2,(vlookup(P20,$A$3:$I$14,11,FALSE)),if($P$18=L$2,(vlookup(P20,$A$3:$I$14,12,FALSE)),if($P$18=M$2,(vlookup(P20,$A$3:$I$14,13,FALSE)),0))))))))))))) | R20: =if($P$18="","",if($P$18=B$18,(vlookup($P20,$A$19:$I$30,2,FALSE)),if($P$18=C$18,(vlookup($P20,$A$19:$I$30,3,FALSE)),if($P$18=D$18,(vlookup($P20,$A$19:$I$30,4,FALSE)),if($P$18=E$18,(vlookup($P20,$A$19:$I$30,5,FALSE)),if($P$18=F$18,(vlookup($P20,$A$19:$I$30,6,FALSE)),if($P$18=G$18,(vlookup($P20,$A$19:$I$30,7,FALSE)),if($P$18=H$18,(vlookup($P20,$A$19:$I$30,8,FALSE)), if($P$18=I$18,(vlookup($P20,$A$19:$I$30,9,FALSE)),if($P$18=J$18,(vlookup($P20,$A$19:$I$30,10,FALSE)),if($P$18=K$18,(vlookup($P20,$A$19:$I$30,11,FALSE)), if($P$18=L$18,(vlookup($P20,$A$19:$I$30,12,FALSE)), if($P$18=M$18,(vlookup($P20,$A$19:$I$30,13,FALSE)))))))))))))))
A21: =SETUP!A7 -> Brian K | B21: 2 | C21: 2 | D21: 6 | N21: =sum(B21:M21)*$B$17 -> 20 | P21: =SETUP!A7 -> Brian K | Q21: =if($P$18="","",if($P$18=B$2,(vlookup(P21,$A$3:$I$14,2,FALSE)),if($P$18=C$2,(vlookup(P21,$A$3:$I$14,3,FALSE)),if($P$18=D$2,(vlookup(P21,$A$3:$I$14,4,FALSE)),if($P$18=E$2,(vlookup(P21,$A$3:$I$14,5,FALSE)),if($P$18=F$2,(vlookup(P21,$A$3:$I$14,6,FALSE)),if($P$18=G$2,(vlookup(P21,$A$3:$I$14,7,FALSE)),if($P$18=H$2,(vlookup(P21,$A$3:$I$14,8,FALSE)),if($P$18=I$2,(vlookup(P21,$A$3:$I$14,9,FALSE)),if($P$18=J$2,(vlookup(P21,$A$3:$I$14,10,FALSE)),if($P$18=K$2,(vlookup(P21,$A$3:$I$14,11,FALSE)),if($P$18=L$2,(vlookup(P21,$A$3:$I$14,12,FALSE)),if($P$18=M$2,(vlookup(P21,$A$3:$I$14,13,FALSE)),0))))))))))))) -> 2 | R21: =if($P$18="","",if($P$18=B$18,(vlookup($P21,$A$19:$I$30,2,FALSE)),if($P$18=C$18,(vlookup($P21,$A$19:$I$30,3,FALSE)),if($P$18=D$18,(vlookup($P21,$A$19:$I$30,4,FALSE)),if($P$18=E$18,(vlookup($P21,$A$19:$I$30,5,FALSE)),if($P$18=F$18,(vlookup($P21,$A$19:$I$30,6,FALSE)),if($P$18=G$18,(vlookup($P21,$A$19:$I$30,7,FALSE)),if($P$18=H$18,(vlookup($P21,$A$19:$I$30,8,FALSE)), if($P$18=I$18,(vlookup($P21,$A$19:$I$30,9,FALSE)),if($P$18=J$18,(vlookup($P21,$A$19:$I$30,10,FALSE)),if($P$18=K$18,(vlookup($P21,$A$19:$I$30,11,FALSE)), if($P$18=L$18,(vlookup($P21,$A$19:$I$30,12,FALSE)), if($P$18=M$18,(vlookup($P21,$A$19:$I$30,13,FALSE))))))))))))))) -> 2
A22: =SETUP!A8 -> Eric O | N22: =sum(B22:M22)*$B$17 -> 0 | P22: =SETUP!A8 -> Eric O | Q22: =if($P$18="","",if($P$18=B$2,(vlookup(P22,$A$3:$I$14,2,FALSE)),if($P$18=C$2,(vlookup(P22,$A$3:$I$14,3,FALSE)),if($P$18=D$2,(vlookup(P22,$A$3:$I$14,4,FALSE)),if($P$18=E$2,(vlookup(P22,$A$3:$I$14,5,FALSE)),if($P$18=F$2,(vlookup(P22,$A$3:$I$14,6,FALSE)),if($P$18=G$2,(vlookup(P22,$A$3:$I$14,7,FALSE)),if($P$18=H$2,(vlookup(P22,$A$3:$I$14,8,FALSE)),if($P$18=I$2,(vlookup(P22,$A$3:$I$14,9,FALSE)),if($P$18=J$2,(vlookup(P22,$A$3:$I$14,10,FALSE)),if($P$18=K$2,(vlookup(P22,$A$3:$I$14,11,FALSE)),if($P$18=L$2,(vlookup(P22,$A$3:$I$14,12,FALSE)),if($P$18=M$2,(vlookup(P22,$A$3:$I$14,13,FALSE)),0))))))))))))) -> 5 | R22: =if($P$18="","",if($P$18=B$18,(vlookup($P22,$A$19:$I$30,2,FALSE)),if($P$18=C$18,(vlookup($P22,$A$19:$I$30,3,FALSE)),if($P$18=D$18,(vlookup($P22,$A$19:$I$30,4,FALSE)),if($P$18=E$18,(vlookup($P22,$A$19:$I$30,5,FALSE)),if($P$18=F$18,(vlookup($P22,$A$19:$I$30,6,FALSE)),if($P$18=G$18,(vlookup($P22,$A$19:$I$30,7,FALSE)),if($P$18=H$18,(vlookup($P22,$A$19:$I$30,8,FALSE)), if($P$18=I$18,(vlookup($P22,$A$19:$I$30,9,FALSE)),if($P$18=J$18,(vlookup($P22,$A$19:$I$30,10,FALSE)),if($P$18=K$18,(vlookup($P22,$A$19:$I$30,11,FALSE)), if($P$18=L$18,(vlookup($P22,$A$19:$I$30,12,FALSE)), if($P$18=M$18,(vlookup($P22,$A$19:$I$30,13,FALSE)))))))))))))))
A23: =SETUP!A9 -> Matt V | J23: 10 | N23: =sum(B23:M23)*$B$17 -> 20 | P23: =SETUP!A9 -> Matt V | Q23: =if($P$18="","",if($P$18=B$2,(vlookup(P23,$A$3:$I$14,2,FALSE)),if($P$18=C$2,(vlookup(P23,$A$3:$I$14,3,FALSE)),if($P$18=D$2,(vlookup(P23,$A$3:$I$14,4,FALSE)),if($P$18=E$2,(vlookup(P23,$A$3:$I$14,5,FALSE)),if($P$18=F$2,(vlookup(P23,$A$3:$I$14,6,FALSE)),if($P$18=G$2,(vlookup(P23,$A$3:$I$14,7,FALSE)),if($P$18=H$2,(vlookup(P23,$A$3:$I$14,8,FALSE)),if($P$18=I$2,(vlookup(P23,$A$3:$I$14,9,FALSE)),if($P$18=J$2,(vlookup(P23,$A$3:$I$14,10,FALSE)),if($P$18=K$2,(vlookup(P23,$A$3:$I$14,11,FALSE)),if($P$18=L$2,(vlookup(P23,$A$3:$I$14,12,FALSE)),if($P$18=M$2,(vlookup(P23,$A$3:$I$14,13,FALSE)),0))))))))))))) -> 2 | R23: =if($P$18="","",if($P$18=B$18,(vlookup($P23,$A$19:$I$30,2,FALSE)),if($P$18=C$18,(vlookup($P23,$A$19:$I$30,3,FALSE)),if($P$18=D$18,(vlookup($P23,$A$19:$I$30,4,FALSE)),if($P$18=E$18,(vlookup($P23,$A$19:$I$30,5,FALSE)),if($P$18=F$18,(vlookup($P23,$A$19:$I$30,6,FALSE)),if($P$18=G$18,(vlookup($P23,$A$19:$I$30,7,FALSE)),if($P$18=H$18,(vlookup($P23,$A$19:$I$30,8,FALSE)), if($P$18=I$18,(vlookup($P23,$A$19:$I$30,9,FALSE)),if($P$18=J$18,(vlookup($P23,$A$19:$I$30,10,FALSE)),if($P$18=K$18,(vlookup($P23,$A$19:$I$30,11,FALSE)), if($P$18=L$18,(vlookup($P23,$A$19:$I$30,12,FALSE)), if($P$18=M$18,(vlookup($P23,$A$19:$I$30,13,FALSE)))))))))))))))
A24: =SETUP!A10 -> Scott R | N24: =sum(B24:M24)*$B$17 -> 0 | P24: =SETUP!A10 -> Scott R | Q24: =if($P$18="","",if($P$18=B$2,(vlookup(P24,$A$3:$I$14,2,FALSE)),if($P$18=C$2,(vlookup(P24,$A$3:$I$14,3,FALSE)),if($P$18=D$2,(vlookup(P24,$A$3:$I$14,4,FALSE)),if($P$18=E$2,(vlookup(P24,$A$3:$I$14,5,FALSE)),if($P$18=F$2,(vlookup(P24,$A$3:$I$14,6,FALSE)),if($P$18=G$2,(vlookup(P24,$A$3:$I$14,7,FALSE)),if($P$18=H$2,(vlookup(P24,$A$3:$I$14,8,FALSE)),if($P$18=I$2,(vlookup(P24,$A$3:$I$14,9,FALSE)),if($P$18=J$2,(vlookup(P24,$A$3:$I$14,10,FALSE)),if($P$18=K$2,(vlookup(P24,$A$3:$I$14,11,FALSE)),if($P$18=L$2,(vlookup(P24,$A$3:$I$14,12,FALSE)),if($P$18=M$2,(vlookup(P24,$A$3:$I$14,13,FALSE)),0))))))))))))) | R24: =if($P$18="","",if($P$18=B$18,(vlookup($P24,$A$19:$I$30,2,FALSE)),if($P$18=C$18,(vlookup($P24,$A$19:$I$30,3,FALSE)),if($P$18=D$18,(vlookup($P24,$A$19:$I$30,4,FALSE)),if($P$18=E$18,(vlookup($P24,$A$19:$I$30,5,FALSE)),if($P$18=F$18,(vlookup($P24,$A$19:$I$30,6,FALSE)),if($P$18=G$18,(vlookup($P24,$A$19:$I$30,7,FALSE)),if($P$18=H$18,(vlookup($P24,$A$19:$I$30,8,FALSE)), if($P$18=I$18,(vlookup($P24,$A$19:$I$30,9,FALSE)),if($P$18=J$18,(vlookup($P24,$A$19:$I$30,10,FALSE)),if($P$18=K$18,(vlookup($P24,$A$19:$I$30,11,FALSE)), if($P$18=L$18,(vlookup($P24,$A$19:$I$30,12,FALSE)), if($P$18=M$18,(vlookup($P24,$A$19:$I$30,13,FALSE)))))))))))))))
A25: =SETUP!A11 -> N/A | B25: 3 | C25: 1 | E25: 3 | J25: 3 | N25: =sum(B25:M25)*$B$17 -> 20 | P25: =SETUP!A11 -> N/A | Q25: =if($P$18="","",if($P$18=B$2,(vlookup(P25,$A$3:$I$14,2,FALSE)),if($P$18=C$2,(vlookup(P25,$A$3:$I$14,3,FALSE)),if($P$18=D$2,(vlookup(P25,$A$3:$I$14,4,FALSE)),if($P$18=E$2,(vlookup(P25,$A$3:$I$14,5,FALSE)),if($P$18=F$2,(vlookup(P25,$A$3:$I$14,6,FALSE)),if($P$18=G$2,(vlookup(P25,$A$3:$I$14,7,FALSE)),if($P$18=H$2,(vlookup(P25,$A$3:$I$14,8,FALSE)),if($P$18=I$2,(vlookup(P25,$A$3:$I$14,9,FALSE)),if($P$18=J$2,(vlookup(P25,$A$3:$I$14,10,FALSE)),if($P$18=K$2,(vlookup(P25,$A$3:$I$14,11,FALSE)),if($P$18=L$2,(vlookup(P25,$A$3:$I$14,12,FALSE)),if($P$18=M$2,(vlookup(P25,$A$3:$I$14,13,FALSE)),0))))))))))))) | R25: =if($P$18="","",if($P$18=B$18,(vlookup($P25,$A$19:$I$30,2,FALSE)),if($P$18=C$18,(vlookup($P25,$A$19:$I$30,3,FALSE)),if($P$18=D$18,(vlookup($P25,$A$19:$I$30,4,FALSE)),if($P$18=E$18,(vlookup($P25,$A$19:$I$30,5,FALSE)),if($P$18=F$18,(vlookup($P25,$A$19:$I$30,6,FALSE)),if($P$18=G$18,(vlookup($P25,$A$19:$I$30,7,FALSE)),if($P$18=H$18,(vlookup($P25,$A$19:$I$30,8,FALSE)), if($P$18=I$18,(vlookup($P25,$A$19:$I$30,9,FALSE)),if($P$18=J$18,(vlookup($P25,$A$19:$I$30,10,FALSE)),if($P$18=K$18,(vlookup($P25,$A$19:$I$30,11,FALSE)), if($P$18=L$18,(vlookup($P25,$A$19:$I$30,12,FALSE)), if($P$18=M$18,(vlookup($P25,$A$19:$I$30,13,FALSE))))))))))))))) -> 3
A26: =SETUP!A12 -> N/A | C26: 8 | D26: 2 | N26: =sum(B26:M26)*$B$17 -> 20 | P26: =SETUP!A12 -> N/A | Q26: =if($P$18="","",if($P$18=B$2,(vlookup(P26,$A$3:$I$14,2,FALSE)),if($P$18=C$2,(vlookup(P26,$A$3:$I$14,3,FALSE)),if($P$18=D$2,(vlookup(P26,$A$3:$I$14,4,FALSE)),if($P$18=E$2,(vlookup(P26,$A$3:$I$14,5,FALSE)),if($P$18=F$2,(vlookup(P26,$A$3:$I$14,6,FALSE)),if($P$18=G$2,(vlookup(P26,$A$3:$I$14,7,FALSE)),if($P$18=H$2,(vlookup(P26,$A$3:$I$14,8,FALSE)),if($P$18=I$2,(vlookup(P26,$A$3:$I$14,9,FALSE)),if($P$18=J$2,(vlookup(P26,$A$3:$I$14,10,FALSE)),if($P$18=K$2,(vlookup(P26,$A$3:$I$14,11,FALSE)),if($P$18=L$2,(vlookup(P26,$A$3:$I$14,12,FALSE)),if($P$18=M$2,(vlookup(P26,$A$3:$I$14,13,FALSE)),0))))))))))))) | R26: =if($P$18="","",if($P$18=B$18,(vlookup($P26,$A$19:$I$30,2,FALSE)),if($P$18=C$18,(vlookup($P26,$A$19:$I$30,3,FALSE)),if($P$18=D$18,(vlookup($P26,$A$19:$I$30,4,FALSE)),if($P$18=E$18,(vlookup($P26,$A$19:$I$30,5,FALSE)),if($P$18=F$18,(vlookup($P26,$A$19:$I$30,6,FALSE)),if($P$18=G$18,(vlookup($P26,$A$19:$I$30,7,FALSE)),if($P$18=H$18,(vlookup($P26,$A$19:$I$30,8,FALSE)), if($P$18=I$18,(vlookup($P26,$A$19:$I$30,9,FALSE)),if($P$18=J$18,(vlookup($P26,$A$19:$I$30,10,FALSE)),if($P$18=K$18,(vlookup($P26,$A$19:$I$30,11,FALSE)), if($P$18=L$18,(vlookup($P26,$A$19:$I$30,12,FALSE)), if($P$18=M$18,(vlookup($P26,$A$19:$I$30,13,FALSE))))))))))))))) -> 3
A27: =SETUP!A13 -> N/A | J27: 10 | N27: =sum(B27:M27)*$B$17 -> 20 | P27: =SETUP!A13 -> N/A | Q27: =if($P$18="","",if($P$18=B$2,(vlookup(P27,$A$3:$I$14,2,FALSE)),if($P$18=C$2,(vlookup(P27,$A$3:$I$14,3,FALSE)),if($P$18=D$2,(vlookup(P27,$A$3:$I$14,4,FALSE)),if($P$18=E$2,(vlookup(P27,$A$3:$I$14,5,FALSE)),if($P$18=F$2,(vlookup(P27,$A$3:$I$14,6,FALSE)),if($P$18=G$2,(vlookup(P27,$A$3:$I$14,7,FALSE)),if($P$18=H$2,(vlookup(P27,$A$3:$I$14,8,FALSE)),if($P$18=I$2,(vlookup(P27,$A$3:$I$14,9,FALSE)),if($P$18=J$2,(vlookup(P27,$A$3:$I$14,10,FALSE)),if($P$18=K$2,(vlookup(P27,$A$3:$I$14,11,FALSE)),if($P$18=L$2,(vlookup(P27,$A$3:$I$14,12,FALSE)),if($P$18=M$2,(vlookup(P27,$A$3:$I$14,13,FALSE)),0))))))))))))) | R27: =if($P$18="","",if($P$18=B$18,(vlookup($P27,$A$19:$I$30,2,FALSE)),if($P$18=C$18,(vlookup($P27,$A$19:$I$30,3,FALSE)),if($P$18=D$18,(vlookup($P27,$A$19:$I$30,4,FALSE)),if($P$18=E$18,(vlookup($P27,$A$19:$I$30,5,FALSE)),if($P$18=F$18,(vlookup($P27,$A$19:$I$30,6,FALSE)),if($P$18=G$18,(vlookup($P27,$A$19:$I$30,7,FALSE)),if($P$18=H$18,(vlookup($P27,$A$19:$I$30,8,FALSE)), if($P$18=I$18,(vlookup($P27,$A$19:$I$30,9,FALSE)),if($P$18=J$18,(vlookup($P27,$A$19:$I$30,10,FALSE)),if($P$18=K$18,(vlookup($P27,$A$19:$I$30,11,FALSE)), if($P$18=L$18,(vlookup($P27,$A$19:$I$30,12,FALSE)), if($P$18=M$18,(vlookup($P27,$A$19:$I$30,13,FALSE))))))))))))))) -> 3
A28: =SETUP!A14 -> N/A | N28: =sum(B28:M28)*$B$17 -> 0 | P28: =SETUP!A14 -> N/A | Q28: =if($P$18="","",if($P$18=B$2,(vlookup(P28,$A$3:$I$14,2,FALSE)),if($P$18=C$2,(vlookup(P28,$A$3:$I$14,3,FALSE)),if($P$18=D$2,(vlookup(P28,$A$3:$I$14,4,FALSE)),if($P$18=E$2,(vlookup(P28,$A$3:$I$14,5,FALSE)),if($P$18=F$2,(vlookup(P28,$A$3:$I$14,6,FALSE)),if($P$18=G$2,(vlookup(P28,$A$3:$I$14,7,FALSE)),if($P$18=H$2,(vlookup(P28,$A$3:$I$14,8,FALSE)),if($P$18=I$2,(vlookup(P28,$A$3:$I$14,9,FALSE)),if($P$18=J$2,(vlookup(P28,$A$3:$I$14,10,FALSE)),if($P$18=K$2,(vlookup(P28,$A$3:$I$14,11,FALSE)),if($P$18=L$2,(vlookup(P28,$A$3:$I$14,12,FALSE)),if($P$18=M$2,(vlookup(P28,$A$3:$I$14,13,FALSE)),0))))))))))))) | R28: =if($P$18="","",if($P$18=B$18,(vlookup($P28,$A$19:$I$30,2,FALSE)),if($P$18=C$18,(vlookup($P28,$A$19:$I$30,3,FALSE)),if($P$18=D$18,(vlookup($P28,$A$19:$I$30,4,FALSE)),if($P$18=E$18,(vlookup($P28,$A$19:$I$30,5,FALSE)),if($P$18=F$18,(vlookup($P28,$A$19:$I$30,6,FALSE)),if($P$18=G$18,(vlookup($P28,$A$19:$I$30,7,FALSE)),if($P$18=H$18,(vlookup($P28,$A$19:$I$30,8,FALSE)), if($P$18=I$18,(vlookup($P28,$A$19:$I$30,9,FALSE)),if($P$18=J$18,(vlookup($P28,$A$19:$I$30,10,FALSE)),if($P$18=K$18,(vlookup($P28,$A$19:$I$30,11,FALSE)), if($P$18=L$18,(vlookup($P28,$A$19:$I$30,12,FALSE)), if($P$18=M$18,(vlookup($P28,$A$19:$I$30,13,FALSE))))))))))))))) -> 3
A29: =SETUP!A15 -> N/A | J29: 5 | K29: 5 | N29: =sum(B29:M29)*$B$17 -> 20 | P29: =SETUP!A15 -> N/A | Q29: =if($P$18="","",if($P$18=B$2,(vlookup(P29,$A$3:$I$14,2,FALSE)),if($P$18=C$2,(vlookup(P29,$A$3:$I$14,3,FALSE)),if($P$18=D$2,(vlookup(P29,$A$3:$I$14,4,FALSE)),if($P$18=E$2,(vlookup(P29,$A$3:$I$14,5,FALSE)),if($P$18=F$2,(vlookup(P29,$A$3:$I$14,6,FALSE)),if($P$18=G$2,(vlookup(P29,$A$3:$I$14,7,FALSE)),if($P$18=H$2,(vlookup(P29,$A$3:$I$14,8,FALSE)),if($P$18=I$2,(vlookup(P29,$A$3:$I$14,9,FALSE)),if($P$18=J$2,(vlookup(P29,$A$3:$I$14,10,FALSE)),if($P$18=K$2,(vlookup(P29,$A$3:$I$14,11,FALSE)),if($P$18=L$2,(vlookup(P29,$A$3:$I$14,12,FALSE)),if($P$18=M$2,(vlookup(P29,$A$3:$I$14,13,FALSE)),0))))))))))))) | R29: =if($P$18="","",if($P$18=B$18,(vlookup($P29,$A$19:$I$30,2,FALSE)),if($P$18=C$18,(vlookup($P29,$A$19:$I$30,3,FALSE)),if($P$18=D$18,(vlookup($P29,$A$19:$I$30,4,FALSE)),if($P$18=E$18,(vlookup($P29,$A$19:$I$30,5,FALSE)),if($P$18=F$18,(vlookup($P29,$A$19:$I$30,6,FALSE)),if($P$18=G$18,(vlookup($P29,$A$19:$I$30,7,FALSE)),if($P$18=H$18,(vlookup($P29,$A$19:$I$30,8,FALSE)), if($P$18=I$18,(vlookup($P29,$A$19:$I$30,9,FALSE)),if($P$18=J$18,(vlookup($P29,$A$19:$I$30,10,FALSE)),if($P$18=K$18,(vlookup($P29,$A$19:$I$30,11,FALSE)), if($P$18=L$18,(vlookup($P29,$A$19:$I$30,12,FALSE)), if($P$18=M$18,(vlookup($P29,$A$19:$I$30,13,FALSE))))))))))))))) -> 3
A30: =SETUP!A16 -> N/A | B30: 4 | C30: 3 | J30: 3 | N30: =sum(B30:M30)*$B$17 -> 20 | P30: =SETUP!A16 -> N/A | Q30: =if($P$18="","",if($P$18=B$2,(vlookup(P30,$A$3:$I$14,2,FALSE)),if($P$18=C$2,(vlookup(P30,$A$3:$I$14,3,FALSE)),if($P$18=D$2,(vlookup(P30,$A$3:$I$14,4,FALSE)),if($P$18=E$2,(vlookup(P30,$A$3:$I$14,5,FALSE)),if($P$18=F$2,(vlookup(P30,$A$3:$I$14,6,FALSE)),if($P$18=G$2,(vlookup(P30,$A$3:$I$14,7,FALSE)),if($P$18=H$2,(vlookup(P30,$A$3:$I$14,8,FALSE)),if($P$18=I$2,(vlookup(P30,$A$3:$I$14,9,FALSE)),if($P$18=J$2,(vlookup(P30,$A$3:$I$14,10,FALSE)),if($P$18=K$2,(vlookup(P30,$A$3:$I$14,11,FALSE)),if($P$18=L$2,(vlookup(P30,$A$3:$I$14,12,FALSE)),if($P$18=M$2,(vlookup(P30,$A$3:$I$14,13,FALSE)),0))))))))))))) | R30: =if($P$18="","",if($P$18=B$18,(vlookup($P30,$A$19:$I$30,2,FALSE)),if($P$18=C$18,(vlookup($P30,$A$19:$I$30,3,FALSE)),if($P$18=D$18,(vlookup($P30,$A$19:$I$30,4,FALSE)),if($P$18=E$18,(vlookup($P30,$A$19:$I$30,5,FALSE)),if($P$18=F$18,(vlookup($P30,$A$19:$I$30,6,FALSE)),if($P$18=G$18,(vlookup($P30,$A$19:$I$30,7,FALSE)),if($P$18=H$18,(vlookup($P30,$A$19:$I$30,8,FALSE)), if($P$18=I$18,(vlookup($P30,$A$19:$I$30,9,FALSE)),if($P$18=J$18,(vlookup($P30,$A$19:$I$30,10,FALSE)),if($P$18=K$18,(vlookup($P30,$A$19:$I$30,11,FALSE)), if($P$18=L$18,(vlookup($P30,$A$19:$I$30,12,FALSE)), if($P$18=M$18,(vlookup($P30,$A$19:$I$30,13,FALSE))))))))))))))) -> 3
B31: =SUM(B19:B30) -> 9 | C31: =SUM(C19:C30) -> 27 | D31: =SUM(D19:D30) -> 10 | E31: =SUM(E19:E30) -> 3 | F31: =SUM(F19:F30) -> 0 | G31: =SUM(G19:G30) -> 0 | H31: =SUM(H19:H30) -> 0 | I31: =SUM(I19:I30) -> 0 | ... M31: =SUM(M19:M30) -> 0 | N31: =sum(B31:M31) -> 90 | Q31: =if($P$18="","TBD",if($P$18=B2,B15,if($P$18=C2,C15,if($P$18=D2,D15,if($P$18=E2,E15,if($P$18=F2,F15,if($P$18=G2,G15,if($P$18=H2,H15,if($P$18=I2,I15,"TBD"))))))))) -> 16 | R31: =if(P18="","TBD",if($P$18=B18,B31,if($P$18=C18,C31,if($P$18=D18,D31,if($P$18=E18,E31,if($P$18=F18,F31,if($P$18=G18,G31,if($P$18=H18,H31,if($P$18=I18,I31,"TBD"))))))))) -> 9

Sheet Score Calcuations
A1: Player | B1: RANK | C1: RANK | D1: =SETUP!C1 -> BLACK FOREST | F1: =SETUP!D1 -> LOCHENHEATH | H1: =SETUP!E1 -> THE LEGEND | J1: =SETUP!F1 -> FOREST DUNES | L1: TOTAL
B2: w/o TIES | C2: w/ TIES | D2: GROSS | E2: NET | F2: GROSS | G2: NET | H2: GROSS | I2: NET | J2: GROSS | K2: NET | L2: GROSS | M2: NET | N2: TO PAR
A3: =SETUP!A5 -> Aaron J | B3: =if(A3="N/A","",RANK(M3,$M$3:$M$14,1)+COUNTIF($M$3:M3,M3)-1) -> 2 | C3: =if(A3="N/A","",if(countif($M$3:$M$14,M3)=1,RANK(M3,$M$3:$M$14,1),"T"&RANK(M3,$M$3:$M$14,1))) -> 2 | D3: {=if(A3="N/A","",index(Scorecards!$X$4:$X$15,match($A3,Scorecards!$A$4:$A$15,0)))} -> 95 | E3: {=if(A3="N/A","",index(Scorecards!$Y$4:$Y$15,match($A3,Scorecards!$A$4:$A$15,0)))} -> 82 | F3: {=if(A3="N/A","",index(Scorecards!$X$22:$X$33,match($A3,Scorecards!$A$22:$A$33,0)))} -> 96 | G3: {=if(A3="N/A","",index(Scorecards!$Y$22:$Y$33,match($A3,Scorecards!$A$22:$A$33,0)))} -> 83 | H3: {=if(A3="N/A","",index(Scorecards!$X$40:$X$51,match($A3,Scorecards!$A$40:$A$51,0)))} -> 89 | I3: {=if(A3="N/A","",index(Scorecards!$Y$40:$Y$51,match($A3,Scorecards!$A$40:$A$51,0)))} -> 76 | J3: {=if(A3="N/A","",index(Scorecards!$X$58:$X$69,match($A3,Scorecards!$A$58:$A$69,0)))} -> 94 | K3: {=if(A3="N/A","",index(Scorecards!$Y$58:$Y$69,match($A3,Scorecards!$A$58:$A$69,0)))} -> 81 | L3: =if(A3="N/A","",SUM(D3,F3,H3,J3)) -> 374 | M3: =if(A3="N/A","",SUM(E3,G3,I3,K3)) -> 322 | N3: =if(A3="N/A","N/A",if(COUNT($D3:$K3)=8,$M3-sum(SETUP!$C$4:$F$4),if(count($D3:$K3)=6,$M3-sum(SETUP!$C$4:$E$4),if(count($D3:$I3)=4,$M3-sum(SETUP!$C$4:$D$4),if(count($D3:$I3)=2,$M3-SETUP!$C$4,""))))) -> 33
