Workbook

Sheet LEADERBOARD
A1: 2025 WANNABE CUP
A2: TO PAR | B2: POS | C2: PLAYER | D2: SCORE | E2: =SETUP!C1 -> THE TRIBUTE | F2: =SETUP!D1 -> THE PREMIER | G2: =SETUP!E1 -> THE LOON | H2: =SETUP!F1 -> THE LAKES
A3: {=index('Score Calcuations'!$N$3:$N$14,match(C3,'Score Calcuations'!$A$3:$A$14))} -> 4 | B3: =IFERROR(__xludf.DUMMYFUNCTION("query(index('Score Calcuations'!A3:N14&""""),""select Col3,Col1,Col14,Col5,Col7,Col9,Col11 ORDER BY Col13"",0)"),"1") -> 1 | C3: =IFERROR(__xludf.DUMMYFUNCTION("""COMPUTED_VALUE"""),"Joe S") -> Joe S | D3: =IFERROR(__xludf.DUMMYFUNCTION("""COMPUTED_VALUE"""),"4") -> 4 | E3: =IFERROR(__xludf.DUMMYFUNCTION("""COMPUTED_VALUE"""),"72") -> 72 | F3: =IFERROR(__xludf.DUMMYFUNCTION("""COMPUTED_VALUE"""),"72") -> 72 | G3: =IFERROR(__xludf.DUMMYFUNCTION("""COMPUTED_VALUE"""),"79") -> 79 | H3: =IFERROR(__xludf.DUMMYFUNCTION("""COMPUTED_VALUE"""),"69") -> 69
A4: {=index('Score Calcuations'!$N$3:$N$14,match(C4,'Score Calcuations'!$A$3:$A$14))} -> 10 | B4: =IFERROR(__xludf.DUMMYFUNCTION("""COMPUTED_VALUE"""),"2") -> 2 | C4: =IFERROR(__xludf.DUMMYFUNCTION("""COMPUTED_VALUE"""),"Scott R") -> Scott R | D4: =IFERROR(__xludf.DUMMYFUNCTION("""COMPUTED_VALUE"""),"10") -> 10 | E4: =IFERROR(__xludf.DUMMYFUNCTION("""COMPUTED_VALUE"""),"76") -> 76 | F4: =IFERROR(__xludf.DUMMYFUNCTION("""COMPUTED_VALUE"""),"71") -> 71 | G4: =IFERROR(__xludf.DUMMYFUNCTION("""COMPUTED_VALUE"""),"75") -> 75 | H4: =IFERROR(__xludf.DUMMYFUNCTION("""COMPUTED_VALUE"""),"76") -> 76
A5: {=index('Score Calcuations'!$N$3:$N$14,match(C5,'Score Calcuations'!$A$3:$A$14))} -> 11 | B5: =IFERROR(__xludf.DUMMYFUNCTION("""COMPUTED_VALUE"""),"3") -> 3 | C5: =IFERROR(__xludf.DUMMYFUNCTION("""COMPUTED_VALUE"""),"Bob B") -> Bob B | D5: =IFERROR(__xludf.DUMMYFUNCTION("""COMPUTED_VALUE"""),"11") -> 11 | E5: =IFERROR(__xludf.DUMMYFUNCTION("""COMPUTED_VALUE"""),"76") -> 76 | F5: =IFERROR(__xludf.DUMMYFUNCTION("""COMPUTED_VALUE"""),"69") -> 69 | G5: =IFERROR(__xludf.DUMMYFUNCTION("""COMPUTED_VALUE"""),"77") -> 77 | H5: =IFERROR(__xludf.DUMMYFUNCTION("""COMPUTED_VALUE"""),"77") -> 77
A6: {=index('Score Calcuations'!$N$3:$N$14,match(C6,'Score Calcuations'!$A$3:$A$14))} -> 16 | B6: =IFERROR(__xludf.DUMMYFUNCTION("""COMPUTED_VALUE"""),"4") -> 4 | C6: =IFERROR(__xludf.DUMMYFUNCTION("""COMPUTED_VALUE"""),"Andy V") -> Andy V | D6: =IFERROR(__xludf.DUMMYFUNCTION("""COMPUTED_VALUE"""),"16") -> 16 | E6: =IFERROR(__xludf.DUMMYFUNCTION("""COMPUTED_VALUE"""),"82") -> 82 | F6: =IFERROR(__xludf.DUMMYFUNCTION("""COMPUTED_VALUE"""),"74") -> 74 | G6: =IFERROR(__xludf.DUMMYFUNCTION("""COMPUTED_VALUE"""),"74") -> 74 | H6: =IFERROR(__xludf.DUMMYFUNCTION("""COMPUTED_VALUE"""),"74") -> 74
A7: {=index('Score Calcuations'!$N$3:$N$14,match(C7,'Score Calcuations'!$A$3:$A$14))} -> 18 | B7: =IFERROR(__xludf.DUMMYFUNCTION("""COMPUTED_VALUE"""),"5") -> 5 | C7: =IFERROR(__xludf.DUMMYFUNCTION("""COMPUTED_VALUE"""),"Dave K") -> Dave K | D7: =IFERROR(__xludf.DUMMYFUNCTION("""COMPUTED_VALUE"""),"18") -> 18 | E7: =IFERROR(__xludf.DUMMYFUNCTION("""COMPUTED_VALUE"""),"73") -> 73 | F7: =IFERROR(__xludf.DUMMYFUNCTION("""COMPUTED_VALUE"""),"79") -> 79 | G7: =IFERROR(__xludf.DUMMYFUNCTION("""COMPUTED_VALUE"""),"77") -> 77 | H7: =IFERROR(__xludf.DUMMYFUNCTION("""COMPUTED_VALUE"""),"77") -> 77
A8: {=index('Score Calcuations'!$N$3:$N$14,match(C8,'Score Calcuations'!$A$3:$A$14))} -> 22 | B8: =IFERROR(__xludf.DUMMYFUNCTION("""COMPUTED_VALUE"""),"6") -> 6 | C8: =IFERROR(__xludf.DUMMYFUNCTION("""COMPUTED_VALUE"""),"Jeff B") -> Jeff B | D8: =IFERROR(__xludf.DUMMYFUNCTION("""COMPUTED_VALUE"""),"22") -> 22 | E8: =IFERROR(__xludf.DUMMYFUNCTION("""COMPUTED_VALUE"""),"77") -> 77 | F8: =IFERROR(__xludf.DUMMYFUNCTION("""COMPUTED_VALUE"""),"77") -> 77 | G8: =IFERROR(__xludf.DUMMYFUNCTION("""COMPUTED_VALUE"""),"76") -> 76 | H8: =IFERROR(__xludf.DUMMYFUNCTION("""COMPUTED_VALUE"""),"80") -> 80
A9: {=index('Score Calcuations'!$N$3:$N$14,match(C9,'Score Calcuations'!$A$3:$A$14))} -> 23 | B9: =IFERROR(__xludf.DUMMYFUNCTION("""COMPUTED_VALUE"""),"7") -> 7 | C9: =IFERROR(__xludf.DUMMYFUNCTION("""COMPUTED_VALUE"""),"Eric O") -> Eric O | D9: =IFERROR(__xludf.DUMMYFUNCTION("""COMPUTED_VALUE"""),"23") -> 23 | E9: =IFERROR(__xludf.DUMMYFUNCTION("""COMPUTED_VALUE"""),"82") -> 82 | F9: =IFERROR(__xludf.DUMMYFUNCTION("""COMPUTED_VALUE"""),"80") -> 80 | G9: =IFERROR(__xludf.DUMMYFUNCTION("""COMPUTED_VALUE"""),"74") -> 74 | H9: =IFERROR(__xludf.DUMMYFUNCTION("""COMPUTED_VALUE"""),"75") -> 75
A10: {=index('Score Calcuations'!$N$3:$N$14,match(C10,'Score Calcuations'!$A$3:$A$14))} -> 24 | B10: =IFERROR(__xludf.DUMMYFUNCTION("""COMPUTED_VALUE"""),"8") -> 8 | C10: =IFERROR(__xludf.DUMMYFUNCTION("""COMPUTED_VALUE"""),"Brian K") -> Brian K | D10: =IFERROR(__xludf.DUMMYFUNCTION("""COMPUTED_VALUE"""),"24") -> 24 | E10: =IFERROR(__xludf.DUMMYFUNCTION("""COMPUTED_VALUE"""),"76") -> 76 | F10: =IFERROR(__xludf.DUMMYFUNCTION("""COMPUTED_VALUE"""),"75") -> 75 | G10: =IFERROR(__xludf.DUMMYFUNCTION("""COMPUTED_VALUE"""),"78") -> 78 | H10: =IFERROR(__xludf.DUMMYFUNCTION("""COMPUTED_VALUE"""),"83") -> 83
A11: {=index('Score Calcuations'!$N$3:$N$14,match(C11,'Score Calcuations'!$A$3:$A$14))} -> 25 | B11: =IFERROR(__xludf.DUMMYFUNCTION("""COMPUTED_VALUE"""),"9") -> 9 | C11: =IFERROR(__xludf.DUMMYFUNCTION("""COMPUTED_VALUE"""),"Russ W") -> Russ W | D11: =IFERROR(__xludf.DUMMYFUNCTION("""COMPUTED_VALUE"""),"25") -> 25 | E11: =IFERROR(__xludf.DUMMYFUNCTION("""COMPUTED_VALUE"""),"71") -> 71 | F11: =IFERROR(__xludf.DUMMYFUNCTION("""COMPUTED_VALUE"""),"80") -> 80 | G11: =IFERROR(__xludf.DUMMYFUNCTION("""COMPUTED_VALUE"""),"85") -> 85 | H11: =IFERROR(__xludf.DUMMYFUNCTION("""COMPUTED_VALUE"""),"77") -> 77
A12: {=index('Score Calcuations'!$N$3:$N$14,match(C12,'Score Calcuations'!$A$3:$A$14))} -> 28 | B12: =IFERROR(__xludf.DUMMYFUNCTION("""COMPUTED_VALUE"""),"10") -> 10 | C12: =IFERROR(__xludf.DUMMYFUNCTION("""COMPUTED_VALUE"""),"Aaron J") -> Aaron J | D12: =IFERROR(__xludf.DUMMYFUNCTION("""COMPUTED_VALUE"""),"28") -> 28 | E12: =IFERROR(__xludf.DUMMYFUNCTION("""COMPUTED_VALUE"""),"74") -> 74 | F12: =IFERROR(__xludf.DUMMYFUNCTION("""COMPUTED_VALUE"""),"77") -> 77 | G12: =IFERROR(__xludf.DUMMYFUNCTION("""COMPUTED_VALUE"""),"85") -> 85 | H12: =IFERROR(__xludf.DUMMYFUNCTION("""COMPUTED_VALUE"""),"80") -> 80
A13: {=index('Score Calcuations'!$N$3:$N$14,match(C13,'Score Calcuations'!$A$3:$A$14))} -> 61 | B13: =IFERROR(__xludf.DUMMYFUNCTION("""COMPUTED_VALUE"""),"11") -> 11 | C13: =IFERROR(__xludf.DUMMYFUNCTION("""COMPUTED_VALUE"""),"Ray H") -> Ray H | D13: =IFERROR(__xludf.DUMMYFUNCTION("""COMPUTED_VALUE"""),"61") -> 61 | E13: =IFERROR(__xludf.DUMMYFUNCTION("""COMPUTED_VALUE"""),"85") -> 85 | F13: =IFERROR(__xludf.DUMMYFUNCTION("""COMPUTED_VALUE"""),"88") -> 88 | G13: =IFERROR(__xludf.DUMMYFUNCTION("""COMPUTED_VALUE"""),"77") -> 77 | H13: =IFERROR(__xludf.DUMMYFUNCTION("""COMPUTED_VALUE"""),"99") -> 99
A14: {=index('Score Calcuations'!$N$3:$N$14,match(C14,'Score Calcuations'!$A$3:$A$14))} -> WD | B14: =IFERROR(__xludf.DUMMYFUNCTION("""COMPUTED_VALUE"""),"WD") -> WD | C14: =IFERROR(__xludf.DUMMYFUNCTION("""COMPUTED_VALUE"""),"John C") -> John C | D14: =IFERROR(__xludf.DUMMYFUNCTION("""COMPUTED_VALUE"""),"WD") -> WD | E14: =IFERROR(__xludf.DUMMYFUNCTION("""COMPUTED_VALUE"""),"71") -> 71 | F14: =IFERROR(__xludf.DUMMYFUNCTION("""COMPUTED_VALUE"""),"86") -> 86 | G14: =IFERROR(__xludf.DUMMYFUNCTION("""COMPUTED_VALUE"""),"76") -> 76 | H14: =IFERROR(__xludf.DUMMYFUNCTION("""COMPUTED_VALUE"""),"WD") -> WD

Sheet Scorecards
C1: =SETUP!C1 -> THE TRIBUTE | X1: =SETUP!C2 -> 72.9 | Y1: =SETUP!C3 -> 136
C2: Hole | D2: 1 | E2: 2 | F2: 3 | G2: 4 | H2: 5 | I2: 6 | J2: 7 | K2: 8 | L2: 9 | M2: 10 | N2: 11 | O2: 12 | P2: 13 | Q2: 14 | R2: 15 | S2: 16 | T2: 17 | U2: 18 | V2: OUT | W2: IN | X2: TOTAL | Y2: NET
C3: Handi | D3: =SETUP!I3 -> 13 | E3: =SETUP!J3 -> 9 | F3: =SETUP!K3 -> 17 | G3: =SETUP!L3 -> 7 | H3: =SETUP!M3 -> 5 | I3: =SETUP!N3 -> 11 | J3: =SETUP!O3 -> 3 | K3: =SETUP!P3 -> 1 | ... U3: =SETUP!Z3 -> 10
A4: =SETUP!A4 -> Player | B4: Handi | C4: Par | D4: =SETUP!I4 -> 4 | E4: =SETUP!J4 -> 4 | F4: =SETUP!K4 -> 4 | G4: =SETUP!L4 -> 5 | H4: =SETUP!M4 -> 4 | I4: =SETUP!N4 -> 3 | J4: =SETUP!O4 -> 5 | K4: =SETUP!P4 -> 4 | ... U4: =SETUP!Z4 -> 4 | V4: =SUM(D4:L4) -> 36 | W4: =SUM(M4:U4) -> 36 | X4: =V4+W4 -> 72 | Z4: Alb | AA4: Eagle | AB4: Birdie | AC4: Par | AD4: Bogey | AE4: Double | AF4: Triple | AG4: Quad+
A5: =SETUP!A5 -> Aaron J | B5: {=if(A5="","",index(SETUP!C:C,match(A5,SETUP!A:A,0)))} -> 9 | D5: 5 | E5: 4 | F5: 4 | G5: 6 | H5: 5 | I5: 3 | J5: 6 | K5: 6 | L5: 3 | M5: 5 | N5: 5 | O5: 8 | P5: 3 | Q5: 6 | R5: 3 | S5: 4 | T5: 3 | U5: 4 | V5: =if(C5="WD","WD", SUM(D5:L5)) -> 42 | W5: =if(C5="WD","WD",SUM(M5:U5)) -> 41 | X5: =if(C5="WD","WD",IF(W5>0,V5+W5,"")) -> 83 | Y5: =if(C5="WD","WD",IF(W5=0,"",X5-B5)) -> 74 | Z5: {=sum(if(D5-$D$4=-3,1,0),if(E5-$E$4=-3,1,0),if(F5-$F$4=-3,1,0),if(G5-$G$4=-3,1,0),if(H5-$H$4=-3,1,0),if(I5-$I$4=-3,1,0),if(J5-$J$4=-3,1,0),if(K5-$K$4=-3,1,0),if(L5-$L$4=-3,1,0),if(M5-$M$4=-3,1,0),if(N5-$N$4=-3,1,0),if(O5-$O$4=-3,1,0),if(P5-$P$4=-3,1,0),if(Q5-$Q$4=-3,1,0),if(R5-$R$4=-3,1,0),if(S5-$S$4=-3,1,0),if(T5-$T$4=-3,1,0),if(U5-$U$4=-3,1,0))} -> 0 | AA5: {=sum(if(D5-$D$4=-2,1,0),if(E5-$E$4=-2,1,0),if(F5-$F$4=-2,1,0),if(G5-$G$4=-2,1,0),if(H5-$H$4=-2,1,0),if(I5-$I$4=-2,1,0),if(J5-$J$4=-2,1,0),if(K5-$K$4=-2,1,0),if(L5-$L$4=-2,1,0),if(M5-$M$4=-2,1,0),if(N5-$N$4=-2,1,0),if(O5-$O$4=-2,1,0),if(P5-$P$4=-2,1,0),if(Q5-$Q$4=-2,1,0),if(R5-$R$4=-2,1,0),if(S5-$S$4=-2,1,0),if(T5-$T$4=-2,1,0),if(U5-$U$4=-2,1,0))} -> 0 | AB5: {=sum(if(D5-$D$4=-1,1,0),if(E5-$E$4=-1,1,0),if(F5-$F$4=-1,1,0),if(G5-$G$4=-1,1,0),if(H5-$H$4=-1,1,0),if(I5-$I$4=-1,1,0),if(J5-$J$4=-1,1,0),if(K5-$K$4=-1,1,0),if(L5-$L$4=-1,1,0),if(M5-$M$4=-1,1,0),if(N5-$N$4=-1,1,0),if(O5-$O$4=-1,1,0),if(P5-$P$4=-1,1,0),if(Q5-$Q$4=-1,1,0),if(R5-$R$4=-1,1,0),if(S5-$S$4=-1,1,0),if(T5-$T$4=-1,1,0),if(U5-$U$4=-1,1,0))} -> 2 | AC5: {=sum(if(D5-$D$4=0,1,0),if(E5-$E$4=0,1,0),if(F5-$F$4=0,1,0),if(G5-$G$4=0,1,0),if(H5-$H$4=0,1,0),if(I5-$I$4=0,1,0),if(J5-$J$4=0,1,0),if(K5-$K$4=0,1,0),if(L5-$L$4=0,1,0),if(M5-$M$4=0,1,0),if(N5-$N$4=0,1,0),if(O5-$O$4=0,1,0),if(P5-$P$4=0,1,0),if(Q5-$Q$4=0,1,0),if(R5-$R$4=0,1,0),if(S5-$S$4=0,1,0),if(T5-$T$4=0,1,0),if(U5-$U$4=0,1,0))} -> 8 | AD5: {=sum(if(D5-$D$4=1,1,0),if(E5-$E$4=1,1,0),if(F5-$F$4=1,1,0),if(G5-$G$4=1,1,0),if(H5-$H$4=1,1,0),if(I5-$I$4=1,1,0),if(J5-$J$4=1,1,0),if(K5-$K$4=1,1,0),if(L5-$L$4=1,1,0),if(M5-$M$4=1,1,0),if(N5-$N$4=1,1,0),if(O5-$O$4=1,1,0),if(P5-$P$4=1,1,0),if(Q5-$Q$4=1,1,0),if(R5-$R$4=1,1,0),if(S5-$S$4=1,1,0),if(T5-$T$4=1,1,0),if(U5-$U$4=1,1,0))} -> 5 | AE5: {=sum(if(D5-$D$4=2,1,0),if(E5-$E$4=2,1,0),if(F5-$F$4=2,1,0),if(G5-$G$4=2,1,0),if(H5-$H$4=2,1,0),if(I5-$I$4=2,1,0),if(J5-$J$4=2,1,0),if(K5-$K$4=2,1,0),if(L5-$L$4=2,1,0),if(M5-$M$4=2,1,0),if(N5-$N$4=2,1,0),if(O5-$O$4=2,1,0),if(P5-$P$4=2,1,0),if(Q5-$Q$4=2,1,0),if(R5-$R$4=2,1,0),if(S5-$S$4=2,1,0),if(T5-$T$4=2,1,0),if(U5-$U$4=2,1,0))} -> 2 | AF5: {=sum(if(D5-$D$4=3,1,0),if(E5-$E$4=3,1,0),if(F5-$F$4=3,1,0),if(G5-$G$4=3,1,0),if(H5-$H$4=3,1,0),if(I5-$I$4=3,1,0),if(J5-$J$4=3,1,0),if(K5-$K$4=3,1,0),if(L5-$L$4=3,1,0),if(M5-$M$4=3,1,0),if(N5-$N$4=3,1,0),if(O5-$O$4=3,1,0),if(P5-$P$4=3,1,0),if(Q5-$Q$4=3,1,0),if(R5-$R$4=3,1,0),if(S5-$S$4=3,1,0),if(T5-$T$4=3,1,0),if(U5-$U$4=3,1,0))} -> 0 | AG5: {=sum(if(D5-$D$4>3,1,0),if(E5-$E$4>3,1,0),if(F5-$F$4>3,1,0),if(G5-$G$4>3,1,0),if(H5-$H$4>3,1,0),if(I5-$I$4>3,1,0),if(J5-$J$4>3,1,0),if(K5-$K$4>3,1,0),if(L5-$L$4>3,1,0),if(M5-$M$4>3,1,0),if(N5-$N$4>3,1,0),if(O5-$O$4>3,1,0),if(P5-$P$4>3,1,0),if(Q5-$Q$4>3,1,0),if(R5-$R$4>3,1,0),if(S5-$S$4>3,1,0),if(T5-$T$4>3,1,0),if(U5-$U$4>3,1,0))} -> 1 | AH5: =sum(Z5:AG5) -> 18
A6: =SETUP!A6 -> Andy V | B6: {=if(A6="","",index(SETUP!C:C,match(A6,SETUP!A:A,0)))} -> 22 | D6: 6 | E6: 7 | F6: 4 | G6: 6 | H6: 6 | I6: 7 | J6: 7 | K6: 8 | L6: 5 | M6: 8 | N6: 8 | O6: 5 | P6: 3 | Q6: 6 | R6: 5 | S6: 6 | T6: 3 | U6: 4 | V6: =if(C6="WD","WD", SUM(D6:L6)) -> 56 | W6: =if(C6="WD","WD",SUM(M6:U6)) -> 48 | X6: =if(C6="WD","WD",IF(W6>0,V6+W6,"")) -> 104 | Y6: =if(C6="WD","WD",IF(W6=0,"",X6-B6)) -> 82 | Z6: {=sum(if(D6-$D$4=-3,1,0),if(E6-$E$4=-3,1,0),if(F6-$F$4=-3,1,0),if(G6-$G$4=-3,1,0),if(H6-$H$4=-3,1,0),if(I6-$I$4=-3,1,0),if(J6-$J$4=-3,1,0),if(K6-$K$4=-3,1,0),if(L6-$L$4=-3,1,0),if(M6-$M$4=-3,1,0),if(N6-$N$4=-3,1,0),if(O6-$O$4=-3,1,0),if(P6-$P$4=-3,1,0),if(Q6-$Q$4=-3,1,0),if(R6-$R$4=-3,1,0),if(S6-$S$4=-3,1,0),if(T6-$T$4=-3,1,0),if(U6-$U$4=-3,1,0))} -> 0 | AA6: {=sum(if(D6-$D$4=-2,1,0),if(E6-$E$4=-2,1,0),if(F6-$F$4=-2,1,0),if(G6-$G$4=-2,1,0),if(H6-$H$4=-2,1,0),if(I6-$I$4=-2,1,0),if(J6-$J$4=-2,1,0),if(K6-$K$4=-2,1,0),if(L6-$L$4=-2,1,0),if(M6-$M$4=-2,1,0),if(N6-$N$4=-2,1,0),if(O6-$O$4=-2,1,0),if(P6-$P$4=-2,1,0),if(Q6-$Q$4=-2,1,0),if(R6-$R$4=-2,1,0),if(S6-$S$4=-2,1,0),if(T6-$T$4=-2,1,0),if(U6-$U$4=-2,1,0))} -> 0 | AB6: {=sum(if(D6-$D$4=-1,1,0),if(E6-$E$4=-1,1,0),if(F6-$F$4=-1,1,0),if(G6-$G$4=-1,1,0),if(H6-$H$4=-1,1,0),if(I6-$I$4=-1,1,0),if(J6-$J$4=-1,1,0),if(K6-$K$4=-1,1,0),if(L6-$L$4=-1,1,0),if(M6-$M$4=-1,1,0),if(N6-$N$4=-1,1,0),if(O6-$O$4=-1,1,0),if(P6-$P$4=-1,1,0),if(Q6-$Q$4=-1,1,0),if(R6-$R$4=-1,1,0),if(S6-$S$4=-1,1,0),if(T6-$T$4=-1,1,0),if(U6-$U$4=-1,1,0))} -> 0 | AC6: {=sum(if(D6-$D$4=0,1,0),if(E6-$E$4=0,1,0),if(F6-$F$4=0,1,0),if(G6-$G$4=0,1,0),if(H6-$H$4=0,1,0),if(I6-$I$4=0,1,0),if(J6-$J$4=0,1,0),if(K6-$K$4=0,1,0),if(L6-$L$4=0,1,0),if(M6-$M$4=0,1,0),if(N6-$N$4=0,1,0),if(O6-$O$4=0,1,0),if(P6-$P$4=0,1,0),if(Q6-$Q$4=0,1,0),if(R6-$R$4=0,1,0),if(S6-$S$4=0,1,0),if(T6-$T$4=0,1,0),if(U6-$U$4=0,1,0))} -> 4 | AD6: {=sum(if(D6-$D$4=1,1,0),if(E6-$E$4=1,1,0),if(F6-$F$4=1,1,0),if(G6-$G$4=1,1,0),if(H6-$H$4=1,1,0),if(I6-$I$4=1,1,0),if(J6-$J$4=1,1,0),if(K6-$K$4=1,1,0),if(L6-$L$4=1,1,0),if(M6-$M$4=1,1,0),if(N6-$N$4=1,1,0),if(O6-$O$4=1,1,0),if(P6-$P$4=1,1,0),if(Q6-$Q$4=1,1,0),if(R6-$R$4=1,1,0),if(S6-$S$4=1,1,0),if(T6-$T$4=1,1,0),if(U6-$U$4=1,1,0))} -> 4 | AE6: {=sum(if(D6-$D$4=2,1,0),if(E6-$E$4=2,1,0),if(F6-$F$4=2,1,0),if(G6-$G$4=2,1,0),if(H6-$H$4=2,1,0),if(I6-$I$4=2,1,0),if(J6-$J$4=2,1,0),if(K6-$K$4=2,1,0),if(L6-$L$4=2,1,0),if(M6-$M$4=2,1,0),if(N6-$N$4=2,1,0),if(O6-$O$4=2,1,0),if(P6-$P$4=2,1,0),if(Q6-$Q$4=2,1,0),if(R6-$R$4=2,1,0),if(S6-$S$4=2,1,0),if(T6-$T$4=2,1,0),if(U6-$U$4=2,1,0))} -> 5 | AF6: {=sum(if(D6-$D$4=3,1,0),if(E6-$E$4=3,1,0),if(F6-$F$4=3,1,0),if(G6-$G$4=3,1,0),if(H6-$H$4=3,1,0),if(I6-$I$4=3,1,0),if(J6-$J$4=3,1,0),if(K6-$K$4=3,1,0),if(L6-$L$4=3,1,0),if(M6-$M$4=3,1,0),if(N6-$N$4=3,1,0),if(O6-$O$4=3,1,0),if(P6-$P$4=3,1,0),if(Q6-$Q$4=3,1,0),if(R6-$R$4=3,1,0),if(S6-$S$4=3,1,0),if(T6-$T$4=3,1,0),if(U6-$U$4=3,1,0))} -> 2 | AG6: {=sum(if(D6-$D$4>3,1,0),if(E6-$E$4>3,1,0),if(F6-$F$4>3,1,0),if(G6-$G$4>3,1,0),if(H6-$H$4>3,1,0),if(I6-$I$4>3,1,0),if(J6-$J$4>3,1,0),if(K6-$K$4>3,1,0),if(L6-$L$4>3,1,0),if(M6-$M$4>3,1,0),if(N6-$N$4>3,1,0),if(O6-$O$4>3,1,0),if(P6-$P$4>3,1,0),if(Q6-$Q$4>3,1,0),if(R6-$R$4>3,1,0),if(S6-$S$4>3,1,0),if(T6-$T$4>3,1,0),if(U6-$U$4>3,1,0))} -> 3 | AH6: =sum(Z6:AG6) -> 18
A7: =SETUP!A7 -> Bob B | B7: {=if(A7="","",index(SETUP!C:C,match(A7,SETUP!A:A,0)))} -> 20 | D7: 5 | E7: 6 | F7: 5 | G7: 8 | H7: 6 | I7: 3 | J7: 8 | K7: 6 | L7: 6 | M7: 5 | N7: 5 | O7: 5 | P7: 3 | Q7: 5 | R7: 7 | S7: 6 | T7: 3 | U7: 4 | V7: =if(C7="WD","WD", SUM(D7:L7)) -> 53 | W7: =if(C7="WD","WD",SUM(M7:U7)) -> 43 | X7: =if(C7="WD","WD",IF(W7>0,V7+W7,"")) -> 96 | Y7: =if(C7="WD","WD",IF(W7=0,"",X7-B7)) -> 76 | Z7: {=sum(if(D7-$D$4=-3,1,0),if(E7-$E$4=-3,1,0),if(F7-$F$4=-3,1,0),if(G7-$G$4=-3,1,0),if(H7-$H$4=-3,1,0),if(I7-$I$4=-3,1,0),if(J7-$J$4=-3,1,0),if(K7-$K$4=-3,1,0),if(L7-$L$4=-3,1,0),if(M7-$M$4=-3,1,0),if(N7-$N$4=-3,1,0),if(O7-$O$4=-3,1,0),if(P7-$P$4=-3,1,0),if(Q7-$Q$4=-3,1,0),if(R7-$R$4=-3,1,0),if(S7-$S$4=-3,1,0),if(T7-$T$4=-3,1,0),if(U7-$U$4=-3,1,0))} -> 0 | AA7: {=sum(if(D7-$D$4=-2,1,0),if(E7-$E$4=-2,1,0),if(F7-$F$4=-2,1,0),if(G7-$G$4=-2,1,0),if(H7-$H$4=-2,1,0),if(I7-$I$4=-2,1,0),if(J7-$J$4=-2,1,0),if(K7-$K$4=-2,1,0),if(L7-$L$4=-2,1,0),if(M7-$M$4=-2,1,0),if(N7-$N$4=-2,1,0),if(O7-$O$4=-2,1,0),if(P7-$P$4=-2,1,0),if(Q7-$Q$4=-2,1,0),if(R7-$R$4=-2,1,0),if(S7-$S$4=-2,1,0),if(T7-$T$4=-2,1,0),if(U7-$U$4=-2,1,0))} -> 0 | AB7: {=sum(if(D7-$D$4=-1,1,0),if(E7-$E$4=-1,1,0),if(F7-$F$4=-1,1,0),if(G7-$G$4=-1,1,0),if(H7-$H$4=-1,1,0),if(I7-$I$4=-1,1,0),if(J7-$J$4=-1,1,0),if(K7-$K$4=-1,1,0),if(L7-$L$4=-1,1,0),if(M7-$M$4=-1,1,0),if(N7-$N$4=-1,1,0),if(O7-$O$4=-1,1,0),if(P7-$P$4=-1,1,0),if(Q7-$Q$4=-1,1,0),if(R7-$R$4=-1,1,0),if(S7-$S$4=-1,1,0),if(T7-$T$4=-1,1,0),if(U7-$U$4=-1,1,0))} -> 0 | AC7: {=sum(if(D7-$D$4=0,1,0),if(E7-$E$4=0,1,0),if(F7-$F$4=0,1,0),if(G7-$G$4=0,1,0),if(H7-$H$4=0,1,0),if(I7-$I$4=0,1,0),if(J7-$J$4=0,1,0),if(K7-$K$4=0,1,0),if(L7-$L$4=0,1,0),if(M7-$M$4=0,1,0),if(N7-$N$4=0,1,0),if(O7-$O$4=0,1,0),if(P7-$P$4=0,1,0),if(Q7-$Q$4=0,1,0),if(R7-$R$4=0,1,0),if(S7-$S$4=0,1,0),if(T7-$T$4=0,1,0),if(U7-$U$4=0,1,0))} -> 5 | AD7: {=sum(if(D7-$D$4=1,1,0),if(E7-$E$4=1,1,0),if(F7-$F$4=1,1,0),if(G7-$G$4=1,1,0),if(H7-$H$4=1,1,0),if(I7-$I$4=1,1,0),if(J7-$J$4=1,1,0),if(K7-$K$4=1,1,0),if(L7-$L$4=1,1,0),if(M7-$M$4=1,1,0),if(N7-$N$4=1,1,0),if(O7-$O$4=1,1,0),if(P7-$P$4=1,1,0),if(Q7-$Q$4=1,1,0),if(R7-$R$4=1,1,0),if(S7-$S$4=1,1,0),if(T7-$T$4=1,1,0),if(U7-$U$4=1,1,0))} -> 6 | AE7: {=sum(if(D7-$D$4=2,1,0),if(E7-$E$4=2,1,0),if(F7-$F$4=2,1,0),if(G7-$G$4=2,1,0),if(H7-$H$4=2,1,0),if(I7-$I$4=2,1,0),if(J7-$J$4=2,1,0),if(K7-$K$4=2,1,0),if(L7-$L$4=2,1,0),if(M7-$M$4=2,1,0),if(N7-$N$4=2,1,0),if(O7-$O$4=2,1,0),if(P7-$P$4=2,1,0),if(Q7-$Q$4=2,1,0),if(R7-$R$4=2,1,0),if(S7-$S$4=2,1,0),if(T7-$T$4=2,1,0),if(U7-$U$4=2,1,0))} -> 3 | AF7: {=sum(if(D7-$D$4=3,1,0),if(E7-$E$4=3,1,0),if(F7-$F$4=3,1,0),if(G7-$G$4=3,1,0),if(H7-$H$4=3,1,0),if(I7-$I$4=3,1,0),if(J7-$J$4=3,1,0),if(K7-$K$4=3,1,0),if(L7-$L$4=3,1,0),if(M7-$M$4=3,1,0),if(N7-$N$4=3,1,0),if(O7-$O$4=3,1,0),if(P7-$P$4=3,1,0),if(Q7-$Q$4=3,1,0),if(R7-$R$4=3,1,0),if(S7-$S$4=3,1,0),if(T7-$T$4=3,1,0),if(U7-$U$4=3,1,0))} -> 4 | AG7: {=sum(if(D7-$D$4>3,1,0),if(E7-$E$4>3,1,0),if(F7-$F$4>3,1,0),if(G7-$G$4>3,1,0),if(H7-$H$4>3,1,0),if(I7-$I$4>3,1,0),if(J7-$J$4>3,1,0),if(K7-$K$4>3,1,0),if(L7-$L$4>3,1,0),if(M7-$M$4>3,1,0),if(N7-$N$4>3,1,0),if(O7-$O$4>3,1,0),if(P7-$P$4>3,1,0),if(Q7-$Q$4>3,1,0),if(R7-$R$4>3,1,0),if(S7-$S$4>3,1,0),if(T7-$T$4>3,1,0),if(U7-$U$4>3,1,0))} -> 0 | AH7: =sum(Z7:AG7) -> 18
A8: =SETUP!A8 -> Brian K | B8: {=if(A8="","",index(SETUP!C:C,match(A8,SETUP!A:A,0)))} -> 13 | D8: 4 | E8: 6 | F8: 6 | G8: 7 | H8: 5 | I8: 4 | J8: 8 | K8: 5 | L8: 4 | M8: 4 | N8: 8 | O8: 4 | P8: 3 | Q8: 4 | R8: 4 | S8: 6 | T8: 3 | U8: 4 | V8: =if(C8="WD","WD", SUM(D8:L8)) -> 49 | W8: =if(C8="WD","WD",SUM(M8:U8)) -> 40 | X8: =if(C8="WD","WD",IF(W8>0,V8+W8,"")) -> 89 | Y8: =if(C8="WD","WD",IF(W8=0,"",X8-B8)) -> 76 | Z8: {=sum(if(D8-$D$4=-3,1,0),if(E8-$E$4=-3,1,0),if(F8-$F$4=-3,1,0),if(G8-$G$4=-3,1,0),if(H8-$H$4=-3,1,0),if(I8-$I$4=-3,1,0),if(J8-$J$4=-3,1,0),if(K8-$K$4=-3,1,0),if(L8-$L$4=-3,1,0),if(M8-$M$4=-3,1,0),if(N8-$N$4=-3,1,0),if(O8-$O$4=-3,1,0),if(P8-$P$4=-3,1,0),if(Q8-$Q$4=-3,1,0),if(R8-$R$4=-3,1,0),if(S8-$S$4=-3,1,0),if(T8-$T$4=-3,1,0),if(U8-$U$4=-3,1,0))} -> 0 | AA8: {=sum(if(D8-$D$4=-2,1,0),if(E8-$E$4=-2,1,0),if(F8-$F$4=-2,1,0),if(G8-$G$4=-2,1,0),if(H8-$H$4=-2,1,0),if(I8-$I$4=-2,1,0),if(J8-$J$4=-2,1,0),if(K8-$K$4=-2,1,0),if(L8-$L$4=-2,1,0),if(M8-$M$4=-2,1,0),if(N8-$N$4=-2,1,0),if(O8-$O$4=-2,1,0),if(P8-$P$4=-2,1,0),if(Q8-$Q$4=-2,1,0),if(R8-$R$4=-2,1,0),if(S8-$S$4=-2,1,0),if(T8-$T$4=-2,1,0),if(U8-$U$4=-2,1,0))} -> 0 | AB8: {=sum(if(D8-$D$4=-1,1,0),if(E8-$E$4=-1,1,0),if(F8-$F$4=-1,1,0),if(G8-$G$4=-1,1,0),if(H8-$H$4=-1,1,0),if(I8-$I$4=-1,1,0),if(J8-$J$4=-1,1,0),if(K8-$K$4=-1,1,0),if(L8-$L$4=-1,1,0),if(M8-$M$4=-1,1,0),if(N8-$N$4=-1,1,0),if(O8-$O$4=-1,1,0),if(P8-$P$4=-1,1,0),if(Q8-$Q$4=-1,1,0),if(R8-$R$4=-1,1,0),if(S8-$S$4=-1,1,0),if(T8-$T$4=-1,1,0),if(U8-$U$4=-1,1,0))} -> 0 | AC8: {=sum(if(D8-$D$4=0,1,0),if(E8-$E$4=0,1,0),if(F8-$F$4=0,1,0),if(G8-$G$4=0,1,0),if(H8-$H$4=0,1,0),if(I8-$I$4=0,1,0),if(J8-$J$4=0,1,0),if(K8-$K$4=0,1,0),if(L8-$L$4=0,1,0),if(M8-$M$4=0,1,0),if(N8-$N$4=0,1,0),if(O8-$O$4=0,1,0),if(P8-$P$4=0,1,0),if(Q8-$Q$4=0,1,0),if(R8-$R$4=0,1,0),if(S8-$S$4=0,1,0),if(T8-$T$4=0,1,0),if(U8-$U$4=0,1,0))} -> 8 | AD8: {=sum(if(D8-$D$4=1,1,0),if(E8-$E$4=1,1,0),if(F8-$F$4=1,1,0),if(G8-$G$4=1,1,0),if(H8-$H$4=1,1,0),if(I8-$I$4=1,1,0),if(J8-$J$4=1,1,0),if(K8-$K$4=1,1,0),if(L8-$L$4=1,1,0),if(M8-$M$4=1,1,0),if(N8-$N$4=1,1,0),if(O8-$O$4=1,1,0),if(P8-$P$4=1,1,0),if(Q8-$Q$4=1,1,0),if(R8-$R$4=1,1,0),if(S8-$S$4=1,1,0),if(T8-$T$4=1,1,0),if(U8-$U$4=1,1,0))} -> 5 | AE8: {=sum(if(D8-$D$4=2,1,0),if(E8-$E$4=2,1,0),if(F8-$F$4=2,1,0),if(G8-$G$4=2,1,0),if(H8-$H$4=2,1,0),if(I8-$I$4=2,1,0),if(J8-$J$4=2,1,0),if(K8-$K$4=2,1,0),if(L8-$L$4=2,1,0),if(M8-$M$4=2,1,0),if(N8-$N$4=2,1,0),if(O8-$O$4=2,1,0),if(P8-$P$4=2,1,0),if(Q8-$Q$4=2,1,0),if(R8-$R$4=2,1,0),if(S8-$S$4=2,1,0),if(T8-$T$4=2,1,0),if(U8-$U$4=2,1,0))} -> 3 | AF8: {=sum(if(D8-$D$4=3,1,0),if(E8-$E$4=3,1,0),if(F8-$F$4=3,1,0),if(G8-$G$4=3,1,0),if(H8-$H$4=3,1,0),if(I8-$I$4=3,1,0),if(J8-$J$4=3,1,0),if(K8-$K$4=3,1,0),if(L8-$L$4=3,1,0),if(M8-$M$4=3,1,0),if(N8-$N$4=3,1,0),if(O8-$O$4=3,1,0),if(P8-$P$4=3,1,0),if(Q8-$Q$4=3,1,0),if(R8-$R$4=3,1,0),if(S8-$S$4=3,1,0),if(T8-$T$4=3,1,0),if(U8-$U$4=3,1,0))} -> 2 | AG8: {=sum(if(D8-$D$4>3,1,0),if(E8-$E$4>3,1,0),if(F8-$F$4>3,1,0),if(G8-$G$4>3,1,0),if(H8-$H$4>3,1,0),if(I8-$I$4>3,1,0),if(J8-$J$4>3,1,0),if(K8-$K$4>3,1,0),if(L8-$L$4>3,1,0),if(M8-$M$4>3,1,0),if(N8-$N$4>3,1,0),if(O8-$O$4>3,1,0),if(P8-$P$4>3,1,0),if(Q8-$Q$4>3,1,0),if(R8-$R$4>3,1,0),if(S8-$S$4>3,1,0),if(T8-$T$4>3,1,0),if(U8-$U$4>3,1,0))} -> 0 | AH8: =sum(Z8:AG8) -> 18
A9: =SETUP!A9 -> Dave K | B9: {=if(A9="","",index(SETUP!C:C,match(A9,SETUP!A:A,0)))} -> 20 | D9: 5 | E9: 5 | F9: 4 | G9: 8 | H9: 4 | I9: 5 | J9: 8 | K9: 4 | L9: 5 | M9: 5 | N9: 5 | O9: 5 | P9: 5 | Q9: 5 | R9: 5 | S9: 7 | T9: 4 | U9: 4 | V9: =if(C9="WD","WD", SUM(D9:L9)) -> 48 | W9: =if(C9="WD","WD",SUM(M9:U9)) -> 45 | X9: =if(C9="WD","WD",IF(W9>0,V9+W9,"")) -> 93 | Y9: =if(C9="WD","WD",IF(W9=0,"",X9-B9)) -> 73 | Z9: {=sum(if(D9-$D$4=-3,1,0),if(E9-$E$4=-3,1,0),if(F9-$F$4=-3,1,0),if(G9-$G$4=-3,1,0),if(H9-$H$4=-3,1,0),if(I9-$I$4=-3,1,0),if(J9-$J$4=-3,1,0),if(K9-$K$4=-3,1,0),if(L9-$L$4=-3,1,0),if(M9-$M$4=-3,1,0),if(N9-$N$4=-3,1,0),if(O9-$O$4=-3,1,0),if(P9-$P$4=-3,1,0),if(Q9-$Q$4=-3,1,0),if(R9-$R$4=-3,1,0),if(S9-$S$4=-3,1,0),if(T9-$T$4=-3,1,0),if(U9-$U$4=-3,1,0))} -> 0 | AA9: {=sum(if(D9-$D$4=-2,1,0),if(E9-$E$4=-2,1,0),if(F9-$F$4=-2,1,0),if(G9-$G$4=-2,1,0),if(H9-$H$4=-2,1,0),if(I9-$I$4=-2,1,0),if(J9-$J$4=-2,1,0),if(K9-$K$4=-2,1,0),if(L9-$L$4=-2,1,0),if(M9-$M$4=-2,1,0),if(N9-$N$4=-2,1,0),if(O9-$O$4=-2,1,0),if(P9-$P$4=-2,1,0),if(Q9-$Q$4=-2,1,0),if(R9-$R$4=-2,1,0),if(S9-$S$4=-2,1,0),if(T9-$T$4=-2,1,0),if(U9-$U$4=-2,1,0))} -> 0 | AB9: {=sum(if(D9-$D$4=-1,1,0),if(E9-$E$4=-1,1,0),if(F9-$F$4=-1,1,0),if(G9-$G$4=-1,1,0),if(H9-$H$4=-1,1,0),if(I9-$I$4=-1,1,0),if(J9-$J$4=-1,1,0),if(K9-$K$4=-1,1,0),if(L9-$L$4=-1,1,0),if(M9-$M$4=-1,1,0),if(N9-$N$4=-1,1,0),if(O9-$O$4=-1,1,0),if(P9-$P$4=-1,1,0),if(Q9-$Q$4=-1,1,0),if(R9-$R$4=-1,1,0),if(S9-$S$4=-1,1,0),if(T9-$T$4=-1,1,0),if(U9-$U$4=-1,1,0))} -> 0 | AC9: {=sum(if(D9-$D$4=0,1,0),if(E9-$E$4=0,1,0),if(F9-$F$4=0,1,0),if(G9-$G$4=0,1,0),if(H9-$H$4=0,1,0),if(I9-$I$4=0,1,0),if(J9-$J$4=0,1,0),if(K9-$K$4=0,1,0),if(L9-$L$4=0,1,0),if(M9-$M$4=0,1,0),if(N9-$N$4=0,1,0),if(O9-$O$4=0,1,0),if(P9-$P$4=0,1,0),if(Q9-$Q$4=0,1,0),if(R9-$R$4=0,1,0),if(S9-$S$4=0,1,0),if(T9-$T$4=0,1,0),if(U9-$U$4=0,1,0))} -> 5 | AD9: {=sum(if(D9-$D$4=1,1,0),if(E9-$E$4=1,1,0),if(F9-$F$4=1,1,0),if(G9-$G$4=1,1,0),if(H9-$H$4=1,1,0),if(I9-$I$4=1,1,0),if(J9-$J$4=1,1,0),if(K9-$K$4=1,1,0),if(L9-$L$4=1,1,0),if(M9-$M$4=1,1,0),if(N9-$N$4=1,1,0),if(O9-$O$4=1,1,0),if(P9-$P$4=1,1,0),if(Q9-$Q$4=1,1,0),if(R9-$R$4=1,1,0),if(S9-$S$4=1,1,0),if(T9-$T$4=1,1,0),if(U9-$U$4=1,1,0))} -> 7 | AE9: {=sum(if(D9-$D$4=2,1,0),if(E9-$E$4=2,1,0),if(F9-$F$4=2,1,0),if(G9-$G$4=2,1,0),if(H9-$H$4=2,1,0),if(I9-$I$4=2,1,0),if(J9-$J$4=2,1,0),if(K9-$K$4=2,1,0),if(L9-$L$4=2,1,0),if(M9-$M$4=2,1,0),if(N9-$N$4=2,1,0),if(O9-$O$4=2,1,0),if(P9-$P$4=2,1,0),if(Q9-$Q$4=2,1,0),if(R9-$R$4=2,1,0),if(S9-$S$4=2,1,0),if(T9-$T$4=2,1,0),if(U9-$U$4=2,1,0))} -> 4 | AF9: {=sum(if(D9-$D$4=3,1,0),if(E9-$E$4=3,1,0),if(F9-$F$4=3,1,0),if(G9-$G$4=3,1,0),if(H9-$H$4=3,1,0),if(I9-$I$4=3,1,0),if(J9-$J$4=3,1,0),if(K9-$K$4=3,1,0),if(L9-$L$4=3,1,0),if(M9-$M$4=3,1,0),if(N9-$N$4=3,1,0),if(O9-$O$4=3,1,0),if(P9-$P$4=3,1,0),if(Q9-$Q$4=3,1,0),if(R9-$R$4=3,1,0),if(S9-$S$4=3,1,0),if(T9-$T$4=3,1,0),if(U9-$U$4=3,1,0))} -> 2 | AG9: {=sum(if(D9-$D$4>3,1,0),if(E9-$E$4>3,1,0),if(F9-$F$4>3,1,0),if(G9-$G$4>3,1,0),if(H9-$H$4>3,1,0),if(I9-$I$4>3,1,0),if(J9-$J$4>3,1,0),if(K9-$K$4>3,1,0),if(L9-$L$4>3,1,0),if(M9-$M$4>3,1,0),if(N9-$N$4>3,1,0),if(O9-$O$4>3,1,0),if(P9-$P$4>3,1,0),if(Q9-$Q$4>3,1,0),if(R9-$R$4>3,1,0),if(S9-$S$4>3,1,0),if(T9-$T$4>3,1,0),if(U9-$U$4>3,1,0))} -> 0 | AH9: =sum(Z9:AG9) -> 18
A10: =SETUP!A10 -> Eric O | B10: {=if(A10="","",index(SETUP!C:C,match(A10,SETUP!A:A,0)))} -> 19 | D10: 4 | E10: 4 | F10: 5 | G10: 6 | H10: 6 | I10: 5 | J10: 7 | K10: 8 | L10: 4 | M10: 5 | N10: 6 | O10: 7 | P10: 6 | Q10: 4 | R10: 6 | S10: 7 | T10: 4 | U10: 7 | V10: =if(C10="WD","WD", SUM(D10:L10)) -> 49 | W10: =if(C10="WD","WD",SUM(M10:U10)) -> 52 | X10: =if(C10="WD","WD",IF(W10>0,V10+W10,"")) -> 101 | Y10: =if(C10="WD","WD",IF(W10=0,"",X10-B10)) -> 82 | Z10: {=sum(if(D10-$D$4=-3,1,0),if(E10-$E$4=-3,1,0),if(F10-$F$4=-3,1,0),if(G10-$G$4=-3,1,0),if(H10-$H$4=-3,1,0),if(I10-$I$4=-3,1,0),if(J10-$J$4=-3,1,0),if(K10-$K$4=-3,1,0),if(L10-$L$4=-3,1,0),if(M10-$M$4=-3,1,0),if(N10-$N$4=-3,1,0),if(O10-$O$4=-3,1,0),if(P10-$P$4=-3,1,0),if(Q10-$Q$4=-3,1,0),if(R10-$R$4=-3,1,0),if(S10-$S$4=-3,1,0),if(T10-$T$4=-3,1,0),if(U10-$U$4=-3,1,0))} -> 0 | AA10: {=sum(if(D10-$D$4=-2,1,0),if(E10-$E$4=-2,1,0),if(F10-$F$4=-2,1,0),if(G10-$G$4=-2,1,0),if(H10-$H$4=-2,1,0),if(I10-$I$4=-2,1,0),if(J10-$J$4=-2,1,0),if(K10-$K$4=-2,1,0),if(L10-$L$4=-2,1,0),if(M10-$M$4=-2,1,0),if(N10-$N$4=-2,1,0),if(O10-$O$4=-2,1,0),if(P10-$P$4=-2,1,0),if(Q10-$Q$4=-2,1,0),if(R10-$R$4=-2,1,0),if(S10-$S$4=-2,1,0),if(T10-$T$4=-2,1,0),if(U10-$U$4=-2,1,0))} -> 0 | AB10: {=sum(if(D10-$D$4=-1,1,0),if(E10-$E$4=-1,1,0),if(F10-$F$4=-1,1,0),if(G10-$G$4=-1,1,0),if(H10-$H$4=-1,1,0),if(I10-$I$4=-1,1,0),if(J10-$J$4=-1,1,0),if(K10-$K$4=-1,1,0),if(L10-$L$4=-1,1,0),if(M10-$M$4=-1,1,0),if(N10-$N$4=-1,1,0),if(O10-$O$4=-1,1,0),if(P10-$P$4=-1,1,0),if(Q10-$Q$4=-1,1,0),if(R10-$R$4=-1,1,0),if(S10-$S$4=-1,1,0),if(T10-$T$4=-1,1,0),if(U10-$U$4=-1,1,0))} -> 0 | AC10: {=sum(if(D10-$D$4=0,1,0),if(E10-$E$4=0,1,0),if(F10-$F$4=0,1,0),if(G10-$G$4=0,1,0),if(H10-$H$4=0,1,0),if(I10-$I$4=0,1,0),if(J10-$J$4=0,1,0),if(K10-$K$4=0,1,0),if(L10-$L$4=0,1,0),if(M10-$M$4=0,1,0),if(N10-$N$4=0,1,0),if(O10-$O$4=0,1,0),if(P10-$P$4=0,1,0),if(Q10-$Q$4=0,1,0),if(R10-$R$4=0,1,0),if(S10-$S$4=0,1,0),if(T10-$T$4=0,1,0),if(U10-$U$4=0,1,0))} -> 3 | AD10: {=sum(if(D10-$D$4=1,1,0),if(E10-$E$4=1,1,0),if(F10-$F$4=1,1,0),if(G10-$G$4=1,1,0),if(H10-$H$4=1,1,0),if(I10-$I$4=1,1,0),if(J10-$J$4=1,1,0),if(K10-$K$4=1,1,0),if(L10-$L$4=1,1,0),if(M10-$M$4=1,1,0),if(N10-$N$4=1,1,0),if(O10-$O$4=1,1,0),if(P10-$P$4=1,1,0),if(Q10-$Q$4=1,1,0),if(R10-$R$4=1,1,0),if(S10-$S$4=1,1,0),if(T10-$T$4=1,1,0),if(U10-$U$4=1,1,0))} -> 6 | AE10: {=sum(if(D10-$D$4=2,1,0),if(E10-$E$4=2,1,0),if(F10-$F$4=2,1,0),if(G10-$G$4=2,1,0),if(H10-$H$4=2,1,0),if(I10-$I$4=2,1,0),if(J10-$J$4=2,1,0),if(K10-$K$4=2,1,0),if(L10-$L$4=2,1,0),if(M10-$M$4=2,1,0),if(N10-$N$4=2,1,0),if(O10-$O$4=2,1,0),if(P10-$P$4=2,1,0),if(Q10-$Q$4=2,1,0),if(R10-$R$4=2,1,0),if(S10-$S$4=2,1,0),if(T10-$T$4=2,1,0),if(U10-$U$4=2,1,0))} -> 5 | AF10: {=sum(if(D10-$D$4=3,1,0),if(E10-$E$4=3,1,0),if(F10-$F$4=3,1,0),if(G10-$G$4=3,1,0),if(H10-$H$4=3,1,0),if(I10-$I$4=3,1,0),if(J10-$J$4=3,1,0),if(K10-$K$4=3,1,0),if(L10-$L$4=3,1,0),if(M10-$M$4=3,1,0),if(N10-$N$4=3,1,0),if(O10-$O$4=3,1,0),if(P10-$P$4=3,1,0),if(Q10-$Q$4=3,1,0),if(R10-$R$4=3,1,0),if(S10-$S$4=3,1,0),if(T10-$T$4=3,1,0),if(U10-$U$4=3,1,0))} -> 3 | AG10: {=sum(if(D10-$D$4>3,1,0),if(E10-$E$4>3,1,0),if(F10-$F$4>3,1,0),if(G10-$G$4>3,1,0),if(H10-$H$4>3,1,0),if(I10-$I$4>3,1,0),if(J10-$J$4>3,1,0),if(K10-$K$4>3,1,0),if(L10-$L$4>3,1,0),if(M10-$M$4>3,1,0),if(N10-$N$4>3,1,0),if(O10-$O$4>3,1,0),if(P10-$P$4>3,1,0),if(Q10-$Q$4>3,1,0),if(R10-$R$4>3,1,0),if(S10-$S$4>3,1,0),if(T10-$T$4>3,1,0),if(U10-$U$4>3,1,0))} -> 1 | AH10: =sum(Z10:AG10) -> 18
A11: =SETUP!A11 -> Jeff B | B11: {=if(A11="","",index(SETUP!C:C,match(A11,SETUP!A:A,0)))} -> 22 | D11: 4 | E11: 6 | F11: 6 | G11: 5 | H11: 6 | I11: 4 | J11: 9 | K11: 5 | L11: 4 | M11: 4 | N11: 5 | O11: 6 | P11: 4 | Q11: 8 | R11: 6 | S11: 7 | T11: 5 | U11: 5 | V11: =if(C11="WD","WD", SUM(D11:L11)) -> 49 | W11: =if(C11="WD","WD",SUM(M11:U11)) -> 50 | X11: =if(C11="WD","WD",IF(W11>0,V11+W11,"")) -> 99 | Y11: =if(C11="WD","WD",IF(W11=0,"",X11-B11)) -> 77 | Z11: {=sum(if(D11-$D$4=-3,1,0),if(E11-$E$4=-3,1,0),if(F11-$F$4=-3,1,0),if(G11-$G$4=-3,1,0),if(H11-$H$4=-3,1,0),if(I11-$I$4=-3,1,0),if(J11-$J$4=-3,1,0),if(K11-$K$4=-3,1,0),if(L11-$L$4=-3,1,0),if(M11-$M$4=-3,1,0),if(N11-$N$4=-3,1,0),if(O11-$O$4=-3,1,0),if(P11-$P$4=-3,1,0),if(Q11-$Q$4=-3,1,0),if(R11-$R$4=-3,1,0),if(S11-$S$4=-3,1,0),if(T11-$T$4=-3,1,0),if(U11-$U$4=-3,1,0))} -> 0 | AA11: {=sum(if(D11-$D$4=-2,1,0),if(E11-$E$4=-2,1,0),if(F11-$F$4=-2,1,0),if(G11-$G$4=-2,1,0),if(H11-$H$4=-2,1,0),if(I11-$I$4=-2,1,0),if(J11-$J$4=-2,1,0),if(K11-$K$4=-2,1,0),if(L11-$L$4=-2,1,0),if(M11-$M$4=-2,1,0),if(N11-$N$4=-2,1,0),if(O11-$O$4=-2,1,0),if(P11-$P$4=-2,1,0),if(Q11-$Q$4=-2,1,0),if(R11-$R$4=-2,1,0),if(S11-$S$4=-2,1,0),if(T11-$T$4=-2,1,0),if(U11-$U$4=-2,1,0))} -> 0 | AB11: {=sum(if(D11-$D$4=-1,1,0),if(E11-$E$4=-1,1,0),if(F11-$F$4=-1,1,0),if(G11-$G$4=-1,1,0),if(H11-$H$4=-1,1,0),if(I11-$I$4=-1,1,0),if(J11-$J$4=-1,1,0),if(K11-$K$4=-1,1,0),if(L11-$L$4=-1,1,0),if(M11-$M$4=-1,1,0),if(N11-$N$4=-1,1,0),if(O11-$O$4=-1,1,0),if(P11-$P$4=-1,1,0),if(Q11-$Q$4=-1,1,0),if(R11-$R$4=-1,1,0),if(S11-$S$4=-1,1,0),if(T11-$T$4=-1,1,0),if(U11-$U$4=-1,1,0))} -> 0 | AC11: {=sum(if(D11-$D$4=0,1,0),if(E11-$E$4=0,1,0),if(F11-$F$4=0,1,0),if(G11-$G$4=0,1,0),if(H11-$H$4=0,1,0),if(I11-$I$4=0,1,0),if(J11-$J$4=0,1,0),if(K11-$K$4=0,1,0),if(L11-$L$4=0,1,0),if(M11-$M$4=0,1,0),if(N11-$N$4=0,1,0),if(O11-$O$4=0,1,0),if(P11-$P$4=0,1,0),if(Q11-$Q$4=0,1,0),if(R11-$R$4=0,1,0),if(S11-$S$4=0,1,0),if(T11-$T$4=0,1,0),if(U11-$U$4=0,1,0))} -> 4 | AD11: {=sum(if(D11-$D$4=1,1,0),if(E11-$E$4=1,1,0),if(F11-$F$4=1,1,0),if(G11-$G$4=1,1,0),if(H11-$H$4=1,1,0),if(I11-$I$4=1,1,0),if(J11-$J$4=1,1,0),if(K11-$K$4=1,1,0),if(L11-$L$4=1,1,0),if(M11-$M$4=1,1,0),if(N11-$N$4=1,1,0),if(O11-$O$4=1,1,0),if(P11-$P$4=1,1,0),if(Q11-$Q$4=1,1,0),if(R11-$R$4=1,1,0),if(S11-$S$4=1,1,0),if(T11-$T$4=1,1,0),if(U11-$U$4=1,1,0))} -> 5 | AE11: {=sum(if(D11-$D$4=2,1,0),if(E11-$E$4=2,1,0),if(F11-$F$4=2,1,0),if(G11-$G$4=2,1,0),if(H11-$H$4=2,1,0),if(I11-$I$4=2,1,0),if(J11-$J$4=2,1,0),if(K11-$K$4=2,1,0),if(L11-$L$4=2,1,0),if(M11-$M$4=2,1,0),if(N11-$N$4=2,1,0),if(O11-$O$4=2,1,0),if(P11-$P$4=2,1,0),if(Q11-$Q$4=2,1,0),if(R11-$R$4=2,1,0),if(S11-$S$4=2,1,0),if(T11-$T$4=2,1,0),if(U11-$U$4=2,1,0))} -> 7 | AF11: {=sum(if(D11-$D$4=3,1,0),if(E11-$E$4=3,1,0),if(F11-$F$4=3,1,0),if(G11-$G$4=3,1,0),if(H11-$H$4=3,1,0),if(I11-$I$4=3,1,0),if(J11-$J$4=3,1,0),if(K11-$K$4=3,1,0),if(L11-$L$4=3,1,0),if(M11-$M$4=3,1,0),if(N11-$N$4=3,1,0),if(O11-$O$4=3,1,0),if(P11-$P$4=3,1,0),if(Q11-$Q$4=3,1,0),if(R11-$R$4=3,1,0),if(S11-$S$4=3,1,0),if(T11-$T$4=3,1,0),if(U11-$U$4=3,1,0))} -> 0 | AG11: {=sum(if(D11-$D$4>3,1,0),if(E11-$E$4>3,1,0),if(F11-$F$4>3,1,0),if(G11-$G$4>3,1,0),if(H11-$H$4>3,1,0),if(I11-$I$4>3,1,0),if(J11-$J$4>3,1,0),if(K11-$K$4>3,1,0),if(L11-$L$4>3,1,0),if(M11-$M$4>3,1,0),if(N11-$N$4>3,1,0),if(O11-$O$4>3,1,0),if(P11-$P$4>3,1,0),if(Q11-$Q$4>3,1,0),if(R11-$R$4>3,1,0),if(S11-$S$4>3,1,0),if(T11-$T$4>3,1,0),if(U11-$U$4>3,1,0))} -> 2 | AH11: =sum(Z11:AG11) -> 18
A12: =SETUP!A12 -> Joe S | B12: {=if(A12="","",index(SETUP!C:C,match(A12,SETUP!A:A,0)))} -> 15 | D12: 5 | E12: 5 | F12: 5 | G12: 7 | H12: 5 | I12: 4 | J12: 6 | K12: 5 | L12: 5 | M12: 5 | N12: 4 | O12: 5 | P12: 4 | Q12: 6 | R12: 4 | S12: 5 | T12: 3 | U12: 4 | V12: =if(C12="WD","WD", SUM(D12:L12)) -> 47 | W12: =if(C12="WD","WD",SUM(M12:U12)) -> 40 | X12: =if(C12="WD","WD",IF(W12>0,V12+W12,"")) -> 87 | Y12: =if(C12="WD","WD",IF(W12=0,"",X12-B12)) -> 72 | Z12: {=sum(if(D12-$D$4=-3,1,0),if(E12-$E$4=-3,1,0),if(F12-$F$4=-3,1,0),if(G12-$G$4=-3,1,0),if(H12-$H$4=-3,1,0),if(I12-$I$4=-3,1,0),if(J12-$J$4=-3,1,0),if(K12-$K$4=-3,1,0),if(L12-$L$4=-3,1,0),if(M12-$M$4=-3,1,0),if(N12-$N$4=-3,1,0),if(O12-$O$4=-3,1,0),if(P12-$P$4=-3,1,0),if(Q12-$Q$4=-3,1,0),if(R12-$R$4=-3,1,0),if(S12-$S$4=-3,1,0),if(T12-$T$4=-3,1,0),if(U12-$U$4=-3,1,0))} -> 0 | AA12: {=sum(if(D12-$D$4=-2,1,0),if(E12-$E$4=-2,1,0),if(F12-$F$4=-2,1,0),if(G12-$G$4=-2,1,0),if(H12-$H$4=-2,1,0),if(I12-$I$4=-2,1,0),if(J12-$J$4=-2,1,0),if(K12-$K$4=-2,1,0),if(L12-$L$4=-2,1,0),if(M12-$M$4=-2,1,0),if(N12-$N$4=-2,1,0),if(O12-$O$4=-2,1,0),if(P12-$P$4=-2,1,0),if(Q12-$Q$4=-2,1,0),if(R12-$R$4=-2,1,0),if(S12-$S$4=-2,1,0),if(T12-$T$4=-2,1,0),if(U12-$U$4=-2,1,0))} -> 0 | AB12: {=sum(if(D12-$D$4=-1,1,0),if(E12-$E$4=-1,1,0),if(F12-$F$4=-1,1,0),if(G12-$G$4=-1,1,0),if(H12-$H$4=-1,1,0),if(I12-$I$4=-1,1,0),if(J12-$J$4=-1,1,0),if(K12-$K$4=-1,1,0),if(L12-$L$4=-1,1,0),if(M12-$M$4=-1,1,0),if(N12-$N$4=-1,1,0),if(O12-$O$4=-1,1,0),if(P12-$P$4=-1,1,0),if(Q12-$Q$4=-1,1,0),if(R12-$R$4=-1,1,0),if(S12-$S$4=-1,1,0),if(T12-$T$4=-1,1,0),if(U12-$U$4=-1,1,0))} -> 1 | AC12: {=sum(if(D12-$D$4=0,1,0),if(E12-$E$4=0,1,0),if(F12-$F$4=0,1,0),if(G12-$G$4=0,1,0),if(H12-$H$4=0,1,0),if(I12-$I$4=0,1,0),if(J12-$J$4=0,1,0),if(K12-$K$4=0,1,0),if(L12-$L$4=0,1,0),if(M12-$M$4=0,1,0),if(N12-$N$4=0,1,0),if(O12-$O$4=0,1,0),if(P12-$P$4=0,1,0),if(Q12-$Q$4=0,1,0),if(R12-$R$4=0,1,0),if(S12-$S$4=0,1,0),if(T12-$T$4=0,1,0),if(U12-$U$4=0,1,0))} -> 4 | AD12: {=sum(if(D12-$D$4=1,1,0),if(E12-$E$4=1,1,0),if(F12-$F$4=1,1,0),if(G12-$G$4=1,1,0),if(H12-$H$4=1,1,0),if(I12-$I$4=1,1,0),if(J12-$J$4=1,1,0),if(K12-$K$4=1,1,0),if(L12-$L$4=1,1,0),if(M12-$M$4=1,1,0),if(N12-$N$4=1,1,0),if(O12-$O$4=1,1,0),if(P12-$P$4=1,1,0),if(Q12-$Q$4=1,1,0),if(R12-$R$4=1,1,0),if(S12-$S$4=1,1,0),if(T12-$T$4=1,1,0),if(U12-$U$4=1,1,0))} -> 10 | AE12: {=sum(if(D12-$D$4=2,1,0),if(E12-$E$4=2,1,0),if(F12-$F$4=2,1,0),if(G12-$G$4=2,1,0),if(H12-$H$4=2,1,0),if(I12-$I$4=2,1,0),if(J12-$J$4=2,1,0),if(K12-$K$4=2,1,0),if(L12-$L$4=2,1,0),if(M12-$M$4=2,1,0),if(N12-$N$4=2,1,0),if(O12-$O$4=2,1,0),if(P12-$P$4=2,1,0),if(Q12-$Q$4=2,1,0),if(R12-$R$4=2,1,0),if(S12-$S$4=2,1,0),if(T12-$T$4=2,1,0),if(U12-$U$4=2,1,0))} -> 3 | AF12: {=sum(if(D12-$D$4=3,1,0),if(E12-$E$4=3,1,0),if(F12-$F$4=3,1,0),if(G12-$G$4=3,1,0),if(H12-$H$4=3,1,0),if(I12-$I$4=3,1,0),if(J12-$J$4=3,1,0),if(K12-$K$4=3,1,0),if(L12-$L$4=3,1,0),if(M12-$M$4=3,1,0),if(N12-$N$4=3,1,0),if(O12-$O$4=3,1,0),if(P12-$P$4=3,1,0),if(Q12-$Q$4=3,1,0),if(R12-$R$4=3,1,0),if(S12-$S$4=3,1,0),if(T12-$T$4=3,1,0),if(U12-$U$4=3,1,0))} -> 0 | AG12: {=sum(if(D12-$D$4>3,1,0),if(E12-$E$4>3,1,0),if(F12-$F$4>3,1,0),if(G12-$G$4>3,1,0),if(H12-$H$4>3,1,0),if(I12-$I$4>3,1,0),if(J12-$J$4>3,1,0),if(K12-$K$4>3,1,0),if(L12-$L$4>3,1,0),if(M12-$M$4>3,1,0),if(N12-$N$4>3,1,0),if(O12-$O$4>3,1,0),if(P12-$P$4>3,1,0),if(Q12-$Q$4>3,1,0),if(R12-$R$4>3,1,0),if(S12-$S$4>3,1,0),if(T12-$T$4>3,1,0),if(U12-$U$4>3,1,0))} -> 0 | AH12: =sum(Z12:AG12) -> 18
A13: =SETUP!A13 -> John C | B13: {=if(A13="","",index(SETUP!C:C,match(A13,SETUP!A:A,0)))} -> 23 | D13: 7 | E13: 6 | F13: 4 | G13: 7 | H13: 5 | I13: 3 | J13: 6 | K13: 4 | L13: 3 | M13: 7 | N13: 7 | O13: 5 | P13: 3 | Q13: 5 | R13: 5 | S13: 6 | T13: 5 | U13: 6 | V13: =if(C13="WD","WD", SUM(D13:L13)) -> 45 | W13: =if(C13="WD","WD",SUM(M13:U13)) -> 49 | X13: =if(C13="WD","WD",IF(W13>0,V13+W13,"")) -> 94 | Y13: =if(C13="WD","WD",IF(W13=0,"",X13-B13)) -> 71 | Z13: {=sum(if(D13-$D$4=-3,1,0),if(E13-$E$4=-3,1,0),if(F13-$F$4=-3,1,0),if(G13-$G$4=-3,1,0),if(H13-$H$4=-3,1,0),if(I13-$I$4=-3,1,0),if(J13-$J$4=-3,1,0),if(K13-$K$4=-3,1,0),if(L13-$L$4=-3,1,0),if(M13-$M$4=-3,1,0),if(N13-$N$4=-3,1,0),if(O13-$O$4=-3,1,0),if(P13-$P$4=-3,1,0),if(Q13-$Q$4=-3,1,0),if(R13-$R$4=-3,1,0),if(S13-$S$4=-3,1,0),if(T13-$T$4=-3,1,0),if(U13-$U$4=-3,1,0))} -> 0 | AA13: {=sum(if(D13-$D$4=-2,1,0),if(E13-$E$4=-2,1,0),if(F13-$F$4=-2,1,0),if(G13-$G$4=-2,1,0),if(H13-$H$4=-2,1,0),if(I13-$I$4=-2,1,0),if(J13-$J$4=-2,1,0),if(K13-$K$4=-2,1,0),if(L13-$L$4=-2,1,0),if(M13-$M$4=-2,1,0),if(N13-$N$4=-2,1,0),if(O13-$O$4=-2,1,0),if(P13-$P$4=-2,1,0),if(Q13-$Q$4=-2,1,0),if(R13-$R$4=-2,1,0),if(S13-$S$4=-2,1,0),if(T13-$T$4=-2,1,0),if(U13-$U$4=-2,1,0))} -> 0 | AB13: {=sum(if(D13-$D$4=-1,1,0),if(E13-$E$4=-1,1,0),if(F13-$F$4=-1,1,0),if(G13-$G$4=-1,1,0),if(H13-$H$4=-1,1,0),if(I13-$I$4=-1,1,0),if(J13-$J$4=-1,1,0),if(K13-$K$4=-1,1,0),if(L13-$L$4=-1,1,0),if(M13-$M$4=-1,1,0),if(N13-$N$4=-1,1,0),if(O13-$O$4=-1,1,0),if(P13-$P$4=-1,1,0),if(Q13-$Q$4=-1,1,0),if(R13-$R$4=-1,1,0),if(S13-$S$4=-1,1,0),if(T13-$T$4=-1,1,0),if(U13-$U$4=-1,1,0))} -> 0 | AC13: {=sum(if(D13-$D$4=0,1,0),if(E13-$E$4=0,1,0),if(F13-$F$4=0,1,0),if(G13-$G$4=0,1,0),if(H13-$H$4=0,1,0),if(I13-$I$4=0,1,0),if(J13-$J$4=0,1,0),if(K13-$K$4=0,1,0),if(L13-$L$4=0,1,0),if(M13-$M$4=0,1,0),if(N13-$N$4=0,1,0),if(O13-$O$4=0,1,0),if(P13-$P$4=0,1,0),if(Q13-$Q$4=0,1,0),if(R13-$R$4=0,1,0),if(S13-$S$4=0,1,0),if(T13-$T$4=0,1,0),if(U13-$U$4=0,1,0))} -> 5 | AD13: {=sum(if(D13-$D$4=1,1,0),if(E13-$E$4=1,1,0),if(F13-$F$4=1,1,0),if(G13-$G$4=1,1,0),if(H13-$H$4=1,1,0),if(I13-$I$4=1,1,0),if(J13-$J$4=1,1,0),if(K13-$K$4=1,1,0),if(L13-$L$4=1,1,0),if(M13-$M$4=1,1,0),if(N13-$N$4=1,1,0),if(O13-$O$4=1,1,0),if(P13-$P$4=1,1,0),if(Q13-$Q$4=1,1,0),if(R13-$R$4=1,1,0),if(S13-$S$4=1,1,0),if(T13-$T$4=1,1,0),if(U13-$U$4=1,1,0))} -> 6 | AE13: {=sum(if(D13-$D$4=2,1,0),if(E13-$E$4=2,1,0),if(F13-$F$4=2,1,0),if(G13-$G$4=2,1,0),if(H13-$H$4=2,1,0),if(I13-$I$4=2,1,0),if(J13-$J$4=2,1,0),if(K13-$K$4=2,1,0),if(L13-$L$4=2,1,0),if(M13-$M$4=2,1,0),if(N13-$N$4=2,1,0),if(O13-$O$4=2,1,0),if(P13-$P$4=2,1,0),if(Q13-$Q$4=2,1,0),if(R13-$R$4=2,1,0),if(S13-$S$4=2,1,0),if(T13-$T$4=2,1,0),if(U13-$U$4=2,1,0))} -> 5 | AF13: {=sum(if(D13-$D$4=3,1,0),if(E13-$E$4=3,1,0),if(F13-$F$4=3,1,0),if(G13-$G$4=3,1,0),if(H13-$H$4=3,1,0),if(I13-$I$4=3,1,0),if(J13-$J$4=3,1,0),if(K13-$K$4=3,1,0),if(L13-$L$4=3,1,0),if(M13-$M$4=3,1,0),if(N13-$N$4=3,1,0),if(O13-$O$4=3,1,0),if(P13-$P$4=3,1,0),if(Q13-$Q$4=3,1,0),if(R13-$R$4=3,1,0),if(S13-$S$4=3,1,0),if(T13-$T$4=3,1,0),if(U13-$U$4=3,1,0))} -> 2 | AG13: {=sum(if(D13-$D$4>3,1,0),if(E13-$E$4>3,1,0),if(F13-$F$4>3,1,0),if(G13-$G$4>3,1,0),if(H13-$H$4>3,1,0),if(I13-$I$4>3,1,0),if(J13-$J$4>3,1,0),if(K13-$K$4>3,1,0),if(L13-$L$4>3,1,0),if(M13-$M$4>3,1,0),if(N13-$N$4>3,1,0),if(O13-$O$4>3,1,0),if(P13-$P$4>3,1,0),if(Q13-$Q$4>3,1,0),if(R13-$R$4>3,1,0),if(S13-$S$4>3,1,0),if(T13-$T$4>3,1,0),if(U13-$U$4>3,1,0))} -> 0 | AH13: =sum(Z13:AG13) -> 18
A14: =SETUP!A14 -> Ray H | B14: {=if(A14="","",index(SETUP!C:C,match(A14,SETUP!A:A,0)))} -> 23 | D14: 4 | E14: 7 | F14: 7 | G14: 7 | H14: 8 | I14: 5 | J14: 7 | K14: 7 | L14: 5 | M14: 5 | N14: 6 | O14: 4 | P14: 5 | Q14: 6 | R14: 6 | S14: 7 | T14: 5 | U14: 7 | V14: =if(C14="WD","WD", SUM(D14:L14)) -> 57 | W14: =if(C14="WD","WD",SUM(M14:U14)) -> 51 | X14: =if(C14="WD","WD",IF(W14>0,V14+W14,"")) -> 108 | Y14: =if(C14="WD","WD",IF(W14=0,"",X14-B14)) -> 85 | Z14: {=sum(if(D14-$D$4=-3,1,0),if(E14-$E$4=-3,1,0),if(F14-$F$4=-3,1,0),if(G14-$G$4=-3,1,0),if(H14-$H$4=-3,1,0),if(I14-$I$4=-3,1,0),if(J14-$J$4=-3,1,0),if(K14-$K$4=-3,1,0),if(L14-$L$4=-3,1,0),if(M14-$M$4=-3,1,0),if(N14-$N$4=-3,1,0),if(O14-$O$4=-3,1,0),if(P14-$P$4=-3,1,0),if(Q14-$Q$4=-3,1,0),if(R14-$R$4=-3,1,0),if(S14-$S$4=-3,1,0),if(T14-$T$4=-3,1,0),if(U14-$U$4=-3,1,0))} -> 0 | AA14: {=sum(if(D14-$D$4=-2,1,0),if(E14-$E$4=-2,1,0),if(F14-$F$4=-2,1,0),if(G14-$G$4=-2,1,0),if(H14-$H$4=-2,1,0),if(I14-$I$4=-2,1,0),if(J14-$J$4=-2,1,0),if(K14-$K$4=-2,1,0),if(L14-$L$4=-2,1,0),if(M14-$M$4=-2,1,0),if(N14-$N$4=-2,1,0),if(O14-$O$4=-2,1,0),if(P14-$P$4=-2,1,0),if(Q14-$Q$4=-2,1,0),if(R14-$R$4=-2,1,0),if(S14-$S$4=-2,1,0),if(T14-$T$4=-2,1,0),if(U14-$U$4=-2,1,0))} -> 0 | AB14: {=sum(if(D14-$D$4=-1,1,0),if(E14-$E$4=-1,1,0),if(F14-$F$4=-1,1,0),if(G14-$G$4=-1,1,0),if(H14-$H$4=-1,1,0),if(I14-$I$4=-1,1,0),if(J14-$J$4=-1,1,0),if(K14-$K$4=-1,1,0),if(L14-$L$4=-1,1,0),if(M14-$M$4=-1,1,0),if(N14-$N$4=-1,1,0),if(O14-$O$4=-1,1,0),if(P14-$P$4=-1,1,0),if(Q14-$Q$4=-1,1,0),if(R14-$R$4=-1,1,0),if(S14-$S$4=-1,1,0),if(T14-$T$4=-1,1,0),if(U14-$U$4=-1,1,0))} -> 0 | AC14: {=sum(if(D14-$D$4=0,1,0),if(E14-$E$4=0,1,0),if(F14-$F$4=0,1,0),if(G14-$G$4=0,1,0),if(H14-$H$4=0,1,0),if(I14-$I$4=0,1,0),if(J14-$J$4=0,1,0),if(K14-$K$4=0,1,0),if(L14-$L$4=0,1,0),if(M14-$M$4=0,1,0),if(N14-$N$4=0,1,0),if(O14-$O$4=0,1,0),if(P14-$P$4=0,1,0),if(Q14-$Q$4=0,1,0),if(R14-$R$4=0,1,0),if(S14-$S$4=0,1,0),if(T14-$T$4=0,1,0),if(U14-$U$4=0,1,0))} -> 2 | AD14: {=sum(if(D14-$D$4=1,1,0),if(E14-$E$4=1,1,0),if(F14-$F$4=1,1,0),if(G14-$G$4=1,1,0),if(H14-$H$4=1,1,0),if(I14-$I$4=1,1,0),if(J14-$J$4=1,1,0),if(K14-$K$4=1,1,0),if(L14-$L$4=1,1,0),if(M14-$M$4=1,1,0),if(N14-$N$4=1,1,0),if(O14-$O$4=1,1,0),if(P14-$P$4=1,1,0),if(Q14-$Q$4=1,1,0),if(R14-$R$4=1,1,0),if(S14-$S$4=1,1,0),if(T14-$T$4=1,1,0),if(U14-$U$4=1,1,0))} -> 2 | AE14: {=sum(if(D14-$D$4=2,1,0),if(E14-$E$4=2,1,0),if(F14-$F$4=2,1,0),if(G14-$G$4=2,1,0),if(H14-$H$4=2,1,0),if(I14-$I$4=2,1,0),if(J14-$J$4=2,1,0),if(K14-$K$4=2,1,0),if(L14-$L$4=2,1,0),if(M14-$M$4=2,1,0),if(N14-$N$4=2,1,0),if(O14-$O$4=2,1,0),if(P14-$P$4=2,1,0),if(Q14-$Q$4=2,1,0),if(R14-$R$4=2,1,0),if(S14-$S$4=2,1,0),if(T14-$T$4=2,1,0),if(U14-$U$4=2,1,0))} -> 9 | AF14: {=sum(if(D14-$D$4=3,1,0),if(E14-$E$4=3,1,0),if(F14-$F$4=3,1,0),if(G14-$G$4=3,1,0),if(H14-$H$4=3,1,0),if(I14-$I$4=3,1,0),if(J14-$J$4=3,1,0),if(K14-$K$4=3,1,0),if(L14-$L$4=3,1,0),if(M14-$M$4=3,1,0),if(N14-$N$4=3,1,0),if(O14-$O$4=3,1,0),if(P14-$P$4=3,1,0),if(Q14-$Q$4=3,1,0),if(R14-$R$4=3,1,0),if(S14-$S$4=3,1,0),if(T14-$T$4=3,1,0),if(U14-$U$4=3,1,0))} -> 4 | AG14: {=sum(if(D14-$D$4>3,1,0),if(E14-$E$4>3,1,0),if(F14-$F$4>3,1,0),if(G14-$G$4>3,1,0),if(H14-$H$4>3,1,0),if(I14-$I$4>3,1,0),if(J14-$J$4>3,1,0),if(K14-$K$4>3,1,0),if(L14-$L$4>3,1,0),if(M14-$M$4>3,1,0),if(N14-$N$4>3,1,0),if(O14-$O$4>3,1,0),if(P14-$P$4>3,1,0),if(Q14-$Q$4>3,1,0),if(R14-$R$4>3,1,0),if(S14-$S$4>3,1,0),if(T14-$T$4>3,1,0),if(U14-$U$4>3,1,0))} -> 1 | AH14: =sum(Z14:AG14) -> 18
A15: =SETUP!A15 -> Russ W | B15: {=if(A15="","",index(SETUP!C:C,match(A15,SETUP!A:A,0)))} -> 17 | D15: 5 | E15: 5 | F15: 6 | G15: 8 | H15: 4 | I15: 3 | J15: 7 | K15: 4 | L15: 4 | M15: 4 | N15: 5 | O15: 5 | P15: 4 | Q15: 5 | R15: 4 | S15: 6 | T15: 4 | U15: 5 | V15: =if(C15="WD","WD", SUM(D15:L15)) -> 46 | W15: =if(C15="WD","WD",SUM(M15:U15)) -> 42 | X15: =if(C15="WD","WD",IF(W15>0,V15+W15,"")) -> 88 | Y15: =if(C15="WD","WD",IF(W15=0,"",X15-B15)) -> 71 | Z15: {=sum(if(D15-$D$4=-3,1,0),if(E15-$E$4=-3,1,0),if(F15-$F$4=-3,1,0),if(G15-$G$4=-3,1,0),if(H15-$H$4=-3,1,0),if(I15-$I$4=-3,1,0),if(J15-$J$4=-3,1,0),if(K15-$K$4=-3,1,0),if(L15-$L$4=-3,1,0),if(M15-$M$4=-3,1,0),if(N15-$N$4=-3,1,0),if(O15-$O$4=-3,1,0),if(P15-$P$4=-3,1,0),if(Q15-$Q$4=-3,1,0),if(R15-$R$4=-3,1,0),if(S15-$S$4=-3,1,0),if(T15-$T$4=-3,1,0),if(U15-$U$4=-3,1,0))} -> 0 | AA15: {=sum(if(D15-$D$4=-2,1,0),if(E15-$E$4=-2,1,0),if(F15-$F$4=-2,1,0),if(G15-$G$4=-2,1,0),if(H15-$H$4=-2,1,0),if(I15-$I$4=-2,1,0),if(J15-$J$4=-2,1,0),if(K15-$K$4=-2,1,0),if(L15-$L$4=-2,1,0),if(M15-$M$4=-2,1,0),if(N15-$N$4=-2,1,0),if(O15-$O$4=-2,1,0),if(P15-$P$4=-2,1,0),if(Q15-$Q$4=-2,1,0),if(R15-$R$4=-2,1,0),if(S15-$S$4=-2,1,0),if(T15-$T$4=-2,1,0),if(U15-$U$4=-2,1,0))} -> 0 | AB15: {=sum(if(D15-$D$4=-1,1,0),if(E15-$E$4=-1,1,0),if(F15-$F$4=-1,1,0),if(G15-$G$4=-1,1,0),if(H15-$H$4=-1,1,0),if(I15-$I$4=-1,1,0),if(J15-$J$4=-1,1,0),if(K15-$K$4=-1,1,0),if(L15-$L$4=-1,1,0),if(M15-$M$4=-1,1,0),if(N15-$N$4=-1,1,0),if(O15-$O$4=-1,1,0),if(P15-$P$4=-1,1,0),if(Q15-$Q$4=-1,1,0),if(R15-$R$4=-1,1,0),if(S15-$S$4=-1,1,0),if(T15-$T$4=-1,1,0),if(U15-$U$4=-1,1,0))} -> 0 | AC15: {=sum(if(D15-$D$4=0,1,0),if(E15-$E$4=0,1,0),if(F15-$F$4=0,1,0),if(G15-$G$4=0,1,0),if(H15-$H$4=0,1,0),if(I15-$I$4=0,1,0),if(J15-$J$4=0,1,0),if(K15-$K$4=0,1,0),if(L15-$L$4=0,1,0),if(M15-$M$4=0,1,0),if(N15-$N$4=0,1,0),if(O15-$O$4=0,1,0),if(P15-$P$4=0,1,0),if(Q15-$Q$4=0,1,0),if(R15-$R$4=0,1,0),if(S15-$S$4=0,1,0),if(T15-$T$4=0,1,0),if(U15-$U$4=0,1,0))} -> 6 | AD15: {=sum(if(D15-$D$4=1,1,0),if(E15-$E$4=1,1,0),if(F15-$F$4=1,1,0),if(G15-$G$4=1,1,0),if(H15-$H$4=1,1,0),if(I15-$I$4=1,1,0),if(J15-$J$4=1,1,0),if(K15-$K$4=1,1,0),if(L15-$L$4=1,1,0),if(M15-$M$4=1,1,0),if(N15-$N$4=1,1,0),if(O15-$O$4=1,1,0),if(P15-$P$4=1,1,0),if(Q15-$Q$4=1,1,0),if(R15-$R$4=1,1,0),if(S15-$S$4=1,1,0),if(T15-$T$4=1,1,0),if(U15-$U$4=1,1,0))} -> 9 | AE15: {=sum(if(D15-$D$4=2,1,0),if(E15-$E$4=2,1,0),if(F15-$F$4=2,1,0),if(G15-$G$4=2,1,0),if(H15-$H$4=2,1,0),if(I15-$I$4=2,1,0),if(J15-$J$4=2,1,0),if(K15-$K$4=2,1,0),if(L15-$L$4=2,1,0),if(M15-$M$4=2,1,0),if(N15-$N$4=2,1,0),if(O15-$O$4=2,1,0),if(P15-$P$4=2,1,0),if(Q15-$Q$4=2,1,0),if(R15-$R$4=2,1,0),if(S15-$S$4=2,1,0),if(T15-$T$4=2,1,0),if(U15-$U$4=2,1,0))} -> 2 | AF15: {=sum(if(D15-$D$4=3,1,0),if(E15-$E$4=3,1,0),if(F15-$F$4=3,1,0),if(G15-$G$4=3,1,0),if(H15-$H$4=3,1,0),if(I15-$I$4=3,1,0),if(J15-$J$4=3,1,0),if(K15-$K$4=3,1,0),if(L15-$L$4=3,1,0),if(M15-$M$4=3,1,0),if(N15-$N$4=3,1,0),if(O15-$O$4=3,1,0),if(P15-$P$4=3,1,0),if(Q15-$Q$4=3,1,0),if(R15-$R$4=3,1,0),if(S15-$S$4=3,1,0),if(T15-$T$4=3,1,0),if(U15-$U$4=3,1,0))} -> 1 | AG15: {=sum(if(D15-$D$4>3,1,0),if(E15-$E$4>3,1,0),if(F15-$F$4>3,1,0),if(G15-$G$4>3,1,0),if(H15-$H$4>3,1,0),if(I15-$I$4>3,1,0),if(J15-$J$4>3,1,0),if(K15-$K$4>3,1,0),if(L15-$L$4>3,1,0),if(M15-$M$4>3,1,0),if(N15-$N$4>3,1,0),if(O15-$O$4>3,1,0),if(P15-$P$4>3,1,0),if(Q15-$Q$4>3,1,0),if(R15-$R$4>3,1,0),if(S15-$S$4>3,1,0),if(T15-$T$4>3,1,0),if(U15-$U$4>3,1,0))} -> 0 | AH15: =sum(Z15:AG15) -> 18
A16: =SETUP!A16 -> Scott R | B16: {=if(A16="","",index(SETUP!C:C,match(A16,SETUP!A:A,0)))} -> 10 | D16: 5 | E16: 4 | F16: 5 | G16: 6 | H16: 6 | I16: 3 | J16: 6 | K16: 4 | L16: 4 | M16: 5 | N16: 5 | O16: 5 | P16: 5 | Q16: 4 | R16: 4 | S16: 6 | T16: 3 | U16: 6 | V16: =if(C16="WD","WD", SUM(D16:L16)) -> 43 | W16: =if(C16="WD","WD",SUM(M16:U16)) -> 43 | X16: =if(C16="WD","WD",IF(W16>0,V16+W16,"")) -> 86 | Y16: =if(C16="WD","WD",IF(W16=0,"",X16-B16)) -> 76 | Z16: {=sum(if(D16-$D$4=-3,1,0),if(E16-$E$4=-3,1,0),if(F16-$F$4=-3,1,0),if(G16-$G$4=-3,1,0),if(H16-$H$4=-3,1,0),if(I16-$I$4=-3,1,0),if(J16-$J$4=-3,1,0),if(K16-$K$4=-3,1,0),if(L16-$L$4=-3,1,0),if(M16-$M$4=-3,1,0),if(N16-$N$4=-3,1,0),if(O16-$O$4=-3,1,0),if(P16-$P$4=-3,1,0),if(Q16-$Q$4=-3,1,0),if(R16-$R$4=-3,1,0),if(S16-$S$4=-3,1,0),if(T16-$T$4=-3,1,0),if(U16-$U$4=-3,1,0))} -> 0 | AA16: {=sum(if(D16-$D$4=-2,1,0),if(E16-$E$4=-2,1,0),if(F16-$F$4=-2,1,0),if(G16-$G$4=-2,1,0),if(H16-$H$4=-2,1,0),if(I16-$I$4=-2,1,0),if(J16-$J$4=-2,1,0),if(K16-$K$4=-2,1,0),if(L16-$L$4=-2,1,0),if(M16-$M$4=-2,1,0),if(N16-$N$4=-2,1,0),if(O16-$O$4=-2,1,0),if(P16-$P$4=-2,1,0),if(Q16-$Q$4=-2,1,0),if(R16-$R$4=-2,1,0),if(S16-$S$4=-2,1,0),if(T16-$T$4=-2,1,0),if(U16-$U$4=-2,1,0))} -> 0 | AB16: {=sum(if(D16-$D$4=-1,1,0),if(E16-$E$4=-1,1,0),if(F16-$F$4=-1,1,0),if(G16-$G$4=-1,1,0),if(H16-$H$4=-1,1,0),if(I16-$I$4=-1,1,0),if(J16-$J$4=-1,1,0),if(K16-$K$4=-1,1,0),if(L16-$L$4=-1,1,0),if(M16-$M$4=-1,1,0),if(N16-$N$4=-1,1,0),if(O16-$O$4=-1,1,0),if(P16-$P$4=-1,1,0),if(Q16-$Q$4=-1,1,0),if(R16-$R$4=-1,1,0),if(S16-$S$4=-1,1,0),if(T16-$T$4=-1,1,0),if(U16-$U$4=-1,1,0))} -> 0 | AC16: {=sum(if(D16-$D$4=0,1,0),if(E16-$E$4=0,1,0),if(F16-$F$4=0,1,0),if(G16-$G$4=0,1,0),if(H16-$H$4=0,1,0),if(I16-$I$4=0,1,0),if(J16-$J$4=0,1,0),if(K16-$K$4=0,1,0),if(L16-$L$4=0,1,0),if(M16-$M$4=0,1,0),if(N16-$N$4=0,1,0),if(O16-$O$4=0,1,0),if(P16-$P$4=0,1,0),if(Q16-$Q$4=0,1,0),if(R16-$R$4=0,1,0),if(S16-$S$4=0,1,0),if(T16-$T$4=0,1,0),if(U16-$U$4=0,1,0))} -> 7 | AD16: {=sum(if(D16-$D$4=1,1,0),if(E16-$E$4=1,1,0),if(F16-$F$4=1,1,0),if(G16-$G$4=1,1,0),if(H16-$H$4=1,1,0),if(I16-$I$4=1,1,0),if(J16-$J$4=1,1,0),if(K16-$K$4=1,1,0),if(L16-$L$4=1,1,0),if(M16-$M$4=1,1,0),if(N16-$N$4=1,1,0),if(O16-$O$4=1,1,0),if(P16-$P$4=1,1,0),if(Q16-$Q$4=1,1,0),if(R16-$R$4=1,1,0),if(S16-$S$4=1,1,0),if(T16-$T$4=1,1,0),if(U16-$U$4=1,1,0))} -> 8 | AE16: {=sum(if(D16-$D$4=2,1,0),if(E16-$E$4=2,1,0),if(F16-$F$4=2,1,0),if(G16-$G$4=2,1,0),if(H16-$H$4=2,1,0),if(I16-$I$4=2,1,0),if(J16-$J$4=2,1,0),if(K16-$K$4=2,1,0),if(L16-$L$4=2,1,0),if(M16-$M$4=2,1,0),if(N16-$N$4=2,1,0),if(O16-$O$4=2,1,0),if(P16-$P$4=2,1,0),if(Q16-$Q$4=2,1,0),if(R16-$R$4=2,1,0),if(S16-$S$4=2,1,0),if(T16-$T$4=2,1,0),if(U16-$U$4=2,1,0))} -> 3 | AF16: {=sum(if(D16-$D$4=3,1,0),if(E16-$E$4=3,1,0),if(F16-$F$4=3,1,0),if(G16-$G$4=3,1,0),if(H16-$H$4=3,1,0),if(I16-$I$4=3,1,0),if(J16-$J$4=3,1,0),if(K16-$K$4=3,1,0),if(L16-$L$4=3,1,0),if(M16-$M$4=3,1,0),if(N16-$N$4=3,1,0),if(O16-$O$4=3,1,0),if(P16-$P$4=3,1,0),if(Q16-$Q$4=3,1,0),if(R16-$R$4=3,1,0),if(S16-$S$4=3,1,0),if(T16-$T$4=3,1,0),if(U16-$U$4=3,1,0))} -> 0 | AG16: {=sum(if(D16-$D$4>3,1,0),if(E16-$E$4>3,1,0),if(F16-$F$4>3,1,0),if(G16-$G$4>3,1,0),if(H16-$H$4>3,1,0),if(I16-$I$4>3,1,0),if(J16-$J$4>3,1,0),if(K16-$K$4>3,1,0),if(L16-$L$4>3,1,0),if(M16-$M$4>3,1,0),if(N16-$N$4>3,1,0),if(O16-$O$4>3,1,0),if(P16-$P$4>3,1,0),if(Q16-$Q$4>3,1,0),if(R16-$R$4>3,1,0),if(S16-$S$4>3,1,0),if(T16-$T$4>3,1,0),if(U16-$U$4>3,1,0))} -> 0 | AH16: =sum(Z16:AG16) -> 18
C17: SKIN | D17: {=IF(SUM(IF(IF('Betting SETUP'!$D$5:$D$16="Y", D5:D16, 10)=MIN(IF('Betting SETUP'!$D$5:$D$16="Y", D5:D16, 10)), 1, 0)) > 1, "", INDEX('Betting SETUP'!$A$5:$A$16,MATCH(MIN(IF('Betting SETUP'!$D$5:$D$16="Y",D5:D16,10)),IF('Betting SETUP'!$D$5:$D$16="Y",D5:D16,10),0)))} | E17: {=IF(SUM(IF(IF('Betting SETUP'!$D$5:$D$16="Y", E5:E16, 10)=MIN(IF('Betting SETUP'!$D$5:$D$16="Y", E5:E16, 10)), 1, 0)) > 1, "", INDEX('Betting SETUP'!$A$5:$A$16,MATCH(MIN(IF('Betting SETUP'!$D$5:$D$16="Y",E5:E16,10)),IF('Betting SETUP'!$D$5:$D$16="Y",E5:E16,10),0)))} | F17: {=IF(SUM(IF(IF('Betting SETUP'!$D$5:$D$16="Y", F5:F16, 10)=MIN(IF('Betting SETUP'!$D$5:$D$16="Y", F5:F16, 10)), 1, 0)) > 1, "", INDEX('Betting SETUP'!$A$5:$A$16,MATCH(MIN(IF('Betting SETUP'!$D$5:$D$16="Y",F5:F16,10)),IF('Betting SETUP'!$D$5:$D$16="Y",F5:F16,10),0)))} | G17: {=IF(SUM(IF(IF('Betting SETUP'!$D$5:$D$16="Y", G5:G16, 10)=MIN(IF('Betting SETUP'!$D$5:$D$16="Y", G5:G16, 10)), 1, 0)) > 1, "", INDEX('Betting SETUP'!$A$5:$A$16,MATCH(MIN(IF('Betting SETUP'!$D$5:$D$16="Y",G5:G16,10)),IF('Betting SETUP'!$D$5:$D$16="Y",G5:G16,10),0)))} -> Jeff B | H17: {=IF(SUM(IF(IF('Betting SETUP'!$D$5:$D$16="Y", H5:H16, 10)=MIN(IF('Betting SETUP'!$D$5:$D$16="Y", H5:H16, 10)), 1, 0)) > 1, "", INDEX('Betting SETUP'!$A$5:$A$16,MATCH(MIN(IF('Betting SETUP'!$D$5:$D$16="Y",H5:H16,10)),IF('Betting SETUP'!$D$5:$D$16="Y",H5:H16,10),0)))} | I17: {=IF(SUM(IF(IF('Betting SETUP'!$D$5:$D$16="Y", I5:I16, 10)=MIN(IF('Betting SETUP'!$D$5:$D$16="Y", I5:I16, 10)), 1, 0)) > 1, "", INDEX('Betting SETUP'!$A$5:$A$16,MATCH(MIN(IF('Betting SETUP'!$D$5:$D$16="Y",I5:I16,10)),IF('Betting SETUP'!$D$5:$D$16="Y",I5:I16,10),0)))} | J17: {=IF(SUM(IF(IF('Betting SETUP'!$D$5:$D$16="Y", J5:J16, 10)=MIN(IF('Betting SETUP'!$D$5:$D$16="Y", J5:J16, 10)), 1, 0)) > 1, "", INDEX('Betting SETUP'!$A$5:$A$16,MATCH(MIN(IF('Betting SETUP'!$D$5:$D$16="Y",J5:J16,10)),IF('Betting SETUP'!$D$5:$D$16="Y",J5:J16,10),0)))} | K17: {=IF(SUM(IF(IF('Betting SETUP'!$D$5:$D$16="Y", K5:K16, 10)=MIN(IF('Betting SETUP'!$D$5:$D$16="Y", K5:K16, 10)), 1, 0)) > 1, "", INDEX('Betting SETUP'!$A$5:$A$16,MATCH(MIN(IF('Betting SETUP'!$D$5:$D$16="Y",K5:K16,10)),IF('Betting SETUP'!$D$5:$D$16="Y",K5:K16,10),0)))} | ... U17: {=IF(SUM(IF(IF('Betting SETUP'!$D$5:$D$16="Y", U5:U16, 10)=MIN(IF('Betting SETUP'!$D$5:$D$16="Y", U5:U16, 10)), 1, 0)) > 1, "", INDEX('Betting SETUP'!$A$5:$A$16,MATCH(MIN(IF('Betting SETUP'!$D$5:$D$16="Y",U5:U16,10)),IF('Betting SETUP'!$D$5:$D$16="Y",U5:U16,10),0)))} | X17: =18-COUNTBLANK(D17:U17) -> 4
C18: CTP | I18: Bob B | L18: Jeff B | P18: Brian K | T18: Brian K | X18: =COUNTA(D18:U18) -> 4
C20: =SETUP!D1 -> THE PREMIER | X20: =SETUP!D2 -> 71 | Y20: =SETUP!D3 -> 132
C21: Hole | D21: 1 | E21: 2 | F21: 3 | G21: 4 | H21: 5 | I21: 6 | J21: 7 | K21: 8 | L21: 9 | M21: 10 | N21: 11 | O21: 12 | P21: 13 | Q21: 14 | R21: 15 | S21: 16 | T21: 17 | U21: 18 | V21: OUT | W21: IN | X21: TOTAL | Y21: NET
C22: Handi | D22: =SETUP!I7 -> 5 | E22: =SETUP!J7 -> 11 | F22: =SETUP!K7 -> 1 | G22: =SETUP!L7 -> 13 | H22: =SETUP!M7 -> 17 | I22: =SETUP!N7 -> 15 | J22: =SETUP!O7 -> 3 | K22: =SETUP!P7 -> 7 | ... U22: =SETUP!Z7 -> 6
A23: Player | B23: Handi | C23: Par | D23: =SETUP!I8 -> 4 | E23: =SETUP!J8 -> 5 | F23: =SETUP!K8 -> 4 | G23: =SETUP!L8 -> 3 | H23: =SETUP!M8 -> 4 | I23: =SETUP!N8 -> 5 | J23: =SETUP!O8 -> 4 | K23: =SETUP!P8 -> 3 | ... U23: =SETUP!Z8 -> 4 | V23: =SUM(D23:L23) -> 36 | W23: =SUM(M23:U23) -> 36 | X23: =V23+W23 -> 72 | Z23: Alb | AA23: Eagle | AB23: Birdie | AC23: Par | AD23: Bogey | AE23: Double | AF23: Triple | AG23: Quad+
A24: =SETUP!A5 -> Aaron J | B24: {=if(A24="","",index(SETUP!D:D,match(A24,SETUP!A:A,0)))} -> 7 | D24: 5 | E24: 4 | F24: 4 | G24: 4 | H24: 4 | I24: 5 | J24: 6 | K24: 4 | L24: 5 | M24: 4 | N24: 4 | O24: 5 | P24: 4 | Q24: 4 | R24: 4 | S24: 7 | T24: 4 | U24: 7 | V24: =if(C24="WD","WD", SUM(D24:L24)) -> 41 | W24: =if(C24="WD","WD",SUM(M24:U24)) -> 43 | X24: =if(C24="WD","WD",IF(W24>0,V24+W24,"")) -> 84 | Y24: =if(C24="WD","WD",IF(W24=0,"",X24-B24)) -> 77 | Z24: {=sum(if(D24-$D$23=-3,1,0),if(E24-$E$23=-3,1,0),if(F24-$F$23=-3,1,0),if(G24-$G$23=-3,1,0),if(H24-$H$23=-3,1,0),if(I24-$I$23=-3,1,0),if(J24-$J$23=-3,1,0),if(K24-$K$23=-3,1,0),if(L24-$L$23=-3,1,0),if(M24-$M$23=-3,1,0),if(N24-$N$23=-3,1,0),if(O24-$O$23=-3,1,0),if(P24-$P$23=-3,1,0),if(Q24-$Q$23=-3,1,0),if(R24-$R$23=-3,1,0),if(S24-$S$23=-3,1,0),if(T24-$T$23=-3,1,0),if(U24-$U$23=-3,1,0))} -> 0 | AA24: {=sum(if(D24-$D$23=-2,1,0),if(E24-$E$23=-2,1,0),if(F24-$F$23=-2,1,0),if(G24-$G$23=-2,1,0),if(H24-$H$23=-2,1,0),if(I24-$I$23=-2,1,0),if(J24-$J$23=-2,1,0),if(K24-$K$23=-2,1,0),if(L24-$L$23=-2,1,0),if(M24-$M$23=-2,1,0),if(N24-$N$23=-2,1,0),if(O24-$O$23=-2,1,0),if(P24-$P$23=-2,1,0),if(Q24-$Q$23=-2,1,0),if(R24-$R$23=-2,1,0),if(S24-$S$23=-2,1,0),if(T24-$T$23=-2,1,0),if(U24-$U$23=-2,1,0))} -> 0 | AB24: {=sum(if(D24-$D$23=-1,1,0),if(E24-$E$23=-1,1,0),if(F24-$F$23=-1,1,0),if(G24-$G$23=-1,1,0),if(H24-$H$23=-1,1,0),if(I24-$I$23=-1,1,0),if(J24-$J$23=-1,1,0),if(K24-$K$23=-1,1,0),if(L24-$L$23=-1,1,0),if(M24-$M$23=-1,1,0),if(N24-$N$23=-1,1,0),if(O24-$O$23=-1,1,0),if(P24-$P$23=-1,1,0),if(Q24-$Q$23=-1,1,0),if(R24-$R$23=-1,1,0),if(S24-$S$23=-1,1,0),if(T24-$T$23=-1,1,0),if(U24-$U$23=-1,1,0))} -> 1 | AC24: {=sum(if(D24-$D$23=0,1,0),if(E24-$E$23=0,1,0),if(F24-$F$23=0,1,0),if(G24-$G$23=0,1,0),if(H24-$H$23=0,1,0),if(I24-$I$23=0,1,0),if(J24-$J$23=0,1,0),if(K24-$K$23=0,1,0),if(L24-$L$23=0,1,0),if(M24-$M$23=0,1,0),if(N24-$N$23=0,1,0),if(O24-$O$23=0,1,0),if(P24-$P$23=0,1,0),if(Q24-$Q$23=0,1,0),if(R24-$R$23=0,1,0),if(S24-$S$23=0,1,0),if(T24-$T$23=0,1,0),if(U24-$U$23=0,1,0))} -> 8 | AD24: {=sum(if(D24-$D$23=1,1,0),if(E24-$E$23=1,1,0),if(F24-$F$23=1,1,0),if(G24-$G$23=1,1,0),if(H24-$H$23=1,1,0),if(I24-$I$23=1,1,0),if(J24-$J$23=1,1,0),if(K24-$K$23=1,1,0),if(L24-$L$23=1,1,0),if(M24-$M$23=1,1,0),if(N24-$N$23=1,1,0),if(O24-$O$23=1,1,0),if(P24-$P$23=1,1,0),if(Q24-$Q$23=1,1,0),if(R24-$R$23=1,1,0),if(S24-$S$23=1,1,0),if(T24-$T$23=1,1,0),if(U24-$U$23=1,1,0))} -> 6 | AE24: {=sum(if(D24-$D$23=2,1,0),if(E24-$E$23=2,1,0),if(F24-$F$23=2,1,0),if(G24-$G$23=2,1,0),if(H24-$H$23=2,1,0),if(I24-$I$23=2,1,0),if(J24-$J$23=2,1,0),if(K24-$K$23=2,1,0),if(L24-$L$23=2,1,0),if(M24-$M$23=2,1,0),if(N24-$N$23=2,1,0),if(O24-$O$23=2,1,0),if(P24-$P$23=2,1,0),if(Q24-$Q$23=2,1,0),if(R24-$R$23=2,1,0),if(S24-$S$23=2,1,0),if(T24-$T$23=2,1,0),if(U24-$U$23=2,1,0))} -> 2 | AF24: {=sum(if(D24-$D$23=3,1,0),if(E24-$E$23=3,1,0),if(F24-$F$23=3,1,0),if(G24-$G$23=3,1,0),if(H24-$H$23=3,1,0),if(I24-$I$23=3,1,0),if(J24-$J$23=3,1,0),if(K24-$K$23=3,1,0),if(L24-$L$23=3,1,0),if(M24-$M$23=3,1,0),if(N24-$N$23=3,1,0),if(O24-$O$23=3,1,0),if(P24-$P$23=3,1,0),if(Q24-$Q$23=3,1,0),if(R24-$R$23=3,1,0),if(S24-$S$23=3,1,0),if(T24-$T$23=3,1,0),if(U24-$U$23=3,1,0))} -> 1 | AG24: {=sum(if(D24-$D$23>3,1,0),if(E24-$E$23>3,1,0),if(F24-$F$23>3,1,0),if(G24-$G$23>3,1,0),if(H24-$H$23>3,1,0),if(I24-$I$23>3,1,0),if(J24-$J$23>3,1,0),if(K24-$K$23>3,1,0),if(L24-$L$23>3,1,0),if(M24-$M$23>3,1,0),if(N24-$N$23>3,1,0),if(O24-$O$23>3,1,0),if(P24-$P$23>3,1,0),if(Q24-$Q$23>3,1,0),if(R24-$R$23>3,1,0),if(S24-$S$23>3,1,0),if(T24-$T$23>3,1,0),if(U24-$U$23>3,1,0))} -> 0 | AH24: =sum(Z24:AG24) -> 18
A25: =SETUP!A6 -> Andy V | B25: {=if(A25="","",index(SETUP!D:D,match(A25,SETUP!A:A,0)))} -> 19 | D25: 5 | E25: 7 | F25: 5 | G25: 3 | H25: 4 | I25: 7 | J25: 6 | K25: 7 | L25: 5 | M25: 4 | N25: 4 | O25: 6 | P25: 4 | Q25: 5 | R25: 5 | S25: 6 | T25: 4 | U25: 6 | V25: =if(C25="WD","WD", SUM(D25:L25)) -> 49 | W25: =if(C25="WD","WD",SUM(M25:U25)) -> 44 | X25: =if(C25="WD","WD",IF(W25>0,V25+W25,"")) -> 93 | Y25: =if(C25="WD","WD",IF(W25=0,"",X25-B25)) -> 74 | Z25: {=sum(if(D25-$D$23=-3,1,0),if(E25-$E$23=-3,1,0),if(F25-$F$23=-3,1,0),if(G25-$G$23=-3,1,0),if(H25-$H$23=-3,1,0),if(I25-$I$23=-3,1,0),if(J25-$J$23=-3,1,0),if(K25-$K$23=-3,1,0),if(L25-$L$23=-3,1,0),if(M25-$M$23=-3,1,0),if(N25-$N$23=-3,1,0),if(O25-$O$23=-3,1,0),if(P25-$P$23=-3,1,0),if(Q25-$Q$23=-3,1,0),if(R25-$R$23=-3,1,0),if(S25-$S$23=-3,1,0),if(T25-$T$23=-3,1,0),if(U25-$U$23=-3,1,0))} -> 0 | AA25: {=sum(if(D25-$D$23=-2,1,0),if(E25-$E$23=-2,1,0),if(F25-$F$23=-2,1,0),if(G25-$G$23=-2,1,0),if(H25-$H$23=-2,1,0),if(I25-$I$23=-2,1,0),if(J25-$J$23=-2,1,0),if(K25-$K$23=-2,1,0),if(L25-$L$23=-2,1,0),if(M25-$M$23=-2,1,0),if(N25-$N$23=-2,1,0),if(O25-$O$23=-2,1,0),if(P25-$P$23=-2,1,0),if(Q25-$Q$23=-2,1,0),if(R25-$R$23=-2,1,0),if(S25-$S$23=-2,1,0),if(T25-$T$23=-2,1,0),if(U25-$U$23=-2,1,0))} -> 0 | AB25: {=sum(if(D25-$D$23=-1,1,0),if(E25-$E$23=-1,1,0),if(F25-$F$23=-1,1,0),if(G25-$G$23=-1,1,0),if(H25-$H$23=-1,1,0),if(I25-$I$23=-1,1,0),if(J25-$J$23=-1,1,0),if(K25-$K$23=-1,1,0),if(L25-$L$23=-1,1,0),if(M25-$M$23=-1,1,0),if(N25-$N$23=-1,1,0),if(O25-$O$23=-1,1,0),if(P25-$P$23=-1,1,0),if(Q25-$Q$23=-1,1,0),if(R25-$R$23=-1,1,0),if(S25-$S$23=-1,1,0),if(T25-$T$23=-1,1,0),if(U25-$U$23=-1,1,0))} -> 0 | AC25: {=sum(if(D25-$D$23=0,1,0),if(E25-$E$23=0,1,0),if(F25-$F$23=0,1,0),if(G25-$G$23=0,1,0),if(H25-$H$23=0,1,0),if(I25-$I$23=0,1,0),if(J25-$J$23=0,1,0),if(K25-$K$23=0,1,0),if(L25-$L$23=0,1,0),if(M25-$M$23=0,1,0),if(N25-$N$23=0,1,0),if(O25-$O$23=0,1,0),if(P25-$P$23=0,1,0),if(Q25-$Q$23=0,1,0),if(R25-$R$23=0,1,0),if(S25-$S$23=0,1,0),if(T25-$T$23=0,1,0),if(U25-$U$23=0,1,0))} -> 4 | AD25: {=sum(if(D25-$D$23=1,1,0),if(E25-$E$23=1,1,0),if(F25-$F$23=1,1,0),if(G25-$G$23=1,1,0),if(H25-$H$23=1,1,0),if(I25-$I$23=1,1,0),if(J25-$J$23=1,1,0),if(K25-$K$23=1,1,0),if(L25-$L$23=1,1,0),if(M25-$M$23=1,1,0),if(N25-$N$23=1,1,0),if(O25-$O$23=1,1,0),if(P25-$P$23=1,1,0),if(Q25-$Q$23=1,1,0),if(R25-$R$23=1,1,0),if(S25-$S$23=1,1,0),if(T25-$T$23=1,1,0),if(U25-$U$23=1,1,0))} -> 9 | AE25: {=sum(if(D25-$D$23=2,1,0),if(E25-$E$23=2,1,0),if(F25-$F$23=2,1,0),if(G25-$G$23=2,1,0),if(H25-$H$23=2,1,0),if(I25-$I$23=2,1,0),if(J25-$J$23=2,1,0),if(K25-$K$23=2,1,0),if(L25-$L$23=2,1,0),if(M25-$M$23=2,1,0),if(N25-$N$23=2,1,0),if(O25-$O$23=2,1,0),if(P25-$P$23=2,1,0),if(Q25-$Q$23=2,1,0),if(R25-$R$23=2,1,0),if(S25-$S$23=2,1,0),if(T25-$T$23=2,1,0),if(U25-$U$23=2,1,0))} -> 4 | AF25: {=sum(if(D25-$D$23=3,1,0),if(E25-$E$23=3,1,0),if(F25-$F$23=3,1,0),if(G25-$G$23=3,1,0),if(H25-$H$23=3,1,0),if(I25-$I$23=3,1,0),if(J25-$J$23=3,1,0),if(K25-$K$23=3,1,0),if(L25-$L$23=3,1,0),if(M25-$M$23=3,1,0),if(N25-$N$23=3,1,0),if(O25-$O$23=3,1,0),if(P25-$P$23=3,1,0),if(Q25-$Q$23=3,1,0),if(R25-$R$23=3,1,0),if(S25-$S$23=3,1,0),if(T25-$T$23=3,1,0),if(U25-$U$23=3,1,0))} -> 0 | AG25: {=sum(if(D25-$D$23>3,1,0),if(E25-$E$23>3,1,0),if(F25-$F$23>3,1,0),if(G25-$G$23>3,1,0),if(H25-$H$23>3,1,0),if(I25-$I$23>3,1,0),if(J25-$J$23>3,1,0),if(K25-$K$23>3,1,0),if(L25-$L$23>3,1,0),if(M25-$M$23>3,1,0),if(N25-$N$23>3,1,0),if(O25-$O$23>3,1,0),if(P25-$P$23>3,1,0),if(Q25-$Q$23>3,1,0),if(R25-$R$23>3,1,0),if(S25-$S$23>3,1,0),if(T25-$T$23>3,1,0),if(U25-$U$23>3,1,0))} -> 1 | AH25: =sum(Z25:AG25) -> 18
