Workbook

Sheet Scorecards
G1: BLACK LAKE | AB1: 71.9 | AC1: 137
D2: 10 | E2: 0 | F2: 0 | G2: Hole | H2: 1 | I2: 2 | J2: 3 | K2: 4 | L2: 5 | M2: 6 | N2: 7 | O2: 8 | P2: 9 | Q2: 10 | R2: 11 | S2: 12 | T2: 13 | U2: 14 | V2: 15 | W2: 16 | X2: 17 | Y2: 18 | Z2: OUT | AA2: IN | AB2: TOTAL | AC2: NET
B3: Player | C3: Handi | D3: SK | E3: CTP | F3: LO | G3: Par | H3: 5 | I3: 4 | J3: 4 | K3: 4 | L3: 3 | M3: 4 | N3: 4 | O3: 3 | P3: 5 | Q3: 4 | R3: 4 | S3: 3 | T3: 4 | U3: 3 | V3: 5 | W3: 4 | X3: 4 | Y3: 5 | Z3: =SUM(H3:P3) -> 36 | AA3: =SUM(Q3:Y3) -> 36 | AB3: =Z3+AA3 -> 72
B4: AJ | C4: 21 | D4: Y | E4: Y | F4: Y | H4: 6 | I4: 6 | J4: 7 | K4: 4 | L4: 3 | M4: 7 | N4: 5 | O4: 4 | P4: 6 | Q4: 6 | R4: 5 | S4: 5 | T4: 5 | U4: 7 | V4: 8 | W4: 5 | X4: 4 | Y4: 6 | Z4: =SUM(H4:P4) -> 48 | AA4: =SUM(Q4:Y4) -> 51 | AB4: =Z4+AA4 -> 99 | AC4: =IF(AB4>0,AB4-C4,"") -> 78
B5: BB | C5: 18 | D5: Y | E5: Y | F5: Y | H5: 7 | I5: 6 | J5: 3 | K5: 5 | L5: 4 | M5: 4 | N5: 6 | O5: 4 | P5: 7 | Q5: 6 | R5: 4 | S5: 3 | T5: 4 | U5: 4 | V5: 6 | W5: 6 | X5: 5 | Y5: 5 | Z5: =SUM(H5:P5) -> 46 | AA5: =SUM(Q5:Y5) -> 43 | AB5: =Z5+AA5 -> 89 | AC5: =IF(AB5>0,AB5-C5,"") -> 71
B6: BK | C6: 16 | D6: Y | E6: Y | F6: Y | H6: 5 | I6: 5 | J6: 5 | K6: 6 | L6: 4 | M6: 6 | N6: 5 | O6: 4 | P6: 7 | Q6: 4 | R6: 4 | S6: 3 | T6: 6 | U6: 5 | V6: 6 | W6: 5 | X6: 6 | Y6: 5 | Z6: =SUM(H6:P6) -> 47 | AA6: =SUM(Q6:Y6) -> 44 | AB6: =Z6+AA6 -> 91 | AC6: =IF(AB6>0,AB6-C6,"") -> 75
B7: EO | C7: 23 | D7: Y | E7: Y | F7: Y | H7: 5 | I7: 5 | J7: 6 | K7: 5 | L7: 4 | M7: 5 | N7: 5 | O7: 2 | P7: 6 | Q7: 6 | R7: 6 | S7: 7 | T7: 6 | U7: 3 | V7: 6 | W7: 4 | X7: 6 | Y7: 7 | Z7: =SUM(H7:P7) -> 43 | AA7: =SUM(Q7:Y7) -> 51 | AB7: =Z7+AA7 -> 94 | AC7: =IF(AB7>0,AB7-C7,"") -> 71
B8: MV | C8: 18 | D8: Y | E8: Y | F8: Y | H8: 6 | I8: 6 | J8: 6 | K8: 7 | L8: 4 | M8: 4 | N8: 5 | O8: 5 | P8: 5 | Q8: 7 | R8: 3 | S8: 4 | T8: 4 | U8: 3 | V8: 7 | W8: 6 | X8: 6 | Y8: 7 | Z8: =SUM(H8:P8) -> 48 | AA8: =SUM(Q8:Y8) -> 47 | AB8: =Z8+AA8 -> 95 | AC8: =IF(AB8>0,AB8-C8,"") -> 77
B9: SR | C9: 11 | D9: Y | E9: Y | F9: Y | H9: 6 | I9: 6 | J9: 5 | K9: 5 | L9: 3 | M9: 7 | N9: 4 | O9: 4 | P9: 5 | Q9: 5 | R9: 6 | S9: 3 | T9: 5 | U9: 4 | V9: 6 | W9: 5 | X9: 4 | Y9: 5 | Z9: =SUM(H9:P9) -> 45 | AA9: =SUM(Q9:Y9) -> 43 | AB9: =Z9+AA9 -> 88 | AC9: =IF(AB9>0,AB9-C9,"") -> 77
AC10: =IF(AB10>0,AB10-C10,"")
AC11: =IF(AB11>0,AB11-C11,"")
D12: =COUNTIF(Scorecards!$D$4:$D$11, "Y")*D2 -> 60 | E12: =COUNTIF(Scorecards!$E$4:$E$11, "Y")*E2 -> 0 | F12: =COUNTIF(Scorecards!$F$4:$F$11, "Y")*F2 -> 0 | G12: SKIN | H12: {=IF(OR(SUM(IF(IF(Scorecards!$D$4:$D$11="Y", H4:H11, 10)=MIN(IF(Scorecards!$D$4:$D$11="Y", H4:H11, 10)), 1, 0)) > 1, MIN(IF(Scorecards!$D$4:$D$11="Y", H4:H11, 10)) > H3), "", INDEX(Scorecards!$B$4:$B$11,MATCH(MIN(IF(Scorecards!$D$4:$D$11="Y",H4:H11,10)),IF(Scorecards!$D$4:$D$11="Y",H4:H11,10),0)))} | I12: {=IF(OR(SUM(IF(IF(Scorecards!$D$4:$D$11="Y", I4:I11, 10)=MIN(IF(Scorecards!$D$4:$D$11="Y", I4:I11, 10)), 1, 0)) > 1, MIN(IF(Scorecards!$D$4:$D$11="Y", I4:I11, 10)) > I3), "", INDEX(Scorecards!$B$4:$B$11,MATCH(MIN(IF(Scorecards!$D$4:$D$11="Y",I4:I11,10)),IF(Scorecards!$D$4:$D$11="Y",I4:I11,10),0)))} | J12: {=IF(OR(SUM(IF(IF(Scorecards!$D$4:$D$11="Y", J4:J11, 10)=MIN(IF(Scorecards!$D$4:$D$11="Y", J4:J11, 10)), 1, 0)) > 1, MIN(IF(Scorecards!$D$4:$D$11="Y", J4:J11, 10)) > J3), "", INDEX(Scorecards!$B$4:$B$11,MATCH(MIN(IF(Scorecards!$D$4:$D$11="Y",J4:J11,10)),IF(Scorecards!$D$4:$D$11="Y",J4:J11,10),0)))} -> BB | K12: {=IF(OR(SUM(IF(IF(Scorecards!$D$4:$D$11="Y", K4:K11, 10)=MIN(IF(Scorecards!$D$4:$D$11="Y", K4:K11, 10)), 1, 0)) > 1, MIN(IF(Scorecards!$D$4:$D$11="Y", K4:K11, 10)) > K3), "", INDEX(Scorecards!$B$4:$B$11,MATCH(MIN(IF(Scorecards!$D$4:$D$11="Y",K4:K11,10)),IF(Scorecards!$D$4:$D$11="Y",K4:K11,10),0)))} -> AJ | L12: {=IF(OR(SUM(IF(IF(Scorecards!$D$4:$D$11="Y", L4:L11, 10)=MIN(IF(Scorecards!$D$4:$D$11="Y", L4:L11, 10)), 1, 0)) > 1, MIN(IF(Scorecards!$D$4:$D$11="Y", L4:L11, 10)) > L3), "", INDEX(Scorecards!$B$4:$B$11,MATCH(MIN(IF(Scorecards!$D$4:$D$11="Y",L4:L11,10)),IF(Scorecards!$D$4:$D$11="Y",L4:L11,10),0)))} | M12: {=IF(OR(SUM(IF(IF(Scorecards!$D$4:$D$11="Y", M4:M11, 10)=MIN(IF(Scorecards!$D$4:$D$11="Y", M4:M11, 10)), 1, 0)) > 1, MIN(IF(Scorecards!$D$4:$D$11="Y", M4:M11, 10)) > M3), "", INDEX(Scorecards!$B$4:$B$11,MATCH(MIN(IF(Scorecards!$D$4:$D$11="Y",M4:M11,10)),IF(Scorecards!$D$4:$D$11="Y",M4:M11,10),0)))} | N12: {=IF(OR(SUM(IF(IF(Scorecards!$D$4:$D$11="Y", N4:N11, 10)=MIN(IF(Scorecards!$D$4:$D$11="Y", N4:N11, 10)), 1, 0)) > 1, MIN(IF(Scorecards!$D$4:$D$11="Y", N4:N11, 10)) > N3), "", INDEX(Scorecards!$B$4:$B$11,MATCH(MIN(IF(Scorecards!$D$4:$D$11="Y",N4:N11,10)),IF(Scorecards!$D$4:$D$11="Y",N4:N11,10),0)))} -> SR | O12: {=IF(OR(SUM(IF(IF(Scorecards!$D$4:$D$11="Y", O4:O11, 10)=MIN(IF(Scorecards!$D$4:$D$11="Y", O4:O11, 10)), 1, 0)) > 1, MIN(IF(Scorecards!$D$4:$D$11="Y", O4:O11, 10)) > O3), "", INDEX(Scorecards!$B$4:$B$11,MATCH(MIN(IF(Scorecards!$D$4:$D$11="Y",O4:O11,10)),IF(Scorecards!$D$4:$D$11="Y",O4:O11,10),0)))} -> EO | ... Y12: {=IF(OR(SUM(IF(IF(Scorecards!$D$4:$D$11="Y", Y4:Y11, 10)=MIN(IF(Scorecards!$D$4:$D$11="Y", Y4:Y11, 10)), 1, 0)) > 1, MIN(IF(Scorecards!$D$4:$D$11="Y", Y4:Y11, 10)) > Y3), "", INDEX(Scorecards!$B$4:$B$11,MATCH(MIN(IF(Scorecards!$D$4:$D$11="Y",Y4:Y11,10)),IF(Scorecards!$D$4:$D$11="Y",Y4:Y11,10),0)))} | AB12: =18-COUNTBLANK(H12:Y12) -> 7 | AC12: =IF(AB12 = 0, 0, D12/AB12) -> 8.5714286
G13: CTP | AB13: =COUNTA(I13,L13,U13,X13) -> 0 | AC13: =IF(AB13 = 0, 0, E12/AB13) -> 0
G15: THE TRIBUTE | AB15: 70 | AC15: 125
D16: 10 | E16: 0 | F16: 0 | G16: Hole | H16: 1 | I16: 2 | J16: 3 | K16: 4 | L16: 5 | M16: 6 | N16: 7 | O16: 8 | P16: 9 | Q16: 10 | R16: 11 | S16: 12 | T16: 13 | U16: 14 | V16: 15 | W16: 16 | X16: 17 | Y16: 18 | Z16: OUT | AA16: IN | AB16: TOTAL | AC16: NET
B17: Player | C17: Handi | D17: SK | E17: CTP | F17: LO | G17: Par | H17: 4 | I17: 4 | J17: 4 | K17: 5 | L17: 4 | M17: 3 | N17: 5 | O17: 4 | P17: 3 | Q17: 4 | R17: 5 | S17: 4 | T17: 3 | U17: 4 | V17: 4 | W17: 5 | X17: 3 | Y17: 4 | Z17: =SUM(H17:P17) -> 36 | AA17: =SUM(Q17:Y17) -> 36 | AB17: =Z17+AA17 -> 72
B18: AJ | C18: 21 | D18: Y | E18: Y | F18: Y | H18: 5 | I18: 7 | J18: 4 | K18: 8 | L18: 5 | M18: 3 | N18: 7 | O18: 6 | P18: 4 | Q18: 5 | R18: 9 | S18: 5 | T18: 4 | U18: 4 | V18: 4 | W18: 8 | X18: 4 | Y18: 6 | Z18: =SUM(H18:P18) -> 49 | AA18: =SUM(Q18:Y18) -> 49 | AB18: =Z18+AA18 -> 98 | AC18: =IF(AB18>0,AB18-C18,"") -> 77
B19: BB | C19: 18 | D19: Y | E19: Y | F19: Y | H19: 5 | I19: 4 | J19: 5 | K19: 5 | L19: 6 | M19: 3 | N19: 6 | O19: 7 | P19: 4 | Q19: 5 | R19: 7 | S19: 5 | T19: 6 | U19: 4 | V19: 5 | W19: 7 | X19: 6 | Y19: 6 | Z19: =SUM(H19:P19) -> 45 | AA19: =SUM(Q19:Y19) -> 51 | AB19: =Z19+AA19 -> 96 | AC19: =IF(AB19>0,AB19-C19,"") -> 78
B20: BK | C20: 16 | D20: Y | E20: Y | F20: Y | H20: 6 | I20: 4 | J20: 4 | K20: 6 | L20: 7 | M20: 4 | N20: 7 | O20: 6 | P20: 3 | Q20: 7 | R20: 7 | S20: 5 | T20: 4 | U20: 5 | V20: 6 | W20: 5 | X20: 4 | Y20: 4 | Z20: =SUM(H20:P20) -> 47 | AA20: =SUM(Q20:Y20) -> 47 | AB20: =Z20+AA20 -> 94 | AC20: =IF(AB20>0,AB20-C20,"") -> 78
B21: EO | C21: 23 | D21: Y | E21: Y | F21: Y | H21: 4 | I21: 4 | J21: 6 | K21: 7 | L21: 6 | M21: 5 | N21: 6 | O21: 6 | P21: 4 | Q21: 7 | R21: 5 | S21: 4 | T21: 5 | U21: 4 | V21: 4 | W21: 7 | X21: 3 | Y21: 5 | Z21: =SUM(H21:P21) -> 48 | AA21: =SUM(Q21:Y21) -> 44 | AB21: =Z21+AA21 -> 92 | AC21: =IF(AB21>0,AB21-C21,"") -> 69
B22: MV | C22: 18 | D22: Y | E22: Y | F22: Y | H22: 5 | I22: 4 | J22: 5 | K22: 6 | L22: 5 | M22: 3 | N22: 6 | O22: 6 | P22: 5 | Q22: 6 | R22: 7 | S22: 5 | T22: 4 | U22: 5 | V22: 5 | W22: 5 | X22: 3 | Y22: 5 | Z22: =SUM(H22:P22) -> 45 | AA22: =SUM(Q22:Y22) -> 45 | AB22: =Z22+AA22 -> 90 | AC22: =IF(AB22>0,AB22-C22,"") -> 72
B23: SR | C23: 11 | D23: Y | E23: Y | F23: Y | H23: 4 | I23: 6 | J23: 4 | K23: 6 | L23: 5 | M23: 2 | N23: 4 | O23: 5 | P23: 4 | Q23: 5 | R23: 7 | S23: 4 | T23: 3 | U23: 5 | V23: 3 | W23: 6 | X23: 4 | Y23: 4 | Z23: =SUM(H23:P23) -> 40 | AA23: =SUM(Q23:Y23) -> 41 | AB23: =Z23+AA23 -> 81 | AC23: =IF(AB23>0,AB23-C23,"") -> 70
AC24: =IF(AB24>0,AB24-C24,"")
AC25: =IF(AB25>0,AB25-C25,"")
D26: =COUNTIF(Scorecards!$D$4:$D$11, "Y")*D16 -> 60 | E26: =COUNTIF(Scorecards!$E$4:$E$11, "Y")*E16 -> 0 | F26: =COUNTIF(Scorecards!$F$18:$F$25, "Y")*F16 -> 0 | G26: SKIN | H26: {=IF(OR(SUM(IF(IF(Scorecards!$D$18:$D$25="Y", H18:H25, 10)=MIN(IF(Scorecards!$D$18:$D$25="Y", H18:H25, 10)), 1, 0)) > 1, MIN(IF(Scorecards!$D$18:$D$25="Y", H18:H25, 10)) > H17), "", INDEX(Scorecards!$B$18:$B$25,MATCH(MIN(IF(Scorecards!$D$18:$D$25="Y",H18:H25,10)),IF(Scorecards!$D$18:$D$25="Y",H18:H25,10),0)))} | I26: {=IF(OR(SUM(IF(IF(Scorecards!$D$18:$D$25="Y", I18:I25, 10)=MIN(IF(Scorecards!$D$18:$D$25="Y", I18:I25, 10)), 1, 0)) > 1, MIN(IF(Scorecards!$D$18:$D$25="Y", I18:I25, 10)) > I17), "", INDEX(Scorecards!$B$18:$B$25,MATCH(MIN(IF(Scorecards!$D$18:$D$25="Y",I18:I25,10)),IF(Scorecards!$D$18:$D$25="Y",I18:I25,10),0)))} | J26: {=IF(OR(SUM(IF(IF(Scorecards!$D$18:$D$25="Y", J18:J25, 10)=MIN(IF(Scorecards!$D$18:$D$25="Y", J18:J25, 10)), 1, 0)) > 1, MIN(IF(Scorecards!$D$18:$D$25="Y", J18:J25, 10)) > J17), "", INDEX(Scorecards!$B$18:$B$25,MATCH(MIN(IF(Scorecards!$D$18:$D$25="Y",J18:J25,10)),IF(Scorecards!$D$18:$D$25="Y",J18:J25,10),0)))} | K26: {=IF(OR(SUM(IF(IF(Scorecards!$D$18:$D$25="Y", K18:K25, 10)=MIN(IF(Scorecards!$D$18:$D$25="Y", K18:K25, 10)), 1, 0)) > 1, MIN(IF(Scorecards!$D$18:$D$25="Y", K18:K25, 10)) > K17), "", INDEX(Scorecards!$B$18:$B$25,MATCH(MIN(IF(Scorecards!$D$18:$D$25="Y",K18:K25,10)),IF(Scorecards!$D$18:$D$25="Y",K18:K25,10),0)))} -> BB | L26: {=IF(OR(SUM(IF(IF(Scorecards!$D$18:$D$25="Y", L18:L25, 10)=MIN(IF(Scorecards!$D$18:$D$25="Y", L18:L25, 10)), 1, 0)) > 1, MIN(IF(Scorecards!$D$18:$D$25="Y", L18:L25, 10)) > L17), "", INDEX(Scorecards!$B$18:$B$25,MATCH(MIN(IF(Scorecards!$D$18:$D$25="Y",L18:L25,10)),IF(Scorecards!$D$18:$D$25="Y",L18:L25,10),0)))} | M26: {=IF(OR(SUM(IF(IF(Scorecards!$D$18:$D$25="Y", M18:M25, 10)=MIN(IF(Scorecards!$D$18:$D$25="Y", M18:M25, 10)), 1, 0)) > 1, MIN(IF(Scorecards!$D$18:$D$25="Y", M18:M25, 10)) > M17), "", INDEX(Scorecards!$B$18:$B$25,MATCH(MIN(IF(Scorecards!$D$18:$D$25="Y",M18:M25,10)),IF(Scorecards!$D$18:$D$25="Y",M18:M25,10),0)))} -> SR | N26: {=IF(OR(SUM(IF(IF(Scorecards!$D$18:$D$25="Y", N18:N25, 10)=MIN(IF(Scorecards!$D$18:$D$25="Y", N18:N25, 10)), 1, 0)) > 1, MIN(IF(Scorecards!$D$18:$D$25="Y", N18:N25, 10)) > N17), "", INDEX(Scorecards!$B$18:$B$25,MATCH(MIN(IF(Scorecards!$D$18:$D$25="Y",N18:N25,10)),IF(Scorecards!$D$18:$D$25="Y",N18:N25,10),0)))} -> SR | O26: {=IF(OR(SUM(IF(IF(Scorecards!$D$18:$D$25="Y", O18:O25, 10)=MIN(IF(Scorecards!$D$18:$D$25="Y", O18:O25, 10)), 1, 0)) > 1, MIN(IF(Scorecards!$D$18:$D$25="Y", O18:O25, 10)) > O17), "", INDEX(Scorecards!$B$18:$B$25,MATCH(MIN(IF(Scorecards!$D$18:$D$25="Y",O18:O25,10)),IF(Scorecards!$D$18:$D$25="Y",O18:O25,10),0)))} | ... Y26: {=IF(OR(SUM(IF(IF(Scorecards!$D$18:$D$25="Y", Y18:Y25, 10)=MIN(IF(Scorecards!$D$18:$D$25="Y", Y18:Y25, 10)), 1, 0)) > 1, MIN(IF(Scorecards!$D$18:$D$25="Y", Y18:Y25, 10)) > Y17), "", INDEX(Scorecards!$B$18:$B$25,MATCH(MIN(IF(Scorecards!$D$18:$D$25="Y",Y18:Y25,10)),IF(Scorecards!$D$18:$D$25="Y",Y18:Y25,10),0)))} | AB26: =18-COUNTBLANK(H26:Y26) -> 7 | AC26: =IF(AB26 = 0, 0, D26/AB26) -> 8.5714286
G27: CTP | AB27: =COUNTA(J27,O27,S27,X27) -> 0 | AC27: =IF(AB27 = 0, 0, E26/AB27) -> 0
G29: THE SIGNATURE | AB29: 71.1 | AC29: 133
D30: 10 | E30: 0 | F30: 0 | G30: Hole | H30: 1 | I30: 2 | J30: 3 | K30: 4 | L30: 5 | M30: 6 | N30: 7 | O30: 8 | P30: 9 | Q30: 10 | R30: 11 | S30: 12 | T30: 13 | U30: 14 | V30: 15 | W30: 16 | X30: 17 | Y30: 18 | Z30: OUT | AA30: IN | AB30: TOTAL | AC30: NET
B31: Player | C31: Handi | D31: SK | E31: CTP | F31: LO | G31: Par | H31: 4 | I31: 5 | J31: 4 | K31: 3 | L31: 4 | M31: 5 | N31: 4 | O31: 3 | P31: 4 | Q31: 4 | R31: 3 | S31: 5 | T31: 4 | U31: 4 | V31: 4 | W31: 5 | X31: 3 | Y31: 4 | Z31: =SUM(H31:P31) -> 36 | AA31: =SUM(Q31:Y31) -> 36 | AB31: =Z31+AA31 -> 72
B32: AJ | C32: 21 | D32: Y | E32: Y | F32: Y | H32: 4 | I32: 4 | J32: 4 | K32: 4 | L32: 9 | M32: 7 | N32: 5 | O32: 4 | P32: 6 | Q32: 6 | R32: 4 | S32: 6 | T32: 12 | U32: 6 | V32: 6 | W32: 6 | X32: 4 | Y32: 5 | Z32: =SUM(H32:P32) -> 47 | AA32: =SUM(Q32:Y32) -> 55 | AB32: =Z32+AA32 -> 102 | AC32: =IF(AB32>0,AB32-C32,"") -> 81
B33: BB | C33: 18 | D33: y | E33: y | F33: Y | H33: 5 | I33: 6 | J33: 4 | K33: 4 | L33: 4 | M33: 6 | N33: 5 | O33: 2 | P33: 6 | Q33: 7 | R33: 4 | S33: 5 | T33: 5 | U33: 4 | V33: 5 | W33: 6 | X33: 4 | Y33: 7 | Z33: =SUM(H33:P33) -> 42 | AA33: =SUM(Q33:Y33) -> 47 | AB33: =Z33+AA33 -> 89 | AC33: =IF(AB33>0,AB33-C33,"") -> 71
B34: BK | C34: 16 | D34: Y | E34: Y | F34: Y | H34: 7 | I34: 4 | J34: 5 | K34: 4 | L34: 5 | M34: 6 | N34: 5 | O34: 5 | P34: 8 | Q34: 7 | R34: 3 | S34: 6 | T34: 6 | U34: 4 | V34: 4 | W34: 5 | X34: 5 | Y34: 6 | Z34: =SUM(H34:P34) -> 49 | AA34: =SUM(Q34:Y34) -> 46 | AB34: =Z34+AA34 -> 95 | AC34: =IF(AB34>0,AB34-C34,"") -> 79
B35: EO | C35: 23 | D35: Y | E35: Y | F35: Y | H35: 5 | I35: 5 | J35: 5 | K35: 6 | L35: 6 | M35: 7 | N35: 5 | O35: 4 | P35: 6 | Q35: 5 | R35: 7 | S35: 6 | T35: 6 | U35: 6 | V35: 6 | W35: 7 | X35: 4 | Y35: 5 | Z35: =SUM(H35:P35) -> 49 | AA35: =SUM(Q35:Y35) -> 52 | AB35: =Z35+AA35 -> 101 | AC35: =IF(AB35>0,AB35-C35,"") -> 78
B36: MV | C36: 18 | D36: Y | E36: Y | F36: Y | H36: 6 | I36: 5 | J36: 5 | K36: 4 | L36: 6 | M36: 5 | N36: 5 | O36: 3 | P36: 5 | Q36: 6 | R36: 6 | S36: 10 | T36: 5 | U36: 4 | V36: 7 | W36: 5 | X36: 5 | Y36: 6 | Z36: =SUM(H36:P36) -> 44 | AA36: =SUM(Q36:Y36) -> 54 | AB36: =Z36+AA36 -> 98 | AC36: =IF(AB36>0,AB36-C36,"") -> 80
B37: SR | C37: 11 | D37: Y | E37: Y | F37: Y | H37: 5 | I37: 6 | J37: 4 | K37: 3 | L37: 4 | M37: 7 | N37: 8 | O37: 4 | P37: 6 | Q37: 6 | R37: 3 | S37: 5 | T37: 8 | U37: 5 | V37: 7 | W37: 4 | X37: 5 | Y37: 3 | Z37: =SUM(H37:P37) -> 47 | AA37: =SUM(Q37:Y37) -> 46 | AB37: =Z37+AA37 -> 93 | AC37: =IF(AB37>0,AB37-C37,"") -> 82
AC38: =IF(AB38>0,AB38-C38,"")
A39: THE SIGNATURE | AC39: =IF(AB39>0,AB39-C39,"")
D40: =COUNTIF(Scorecards!$D$4:$D$11, "Y")*D30 -> 60 | E40: =COUNTIF(Scorecards!$E$4:$E$11, "Y")*E30 -> 0 | F40: =COUNTIF(Scorecards!$F$4:$F$11, "Y")*F30 -> 0 | G40: SKIN | H40: {=IF(OR(SUM(IF(IF(Scorecards!$D$32:$D$39="Y", H32:H39, 10)=MIN(IF(Scorecards!$D$32:$D$39="Y", H32:H39, 10)), 1, 0)) > 1, MIN(IF(Scorecards!$D$32:$D$39="Y", H32:H39, 10)) > H31), "", INDEX(Scorecards!$B$32:$B$39,MATCH(MIN(IF(Scorecards!$D$32:$D$39="Y",H32:H39,10)),IF(Scorecards!$D$32:$D$39="Y",H32:H39,10),0)))} -> AJ | I40: {=IF(OR(SUM(IF(IF(Scorecards!$D$32:$D$39="Y", I32:I39, 10)=MIN(IF(Scorecards!$D$32:$D$39="Y", I32:I39, 10)), 1, 0)) > 1, MIN(IF(Scorecards!$D$32:$D$39="Y", I32:I39, 10)) > I31), "", INDEX(Scorecards!$B$32:$B$39,MATCH(MIN(IF(Scorecards!$D$32:$D$39="Y",I32:I39,10)),IF(Scorecards!$D$32:$D$39="Y",I32:I39,10),0)))} | J40: {=IF(OR(SUM(IF(IF(Scorecards!$D$32:$D$39="Y", J32:J39, 10)=MIN(IF(Scorecards!$D$32:$D$39="Y", J32:J39, 10)), 1, 0)) > 1, MIN(IF(Scorecards!$D$32:$D$39="Y", J32:J39, 10)) > J31), "", INDEX(Scorecards!$B$32:$B$39,MATCH(MIN(IF(Scorecards!$D$32:$D$39="Y",J32:J39,10)),IF(Scorecards!$D$32:$D$39="Y",J32:J39,10),0)))} | K40: {=IF(OR(SUM(IF(IF(Scorecards!$D$32:$D$39="Y", K32:K39, 10)=MIN(IF(Scorecards!$D$32:$D$39="Y", K32:K39, 10)), 1, 0)) > 1, MIN(IF(Scorecards!$D$32:$D$39="Y", K32:K39, 10)) > K31), "", INDEX(Scorecards!$B$32:$B$39,MATCH(MIN(IF(Scorecards!$D$32:$D$39="Y",K32:K39,10)),IF(Scorecards!$D$32:$D$39="Y",K32:K39,10),0)))} -> SR | L40: {=IF(OR(SUM(IF(IF(Scorecards!$D$32:$D$39="Y", L32:L39, 10)=MIN(IF(Scorecards!$D$32:$D$39="Y", L32:L39, 10)), 1, 0)) > 1, MIN(IF(Scorecards!$D$32:$D$39="Y", L32:L39, 10)) > L31), "", INDEX(Scorecards!$B$32:$B$39,MATCH(MIN(IF(Scorecards!$D$32:$D$39="Y",L32:L39,10)),IF(Scorecards!$D$32:$D$39="Y",L32:L39,10),0)))} | M40: {=IF(OR(SUM(IF(IF(Scorecards!$D$32:$D$39="Y", M32:M39, 10)=MIN(IF(Scorecards!$D$32:$D$39="Y", M32:M39, 10)), 1, 0)) > 1, MIN(IF(Scorecards!$D$32:$D$39="Y", M32:M39, 10)) > M31), "", INDEX(Scorecards!$B$32:$B$39,MATCH(MIN(IF(Scorecards!$D$32:$D$39="Y",M32:M39,10)),IF(Scorecards!$D$32:$D$39="Y",M32:M39,10),0)))} -> MV | N40: {=IF(OR(SUM(IF(IF(Scorecards!$D$32:$D$39="Y", N32:N39, 10)=MIN(IF(Scorecards!$D$32:$D$39="Y", N32:N39, 10)), 1, 0)) > 1, MIN(IF(Scorecards!$D$32:$D$39="Y", N32:N39, 10)) > N31), "", INDEX(Scorecards!$B$32:$B$39,MATCH(MIN(IF(Scorecards!$D$32:$D$39="Y",N32:N39,10)),IF(Scorecards!$D$32:$D$39="Y",N32:N39,10),0)))} | O40: {=IF(OR(SUM(IF(IF(Scorecards!$D$32:$D$39="Y", O32:O39, 10)=MIN(IF(Scorecards!$D$32:$D$39="Y", O32:O39, 10)), 1, 0)) > 1, MIN(IF(Scorecards!$D$32:$D$39="Y", O32:O39, 10)) > O31), "", INDEX(Scorecards!$B$32:$B$39,MATCH(MIN(IF(Scorecards!$D$32:$D$39="Y",O32:O39,10)),IF(Scorecards!$D$32:$D$39="Y",O32:O39,10),0)))} -> BB | ... Y40: {=IF(OR(SUM(IF(IF(Scorecards!$D$32:$D$39="Y", Y32:Y39, 10)=MIN(IF(Scorecards!$D$32:$D$39="Y", Y32:Y39, 10)), 1, 0)) > 1, MIN(IF(Scorecards!$D$32:$D$39="Y", Y32:Y39, 10)) > Y31), "", INDEX(Scorecards!$B$32:$B$39,MATCH(MIN(IF(Scorecards!$D$32:$D$39="Y",Y32:Y39,10)),IF(Scorecards!$D$32:$D$39="Y",Y32:Y39,10),0)))} -> SR | AB40: =18-COUNTBLANK(H40:Y40) -> 7 | AC40: =IF(AB40 = 0, 0, D40/AB40) -> 8.5714286
G41: CTP | AB41: =COUNTA(I41,O41,S41,V41) -> 0 | AC41: =IF(AB41 = 0, 0, E40/AB41) -> 0
G43: THREETOPS
...

Sheet Scoreboard
A1: Player | B1: =Scorecards!G1 -> BLACK LAKE | C1: =Scorecards!G15 -> THE TRIBUTE | D1: =Scorecards!G29 -> THE SIGNATURE | E1: =Scorecards!G43 -> THREETOPS | F1: =Scorecards!G57 -> THE MASTERPIECE | G1: TOTAL
A2: Aaron Jensen | B2: =Scorecards!AC4 -> 78 | C2: =Scorecards!AC18 -> 77 | D2: =Scorecards!AC32 -> 81 | E2: =Scorecards!AC46 | F2: =Scorecards!AC60 -> 73 | G2: =SUM(B2:F2) -> 309
A3: Bob Bergeron | B3: =Scorecards!AC5 -> 71 | C3: =Scorecards!AC19 -> 78 | D3: =Scorecards!AC33 -> 71 | E3: =Scorecards!AC47 | F3: =Scorecards!AC61 -> 91 | G3: =SUM(B3:F3) -> 311
A4: Brian Kelly | B4: =Scorecards!AC6 -> 75 | C4: =Scorecards!AC20 -> 78 | D4: =Scorecards!AC34 -> 79 | E4: =Scorecards!AC48 | F4: =Scorecards!AC62 -> 81 | G4: =SUM(B4:F4) -> 313
A5: Eric Olson | B5: =Scorecards!AC7 -> 71 | C5: =Scorecards!AC21 -> 69 | D5: =Scorecards!AC35 -> 78 | E5: =Scorecards!AC49 | F5: =Scorecards!AC63 -> 77 | G5: =SUM(B5:F5) -> 295
A6: Matt Vigo | B6: =Scorecards!AC8 -> 77 | C6: =Scorecards!AC22 -> 72 | D6: =Scorecards!AC36 -> 80 | E6: =Scorecards!AC50 | F6: =Scorecards!AC64 -> 78 | G6: =SUM(B6:F6) -> 307
A7: Scott Rhoades | B7: =Scorecards!AC9 -> 77 | C7: =Scorecards!AC23 -> 70 | D7: =Scorecards!AC37 -> 82 | E7: =Scorecards!AC51 | F7: =Scorecards!AC65 -> 79 | G7: =SUM(B7:F7) -> 308

Sheet WeekendLongBets
B1: 10 | C1: 0
A2: Player | B2: Single Round Low | C2: Low Cumulative
A3: AJ | B3: Y | C3: Y
A4: BB | B4: Y | C4: Y
A5: BK | B5: Y | C5: Y
A6: EO | B6: Y | C6: Y
A7: MV | B7: Y | C7: Y
A8: SR | B8: Y | C8: Y
A11: Totals | B11: =COUNTIF(B3:B10,"Y") *B1 -> 60 | C11: =COUNTIF(C3:C10,"Y") *C1 -> 0

Sheet BettingScoreboard
A1: Low Per Round | B1: Black Lake | C1: The Tribute | D1: The Signature | E1: ThreeTops | F1: The Masterpiece
A2: AJ | B2: =IF(Scorecards!F4="Y",Scoreboard!B2, "") -> 78 | C2: =IF(Scorecards!F18="Y",Scoreboard!C2, "") -> 77 | D2: =IF(Scorecards!F32="Y",Scoreboard!D2, "") -> 81 | E2: =IF(Scorecards!F46="Y",Scoreboard!E2, "") | F2: =IF(Scorecards!F60="Y",Scoreboard!F2, "") -> 73
A3: BB | B3: =IF(Scorecards!F5="Y",Scoreboard!B3, "") -> 71 | C3: =IF(Scorecards!F19="Y",Scoreboard!C3, "") -> 78 | D3: =IF(Scorecards!F33="Y",Scoreboard!D3, "") -> 71 | E3: =IF(Scorecards!F47="Y",Scoreboard!E3, "") | F3: =IF(Scorecards!F61="Y",Scoreboard!F3, "") -> 91
A4: BK | B4: =IF(Scorecards!F6="Y",Scoreboard!B4, "") -> 75 | C4: =IF(Scorecards!F20="Y",Scoreboard!C4, "") -> 78 | D4: =IF(Scorecards!F34="Y",Scoreboard!D4, "") -> 79 | E4: =IF(Scorecards!F48="Y",Scoreboard!E4, "") | F4: =IF(Scorecards!F62="Y",Scoreboard!F4, "") -> 81
A5: EO | B5: =IF(Scorecards!F7="Y",Scoreboard!B5, "") -> 71 | C5: =IF(Scorecards!F21="Y",Scoreboard!C5, "") -> 69 | D5: =IF(Scorecards!F35="Y",Scoreboard!D5, "") -> 78 | E5: =IF(Scorecards!F49="Y",Scoreboard!E5, "") | F5: =IF(Scorecards!F63="Y",Scoreboard!F5, "") -> 77
A6: MV | B6: =IF(Scorecards!F8="Y",Scoreboard!B6, "") -> 77 | C6: =IF(Scorecards!F22="Y",Scoreboard!C6, "") -> 72 | D6: =IF(Scorecards!F36="Y",Scoreboard!D6, "") -> 80 | E6: =IF(Scorecards!F50="Y",Scoreboard!E6, "") | F6: =IF(Scorecards!F64="Y",Scoreboard!F6, "") -> 78
A7: SR | B7: =IF(Scorecards!F9="Y",Scoreboard!B7, "") -> 77 | C7: =IF(Scorecards!F23="Y",Scoreboard!C7, "") -> 70 | D7: =IF(Scorecards!F37="Y",Scoreboard!D7, "") -> 82 | E7: =IF(Scorecards!F51="Y",Scoreboard!E7, "") | F7: =IF(Scorecards!F65="Y",Scoreboard!F7, "") -> 79
B8: =IF(Scorecards!F10="Y",Scoreboard!#REF!, "") -> #ERROR! | C8: =IF(Scorecards!F24="Y",Scoreboard!#REF!, "") -> #ERROR! | D8: =IF(Scorecards!F38="Y",Scoreboard!#REF!, "") -> #ERROR! | E8: =IF(Scorecards!F52="Y",Scoreboard!#REF!, "") -> #ERROR! | F8: =IF(Scorecards!F66="Y",Scoreboard!#REF!, "") -> #ERROR!
B9: =IF(Scorecards!F11="Y",Scoreboard!#REF!, "") -> #ERROR! | C9: =IF(Scorecards!F25="Y",Scoreboard!#REF!, "") -> #ERROR! | D9: =IF(Scorecards!F39="Y",Scoreboard!#REF!, "") -> #ERROR! | E9: =IF(Scorecards!F53="Y",Scoreboard!#REF!, "") -> #ERROR! | F9: =IF(Scorecards!F67="Y",Scoreboard!#REF!, "") -> #ERROR!
A10: # of Winners | B10: =COUNTIF(BettingScoreboard!$B$2:$B$9,MIN(BettingScoreboard!$B$2:$B$9)) -> 2 | C10: =COUNTIF(BettingScoreboard!$C$2:$C$9,MIN(BettingScoreboard!$C$2:$C$9)) -> 2 | D10: =COUNTIF(BettingScoreboard!$D$2:$D$9,MIN(BettingScoreboard!$D$2:$D$9)) -> 2 | E10: =COUNTIF(BettingScoreboard!$E$2:$E$9,MIN(BettingScoreboard!$E$2:$E$9)) -> 2 | F10: =COUNTIF(BettingScoreboard!$F$2:$F$9,MIN(BettingScoreboard!$F$2:$F$9)) -> 2
A12: Single Round Low | D12: Cumulative Low
A13: Player | B13: Score | D13: Player | E13: Score
A14: AJ | B14: =IF(WeekendLongBets!B3="Y",MIN(Scoreboard!B2:F2), "") -> 73 | D14: AJ | E14: =IF(WeekendLongBets!C3="Y",SUM(Scoreboard!B2:F2),"") -> 309
A15: BB | B15: =IF(WeekendLongBets!B4="Y",MIN(Scoreboard!B3:F3), "") -> 71 | D15: BB | E15: =IF(WeekendLongBets!C4="Y",SUM(Scoreboard!B3:F3),"") -> 311
A16: BK | B16: =IF(WeekendLongBets!B5="Y",MIN(Scoreboard!B4:F4), "") -> 75 | D16: BK | E16: =IF(WeekendLongBets!C5="Y",SUM(Scoreboard!B4:F4),"") -> 313
A17: EO | B17: =IF(WeekendLongBets!B6="Y",MIN(Scoreboard!B5:F5), "") -> 69 | D17: EO | E17: =IF(WeekendLongBets!C6="Y",SUM(Scoreboard!B5:F5),"") -> 295
A18: MV | B18: =IF(WeekendLongBets!B7="Y",MIN(Scoreboard!B6:F6), "") -> 72 | D18: MV | E18: =IF(WeekendLongBets!C7="Y",SUM(Scoreboard!B6:F6),"") -> 307
A19: SR | B19: =IF(WeekendLongBets!B8="Y",MIN(Scoreboard!B7:F7), "") -> 70 | D19: SR | E19: =IF(WeekendLongBets!C8="Y",SUM(Scoreboard!B7:F7),"") -> 308
B20: =IF(WeekendLongBets!B9="Y",MIN(Scoreboard!#REF!), "") -> #ERROR! | E20: =IF(WeekendLongBets!C9="Y",SUM(Scoreboard!#REF!),"") -> #ERROR!
B21: =IF(WeekendLongBets!B10="Y",MIN(Scoreboard!#REF!), "") -> #ERROR! | E21: =IF(WeekendLongBets!C10="Y",SUM(Scoreboard!#REF!),"") -> #ERROR!
A22: # of Winners | B22: =COUNTIF(BettingScoreboard!$B$14:$B$21,MIN(BettingScoreboard!$B$14:$B$21)) -> 2 | D22: # of Winners | E22: =COUNTIF(BettingScoreboard!$E$14:$E$21,MIN(BettingScoreboard!$E$14:$E$21)) -> 2
A24: Player | B24: Skins | C24: Skin $ | D24: CTP | E24: CTP $
A25: =Scorecards!B32 -> AJ | B25: =SUM(COUNTIF(Scorecards!$H$12:$Y$12,BettingScoreboard!$A25),COUNTIF(Scorecards!$H$26:$Y$26,BettingScoreboard!$A25),COUNTIF(Scorecards!$H$40:$Y$40,BettingScoreboard!$A25),COUNTIF(Scorecards!$H$54:$Y$54,BettingScoreboard!$A25),COUNTIF(Scorecards!$H$68:$Y$68,BettingScoreboard!$A25)) -> 3 | C25: =SUM(COUNTIF(Scorecards!$H$12:$Y$12,BettingScoreboard!$A25)*Scorecards!$AC$12,COUNTIF(Scorecards!$H$26:$Y$26, BettingScoreboard!$A25)*Scorecards!$AC$26,COUNTIF(Scorecards!$H$40:$Y$40,BettingScoreboard!$A25)*Scorecards!$AC$40,COUNTIF(Scorecards!$H$54:$Y$54, BettingScoreboard!$A25)*Scorecards!$AC$54,COUNTIF(Scorecards!$H$68:$Y$68, BettingScoreboard!$A25)*Scorecards!$AC$68) -> 22.597403 | D25: =SUM(COUNTIF(Scorecards!$H$13:$Y$13,BettingScoreboard!$A25),COUNTIF(Scorecards!$H$27:$Y$27,BettingScoreboard!$A25),COUNTIF(Scorecards!$H$41:$Y$41,BettingScoreboard!$A25),COUNTIF(Scorecards!$H$55:$Y$55,BettingScoreboard!$A25),COUNTIF(Scorecards!$H$69:$Y$69,BettingScoreboard!$A25)) -> 0 | E25: =SUM(COUNTIF(Scorecards!$H$13:$Y$13,BettingScoreboard!$A25)*Scorecards!$AC$13,COUNTIF(Scorecards!$H$27:$Y$27, BettingScoreboard!$A25)*Scorecards!$AC$27,COUNTIF(Scorecards!$H$41:$Y$41,BettingScoreboard!$A25)*Scorecards!$AC$41,COUNTIF(Scorecards!$H$55:$Y$55, BettingScoreboard!$A25)*Scorecards!$AC$55,COUNTIF(Scorecards!$H$69:$Y$69, BettingScoreboard!$A25)*Scorecards!$AC$69) -> 0
A26: =Scorecards!B33 -> BB | B26: =SUM(COUNTIF(Scorecards!$H$12:$Y$12,BettingScoreboard!$A26),COUNTIF(Scorecards!$H$26:$Y$26,BettingScoreboard!$A26),COUNTIF(Scorecards!$H$40:$Y$40,BettingScoreboard!$A26),COUNTIF(Scorecards!$H$54:$Y$54,BettingScoreboard!$A26),COUNTIF(Scorecards!$H$68:$Y$68,BettingScoreboard!$A26)) -> 4 | C26: =SUM(COUNTIF(Scorecards!$H$12:$Y$12,BettingScoreboard!$A26)*Scorecards!$AC$12,COUNTIF(Scorecards!$H$26:$Y$26, BettingScoreboard!$A26)*Scorecards!$AC$26,COUNTIF(Scorecards!$H$40:$Y$40,BettingScoreboard!$A26)*Scorecards!$AC$40,COUNTIF(Scorecards!$H$54:$Y$54, BettingScoreboard!$A26)*Scorecards!$AC$54,COUNTIF(Scorecards!$H$68:$Y$68, BettingScoreboard!$A26)*Scorecards!$AC$68) -> 31.168831 | D26: =SUM(COUNTIF(Scorecards!$H$13:$Y$13,BettingScoreboard!$A26),COUNTIF(Scorecards!$H$27:$Y$27,BettingScoreboard!$A26),COUNTIF(Scorecards!$H$41:$Y$41,BettingScoreboard!$A26),COUNTIF(Scorecards!$H$55:$Y$55,BettingScoreboard!$A26),COUNTIF(Scorecards!$H$69:$Y$69,BettingScoreboard!$A26)) -> 0 | E26: =SUM(COUNTIF(Scorecards!$H$13:$Y$13,BettingScoreboard!$A26)*Scorecards!$AC$13,COUNTIF(Scorecards!$H$27:$Y$27, BettingScoreboard!$A26)*Scorecards!$AC$27,COUNTIF(Scorecards!$H$41:$Y$41,BettingScoreboard!$A26)*Scorecards!$AC$41,COUNTIF(Scorecards!$H$55:$Y$55, BettingScoreboard!$A26)*Scorecards!$AC$55,COUNTIF(Scorecards!$H$69:$Y$69, BettingScoreboard!$A26)*Scorecards!$AC$69) -> 0
A27: =Scorecards!B34 -> BK | B27: =SUM(COUNTIF(Scorecards!$H$12:$Y$12,BettingScoreboard!$A27),COUNTIF(Scorecards!$H$26:$Y$26,BettingScoreboard!$A27),COUNTIF(Scorecards!$H$40:$Y$40,BettingScoreboard!$A27),COUNTIF(Scorecards!$H$54:$Y$54,BettingScoreboard!$A27),COUNTIF(Scorecards!$H$68:$Y$68,BettingScoreboard!$A27)) -> 3 | C27: =SUM(COUNTIF(Scorecards!$H$12:$Y$12,BettingScoreboard!$A27)*Scorecards!$AC$12,COUNTIF(Scorecards!$H$26:$Y$26, BettingScoreboard!$A27)*Scorecards!$AC$26,COUNTIF(Scorecards!$H$40:$Y$40,BettingScoreboard!$A27)*Scorecards!$AC$40,COUNTIF(Scorecards!$H$54:$Y$54, BettingScoreboard!$A27)*Scorecards!$AC$54,COUNTIF(Scorecards!$H$68:$Y$68, BettingScoreboard!$A27)*Scorecards!$AC$68) -> 25.714286 | D27: =SUM(COUNTIF(Scorecards!$H$13:$Y$13,BettingScoreboard!$A27),COUNTIF(Scorecards!$H$27:$Y$27,BettingScoreboard!$A27),COUNTIF(Scorecards!$H$41:$Y$41,BettingScoreboard!$A27),COUNTIF(Scorecards!$H$55:$Y$55,BettingScoreboard!$A27),COUNTIF(Scorecards!$H$69:$Y$69,BettingScoreboard!$A27)) -> 0 | E27: =SUM(COUNTIF(Scorecards!$H$13:$Y$13,BettingScoreboard!$A27)*Scorecards!$AC$13,COUNTIF(Scorecards!$H$27:$Y$27, BettingScoreboard!$A27)*Scorecards!$AC$27,COUNTIF(Scorecards!$H$41:$Y$41,BettingScoreboard!$A27)*Scorecards!$AC$41,COUNTIF(Scorecards!$H$55:$Y$55, BettingScoreboard!$A27)*Scorecards!$AC$55,COUNTIF(Scorecards!$H$69:$Y$69, BettingScoreboard!$A27)*Scorecards!$AC$69) -> 0
A28: =Scorecards!B35 -> EO | B28: =SUM(COUNTIF(Scorecards!$H$12:$Y$12,BettingScoreboard!$A28),COUNTIF(Scorecards!$H$26:$Y$26,BettingScoreboard!$A28),COUNTIF(Scorecards!$H$40:$Y$40,BettingScoreboard!$A28),COUNTIF(Scorecards!$H$54:$Y$54,BettingScoreboard!$A28),COUNTIF(Scorecards!$H$68:$Y$68,BettingScoreboard!$A28)) -> 6 | C28: =SUM(COUNTIF(Scorecards!$H$12:$Y$12,BettingScoreboard!$A28)*Scorecards!$AC$12,COUNTIF(Scorecards!$H$26:$Y$26, BettingScoreboard!$A28)*Scorecards!$AC$26,COUNTIF(Scorecards!$H$40:$Y$40,BettingScoreboard!$A28)*Scorecards!$AC$40,COUNTIF(Scorecards!$H$54:$Y$54, BettingScoreboard!$A28)*Scorecards!$AC$54,COUNTIF(Scorecards!$H$68:$Y$68, BettingScoreboard!$A28)*Scorecards!$AC$68) -> 42.077922 | D28: =SUM(COUNTIF(Scorecards!$H$13:$Y$13,BettingScoreboard!$A28),COUNTIF(Scorecards!$H$27:$Y$27,BettingScoreboard!$A28),COUNTIF(Scorecards!$H$41:$Y$41,BettingScoreboard!$A28),COUNTIF(Scorecards!$H$55:$Y$55,BettingScoreboard!$A28),COUNTIF(Scorecards!$H$69:$Y$69,BettingScoreboard!$A28)) -> 0 | E28: =SUM(COUNTIF(Scorecards!$H$13:$Y$13,BettingScoreboard!$A28)*Scorecards!$AC$13,COUNTIF(Scorecards!$H$27:$Y$27, BettingScoreboard!$A28)*Scorecards!$AC$27,COUNTIF(Scorecards!$H$41:$Y$41,BettingScoreboard!$A28)*Scorecards!$AC$41,COUNTIF(Scorecards!$H$55:$Y$55, BettingScoreboard!$A28)*Scorecards!$AC$55,COUNTIF(Scorecards!$H$69:$Y$69, BettingScoreboard!$A28)*Scorecards!$AC$69) -> 0
A29: =Scorecards!B36 -> MV | B29: =SUM(COUNTIF(Scorecards!$H$12:$Y$12,BettingScoreboard!$A29),COUNTIF(Scorecards!$H$26:$Y$26,BettingScoreboard!$A29),COUNTIF(Scorecards!$H$40:$Y$40,BettingScoreboard!$A29),COUNTIF(Scorecards!$H$54:$Y$54,BettingScoreboard!$A29),COUNTIF(Scorecards!$H$68:$Y$68,BettingScoreboard!$A29)) -> 5 | C29: =SUM(COUNTIF(Scorecards!$H$12:$Y$12,BettingScoreboard!$A29)*Scorecards!$AC$12,COUNTIF(Scorecards!$H$26:$Y$26, BettingScoreboard!$A29)*Scorecards!$AC$26,COUNTIF(Scorecards!$H$40:$Y$40,BettingScoreboard!$A29)*Scorecards!$AC$40,COUNTIF(Scorecards!$H$54:$Y$54, BettingScoreboard!$A29)*Scorecards!$AC$54,COUNTIF(Scorecards!$H$68:$Y$68, BettingScoreboard!$A29)*Scorecards!$AC$68) -> 33.506494 | D29: =SUM(COUNTIF(Scorecards!$H$13:$Y$13,BettingScoreboard!$A29),COUNTIF(Scorecards!$H$27:$Y$27,BettingScoreboard!$A29),COUNTIF(Scorecards!$H$41:$Y$41,BettingScoreboard!$A29),COUNTIF(Scorecards!$H$55:$Y$55,BettingScoreboard!$A29),COUNTIF(Scorecards!$H$69:$Y$69,BettingScoreboard!$A29)) -> 0 | E29: =SUM(COUNTIF(Scorecards!$H$13:$Y$13,BettingScoreboard!$A29)*Scorecards!$AC$13,COUNTIF(Scorecards!$H$27:$Y$27, BettingScoreboard!$A29)*Scorecards!$AC$27,COUNTIF(Scorecards!$H$41:$Y$41,BettingScoreboard!$A29)*Scorecards!$AC$41,COUNTIF(Scorecards!$H$55:$Y$55, BettingScoreboard!$A29)*Scorecards!$AC$55,COUNTIF(Scorecards!$H$69:$Y$69, BettingScoreboard!$A29)*Scorecards!$AC$69) -> 0
A30: =Scorecards!B37 -> SR | B30: =SUM(COUNTIF(Scorecards!$H$12:$Y$12,BettingScoreboard!$A30),COUNTIF(Scorecards!$H$26:$Y$26,BettingScoreboard!$A30),COUNTIF(Scorecards!$H$40:$Y$40,BettingScoreboard!$A30),COUNTIF(Scorecards!$H$54:$Y$54,BettingScoreboard!$A30),COUNTIF(Scorecards!$H$68:$Y$68,BettingScoreboard!$A30)) -> 11 | C30: =SUM(COUNTIF(Scorecards!$H$12:$Y$12,BettingScoreboard!$A30)*Scorecards!$AC$12,COUNTIF(Scorecards!$H$26:$Y$26, BettingScoreboard!$A30)*Scorecards!$AC$26,COUNTIF(Scorecards!$H$40:$Y$40,BettingScoreboard!$A30)*Scorecards!$AC$40,COUNTIF(Scorecards!$H$54:$Y$54, BettingScoreboard!$A30)*Scorecards!$AC$54,COUNTIF(Scorecards!$H$68:$Y$68, BettingScoreboard!$A30)*Scorecards!$AC$68) -> 84.935065 | D30: =SUM(COUNTIF(Scorecards!$H$13:$Y$13,BettingScoreboard!$A30),COUNTIF(Scorecards!$H$27:$Y$27,BettingScoreboard!$A30),COUNTIF(Scorecards!$H$41:$Y$41,BettingScoreboard!$A30),COUNTIF(Scorecards!$H$55:$Y$55,BettingScoreboard!$A30),COUNTIF(Scorecards!$H$69:$Y$69,BettingScoreboard!$A30)) -> 0 | E30: =SUM(COUNTIF(Scorecards!$H$13:$Y$13,BettingScoreboard!$A30)*Scorecards!$AC$13,COUNTIF(Scorecards!$H$27:$Y$27, BettingScoreboard!$A30)*Scorecards!$AC$27,COUNTIF(Scorecards!$H$41:$Y$41,BettingScoreboard!$A30)*Scorecards!$AC$41,COUNTIF(Scorecards!$H$55:$Y$55, BettingScoreboard!$A30)*Scorecards!$AC$55,COUNTIF(Scorecards!$H$69:$Y$69, BettingScoreboard!$A30)*Scorecards!$AC$69) -> 0

Sheet BettingPayouts
A1: Name | B1: Skins Buyin | C1: Skins | D1: CTP Buyin | E1: CTP | F1: Per Round Low Buyin | G1: Per Round Low | H1: Single Round Low Buyin | I1: Single Round Low | J1: Cumulative Buyin | K1: Cumulative Low | L1: Total
A2: Aaron Jensen | B2: =-1*SUM(IF(Scorecards!D4="Y",Scorecards!$D$2, 0),IF(Scorecards!D18="Y",Scorecards!$D$16,0),IF(Scorecards!D32="Y",Scorecards!$D$30,0),IF(Scorecards!D46="Y",Scorecards!$D$44,0),IF(Scorecards!D60="Y",Scorecards!$D$58,0)) -> -40 | C2: =BettingScoreboard!C25 -> 22.597403 | D2: =-1*SUM(IF(Scorecards!E4="Y",Scorecards!$E$2, 0),IF(Scorecards!E18="Y",Scorecards!$E$16,0),IF(Scorecards!E32="Y",Scorecards!$E$30,0),IF(Scorecards!E46="Y",Scorecards!$E$44,0),IF(Scorecards!E60="Y",Scorecards!$E$58,0)) -> 0 | E2: =BettingScoreboard!E25 -> 0 | F2: =-1*SUM(IF(Scorecards!F4="Y",Scorecards!$F$2, 0),IF(Scorecards!F18="Y",Scorecards!$F$16,0),IF(Scorecards!F32="Y",Scorecards!$F$30,0),IF(Scorecards!F46="Y",Scorecards!$F$44,0),IF(Scorecards!F60="Y",Scorecards!$F$58,0)) -> 0 | G2: =SUM(IF(BettingScoreboard!$B2=MIN(BettingScoreboard!$B$2:$B$9),Scorecards!$F$12/BettingScoreboard!$B$10),IF(BettingScoreboard!$C2=MIN(BettingScoreboard!$C$2:$C$9),Scorecards!$F$26/BettingScoreboard!$C$10), IF(BettingScoreboard!$D2=MIN(BettingScoreboard!$D$2:$D$9),Scorecards!$F$40/BettingScoreboard!$D$10),IF(BettingScoreboard!$E2=MIN(BettingScoreboard!$E$2:$E$9),Scorecards!$F$54/BettingScoreboard!$E$10),IF(BettingScoreboard!$F2=MIN(BettingScoreboard!$F$2:$F$9),Scorecards!$F$68/BettingScoreboard!$F$10)) -> #ERROR! | H2: =-1*IF(WeekendLongBets!B3="Y",WeekendLongBets!$B$1,0) -> -10 | I2: =IF(BettingScoreboard!B14=MIN(BettingScoreboard!$B$14:$B$21),WeekendLongBets!$B$11/BettingScoreboard!$B$22, 0) -> #ERROR! | J2: =-1*IF(WeekendLongBets!C3="Y",WeekendLongBets!$C$1,0) -> 0 | K2: =IF(BettingScoreboard!E14=MIN(BettingScoreboard!$E$14:$E$21),WeekendLongBets!$C$11/BettingScoreboard!$E$22, 0) -> #ERROR! | L2: =SUM(B2:K2) -> #ERROR!
A3: Bob Bergeron | B3: =-1*SUM(IF(Scorecards!D5="Y",Scorecards!$D$2, 0),IF(Scorecards!D19="Y",Scorecards!$D$16,0),IF(Scorecards!D33="Y",Scorecards!$D$30,0),IF(Scorecards!D47="Y",Scorecards!$D$44,0),IF(Scorecards!D61="Y",Scorecards!$D$58,0)) -> -40 | C3: =BettingScoreboard!C26 -> 31.168831 | D3: =-1*SUM(IF(Scorecards!E5="Y",Scorecards!$E$2, 0),IF(Scorecards!E19="Y",Scorecards!$E$16,0),IF(Scorecards!E33="Y",Scorecards!$E$30,0),IF(Scorecards!E47="Y",Scorecards!$E$44,0),IF(Scorecards!E61="Y",Scorecards!$E$58,0)) -> 0 | E3: =BettingScoreboard!E26 -> 0 | F3: =-1*SUM(IF(Scorecards!F5="Y",Scorecards!$F$2, 0),IF(Scorecards!F19="Y",Scorecards!$F$16,0),IF(Scorecards!F33="Y",Scorecards!$F$30,0),IF(Scorecards!F47="Y",Scorecards!$F$44,0),IF(Scorecards!F61="Y",Scorecards!$F$58,0)) -> 0 | G3: =SUM(IF(BettingScoreboard!$B3=MIN(BettingScoreboard!$B$2:$B$9),Scorecards!$F$12/BettingScoreboard!$B$10),IF(BettingScoreboard!$C3=MIN(BettingScoreboard!$C$2:$C$9),Scorecards!$F$26/BettingScoreboard!$C$10), IF(BettingScoreboard!$D3=MIN(BettingScoreboard!$D$2:$D$9),Scorecards!$F$40/BettingScoreboard!$D$10),IF(BettingScoreboard!$E3=MIN(BettingScoreboard!$E$2:$E$9),Scorecards!$F$54/BettingScoreboard!$E$10),IF(BettingScoreboard!$F3=MIN(BettingScoreboard!$F$2:$F$9),Scorecards!$F$68/BettingScoreboard!$F$10)) -> #ERROR! | H3: =-1*IF(WeekendLongBets!B4="Y",WeekendLongBets!$B$1,0) -> -10 | I3: =IF(BettingScoreboard!B15=MIN(BettingScoreboard!$B$14:$B$21),WeekendLongBets!$B$11/BettingScoreboard!$B$22, 0) -> #ERROR! | J3: =-1*IF(WeekendLongBets!C4="Y",WeekendLongBets!$C$1,0) -> 0 | K3: =IF(BettingScoreboard!E15=MIN(BettingScoreboard!$E$14:$E$21),WeekendLongBets!$C$11/BettingScoreboard!$E$22, 0) -> #ERROR! | L3: =SUM(B3:K3) -> #ERROR!
A4: Brian Kelly | B4: =-1*SUM(IF(Scorecards!D6="Y",Scorecards!$D$2, 0),IF(Scorecards!D20="Y",Scorecards!$D$16,0),IF(Scorecards!D34="Y",Scorecards!$D$30,0),IF(Scorecards!D48="Y",Scorecards!$D$44,0),IF(Scorecards!D62="Y",Scorecards!$D$58,0)) -> -40 | C4: =BettingScoreboard!C27 -> 25.714286 | D4: =-1*SUM(IF(Scorecards!E6="Y",Scorecards!$E$2, 0),IF(Scorecards!E20="Y",Scorecards!$E$16,0),IF(Scorecards!E34="Y",Scorecards!$E$30,0),IF(Scorecards!E48="Y",Scorecards!$E$44,0),IF(Scorecards!E62="Y",Scorecards!$E$58,0)) -> 0 | E4: =BettingScoreboard!E27 -> 0 | F4: =-1*SUM(IF(Scorecards!F6="Y",Scorecards!$F$2, 0),IF(Scorecards!F20="Y",Scorecards!$F$16,0),IF(Scorecards!F34="Y",Scorecards!$F$30,0),IF(Scorecards!F48="Y",Scorecards!$F$44,0),IF(Scorecards!F62="Y",Scorecards!$F$58,0)) -> 0 | G4: =SUM(IF(BettingScoreboard!$B4=MIN(BettingScoreboard!$B$2:$B$9),Scorecards!$F$12/BettingScoreboard!$B$10),IF(BettingScoreboard!$C4=MIN(BettingScoreboard!$C$2:$C$9),Scorecards!$F$26/BettingScoreboard!$C$10), IF(BettingScoreboard!$D4=MIN(BettingScoreboard!$D$2:$D$9),Scorecards!$F$40/BettingScoreboard!$D$10),IF(BettingScoreboard!$E4=MIN(BettingScoreboard!$E$2:$E$9),Scorecards!$F$54/BettingScoreboard!$E$10),IF(BettingScoreboard!$F4=MIN(BettingScoreboard!$F$2:$F$9),Scorecards!$F$68/BettingScoreboard!$F$10)) -> #ERROR! | H4: =-1*IF(WeekendLongBets!B5="Y",WeekendLongBets!$B$1,0) -> -10 | I4: =IF(BettingScoreboard!B16=MIN(BettingScoreboard!$B$14:$B$21),WeekendLongBets!$B$11/BettingScoreboard!$B$22, 0) -> #ERROR! | J4: =-1*IF(WeekendLongBets!C5="Y",WeekendLongBets!$C$1,0) -> 0 | K4: =IF(BettingScoreboard!E16=MIN(BettingScoreboard!$E$14:$E$21),WeekendLongBets!$C$11/BettingScoreboard!$E$22, 0) -> #ERROR! | L4: =SUM(B4:K4) -> #ERROR!
A5: Eric Olson | B5: =-1*SUM(IF(Scorecards!D7="Y",Scorecards!$D$2, 0),IF(Scorecards!D21="Y",Scorecards!$D$16,0),IF(Scorecards!D35="Y",Scorecards!$D$30,0),IF(Scorecards!D49="Y",Scorecards!$D$44,0),IF(Scorecards!D63="Y",Scorecards!$D$58,0)) -> -40 | C5: =BettingScoreboard!C28 -> 42.077922 | D5: =-1*SUM(IF(Scorecards!E7="Y",Scorecards!$E$2, 0),IF(Scorecards!E21="Y",Scorecards!$E$16,0),IF(Scorecards!E35="Y",Scorecards!$E$30,0),IF(Scorecards!E49="Y",Scorecards!$E$44,0),IF(Scorecards!E63="Y",Scorecards!$E$58,0)) -> 0 | E5: =BettingScoreboard!E28 -> 0 | F5: =-1*SUM(IF(Scorecards!F7="Y",Scorecards!$F$2, 0),IF(Scorecards!F21="Y",Scorecards!$F$16,0),IF(Scorecards!F35="Y",Scorecards!$F$30,0),IF(Scorecards!F49="Y",Scorecards!$F$44,0),IF(Scorecards!F63="Y",Scorecards!$F$58,0)) -> 0 | G5: =SUM(IF(BettingScoreboard!$B5=MIN(BettingScoreboard!$B$2:$B$9),Scorecards!$F$12/BettingScoreboard!$B$10),IF(BettingScoreboard!$C5=MIN(BettingScoreboard!$C$2:$C$9),Scorecards!$F$26/BettingScoreboard!$C$10), IF(BettingScoreboard!$D5=MIN(BettingScoreboard!$D$2:$D$9),Scorecards!$F$40/BettingScoreboard!$D$10),IF(BettingScoreboard!$E5=MIN(BettingScoreboard!$E$2:$E$9),Scorecards!$F$54/BettingScoreboard!$E$10),IF(BettingScoreboard!$F5=MIN(BettingScoreboard!$F$2:$F$9),Scorecards!$F$68/BettingScoreboard!$F$10)) -> #ERROR! | H5: =-1*IF(WeekendLongBets!B6="Y",WeekendLongBets!$B$1,0) -> -10 | I5: =IF(BettingScoreboard!B17=MIN(BettingScoreboard!$B$14:$B$21),WeekendLongBets!$B$11/BettingScoreboard!$B$22, 0) -> #ERROR! | J5: =-1*IF(WeekendLongBets!C6="Y",WeekendLongBets!$C$1,0) -> 0 | K5: =IF(BettingScoreboard!E17=MIN(BettingScoreboard!$E$14:$E$21),WeekendLongBets!$C$11/BettingScoreboard!$E$22, 0) -> #ERROR! | L5: =SUM(B5:K5) -> #ERROR!
A6: Matt Vigo | B6: =-1*SUM(IF(Scorecards!D8="Y",Scorecards!$D$2, 0),IF(Scorecards!D22="Y",Scorecards!$D$16,0),IF(Scorecards!D36="Y",Scorecards!$D$30,0),IF(Scorecards!D50="Y",Scorecards!$D$44,0),IF(Scorecards!D64="Y",Scorecards!$D$58,0)) -> -40 | C6: =BettingScoreboard!C29 -> 33.506494 | D6: =-1*SUM(IF(Scorecards!E8="Y",Scorecards!$E$2, 0),IF(Scorecards!E22="Y",Scorecards!$E$16,0),IF(Scorecards!E36="Y",Scorecards!$E$30,0),IF(Scorecards!E50="Y",Scorecards!$E$44,0),IF(Scorecards!E64="Y",Scorecards!$E$58,0)) -> 0 | E6: =BettingScoreboard!E29 -> 0 | F6: =-1*SUM(IF(Scorecards!F8="Y",Scorecards!$F$2, 0),IF(Scorecards!F22="Y",Scorecards!$F$16,0),IF(Scorecards!F36="Y",Scorecards!$F$30,0),IF(Scorecards!F50="Y",Scorecards!$F$44,0),IF(Scorecards!F64="Y",Scorecards!$F$58,0)) -> 0 | G6: =SUM(IF(BettingScoreboard!$B6=MIN(BettingScoreboard!$B$2:$B$9),Scorecards!$F$12/BettingScoreboard!$B$10),IF(BettingScoreboard!$C6=MIN(BettingScoreboard!$C$2:$C$9),Scorecards!$F$26/BettingScoreboard!$C$10), IF(BettingScoreboard!$D6=MIN(BettingScoreboard!$D$2:$D$9),Scorecards!$F$40/BettingScoreboard!$D$10),IF(BettingScoreboard!$E6=MIN(BettingScoreboard!$E$2:$E$9),Scorecards!$F$54/BettingScoreboard!$E$10),IF(BettingScoreboard!$F6=MIN(BettingScoreboard!$F$2:$F$9),Scorecards!$F$68/BettingScoreboard!$F$10)) -> #ERROR! | H6: =-1*IF(WeekendLongBets!B7="Y",WeekendLongBets!$B$1,0) -> -10 | I6: =IF(BettingScoreboard!B18=MIN(BettingScoreboard!$B$14:$B$21),WeekendLongBets!$B$11/BettingScoreboard!$B$22, 0) -> #ERROR! | J6: =-1*IF(WeekendLongBets!C7="Y",WeekendLongBets!$C$1,0) -> 0 | K6: =IF(BettingScoreboard!E18=MIN(BettingScoreboard!$E$14:$E$21),WeekendLongBets!$C$11/BettingScoreboard!$E$22, 0) -> #ERROR! | L6: =SUM(B6:K6) -> #ERROR!
A7: Scott Rhoades | B7: =-1*SUM(IF(Scorecards!D9="Y",Scorecards!$D$2, 0),IF(Scorecards!D23="Y",Scorecards!$D$16,0),IF(Scorecards!D37="Y",Scorecards!$D$30,0),IF(Scorecards!D51="Y",Scorecards!$D$44,0),IF(Scorecards!D65="Y",Scorecards!$D$58,0)) -> -40 | C7: =BettingScoreboard!C30 -> 84.935065 | D7: =-1*SUM(IF(Scorecards!E9="Y",Scorecards!$E$2, 0),IF(Scorecards!E23="Y",Scorecards!$E$16,0),IF(Scorecards!E37="Y",Scorecards!$E$30,0),IF(Scorecards!E51="Y",Scorecards!$E$44,0),IF(Scorecards!E65="Y",Scorecards!$E$58,0)) -> 0 | E7: =BettingScoreboard!E30 -> 0 | F7: =-1*SUM(IF(Scorecards!F9="Y",Scorecards!$F$2, 0),IF(Scorecards!F23="Y",Scorecards!$F$16,0),IF(Scorecards!F37="Y",Scorecards!$F$30,0),IF(Scorecards!F51="Y",Scorecards!$F$44,0),IF(Scorecards!F65="Y",Scorecards!$F$58,0)) -> 0 | G7: =SUM(IF(BettingScoreboard!$B7=MIN(BettingScoreboard!$B$2:$B$9),Scorecards!$F$12/BettingScoreboard!$B$10),IF(BettingScoreboard!$C7=MIN(BettingScoreboard!$C$2:$C$9),Scorecards!$F$26/BettingScoreboard!$C$10), IF(BettingScoreboard!$D7=MIN(BettingScoreboard!$D$2:$D$9),Scorecards!$F$40/BettingScoreboard!$D$10),IF(BettingScoreboard!$E7=MIN(BettingScoreboard!$E$2:$E$9),Scorecards!$F$54/BettingScoreboard!$E$10),IF(BettingScoreboard!$F7=MIN(BettingScoreboard!$F$2:$F$9),Scorecards!$F$68/BettingScoreboard!$F$10)) -> #ERROR! | H7: =-1*IF(WeekendLongBets!B8="Y",WeekendLongBets!$B$1,0) -> -10 | I7: =IF(BettingScoreboard!B19=MIN(BettingScoreboard!$B$14:$B$21),WeekendLongBets!$B$11/BettingScoreboard!$B$22, 0) -> #ERROR! | J7: =-1*IF(WeekendLongBets!C8="Y",WeekendLongBets!$C$1,0) -> 0 | K7: =IF(BettingScoreboard!E19=MIN(BettingScoreboard!$E$14:$E$21),WeekendLongBets!$C$11/BettingScoreboard!$E$22, 0) -> #ERROR! | L7: =SUM(B7:K7) -> #ERROR!
