Workbook

Sheet LEADERBOARD
A1: 2018 WANNABE CUP
A2: POS | B2: SCORE | C2: TO PAR | D2: PLAYER | E2: =Scorecards!F1 -> GAILES | F2: =Scorecards!F13 -> SERRADELLA | G2: =Scorecards!F25 -> BLACKSHIRE | H2: =Scorecards!F37 -> RED HAWK
A3: =VLOOKUP(D3,Scores!$O$3:$P$8,2,FALSE) -> 1 | B3: =VLOOKUP(D3,Scores!$B$3:$L$8,11,FALSE) -> 303 | C3: =SUM((IF(E3="",0,Scorecards!$AA$3-E3)),(IF(F3="",0,Scorecards!$AA$15-F3)),(IF(G3="",0,Scorecards!$AA$27-G3)),(IF(H3="",0,Scorecards!$AA$39-H3)))*-1 -> 16 | D3: =VLOOKUP(1,Scores!$N$3:$O$8,2,FALSE) -> Jeff Blanton | E3: =VLOOKUP(D3,Scores!$B$3:$J$8,3,FALSE) -> 81 | F3: =VLOOKUP(D3,Scores!$B$3:$J$8,5,FALSE) -> 77 | G3: =VLOOKUP(D3,Scores!$B$3:$J$8,7,FALSE) -> 75 | H3: =VLOOKUP(D3,Scores!$B$3:$J$8,9,FALSE) -> 70
A4: =VLOOKUP(D4,Scores!$O$3:$P$8,2,FALSE) -> 2 | B4: =VLOOKUP(D4,Scores!$B$3:$L$8,11,FALSE) -> 306 | C4: =SUM((IF(E4="",0,Scorecards!$AA$3-E4)),(IF(F4="",0,Scorecards!$AA$15-F4)),(IF(G4="",0,Scorecards!$AA$27-G4)),(IF(H4="",0,Scorecards!$AA$39-H4)))*-1 -> 19 | D4: =VLOOKUP(2,Scores!$N$3:$O$8,2,FALSE) -> Aaron Jensen | E4: =VLOOKUP(D4,Scores!$B$3:$J$8,3,FALSE) -> 81 | F4: =VLOOKUP(D4,Scores!$B$3:$J$8,5,FALSE) -> 78 | G4: =VLOOKUP(D4,Scores!$B$3:$J$8,7,FALSE) -> 73 | H4: =VLOOKUP(D4,Scores!$B$3:$J$8,9,FALSE) -> 74
A5: =VLOOKUP(D5,Scores!$O$3:$P$8,2,FALSE) -> 3 | B5: =VLOOKUP(D5,Scores!$B$3:$L$8,11,FALSE) -> 309 | C5: =SUM((IF(E5="",0,Scorecards!$AA$3-E5)),(IF(F5="",0,Scorecards!$AA$15-F5)),(IF(G5="",0,Scorecards!$AA$27-G5)),(IF(H5="",0,Scorecards!$AA$39-H5)))*-1 -> 22 | D5: =VLOOKUP(3,Scores!$N$3:$O$8,2,FALSE) -> Scott Rhoades | E5: =VLOOKUP(D5,Scores!$B$3:$J$8,3,FALSE) -> 80 | F5: =VLOOKUP(D5,Scores!$B$3:$J$8,5,FALSE) -> 76 | G5: =VLOOKUP(D5,Scores!$B$3:$J$8,7,FALSE) -> 80 | H5: =VLOOKUP(D5,Scores!$B$3:$J$8,9,FALSE) -> 73
A6: =VLOOKUP(D6,Scores!$O$3:$P$8,2,FALSE) -> 4 | B6: =VLOOKUP(D6,Scores!$B$3:$L$8,11,FALSE) -> 323 | C6: =SUM((IF(E6="",0,Scorecards!$AA$3-E6)),(IF(F6="",0,Scorecards!$AA$15-F6)),(IF(G6="",0,Scorecards!$AA$27-G6)),(IF(H6="",0,Scorecards!$AA$39-H6)))*-1 -> 36 | D6: =VLOOKUP(4,Scores!$N$3:$O$8,2,FALSE) -> Brian Kelley | E6: =VLOOKUP(D6,Scores!$B$3:$J$8,3,FALSE) -> 88 | F6: =VLOOKUP(D6,Scores!$B$3:$J$8,5,FALSE) -> 77 | G6: =VLOOKUP(D6,Scores!$B$3:$J$8,7,FALSE) -> 73 | H6: =VLOOKUP(D6,Scores!$B$3:$J$8,9,FALSE) -> 85
A7: =VLOOKUP(D7,Scores!$O$3:$P$8,2,FALSE) -> 5 | B7: =VLOOKUP(D7,Scores!$B$3:$L$8,11,FALSE) -> 325 | C7: =SUM((IF(E7="",0,Scorecards!$AA$3-E7)),(IF(F7="",0,Scorecards!$AA$15-F7)),(IF(G7="",0,Scorecards!$AA$27-G7)),(IF(H7="",0,Scorecards!$AA$39-H7)))*-1 -> 38 | D7: =VLOOKUP(5,Scores!$N$3:$O$8,2,FALSE) -> Eric Olson | E7: =VLOOKUP(D7,Scores!$B$3:$J$8,3,FALSE) -> 79 | F7: =VLOOKUP(D7,Scores!$B$3:$J$8,5,FALSE) -> 84 | G7: =VLOOKUP(D7,Scores!$B$3:$J$8,7,FALSE) -> 85 | H7: =VLOOKUP(D7,Scores!$B$3:$J$8,9,FALSE) -> 77
A8: =VLOOKUP(D8,Scores!$O$3:$P$8,2,FALSE) -> 6 | B8: =VLOOKUP(D8,Scores!$B$3:$L$8,11,FALSE) -> 330 | C8: =SUM((IF(E8="",0,Scorecards!$AA$3-E8)),(IF(F8="",0,Scorecards!$AA$15-F8)),(IF(G8="",0,Scorecards!$AA$27-G8)),(IF(H8="",0,Scorecards!$AA$39-H8)))*-1 -> 43 | D8: =VLOOKUP(6,Scores!$N$3:$O$8,2,FALSE) -> Bob Bergeron | E8: =VLOOKUP(D8,Scores!$B$3:$J$8,3,FALSE) -> 83 | F8: =VLOOKUP(D8,Scores!$B$3:$J$8,5,FALSE) -> 76 | G8: =VLOOKUP(D8,Scores!$B$3:$J$8,7,FALSE) -> 85 | H8: =VLOOKUP(D8,Scores!$B$3:$J$8,9,FALSE) -> 86

Sheet Scorecards
F1: GAILES | AA1: 69.7 | AB1: 122
C2: 5 | D2: 5 | E2: 5 | F2: Hole | G2: 1 | H2: 2 | I2: 3 | J2: 4 | K2: 5 | L2: 6 | M2: 7 | N2: 8 | O2: 9 | P2: 10 | Q2: 11 | R2: 12 | S2: 13 | T2: 14 | U2: 15 | V2: 16 | W2: 17 | X2: 18 | Y2: OUT | Z2: IN | AA2: TOTAL | AB2: NET
A3: Player | B3: Handi | C3: SK | D3: CTP | E3: LO | F3: Par | G3: 4 | H3: 3 | I3: 4 | J3: 3 | K3: 4 | L3: 4 | M3: 5 | N3: 5 | O3: 4 | P3: 4 | Q3: 5 | R3: 3 | S3: 4 | T3: 4 | U3: 5 | V3: 3 | W3: 4 | X3: 4 | Y3: =SUM(G3:O3) -> 36 | Z3: =SUM(P3:X3) -> 36 | AA3: =Y3+Z3 -> 72
A4: AJ | B4: 6 | C4: Y | D4: Y | E4: Y | G4: 4 | H4: 3 | I4: 4 | J4: 4 | K4: 6 | L4: 5 | M4: 5 | N4: 7 | O4: 8 | P4: 6 | Q4: 4 | R4: 3 | S4: 6 | T4: 5 | U4: 5 | V4: 3 | W4: 5 | X4: 4 | Y4: =SUM(G4:O4) -> 46 | Z4: =SUM(P4:X4) -> 41 | AA4: =IF(Z4>0,Y4+Z4,"") -> 87 | AB4: =IF(Z4=0,"",AA4-B4) -> 81
A5: BB | B5: 13 | C5: Y | D5: Y | E5: Y | G5: 5 | H5: 3 | I5: 9 | J5: 5 | K5: 7 | L5: 5 | M5: 7 | N5: 6 | O5: 4 | P5: 4 | Q5: 5 | R5: 3 | S5: 8 | T5: 4 | U5: 6 | V5: 3 | W5: 6 | X5: 6 | Y5: =SUM(G5:O5) -> 51 | Z5: =SUM(P5:X5) -> 45 | AA5: =IF(Z5>0,Y5+Z5,"") -> 96 | AB5: =IF(Z5=0,"",AA5-B5) -> 83
A6: BK | B6: 13 | C6: Y | D6: Y | E6: Y | G6: 5 | H6: 4 | I6: 6 | J6: 4 | K6: 5 | L6: 5 | M6: 6 | N6: 5 | O6: 7 | P6: 6 | Q6: 5 | R6: 5 | S6: 5 | T6: 13 | U6: 6 | V6: 5 | W6: 4 | X6: 5 | Y6: =SUM(G6:O6) -> 47 | Z6: =SUM(P6:X6) -> 54 | AA6: =IF(Z6>0,Y6+Z6,"") -> 101 | AB6: =IF(Z6=0,"",AA6-B6) -> 88
A7: EO | B7: 16 | C7: Y | D7: Y | E7: Y | G7: 4 | H7: 3 | I7: 7 | J7: 4 | K7: 6 | L7: 5 | M7: 7 | N7: 5 | O7: 4 | P7: 6 | Q7: 7 | R7: 3 | S7: 6 | T7: 6 | U7: 6 | V7: 5 | W7: 5 | X7: 6 | Y7: =SUM(G7:O7) -> 45 | Z7: =SUM(P7:X7) -> 50 | AA7: =IF(Z7>0,Y7+Z7,"") -> 95 | AB7: =IF(Z7=0,"",AA7-B7) -> 79
A8: SR | B8: 6 | C8: Y | D8: Y | E8: Y | G8: 4 | H8: 4 | I8: 5 | J8: 4 | K8: 4 | L8: 5 | M8: 5 | N8: 8 | O8: 8 | P8: 5 | Q8: 7 | R8: 3 | S8: 4 | T8: 5 | U8: 5 | V8: 2 | W8: 4 | X8: 4 | Y8: =SUM(G8:O8) -> 47 | Z8: =SUM(P8:X8) -> 39 | AA8: =IF(Z8>0,Y8+Z8,"") -> 86 | AB8: =IF(Z8=0,"",AA8-B8) -> 80
A9: JB | B9: 23 | C9: Y | D9: Y | E9: Y | G9: 5 | H9: 4 | I9: 7 | J9: 4 | K9: 7 | L9: 7 | M9: 8 | N9: 6 | O9: 6 | P9: 4 | Q9: 8 | R9: 4 | S9: 6 | T9: 7 | U9: 7 | V9: 4 | W9: 5 | X9: 5 | Y9: =SUM(G9:O9) -> 54 | Z9: =SUM(P9:X9) -> 50 | AA9: =IF(Z9>0,Y9+Z9,"") -> 104 | AB9: =IF(Z9=0,"",AA9-B9) -> 81
C10: =COUNTIF(Scorecards!$C$4:$C$9, "Y")*C2 -> 30 | D10: =COUNTIF(Scorecards!$D$4:$D$9, "Y")*D2 -> 30 | E10: =COUNTIF(Scorecards!$E$4:$E$9, "Y")*E2 -> 30 | F10: SKIN | G10: {=IF(OR(SUM(IF(IF(Scorecards!$C$4:$C$9="Y", G4:G9, 10)=MIN(IF(Scorecards!$C$4:$C$9="Y", G4:G9, 10)), 1, 0)) > 1, MIN(IF(Scorecards!$C$4:$C$9="Y", G4:G9, 10)) > G3), "", INDEX(Scorecards!$A$4:$A$9,MATCH(MIN(IF(Scorecards!$C$4:$C$9="Y",G4:G9,10)),IF(Scorecards!$C$4:$C$9="Y",G4:G9,10),0)))} | H10: {=IF(OR(SUM(IF(IF(Scorecards!$C$4:$C$9="Y", H4:H9, 10)=MIN(IF(Scorecards!$C$4:$C$9="Y", H4:H9, 10)), 1, 0)) > 1, MIN(IF(Scorecards!$C$4:$C$9="Y", H4:H9, 10)) > H3), "", INDEX(Scorecards!$A$4:$A$9,MATCH(MIN(IF(Scorecards!$C$4:$C$9="Y",H4:H9,10)),IF(Scorecards!$C$4:$C$9="Y",H4:H9,10),0)))} | I10: {=IF(OR(SUM(IF(IF(Scorecards!$C$4:$C$9="Y", I4:I9, 10)=MIN(IF(Scorecards!$C$4:$C$9="Y", I4:I9, 10)), 1, 0)) > 1, MIN(IF(Scorecards!$C$4:$C$9="Y", I4:I9, 10)) > I3), "", INDEX(Scorecards!$A$4:$A$9,MATCH(MIN(IF(Scorecards!$C$4:$C$9="Y",I4:I9,10)),IF(Scorecards!$C$4:$C$9="Y",I4:I9,10),0)))} -> AJ | J10: {=IF(OR(SUM(IF(IF(Scorecards!$C$4:$C$9="Y", J4:J9, 10)=MIN(IF(Scorecards!$C$4:$C$9="Y", J4:J9, 10)), 1, 0)) > 1, MIN(IF(Scorecards!$C$4:$C$9="Y", J4:J9, 10)) > J3), "", INDEX(Scorecards!$A$4:$A$9,MATCH(MIN(IF(Scorecards!$C$4:$C$9="Y",J4:J9,10)),IF(Scorecards!$C$4:$C$9="Y",J4:J9,10),0)))} | K10: {=IF(OR(SUM(IF(IF(Scorecards!$C$4:$C$9="Y", K4:K9, 10)=MIN(IF(Scorecards!$C$4:$C$9="Y", K4:K9, 10)), 1, 0)) > 1, MIN(IF(Scorecards!$C$4:$C$9="Y", K4:K9, 10)) > K3), "", INDEX(Scorecards!$A$4:$A$9,MATCH(MIN(IF(Scorecards!$C$4:$C$9="Y",K4:K9,10)),IF(Scorecards!$C$4:$C$9="Y",K4:K9,10),0)))} -> SR | L10: {=IF(OR(SUM(IF(IF(Scorecards!$C$4:$C$9="Y", L4:L9, 10)=MIN(IF(Scorecards!$C$4:$C$9="Y", L4:L9, 10)), 1, 0)) > 1, MIN(IF(Scorecards!$C$4:$C$9="Y", L4:L9, 10)) > L3), "", INDEX(Scorecards!$A$4:$A$9,MATCH(MIN(IF(Scorecards!$C$4:$C$9="Y",L4:L9,10)),IF(Scorecards!$C$4:$C$9="Y",L4:L9,10),0)))} | M10: {=IF(OR(SUM(IF(IF(Scorecards!$C$4:$C$9="Y", M4:M9, 10)=MIN(IF(Scorecards!$C$4:$C$9="Y", M4:M9, 10)), 1, 0)) > 1, MIN(IF(Scorecards!$C$4:$C$9="Y", M4:M9, 10)) > M3), "", INDEX(Scorecards!$A$4:$A$9,MATCH(MIN(IF(Scorecards!$C$4:$C$9="Y",M4:M9,10)),IF(Scorecards!$C$4:$C$9="Y",M4:M9,10),0)))} | N10: {=IF(OR(SUM(IF(IF(Scorecards!$C$4:$C$9="Y", N4:N9, 10)=MIN(IF(Scorecards!$C$4:$C$9="Y", N4:N9, 10)), 1, 0)) > 1, MIN(IF(Scorecards!$C$4:$C$9="Y", N4:N9, 10)) > N3), "", INDEX(Scorecards!$A$4:$A$9,MATCH(MIN(IF(Scorecards!$C$4:$C$9="Y",N4:N9,10)),IF(Scorecards!$C$4:$C$9="Y",N4:N9,10),0)))} | ... X10: {=IF(OR(SUM(IF(IF(Scorecards!$C$4:$C$9="Y", X4:X9, 10)=MIN(IF(Scorecards!$C$4:$C$9="Y", X4:X9, 10)), 1, 0)) > 1, MIN(IF(Scorecards!$C$4:$C$9="Y", X4:X9, 10)) > X3), "", INDEX(Scorecards!$A$4:$A$9,MATCH(MIN(IF(Scorecards!$C$4:$C$9="Y",X4:X9,10)),IF(Scorecards!$C$4:$C$9="Y",X4:X9,10),0)))} | AA10: =18-COUNTBLANK(G10:X10) -> 6 | AB10: =IF(AA10 = 0, 0, C10/AA10) -> 5
F11: CTP | H11: AJ | AA11: =COUNTA(G11:Z11) -> 1 | AB11: =IF(AA11 = 0, 0, D10/AA11) -> 30
F13: SERRADELLA | AA13: 71.5 | AB13: 123
C14: 5 | D14: 5 | E14: 5 | F14: Hole | G14: 1 | H14: 2 | I14: 3 | J14: 4 | K14: 5 | L14: 6 | M14: 7 | N14: 8 | O14: 9 | P14: 10 | Q14: 11 | R14: 12 | S14: 13 | T14: 14 | U14: 15 | V14: 16 | W14: 17 | X14: 18 | Y14: OUT | Z14: IN | AA14: TOTAL | AB14: NET
A15: Player | B15: Handi | C15: SK | D15: CTP | E15: LO | F15: Par | G15: 4 | H15: 4 | I15: 3 | J15: 5 | K15: 4 | L15: 4 | M15: 3 | N15: 5 | O15: 4 | P15: 4 | Q15: 5 | R15: 3 | S15: 4 | T15: 4 | U15: 5 | V15: 3 | W15: 4 | X15: 4 | Y15: =SUM(G15:O15) -> 36 | Z15: =SUM(P15:X15) -> 36 | AA15: =Y15+Z15 -> 72
A16: AJ | B16: 6 | C16: Y | D16: Y | E16: Y | G16: 4 | H16: 5 | I16: 4 | J16: 7 | K16: 4 | L16: 4 | M16: 4 | N16: 4 | O16: 6 | P16: 6 | Q16: 6 | R16: 4 | S16: 3 | T16: 6 | U16: 4 | V16: 4 | W16: 4 | X16: 5 | Y16: =SUM(G16:O16) -> 42 | Z16: =SUM(P16:X16) -> 42 | AA16: =IF(Z16>0,Y16+Z16,"") -> 84 | AB16: =IF(Z16=0,"",AA16-B16) -> 78
A17: BB | B17: 12 | C17: Y | D17: Y | E17: Y | G17: 6 | H17: 4 | I17: 4 | J17: 6 | K17: 5 | L17: 5 | M17: 4 | N17: 6 | O17: 6 | P17: 5 | Q17: 6 | R17: 3 | S17: 3 | T17: 4 | U17: 5 | V17: 4 | W17: 4 | X17: 8 | Y17: =SUM(G17:O17) -> 46 | Z17: =SUM(P17:X17) -> 42 | AA17: =IF(Z17>0,Y17+Z17,"") -> 88 | AB17: =IF(Z17=0,"",AA17-B17) -> 76
A18: BK | B18: 13 | C18: Y | D18: Y | E18: Y | G18: 5 | H18: 5 | I18: 4 | J18: 6 | K18: 7 | L18: 6 | M18: 4 | N18: 7 | O18: 6 | P18: 5 | Q18: 5 | R18: 3 | S18: 5 | T18: 5 | U18: 5 | V18: 3 | W18: 4 | X18: 5 | Y18: =SUM(G18:O18) -> 50 | Z18: =SUM(P18:X18) -> 40 | AA18: =IF(Z18>0,Y18+Z18,"") -> 90 | AB18: =IF(Z18=0,"",AA18-B18) -> 77
A19: EO | B19: 16 | C19: Y | D19: Y | E19: Y | G19: 6 | H19: 4 | I19: 5 | J19: 7 | K19: 5 | L19: 7 | M19: 4 | N19: 5 | O19: 6 | P19: 5 | Q19: 8 | R19: 5 | S19: 5 | T19: 6 | U19: 7 | V19: 3 | W19: 6 | X19: 6 | Y19: =SUM(G19:O19) -> 49 | Z19: =SUM(P19:X19) -> 51 | AA19: =IF(Z19>0,Y19+Z19,"") -> 100 | AB19: =IF(Z19=0,"",AA19-B19) -> 84
A20: SR | B20: 6 | C20: Y | D20: Y | E20: Y | G20: 3 | H20: 4 | I20: 5 | J20: 6 | K20: 4 | L20: 4 | M20: 3 | N20: 6 | O20: 5 | P20: 4 | Q20: 6 | R20: 3 | S20: 5 | T20: 5 | U20: 7 | V20: 4 | W20: 4 | X20: 4 | Y20: =SUM(G20:O20) -> 40 | Z20: =SUM(P20:X20) -> 42 | AA20: =IF(Z20>0,Y20+Z20,"") -> 82 | AB20: =IF(Z20=0,"",AA20-B20) -> 76
A21: JB | B21: 22 | C21: Y | D21: Y | E21: Y | G21: 5 | H21: 5 | I21: 5 | J21: 8 | K21: 7 | L21: 5 | M21: 4 | N21: 6 | O21: 6 | P21: 6 | Q21: 7 | R21: 6 | S21: 4 | T21: 5 | U21: 6 | V21: 3 | W21: 6 | X21: 5 | Y21: =SUM(G21:O21) -> 51 | Z21: =SUM(P21:X21) -> 48 | AA21: =IF(Z21>0,Y21+Z21,"") -> 99 | AB21: =IF(Z21=0,"",AA21-B21) -> 77
C22: =COUNTIF(Scorecards!$C$4:$C$9, "Y")*C14 -> 30 | D22: =COUNTIF(Scorecards!$D$4:$D$9, "Y")*D14 -> 30 | E22: =COUNTIF(Scorecards!$E$16:$E$21, "Y")*E14 -> 30 | F22: SKIN | G22: {=IF(OR(SUM(IF(IF(Scorecards!$C$16:$C$21="Y", G16:G21, 10)=MIN(IF(Scorecards!$C$16:$C$21="Y", G16:G21, 10)), 1, 0)) > 1, MIN(IF(Scorecards!$C$16:$C$21="Y", G16:G21, 10)) > G15), "", INDEX(Scorecards!$A$16:$A$21,MATCH(MIN(IF(Scorecards!$C$16:$C$21="Y",G16:G21,10)),IF(Scorecards!$C$16:$C$21="Y",G16:G21,10),0)))} -> SR | H22: {=IF(OR(SUM(IF(IF(Scorecards!$C$16:$C$21="Y", H16:H21, 10)=MIN(IF(Scorecards!$C$16:$C$21="Y", H16:H21, 10)), 1, 0)) > 1, MIN(IF(Scorecards!$C$16:$C$21="Y", H16:H21, 10)) > H15), "", INDEX(Scorecards!$A$16:$A$21,MATCH(MIN(IF(Scorecards!$C$16:$C$21="Y",H16:H21,10)),IF(Scorecards!$C$16:$C$21="Y",H16:H21,10),0)))} | I22: {=IF(OR(SUM(IF(IF(Scorecards!$C$16:$C$21="Y", I16:I21, 10)=MIN(IF(Scorecards!$C$16:$C$21="Y", I16:I21, 10)), 1, 0)) > 1, MIN(IF(Scorecards!$C$16:$C$21="Y", I16:I21, 10)) > I15), "", INDEX(Scorecards!$A$16:$A$21,MATCH(MIN(IF(Scorecards!$C$16:$C$21="Y",I16:I21,10)),IF(Scorecards!$C$16:$C$21="Y",I16:I21,10),0)))} | J22: {=IF(OR(SUM(IF(IF(Scorecards!$C$16:$C$21="Y", J16:J21, 10)=MIN(IF(Scorecards!$C$16:$C$21="Y", J16:J21, 10)), 1, 0)) > 1, MIN(IF(Scorecards!$C$16:$C$21="Y", J16:J21, 10)) > J15), "", INDEX(Scorecards!$A$16:$A$21,MATCH(MIN(IF(Scorecards!$C$16:$C$21="Y",J16:J21,10)),IF(Scorecards!$C$16:$C$21="Y",J16:J21,10),0)))} | K22: {=IF(OR(SUM(IF(IF(Scorecards!$C$16:$C$21="Y", K16:K21, 10)=MIN(IF(Scorecards!$C$16:$C$21="Y", K16:K21, 10)), 1, 0)) > 1, MIN(IF(Scorecards!$C$16:$C$21="Y", K16:K21, 10)) > K15), "", INDEX(Scorecards!$A$16:$A$21,MATCH(MIN(IF(Scorecards!$C$16:$C$21="Y",K16:K21,10)),IF(Scorecards!$C$16:$C$21="Y",K16:K21,10),0)))} | L22: {=IF(OR(SUM(IF(IF(Scorecards!$C$16:$C$21="Y", L16:L21, 10)=MIN(IF(Scorecards!$C$16:$C$21="Y", L16:L21, 10)), 1, 0)) > 1, MIN(IF(Scorecards!$C$16:$C$21="Y", L16:L21, 10)) > L15), "", INDEX(Scorecards!$A$16:$A$21,MATCH(MIN(IF(Scorecards!$C$16:$C$21="Y",L16:L21,10)),IF(Scorecards!$C$16:$C$21="Y",L16:L21,10),0)))} | M22: {=IF(OR(SUM(IF(IF(Scorecards!$C$16:$C$21="Y", M16:M21, 10)=MIN(IF(Scorecards!$C$16:$C$21="Y", M16:M21, 10)), 1, 0)) > 1, MIN(IF(Scorecards!$C$16:$C$21="Y", M16:M21, 10)) > M15), "", INDEX(Scorecards!$A$16:$A$21,MATCH(MIN(IF(Scorecards!$C$16:$C$21="Y",M16:M21,10)),IF(Scorecards!$C$16:$C$21="Y",M16:M21,10),0)))} -> SR | N22: {=IF(OR(SUM(IF(IF(Scorecards!$C$16:$C$21="Y", N16:N21, 10)=MIN(IF(Scorecards!$C$16:$C$21="Y", N16:N21, 10)), 1, 0)) > 1, MIN(IF(Scorecards!$C$16:$C$21="Y", N16:N21, 10)) > N15), "", INDEX(Scorecards!$A$16:$A$21,MATCH(MIN(IF(Scorecards!$C$16:$C$21="Y",N16:N21,10)),IF(Scorecards!$C$16:$C$21="Y",N16:N21,10),0)))} -> AJ | ... X22: {=IF(OR(SUM(IF(IF(Scorecards!$C$16:$C$21="Y", X16:X21, 10)=MIN(IF(Scorecards!$C$16:$C$21="Y", X16:X21, 10)), 1, 0)) > 1, MIN(IF(Scorecards!$C$16:$C$21="Y", X16:X21, 10)) > X15), "", INDEX(Scorecards!$A$16:$A$21,MATCH(MIN(IF(Scorecards!$C$16:$C$21="Y",X16:X21,10)),IF(Scorecards!$C$16:$C$21="Y",X16:X21,10),0)))} -> SR | AA22: =18-COUNTBLANK(G22:X22) -> 8 | AB22: =IF(AA22 = 0, 0, C22/AA22) -> 3.75
F23: CTP | I23: BK | AA23: =COUNTA(G23:Z23) -> 1 | AB23: =IF(AA23 = 0, 0, D22/AA23) -> 30
F25: BLACKSHIRE | AA25: 69.7 | AB25: 126
C26: 5 | D26: 5 | E26: 5 | F26: Hole | G26: 1 | H26: 2 | I26: 3 | J26: 4 | K26: 5 | L26: 6 | M26: 7 | N26: 8 | O26: 9 | P26: 10 | Q26: 11 | R26: 12 | S26: 13 | T26: 14 | U26: 15 | V26: 16 | W26: 17 | X26: 18 | Y26: OUT | Z26: IN | AA26: TOTAL | AB26: NET
A27: Player | B27: Handi | C27: SK | D27: CTP | E27: LO | F27: Par | G27: 4 | H27: 5 | I27: 4 | J27: 3 | K27: 4 | L27: 4 | M27: 3 | N27: 4 | O27: 5 | P27: 4 | Q27: 3 | R27: 5 | S27: 4 | T27: 4 | U27: 4 | V27: 4 | W27: 3 | X27: 5 | Y27: =SUM(G27:O27) -> 36 | Z27: =SUM(P27:X27) -> 36 | AA27: =Y27+Z27 -> 72
A28: AJ | B28: 6 | C28: Y | D28: Y | E28: Y | G28: 5 | H28: 4 | I28: 3 | J28: 3 | K28: 5 | L28: 4 | M28: 4 | N28: 4 | O28: 5 | P28: 5 | Q28: 3 | R28: 5 | S28: 3 | T28: 6 | U28: 5 | V28: 5 | W28: 3 | X28: 7 | Y28: =SUM(G28:O28) -> 37 | Z28: =SUM(P28:X28) -> 42 | AA28: =IF(Z28>0,Y28+Z28,"") -> 79 | AB28: =IF(Z28=0,"",AA28-B28) -> 73
A29: BB | B29: 13 | C29: Y | D29: Y | E29: Y | G29: 6 | H29: 7 | I29: 8 | J29: 5 | K29: 6 | L29: 5 | M29: 5 | N29: 4 | O29: 6 | P29: 5 | Q29: 3 | R29: 5 | S29: 5 | T29: 6 | U29: 6 | V29: 6 | W29: 4 | X29: 6 | Y29: =SUM(G29:O29) -> 52 | Z29: =SUM(P29:X29) -> 46 | AA29: =IF(Z29>0,Y29+Z29,"") -> 98 | AB29: =IF(Z29=0,"",AA29-B29) -> 85
A30: BK | B30: 13 | C30: Y | D30: Y | E30: Y | G30: 3 | H30: 7 | I30: 5 | J30: 5 | K30: 6 | L30: 6 | M30: 3 | N30: 5 | O30: 4 | P30: 6 | Q30: 4 | R30: 5 | S30: 4 | T30: 4 | U30: 6 | V30: 5 | W30: 3 | X30: 5 | Y30: =SUM(G30:O30) -> 44 | Z30: =SUM(P30:X30) -> 42 | AA30: =IF(Z30>0,Y30+Z30,"") -> 86 | AB30: =IF(Z30=0,"",AA30-B30) -> 73
A31: EO | B31: 17 | C31: Y | D31: Y | E31: Y | G31: 3 | H31: 7 | I31: 7 | J31: 4 | K31: 6 | L31: 7 | M31: 4 | N31: 6 | O31: 8 | P31: 6 | Q31: 3 | R31: 7 | S31: 5 | T31: 7 | U31: 5 | V31: 6 | W31: 5 | X31: 6 | Y31: =SUM(G31:O31) -> 52 | Z31: =SUM(P31:X31) -> 50 | AA31: =IF(Z31>0,Y31+Z31,"") -> 102 | AB31: =IF(Z31=0,"",AA31-B31) -> 85
A32: SR | B32: 6 | C32: Y | D32: Y | E32: Y | G32: 4 | H32: 10 | I32: 5 | J32: 4 | K32: 4 | L32: 5 | M32: 3 | N32: 5 | O32: 6 | P32: 5 | Q32: 3 | R32: 5 | S32: 4 | T32: 4 | U32: 6 | V32: 4 | W32: 3 | X32: 6 | Y32: =SUM(G32:O32) -> 46 | Z32: =SUM(P32:X32) -> 40 | AA32: =IF(Z32>0,Y32+Z32,"") -> 86 | AB32: =IF(Z32=0,"",AA32-B32) -> 80
A33: JB | B33: 23 | C33: Y | D33: Y | E33: Y | G33: 8 | H33: 7 | I33: 5 | J33: 4 | K33: 7 | L33: 5 | M33: 3 | N33: 6 | O33: 6 | P33: 4 | Q33: 5 | R33: 9 | S33: 5 | T33: 5 | U33: 5 | V33: 5 | W33: 4 | X33: 5 | Y33: =SUM(G33:O33) -> 51 | Z33: =SUM(P33:X33) -> 47 | AA33: =IF(Z33>0,Y33+Z33,"") -> 98 | AB33: =IF(Z33=0,"",AA33-B33) -> 75
C34: =COUNTIF(Scorecards!$C$4:$C$9, "Y")*C26 -> 30 | D34: =COUNTIF(Scorecards!$D$4:$D$9, "Y")*D26 -> 30 | E34: =COUNTIF(Scorecards!$E$4:$E$9, "Y")*E26 -> 30 | F34: SKIN | G34: {=IF(OR(SUM(IF(IF(Scorecards!$C$28:$C$33="Y", G28:G33, 10)=MIN(IF(Scorecards!$C$28:$C$33="Y", G28:G33, 10)), 1, 0)) > 1, MIN(IF(Scorecards!$C$28:$C$33="Y", G28:G33, 10)) > G27), "", INDEX(Scorecards!$A$28:$A$33,MATCH(MIN(IF(Scorecards!$C$28:$C$33="Y",G28:G33,10)),IF(Scorecards!$C$28:$C$33="Y",G28:G33,10),0)))} | H34: {=IF(OR(SUM(IF(IF(Scorecards!$C$28:$C$33="Y", H28:H33, 10)=MIN(IF(Scorecards!$C$28:$C$33="Y", H28:H33, 10)), 1, 0)) > 1, MIN(IF(Scorecards!$C$28:$C$33="Y", H28:H33, 10)) > H27), "", INDEX(Scorecards!$A$28:$A$33,MATCH(MIN(IF(Scorecards!$C$28:$C$33="Y",H28:H33,10)),IF(Scorecards!$C$28:$C$33="Y",H28:H33,10),0)))} -> AJ | I34: {=IF(OR(SUM(IF(IF(Scorecards!$C$28:$C$33="Y", I28:I33, 10)=MIN(IF(Scorecards!$C$28:$C$33="Y", I28:I33, 10)), 1, 0)) > 1, MIN(IF(Scorecards!$C$28:$C$33="Y", I28:I33, 10)) > I27), "", INDEX(Scorecards!$A$28:$A$33,MATCH(MIN(IF(Scorecards!$C$28:$C$33="Y",I28:I33,10)),IF(Scorecards!$C$28:$C$33="Y",I28:I33,10),0)))} -> AJ | J34: {=IF(OR(SUM(IF(IF(Scorecards!$C$28:$C$33="Y", J28:J33, 10)=MIN(IF(Scorecards!$C$28:$C$33="Y", J28:J33, 10)), 1, 0)) > 1, MIN(IF(Scorecards!$C$28:$C$33="Y", J28:J33, 10)) > J27), "", INDEX(Scorecards!$A$28:$A$33,MATCH(MIN(IF(Scorecards!$C$28:$C$33="Y",J28:J33,10)),IF(Scorecards!$C$28:$C$33="Y",J28:J33,10),0)))} -> AJ | K34: {=IF(OR(SUM(IF(IF(Scorecards!$C$28:$C$33="Y", K28:K33, 10)=MIN(IF(Scorecards!$C$28:$C$33="Y", K28:K33, 10)), 1, 0)) > 1, MIN(IF(Scorecards!$C$28:$C$33="Y", K28:K33, 10)) > K27), "", INDEX(Scorecards!$A$28:$A$33,MATCH(MIN(IF(Scorecards!$C$28:$C$33="Y",K28:K33,10)),IF(Scorecards!$C$28:$C$33="Y",K28:K33,10),0)))} -> SR | L34: {=IF(OR(SUM(IF(IF(Scorecards!$C$28:$C$33="Y", L28:L33, 10)=MIN(IF(Scorecards!$C$28:$C$33="Y", L28:L33, 10)), 1, 0)) > 1, MIN(IF(Scorecards!$C$28:$C$33="Y", L28:L33, 10)) > L27), "", INDEX(Scorecards!$A$28:$A$33,MATCH(MIN(IF(Scorecards!$C$28:$C$33="Y",L28:L33,10)),IF(Scorecards!$C$28:$C$33="Y",L28:L33,10),0)))} -> AJ | M34: {=IF(OR(SUM(IF(IF(Scorecards!$C$28:$C$33="Y", M28:M33, 10)=MIN(IF(Scorecards!$C$28:$C$33="Y", M28:M33, 10)), 1, 0)) > 1, MIN(IF(Scorecards!$C$28:$C$33="Y", M28:M33, 10)) > M27), "", INDEX(Scorecards!$A$28:$A$33,MATCH(MIN(IF(Scorecards!$C$28:$C$33="Y",M28:M33,10)),IF(Scorecards!$C$28:$C$33="Y",M28:M33,10),0)))} | N34: {=IF(OR(SUM(IF(IF(Scorecards!$C$28:$C$33="Y", N28:N33, 10)=MIN(IF(Scorecards!$C$28:$C$33="Y", N28:N33, 10)), 1, 0)) > 1, MIN(IF(Scorecards!$C$28:$C$33="Y", N28:N33, 10)) > N27), "", INDEX(Scorecards!$A$28:$A$33,MATCH(MIN(IF(Scorecards!$C$28:$C$33="Y",N28:N33,10)),IF(Scorecards!$C$28:$C$33="Y",N28:N33,10),0)))} | ... X34: {=IF(OR(SUM(IF(IF(Scorecards!$C$28:$C$33="Y", X28:X33, 10)=MIN(IF(Scorecards!$C$28:$C$33="Y", X28:X33, 10)), 1, 0)) > 1, MIN(IF(Scorecards!$C$28:$C$33="Y", X28:X33, 10)) > X27), "", INDEX(Scorecards!$A$28:$A$33,MATCH(MIN(IF(Scorecards!$C$28:$C$33="Y",X28:X33,10)),IF(Scorecards!$C$28:$C$33="Y",X28:X33,10),0)))} | AA34: =18-COUNTBLANK(G34:X34) -> 9 | AB34: =IF(AA34 = 0, 0, C34/AA34) -> 3.3333333
F35: CTP | AA35: =COUNTA(G35:Z35) -> 0 | AB35: =IF(AA35 = 0, 0, D34/AA35) -> 0
F37: RED HAWK | AA37: 69.7 | AB37: 135
C38: 5 | D38: 10 | E38: 5 | F38: Hole | G38: 1 | H38: 2 | I38: 3 | J38: 4 | K38: 5 | L38: 6 | M38: 7 | N38: 8 | O38: 9 | P38: 10 | Q38: 11 | R38: 12 | S38: 13 | T38: 14 | U38: 15 | V38: 16 | W38: 17 | X38: 18 | Y38: OUT | Z38: IN | AA38: TOTAL | AB38: NET
A39: Player | B39: Handi | C39: SK | D39: CTP | E39: LO | F39: Par | G39: 4 | H39: 4 | I39: 3 | J39: 4 | K39: 5 | L39: 3 | M39: 5 | N39: 4 | O39: 4 | P39: 4 | Q39: 5 | R39: 3 | S39: 4 | T39: 3 | U39: 4 | V39: 5 | W39: 3 | X39: 4 | Y39: =SUM(G39:O39) -> 36 | Z39: =SUM(P39:X39) -> 35 | AA39: =Y39+Z39 -> 71
A40: AJ | B40: 7 | C40: Y | D40: Y | E40: Y | G40: 5 | H40: 5 | I40: 3 | J40: 4 | K40: 5 | L40: 4 | M40: 5 | N40: 4 | O40: 6 | P40: 5 | Q40: 5 | R40: 3 | S40: 5 | T40: 3 | U40: 5 | V40: 5 | W40: 4 | X40: 5 | Y40: =SUM(G40:O40) -> 41 | Z40: =SUM(P40:X40) -> 40 | AA40: =IF(Z40>0,Y40+Z40,"") -> 81 | AB40: =IF(Z40=0,"",AA40-B40) -> 74
A41: BB | B41: 14 | C41: Y | D41: Y | E41: Y | G41: 6 | H41: 7 | I41: 3 | J41: 7 | K41: 6 | L41: 3 | M41: 6 | N41: 6 | O41: 6 | P41: 6 | Q41: 7 | R41: 3 | S41: 5 | T41: 4 | U41: 7 | V41: 9 | W41: 4 | X41: 5 | Y41: =SUM(G41:O41) -> 50 | Z41: =SUM(P41:X41) -> 50 | AA41: =IF(Z41>0,Y41+Z41,"") -> 100 | AB41: =IF(Z41=0,"",AA41-B41) -> 86
A42: BK | B42: 14 | C42: Y | D42: Y | E42: Y | G42: 5 | H42: 4 | I42: 3 | J42: 5 | K42: 7 | L42: 8 | M42: 6 | N42: 5 | O42: 4 | P42: 6 | Q42: 10 | R42: 4 | S42: 7 | T42: 5 | U42: 5 | V42: 7 | W42: 3 | X42: 5 | Y42: =SUM(G42:O42) -> 47 | Z42: =SUM(P42:X42) -> 52 | AA42: =IF(Z42>0,Y42+Z42,"") -> 99 | AB42: =IF(Z42=0,"",AA42-B42) -> 85
A43: EO | B43: 18 | C43: Y | D43: Y | E43: Y | G43: 6 | H43: 6 | I43: 3 | J43: 4 | K43: 6 | L43: 5 | M43: 6 | N43: 6 | O43: 5 | P43: 5 | Q43: 6 | R43: 3 | S43: 5 | T43: 6 | U43: 5 | V43: 7 | W43: 5 | X43: 6 | Y43: =SUM(G43:O43) -> 47 | Z43: =SUM(P43:X43) -> 48 | AA43: =IF(Z43>0,Y43+Z43,"") -> 95 | AB43: =IF(Z43=0,"",AA43-B43) -> 77
...

Sheet Scores
B1: Player | C1: =Scorecards!F1 -> GAILES | E1: =Scorecards!F13 -> SERRADELLA | G1: =Scorecards!F25 -> BLACKSHIRE | I1: =Scorecards!F37 -> RED HAWK | K1: TOTAL
C2: GROSS | D2: NET | E2: GROSS | F2: NET | G2: GROSS | H2: NET | I2: GROSS | J2: NET | K2: GROSS | L2: NET
A3: =RANK(L3,L$3:L$7,1)+COUNTIF($L$3:L3,L3)-1 -> 1 | B3: Aaron Jensen | C3: =Scorecards!AA4 -> 87 | D3: =Scorecards!AB4 -> 81 | E3: =Scorecards!AA16 -> 84 | F3: =Scorecards!AB16 -> 78 | G3: =Scorecards!AA28 -> 79 | H3: =Scorecards!AB28 -> 73 | I3: =Scorecards!AA40 -> 81 | J3: =Scorecards!AB40 -> 74 | K3: =SUM(C3,E3,G3,I3) -> 331 | L3: =SUM(D3,F3,H3,J3) -> 306 | N3: =RANK(L3,$L$3:$L$8,1)+COUNTIF($L$3:L3,L3)-1 -> 2 | O3: =INDEX($B$3:$N$8,MATCH(N3,$N$3:$N$8,0),1) -> Aaron Jensen | P3: =RANK(L3,$L$3:$L$8,1) -> 2
A4: =RANK(L4,L$3:L$7,1)+COUNTIF($L$3:L4,L4)-1 -> 5 | B4: Bob Bergeron | C4: =Scorecards!AA5 -> 96 | D4: =Scorecards!AB5 -> 83 | E4: =Scorecards!AA17 -> 88 | F4: =Scorecards!AB17 -> 76 | G4: =Scorecards!AA29 -> 98 | H4: =Scorecards!AB29 -> 85 | I4: =Scorecards!AA41 -> 100 | J4: =Scorecards!AB41 -> 86 | K4: =SUM(C4,E4,G4,I4) -> 382 | L4: =SUM(D4,F4,H4,J4) -> 330 | N4: =RANK(L4,$L$3:$L$8,1)+COUNTIF($L$3:L4,L4)-1 -> 6 | O4: =INDEX($B$3:$N$8,MATCH(N4,$N$3:$N$8,0),1) -> Bob Bergeron | P4: =RANK(L4,$L$3:$L$8,1) -> 6
A5: =RANK(L5,L$3:L$7,1)+COUNTIF($L$3:L5,L5)-1 -> 3 | B5: Brian Kelley | C5: =Scorecards!AA6 -> 101 | D5: =Scorecards!AB6 -> 88 | E5: =Scorecards!AA18 -> 90 | F5: =Scorecards!AB18 -> 77 | G5: =Scorecards!AA30 -> 86 | H5: =Scorecards!AB30 -> 73 | I5: =Scorecards!AA42 -> 99 | J5: =Scorecards!AB42 -> 85 | K5: =SUM(C5,E5,G5,I5) -> 376 | L5: =SUM(D5,F5,H5,J5) -> 323 | N5: =RANK(L5,$L$3:$L$8,1)+COUNTIF($L$3:L5,L5)-1 -> 4 | O5: =INDEX($B$3:$N$8,MATCH(N5,$N$3:$N$8,0),1) -> Brian Kelley | P5: =RANK(L5,$L$3:$L$8,1) -> 4
A6: =RANK(L6,L$3:L$7,1)+COUNTIF($L$3:L6,L6)-1 -> 4 | B6: Eric Olson | C6: =Scorecards!AA7 -> 95 | D6: =Scorecards!AB7 -> 79 | E6: =Scorecards!AA19 -> 100 | F6: =Scorecards!AB19 -> 84 | G6: =Scorecards!AA31 -> 102 | H6: =Scorecards!AB31 -> 85 | I6: =Scorecards!AA43 -> 95 | J6: =Scorecards!AB43 -> 77 | K6: =SUM(C6,E6,G6,I6) -> 392 | L6: =SUM(D6,F6,H6,J6) -> 325 | N6: =RANK(L6,$L$3:$L$8,1)+COUNTIF($L$3:L6,L6)-1 -> 5 | O6: =INDEX($B$3:$N$8,MATCH(N6,$N$3:$N$8,0),1) -> Eric Olson | P6: =RANK(L6,$L$3:$L$8,1) -> 5
A7: =RANK(L7,L$3:L$7,1)+COUNTIF($L$3:L7,L7)-1 -> 2 | B7: Scott Rhoades | C7: =Scorecards!AA8 -> 86 | D7: =Scorecards!AB8 -> 80 | E7: =Scorecards!AA20 -> 82 | F7: =Scorecards!AB20 -> 76 | G7: =Scorecards!AA32 -> 86 | H7: =Scorecards!AB32 -> 80 | I7: =Scorecards!AA44 -> 80 | J7: =Scorecards!AB44 -> 73 | K7: =SUM(C7,E7,G7,I7) -> 334 | L7: =SUM(D7,F7,H7,J7) -> 309 | N7: =RANK(L7,$L$3:$L$8,1)+COUNTIF($L$3:L7,L7)-1 -> 3 | O7: =INDEX($B$3:$N$8,MATCH(N7,$N$3:$N$8,0),1) -> Scott Rhoades | P7: =RANK(L7,$L$3:$L$8,1) -> 3
B8: Jeff Blanton | C8: =Scorecards!AA9 -> 104 | D8: =Scorecards!AB9 -> 81 | E8: =Scorecards!AA21 -> 99 | F8: =Scorecards!AB21 -> 77 | G8: =Scorecards!AA33 -> 98 | H8: =Scorecards!AB33 -> 75 | I8: =Scorecards!AA45 -> 95 | J8: =Scorecards!AB45 -> 70 | K8: =SUM(C8,E8,G8,I8) -> 396 | L8: =SUM(D8,F8,H8,J8) -> 303 | N8: =RANK(L8,$L$3:$L$8,1)+COUNTIF($L$3:L8,L8)-1 -> 1 | O8: =INDEX($B$3:$N$8,MATCH(N8,$N$3:$N$8,0),1) -> Jeff Blanton | P8: =RANK(L8,$L$3:$L$8,1) -> 1

Sheet Shares
B1: $1 Shares | J1: =sum(J3:J10) -> 0 | L1: $0.50 Shares | T1: =sum(T3:T10) -> 0 | U1: Invested
B2: AJ | C2: BB | D2: BK | E2: EO | F2: SR | G2: SV | H2: DK | I2: JB | J2: TOTAL $1 | L2: AJ | M2: BB | N2: BK | O2: EO | P2: SR | Q2: SV | R2: DK | S2: JB | T2: TOTAL $0.50 | U2: =sum(U3:U8) -> 0
A3: Aaron Jensen | J3: =sum(B3:I3) -> 0 | K3: Aaron Jensen | T3: =sum(L3:S3)/2 -> 0 | U3: =J3+T3 -> 0
A4: Bob Bergeron | J4: =sum(B4:I4) -> 0 | K4: Bob Bergeron | T4: =sum(L4:S4)/2 -> 0 | U4: =J4+T4 -> 0
A5: Brian Kelley | J5: =sum(B5:I5) -> 0 | K5: Brian Kelley | T5: =sum(L5:S5)/2 -> 0 | U5: =J5+T5 -> 0
A6: Eric Olson | J6: =sum(B6:I6) -> 0 | K6: Eric Olson | T6: =sum(L6:S6)/2 -> 0 | U6: =J6+T6 -> 0
A7: Scott Rhoades | J7: =sum(B7:I7) -> 0 | K7: Scott Rhoades | T7: =sum(L7:S7)/2 -> 0 | U7: =J7+T7 -> 0
A8: Steve Vigo | J8: =sum(B8:I8) -> 0 | K8: Steve Vigo | T8: =sum(L8:S8)/2 -> 0 | U8: =J8+T8 -> 0
A9: Dave Kelley | J9: =sum(B9:I9) -> 0 | K9: Dave Kelley | T9: =sum(L9:S9)/2 -> 0 | U9: =J9+T9 -> 0
A10: Jeff Blanton | J10: =sum(B10:I10) -> 0 | K10: Jeff Blanton | T10: =sum(L10:S10)/2 -> 0 | U10: =J10+T10 -> 0
B11: =SUM(B3:B10) -> 0 | C11: =SUM(C3:C10) -> 0 | D11: =SUM(D3:D10) -> 0 | E11: =SUM(E3:E10) -> 0 | F11: =SUM(F3:F10) -> 0 | G11: =SUM(G3:G10) -> 0 | H11: =SUM(H3:H10) -> 0 | I11: =SUM(I3:I10) -> 0 | L11: =SUM(L3:L10) -> 0 | M11: =SUM(M3:M10) -> 0 | N11: =SUM(N3:N10) -> 0 | O11: =SUM(O3:O10) -> 0 | P11: =SUM(P3:P10) -> 0 | Q11: =SUM(Q3:Q10) -> 0 | R11: =SUM(R3:R10) -> 0 | S11: =SUM(S3:S10) -> 0
A13: WBC Winner
A16: Total $1 share | B16: =SUM(B3:I10) -> 0 | D16: Total $.50 share | E16: =SUM(L3:S10) -> 0
A17: winning shares | B17: =if($A$14=B2,B11,if($A$14=C2,C11,if($A$14=D2,D11,if($A$14=E2,E11,if($A$14=F2,F11,if($A$14=G2,G11,if($A$14=H2,H11,if($A$14=I2,I11,"TBD")))))))) -> TBD | D17: winning shares | E17: =if($A$14=L2,L11,if($A$14=M2,M11,if($A$14=N2,N11,if($A$14=O2,O11,if($A$14=P2,P11,if($A$14=Q2,Q11,if($A$14=R2,R11,if($A$14=S2,S11,"TBD")))))))) -> TBD
A18: per | B18: =if($B$17=0,0,B16/B17) -> #VALUE! | D18: per | E18: =if($E$17=0,0,(E16/E17)*0.5) -> #VALUE!
B19: shares | C19: $ | D19: shares | E19: $
A20: Aaron Jensen | B20: =if($A$14="",0,if($A$14=B$2,(vlookup(A20,$A$3:$I$10,2,FALSE)),if($A$14=C$2,(vlookup(A20,$A$3:$I$10,3,FALSE)),if($A$14=D$2,(vlookup(A20,$A$3:$I$10,4,FALSE)),if($A$14=E$2,(vlookup(A20,$A$3:$I$10,5,FALSE)),if($A$14=F$2,(vlookup(A20,$A$3:$I$10,6,FALSE)),if($A$14=G$2,(vlookup(A20,$A$3:$I$10,7,FALSE)),if($A$14=H$2,(vlookup(A20,$A$3:$I$10,8,FALSE)),if($A$14=I$2,(vlookup(A20,$A$3:$I$10,9,FALSE)),0))))))))) -> 0 | C20: =B20*$B$18 -> #VALUE! | D20: =if($A$14="","",if($A$14=L$2,(vlookup($A20,$K$3:$S$10,2,FALSE)),if($A$14=M$2,(vlookup($A20,$K$3:$S$10,3,FALSE)),if($A$14=N$2,(vlookup($A20,$K$3:$S$10,4,FALSE)),if($A$14=O$2,(vlookup($A20,$K$3:$S$10,5,FALSE)),if($A$14=P$2,(vlookup($A20,$K$3:$S$10,6,FALSE)),if($A$14=Q$2,(vlookup($A20,$K$3:$S$10,7,FALSE)),if($A$14=R$2,(vlookup($A20,$K$3:$S$10,8,FALSE)), if($A$14=S$2,(vlookup($A20,$K$3:$S$10,9,FALSE))))))))))) | E20: =D20*$E$18 -> #VALUE!
A21: Bob Bergeron | B21: =if($A$14="",0,if($A$14=B$2,(vlookup(A21,$A$3:$I$10,2,FALSE)),if($A$14=C$2,(vlookup(A21,$A$3:$I$10,3,FALSE)),if($A$14=D$2,(vlookup(A21,$A$3:$I$10,4,FALSE)),if($A$14=E$2,(vlookup(A21,$A$3:$I$10,5,FALSE)),if($A$14=F$2,(vlookup(A21,$A$3:$I$10,6,FALSE)),if($A$14=G$2,(vlookup(A21,$A$3:$I$10,7,FALSE)),if($A$14=H$2,(vlookup(A21,$A$3:$I$10,8,FALSE)),if($A$14=I$2,(vlookup(A21,$A$3:$I$10,9,FALSE)),0))))))))) -> 0 | C21: =B21*$B$18 -> #VALUE! | D21: =if($A$14="","",if($A$14=L$2,(vlookup($A21,$K$3:$S$10,2,FALSE)),if($A$14=M$2,(vlookup($A21,$K$3:$S$10,3,FALSE)),if($A$14=N$2,(vlookup($A21,$K$3:$S$10,4,FALSE)),if($A$14=O$2,(vlookup($A21,$K$3:$S$10,5,FALSE)),if($A$14=P$2,(vlookup($A21,$K$3:$S$10,6,FALSE)),if($A$14=Q$2,(vlookup($A21,$K$3:$S$10,7,FALSE)),if($A$14=R$2,(vlookup($A21,$K$3:$S$10,8,FALSE)), if($A$14=S$2,(vlookup($A21,$K$3:$S$10,9,FALSE))))))))))) | E21: =D21*$E$18 -> #VALUE!
A22: Brian Kelley | B22: =if($A$14="",0,if($A$14=B$2,(vlookup(A22,$A$3:$I$10,2,FALSE)),if($A$14=C$2,(vlookup(A22,$A$3:$I$10,3,FALSE)),if($A$14=D$2,(vlookup(A22,$A$3:$I$10,4,FALSE)),if($A$14=E$2,(vlookup(A22,$A$3:$I$10,5,FALSE)),if($A$14=F$2,(vlookup(A22,$A$3:$I$10,6,FALSE)),if($A$14=G$2,(vlookup(A22,$A$3:$I$10,7,FALSE)),if($A$14=H$2,(vlookup(A22,$A$3:$I$10,8,FALSE)),if($A$14=I$2,(vlookup(A22,$A$3:$I$10,9,FALSE)),0))))))))) -> 0 | C22: =B22*$B$18 -> #VALUE! | D22: =if($A$14="","",if($A$14=L$2,(vlookup($A22,$K$3:$S$10,2,FALSE)),if($A$14=M$2,(vlookup($A22,$K$3:$S$10,3,FALSE)),if($A$14=N$2,(vlookup($A22,$K$3:$S$10,4,FALSE)),if($A$14=O$2,(vlookup($A22,$K$3:$S$10,5,FALSE)),if($A$14=P$2,(vlookup($A22,$K$3:$S$10,6,FALSE)),if($A$14=Q$2,(vlookup($A22,$K$3:$S$10,7,FALSE)),if($A$14=R$2,(vlookup($A22,$K$3:$S$10,8,FALSE)), if($A$14=S$2,(vlookup($A22,$K$3:$S$10,9,FALSE))))))))))) | E22: =D22*$E$18 -> #VALUE!
A23: Eric Olson | B23: =if($A$14="",0,if($A$14=B$2,(vlookup(A23,$A$3:$I$10,2,FALSE)),if($A$14=C$2,(vlookup(A23,$A$3:$I$10,3,FALSE)),if($A$14=D$2,(vlookup(A23,$A$3:$I$10,4,FALSE)),if($A$14=E$2,(vlookup(A23,$A$3:$I$10,5,FALSE)),if($A$14=F$2,(vlookup(A23,$A$3:$I$10,6,FALSE)),if($A$14=G$2,(vlookup(A23,$A$3:$I$10,7,FALSE)),if($A$14=H$2,(vlookup(A23,$A$3:$I$10,8,FALSE)),if($A$14=I$2,(vlookup(A23,$A$3:$I$10,9,FALSE)),0))))))))) -> 0 | C23: =B23*$B$18 -> #VALUE! | D23: =if($A$14="","",if($A$14=L$2,(vlookup($A23,$K$3:$S$10,2,FALSE)),if($A$14=M$2,(vlookup($A23,$K$3:$S$10,3,FALSE)),if($A$14=N$2,(vlookup($A23,$K$3:$S$10,4,FALSE)),if($A$14=O$2,(vlookup($A23,$K$3:$S$10,5,FALSE)),if($A$14=P$2,(vlookup($A23,$K$3:$S$10,6,FALSE)),if($A$14=Q$2,(vlookup($A23,$K$3:$S$10,7,FALSE)),if($A$14=R$2,(vlookup($A23,$K$3:$S$10,8,FALSE)), if($A$14=S$2,(vlookup($A23,$K$3:$S$10,9,FALSE))))))))))) | E23: =D23*$E$18 -> #VALUE!
A24: Scott Rhoades | B24: =if($A$14="",0,if($A$14=B$2,(vlookup(A24,$A$3:$I$10,2,FALSE)),if($A$14=C$2,(vlookup(A24,$A$3:$I$10,3,FALSE)),if($A$14=D$2,(vlookup(A24,$A$3:$I$10,4,FALSE)),if($A$14=E$2,(vlookup(A24,$A$3:$I$10,5,FALSE)),if($A$14=F$2,(vlookup(A24,$A$3:$I$10,6,FALSE)),if($A$14=G$2,(vlookup(A24,$A$3:$I$10,7,FALSE)),if($A$14=H$2,(vlookup(A24,$A$3:$I$10,8,FALSE)),if($A$14=I$2,(vlookup(A24,$A$3:$I$10,9,FALSE)),0))))))))) -> 0 | C24: =B24*$B$18 -> #VALUE! | D24: =if($A$14="","",if($A$14=L$2,(vlookup($A24,$K$3:$S$10,2,FALSE)),if($A$14=M$2,(vlookup($A24,$K$3:$S$10,3,FALSE)),if($A$14=N$2,(vlookup($A24,$K$3:$S$10,4,FALSE)),if($A$14=O$2,(vlookup($A24,$K$3:$S$10,5,FALSE)),if($A$14=P$2,(vlookup($A24,$K$3:$S$10,6,FALSE)),if($A$14=Q$2,(vlookup($A24,$K$3:$S$10,7,FALSE)),if($A$14=R$2,(vlookup($A24,$K$3:$S$10,8,FALSE)), if($A$14=S$2,(vlookup($A24,$K$3:$S$10,9,FALSE))))))))))) | E24: =D24*$E$18 -> #VALUE!
A25: Steve Vigo | B25: =if($A$14="",0,if($A$14=B$2,(vlookup(A25,$A$3:$I$10,2,FALSE)),if($A$14=C$2,(vlookup(A25,$A$3:$I$10,3,FALSE)),if($A$14=D$2,(vlookup(A25,$A$3:$I$10,4,FALSE)),if($A$14=E$2,(vlookup(A25,$A$3:$I$10,5,FALSE)),if($A$14=F$2,(vlookup(A25,$A$3:$I$10,6,FALSE)),if($A$14=G$2,(vlookup(A25,$A$3:$I$10,7,FALSE)),if($A$14=H$2,(vlookup(A25,$A$3:$I$10,8,FALSE)),if($A$14=I$2,(vlookup(A25,$A$3:$I$10,9,FALSE)),0))))))))) -> 0 | C25: =B25*$B$18 -> #VALUE! | D25: =if($A$14="","",if($A$14=L$2,(vlookup($A25,$K$3:$S$10,2,FALSE)),if($A$14=M$2,(vlookup($A25,$K$3:$S$10,3,FALSE)),if($A$14=N$2,(vlookup($A25,$K$3:$S$10,4,FALSE)),if($A$14=O$2,(vlookup($A25,$K$3:$S$10,5,FALSE)),if($A$14=P$2,(vlookup($A25,$K$3:$S$10,6,FALSE)),if($A$14=Q$2,(vlookup($A25,$K$3:$S$10,7,FALSE)),if($A$14=R$2,(vlookup($A25,$K$3:$S$10,8,FALSE)), if($A$14=S$2,(vlookup($A25,$K$3:$S$10,9,FALSE))))))))))) | E25: =D25*$E$18 -> #VALUE!
A26: Dave Kelley | B26: =if($A$14="",0,if($A$14=B$2,(vlookup(A26,$A$3:$I$10,2,FALSE)),if($A$14=C$2,(vlookup(A26,$A$3:$I$10,3,FALSE)),if($A$14=D$2,(vlookup(A26,$A$3:$I$10,4,FALSE)),if($A$14=E$2,(vlookup(A26,$A$3:$I$10,5,FALSE)),if($A$14=F$2,(vlookup(A26,$A$3:$I$10,6,FALSE)),if($A$14=G$2,(vlookup(A26,$A$3:$I$10,7,FALSE)),if($A$14=H$2,(vlookup(A26,$A$3:$I$10,8,FALSE)),if($A$14=I$2,(vlookup(A26,$A$3:$I$10,9,FALSE)),0))))))))) -> 0 | C26: =B26*$B$18 -> #VALUE! | D26: =if($A$14="","",if($A$14=L$2,(vlookup($A26,$K$3:$S$10,2,FALSE)),if($A$14=M$2,(vlookup($A26,$K$3:$S$10,3,FALSE)),if($A$14=N$2,(vlookup($A26,$K$3:$S$10,4,FALSE)),if($A$14=O$2,(vlookup($A26,$K$3:$S$10,5,FALSE)),if($A$14=P$2,(vlookup($A26,$K$3:$S$10,6,FALSE)),if($A$14=Q$2,(vlookup($A26,$K$3:$S$10,7,FALSE)),if($A$14=R$2,(vlookup($A26,$K$3:$S$10,8,FALSE)), if($A$14=S$2,(vlookup($A26,$K$3:$S$10,9,FALSE))))))))))) | E26: =D26*$E$18 -> #VALUE!
A27: Jeff Blanton | B27: =if($A$14="",0,if($A$14=B$2,(vlookup(A27,$A$3:$I$10,2,FALSE)),if($A$14=C$2,(vlookup(A27,$A$3:$I$10,3,FALSE)),if($A$14=D$2,(vlookup(A27,$A$3:$I$10,4,FALSE)),if($A$14=E$2,(vlookup(A27,$A$3:$I$10,5,FALSE)),if($A$14=F$2,(vlookup(A27,$A$3:$I$10,6,FALSE)),if($A$14=G$2,(vlookup(A27,$A$3:$I$10,7,FALSE)),if($A$14=H$2,(vlookup(A27,$A$3:$I$10,8,FALSE)),if($A$14=I$2,(vlookup(A27,$A$3:$I$10,9,FALSE)),0))))))))) -> 0 | C27: =B27*$B$18 -> #VALUE! | D27: =if($A$14="","",if($A$14=L$2,(vlookup($A27,$K$3:$S$10,2,FALSE)),if($A$14=M$2,(vlookup($A27,$K$3:$S$10,3,FALSE)),if($A$14=N$2,(vlookup($A27,$K$3:$S$10,4,FALSE)),if($A$14=O$2,(vlookup($A27,$K$3:$S$10,5,FALSE)),if($A$14=P$2,(vlookup($A27,$K$3:$S$10,6,FALSE)),if($A$14=Q$2,(vlookup($A27,$K$3:$S$10,7,FALSE)),if($A$14=R$2,(vlookup($A27,$K$3:$S$10,8,FALSE)), if($A$14=S$2,(vlookup($A27,$K$3:$S$10,9,FALSE))))))))))) | E27: =D27*$E$18 -> #VALUE!

Sheet BettingScoreboard
A1: Low Per Round | B1: =Scorecards!F1 -> GAILES | C1: =Scorecards!F13 -> SERRADELLA | D1: =Scorecards!F25 -> BLACKSHIRE | E1: =Scorecards!F37 -> RED HAWK
A2: Aaron Jensen | B2: =IF(Scorecards!E4="Y",Scores!D3, "") -> 81 | C2: =IF(Scorecards!E16="Y",Scores!F3, "") -> 78 | D2: =IF(Scorecards!E28="Y",Scores!H3, "") -> 73 | E2: =IF(Scorecards!E40="Y",Scores!J3, "") -> 74
A3: Bob Bergeron | B3: =IF(Scorecards!E5="Y",Scores!D4, "") -> 83 | C3: =IF(Scorecards!E17="Y",Scores!F4, "") -> 76 | D3: =IF(Scorecards!E29="Y",Scores!H4, "") -> 85 | E3: =IF(Scorecards!E41="Y",Scores!J4, "") -> 86
A4: Brian Kelley | B4: =IF(Scorecards!E6="Y",Scores!D5, "") -> 88 | C4: =IF(Scorecards!E18="Y",Scores!F5, "") -> 77 | D4: =IF(Scorecards!E30="Y",Scores!H5, "") -> 73 | E4: =IF(Scorecards!E42="Y",Scores!J5, "") -> 85
A5: Eric Olson | B5: =IF(Scorecards!E7="Y",Scores!D6, "") -> 79 | C5: =IF(Scorecards!E19="Y",Scores!F6, "") -> 84 | D5: =IF(Scorecards!E31="Y",Scores!H6, "") -> 85 | E5: =IF(Scorecards!E43="Y",Scores!J6, "") -> 77
A6: Scott Rhoades | B6: =IF(Scorecards!E8="Y",Scores!D7, "") -> 80 | C6: =IF(Scorecards!E20="Y",Scores!F7, "") -> 76 | D6: =IF(Scorecards!E32="Y",Scores!H7, "") -> 80 | E6: =IF(Scorecards!E44="Y",Scores!J7, "") -> 73
A7: Steve Vigo | B7: =IF(#REF!="Y",#REF!, "") -> #REF! | C7: =IF(#REF!="Y",#REF!, "") -> #REF! | D7: =IF(#REF!="Y",#REF!, "") -> #REF! | E7: =IF(#REF!="Y",#REF!, "") -> #REF!
A8: Dave Kelley | B8: =IF(#REF!="Y",#REF!, "") -> #REF! | C8: =IF(#REF!="Y",#REF!, "") -> #REF! | D8: =IF(#REF!="Y",#REF!, "") -> #REF! | E8: =IF(#REF!="Y",#REF!, "") -> #REF!
A9: Jeff Blanton | B9: =IF(Scorecards!E9="Y",Scores!D8, "") -> 81 | C9: =IF(Scorecards!E21="Y",Scores!F8, "") -> 77 | D9: =IF(Scorecards!E33="Y",Scores!H8, "") -> 75 | E9: =IF(Scorecards!E45="Y",Scores!J8, "") -> 70
A10: # of Winners | B10: =COUNTIF(BettingScoreboard!$B$2:$B$9,MIN(BettingScoreboard!$B$2:$B$9)) -> 2 | C10: =COUNTIF(BettingScoreboard!$C$2:$C$9,MIN(BettingScoreboard!$C$2:$C$9)) -> 2 | D10: =COUNTIF(BettingScoreboard!$D$2:$D$9,MIN(BettingScoreboard!$D$2:$D$9)) -> 2 | E10: =COUNTIF(BettingScoreboard!$E$2:$E$9,MIN(BettingScoreboard!$E$2:$E$9)) -> 2
A12: Player | B12: Skins | C12: Skin $
A13: AJ | B13: =SUM(COUNTIF(Scorecards!$G$10:$X$10,BettingScoreboard!$A13),COUNTIF(Scorecards!$G$22:$X$22,BettingScoreboard!$A13),COUNTIF(Scorecards!$G$34:$X$34,BettingScoreboard!$A13),COUNTIF(Scorecards!$G$46:$X$46,BettingScoreboard!$A13)) -> 11 | C13: =SUM(COUNTIF(Scorecards!$G$10:$X$10,BettingScoreboard!$A13)*Scorecards!$AB$10,COUNTIF(Scorecards!$G$22:$X$22, BettingScoreboard!$A13)*Scorecards!$AB$22,COUNTIF(Scorecards!$G$34:$X$34,BettingScoreboard!$A13)*Scorecards!$AB$34,COUNTIF(Scorecards!$G$46:$X$46, BettingScoreboard!$A13)*Scorecards!$AB$46) -> 40.166667
A14: BB | B14: =SUM(COUNTIF(Scorecards!$G$10:$X$10,BettingScoreboard!$A14),COUNTIF(Scorecards!$G$22:$X$22,BettingScoreboard!$A14),COUNTIF(Scorecards!$G$34:$X$34,BettingScoreboard!$A14),COUNTIF(Scorecards!$G$46:$X$46,BettingScoreboard!$A14)) -> 3 | C14: =SUM(COUNTIF(Scorecards!$G$10:$X$10,BettingScoreboard!$A14)*Scorecards!$AB$10,COUNTIF(Scorecards!$G$22:$X$22, BettingScoreboard!$A14)*Scorecards!$AB$22,COUNTIF(Scorecards!$G$34:$X$34,BettingScoreboard!$A14)*Scorecards!$AB$34,COUNTIF(Scorecards!$G$46:$X$46, BettingScoreboard!$A14)*Scorecards!$AB$46) -> 11.75
A15: BK | B15: =SUM(COUNTIF(Scorecards!$G$10:$X$10,BettingScoreboard!$A15),COUNTIF(Scorecards!$G$22:$X$22,BettingScoreboard!$A15),COUNTIF(Scorecards!$G$34:$X$34,BettingScoreboard!$A15),COUNTIF(Scorecards!$G$46:$X$46,BettingScoreboard!$A15)) -> 4 | C15: =SUM(COUNTIF(Scorecards!$G$10:$X$10,BettingScoreboard!$A15)*Scorecards!$AB$10,COUNTIF(Scorecards!$G$22:$X$22, BettingScoreboard!$A15)*Scorecards!$AB$22,COUNTIF(Scorecards!$G$34:$X$34,BettingScoreboard!$A15)*Scorecards!$AB$34,COUNTIF(Scorecards!$G$46:$X$46, BettingScoreboard!$A15)*Scorecards!$AB$46) -> 13.083333
A16: EO | B16: =SUM(COUNTIF(Scorecards!$G$10:$X$10,BettingScoreboard!$A16),COUNTIF(Scorecards!$G$22:$X$22,BettingScoreboard!$A16),COUNTIF(Scorecards!$G$34:$X$34,BettingScoreboard!$A16),COUNTIF(Scorecards!$G$46:$X$46,BettingScoreboard!$A16)) -> 0 | C16: =SUM(COUNTIF(Scorecards!$G$10:$X$10,BettingScoreboard!$A16)*Scorecards!$AB$10,COUNTIF(Scorecards!$G$22:$X$22, BettingScoreboard!$A16)*Scorecards!$AB$22,COUNTIF(Scorecards!$G$34:$X$34,BettingScoreboard!$A16)*Scorecards!$AB$34,COUNTIF(Scorecards!$G$46:$X$46, BettingScoreboard!$A16)*Scorecards!$AB$46) -> 0
A17: SR | B17: =SUM(COUNTIF(Scorecards!$G$10:$X$10,BettingScoreboard!$A17),COUNTIF(Scorecards!$G$22:$X$22,BettingScoreboard!$A17),COUNTIF(Scorecards!$G$34:$X$34,BettingScoreboard!$A17),COUNTIF(Scorecards!$G$46:$X$46,BettingScoreboard!$A17)) -> 13 | C17: =SUM(COUNTIF(Scorecards!$G$10:$X$10,BettingScoreboard!$A17)*Scorecards!$AB$10,COUNTIF(Scorecards!$G$22:$X$22, BettingScoreboard!$A17)*Scorecards!$AB$22,COUNTIF(Scorecards!$G$34:$X$34,BettingScoreboard!$A17)*Scorecards!$AB$34,COUNTIF(Scorecards!$G$46:$X$46, BettingScoreboard!$A17)*Scorecards!$AB$46) -> 48.666667
A18: SV | B18: =SUM(COUNTIF(Scorecards!$G$10:$X$10,BettingScoreboard!$A18),COUNTIF(Scorecards!$G$22:$X$22,BettingScoreboard!$A18),COUNTIF(Scorecards!$G$34:$X$34,BettingScoreboard!$A18),COUNTIF(Scorecards!$G$46:$X$46,BettingScoreboard!$A18)) -> 0 | C18: =SUM(COUNTIF(Scorecards!$G$10:$X$10,BettingScoreboard!$A18)*Scorecards!$AB$10,COUNTIF(Scorecards!$G$22:$X$22, BettingScoreboard!$A18)*Scorecards!$AB$22,COUNTIF(Scorecards!$G$34:$X$34,BettingScoreboard!$A18)*Scorecards!$AB$34,COUNTIF(Scorecards!$G$46:$X$46, BettingScoreboard!$A18)*Scorecards!$AB$46) -> 0
A19: DK | B19: =SUM(COUNTIF(Scorecards!$G$10:$X$10,BettingScoreboard!$A19),COUNTIF(Scorecards!$G$22:$X$22,BettingScoreboard!$A19),COUNTIF(Scorecards!$G$34:$X$34,BettingScoreboard!$A19),COUNTIF(Scorecards!$G$46:$X$46,BettingScoreboard!$A19)) -> 0 | C19: =SUM(COUNTIF(Scorecards!$G$10:$X$10,BettingScoreboard!$A19)*Scorecards!$AB$10,COUNTIF(Scorecards!$G$22:$X$22, BettingScoreboard!$A19)*Scorecards!$AB$22,COUNTIF(Scorecards!$G$34:$X$34,BettingScoreboard!$A19)*Scorecards!$AB$34,COUNTIF(Scorecards!$G$46:$X$46, BettingScoreboard!$A19)*Scorecards!$AB$46) -> 0
A20: JB | B20: =SUM(COUNTIF(Scorecards!$G$10:$X$10,BettingScoreboard!$A20),COUNTIF(Scorecards!$G$22:$X$22,BettingScoreboard!$A20),COUNTIF(Scorecards!$G$34:$X$34,BettingScoreboard!$A20),COUNTIF(Scorecards!$G$46:$X$46,BettingScoreboard!$A20)) -> 2 | C20: =SUM(COUNTIF(Scorecards!$G$10:$X$10,BettingScoreboard!$A20)*Scorecards!$AB$10,COUNTIF(Scorecards!$G$22:$X$22, BettingScoreboard!$A20)*Scorecards!$AB$22,COUNTIF(Scorecards!$G$34:$X$34,BettingScoreboard!$A20)*Scorecards!$AB$34,COUNTIF(Scorecards!$G$46:$X$46, BettingScoreboard!$A20)*Scorecards!$AB$46) -> 6.3333333
A22: Player | B22: CTP | C22: CTP $
A23: Aaron Jensen | B23: =SUM(COUNTIF(Scorecards!$G$11:$X$11,BettingScoreboard!$A13),COUNTIF(Scorecards!$G$23:$X$23,BettingScoreboard!$A13),COUNTIF(Scorecards!$G$35:$X$35,BettingScoreboard!$A13),COUNTIF(Scorecards!$G$47:$X$47,BettingScoreboard!$A13)) -> 1 | C23: =SUM(COUNTIF(Scorecards!$G$11:$X$11,BettingScoreboard!$A13)*Scorecards!$AB$11,COUNTIF(Scorecards!$G$23:$X$23, BettingScoreboard!$A13)*Scorecards!$AB$23,COUNTIF(Scorecards!$G$35:$X$35,BettingScoreboard!$A13)*Scorecards!$AB$35,COUNTIF(Scorecards!$G$47:$X$47, BettingScoreboard!$A13)*Scorecards!$AB$47) -> 30
A24: Bob Bergeron | B24: =SUM(COUNTIF(Scorecards!$G$11:$X$11,BettingScoreboard!$A14),COUNTIF(Scorecards!$G$23:$X$23,BettingScoreboard!$A14),COUNTIF(Scorecards!$G$35:$X$35,BettingScoreboard!$A14),COUNTIF(Scorecards!$G$47:$X$47,BettingScoreboard!$A14)) -> 0 | C24: =SUM(COUNTIF(Scorecards!$G$11:$X$11,BettingScoreboard!$A14)*Scorecards!$AB$11,COUNTIF(Scorecards!$G$23:$X$23, BettingScoreboard!$A14)*Scorecards!$AB$23,COUNTIF(Scorecards!$G$35:$X$35,BettingScoreboard!$A14)*Scorecards!$AB$35,COUNTIF(Scorecards!$G$47:$X$47, BettingScoreboard!$A14)*Scorecards!$AB$47) -> 0
A25: Brian Kelley | B25: =SUM(COUNTIF(Scorecards!$G$11:$X$11,BettingScoreboard!$A15),COUNTIF(Scorecards!$G$23:$X$23,BettingScoreboard!$A15),COUNTIF(Scorecards!$G$35:$X$35,BettingScoreboard!$A15),COUNTIF(Scorecards!$G$47:$X$47,BettingScoreboard!$A15)) -> 1 | C25: =SUM(COUNTIF(Scorecards!$G$11:$X$11,BettingScoreboard!$A15)*Scorecards!$AB$11,COUNTIF(Scorecards!$G$23:$X$23, BettingScoreboard!$A15)*Scorecards!$AB$23,COUNTIF(Scorecards!$G$35:$X$35,BettingScoreboard!$A15)*Scorecards!$AB$35,COUNTIF(Scorecards!$G$47:$X$47, BettingScoreboard!$A15)*Scorecards!$AB$47) -> 30
A26: Eric Olson | B26: =SUM(COUNTIF(Scorecards!$G$11:$X$11,BettingScoreboard!$A16),COUNTIF(Scorecards!$G$23:$X$23,BettingScoreboard!$A16),COUNTIF(Scorecards!$G$35:$X$35,BettingScoreboard!$A16),COUNTIF(Scorecards!$G$47:$X$47,BettingScoreboard!$A16)) -> 1 | C26: =SUM(COUNTIF(Scorecards!$G$11:$X$11,BettingScoreboard!$A16)*Scorecards!$AB$11,COUNTIF(Scorecards!$G$23:$X$23, BettingScoreboard!$A16)*Scorecards!$AB$23,COUNTIF(Scorecards!$G$35:$X$35,BettingScoreboard!$A16)*Scorecards!$AB$35,COUNTIF(Scorecards!$G$47:$X$47, BettingScoreboard!$A16)*Scorecards!$AB$47) -> 30
A27: Scott Rhoades | B27: =SUM(COUNTIF(Scorecards!$G$11:$X$11,BettingScoreboard!$A17),COUNTIF(Scorecards!$G$23:$X$23,BettingScoreboard!$A17),COUNTIF(Scorecards!$G$35:$X$35,BettingScoreboard!$A17),COUNTIF(Scorecards!$G$47:$X$47,BettingScoreboard!$A17)) -> 1 | C27: =SUM(COUNTIF(Scorecards!$G$11:$X$11,BettingScoreboard!$A17)*Scorecards!$AB$11,COUNTIF(Scorecards!$G$23:$X$23, BettingScoreboard!$A17)*Scorecards!$AB$23,COUNTIF(Scorecards!$G$35:$X$35,BettingScoreboard!$A17)*Scorecards!$AB$35,COUNTIF(Scorecards!$G$47:$X$47, BettingScoreboard!$A17)*Scorecards!$AB$47) -> 30
A28: Steve Vigo | B28: =SUM(COUNTIF(Scorecards!$G$11:$X$11,BettingScoreboard!$A18),COUNTIF(Scorecards!$G$23:$X$23,BettingScoreboard!$A18),COUNTIF(Scorecards!$G$35:$X$35,BettingScoreboard!$A18),COUNTIF(Scorecards!$G$47:$X$47,BettingScoreboard!$A18)) -> 0 | C28: =SUM(COUNTIF(Scorecards!$G$11:$X$11,BettingScoreboard!$A18)*Scorecards!$AB$11,COUNTIF(Scorecards!$G$23:$X$23, BettingScoreboard!$A18)*Scorecards!$AB$23,COUNTIF(Scorecards!$G$35:$X$35,BettingScoreboard!$A18)*Scorecards!$AB$35,COUNTIF(Scorecards!$G$47:$X$47, BettingScoreboard!$A18)*Scorecards!$AB$47) -> 0
A29: Dave Kelley | B29: =SUM(COUNTIF(Scorecards!$G$11:$X$11,BettingScoreboard!$A19),COUNTIF(Scorecards!$G$23:$X$23,BettingScoreboard!$A19),COUNTIF(Scorecards!$G$35:$X$35,BettingScoreboard!$A19),COUNTIF(Scorecards!$G$47:$X$47,BettingScoreboard!$A19)) -> 0 | C29: =SUM(COUNTIF(Scorecards!$G$11:$X$11,BettingScoreboard!$A19)*Scorecards!$AB$11,COUNTIF(Scorecards!$G$23:$X$23, BettingScoreboard!$A19)*Scorecards!$AB$23,COUNTIF(Scorecards!$G$35:$X$35,BettingScoreboard!$A19)*Scorecards!$AB$35,COUNTIF(Scorecards!$G$47:$X$47, BettingScoreboard!$A19)*Scorecards!$AB$47) -> 0
A30: Jeff Blanton | B30: =SUM(COUNTIF(Scorecards!$G$11:$X$11,BettingScoreboard!$A20),COUNTIF(Scorecards!$G$23:$X$23,BettingScoreboard!$A20),COUNTIF(Scorecards!$G$35:$X$35,BettingScoreboard!$A20),COUNTIF(Scorecards!$G$47:$X$47,BettingScoreboard!$A20)) -> 0 | C30: =SUM(COUNTIF(Scorecards!$G$11:$X$11,BettingScoreboard!$A20)*Scorecards!$AB$11,COUNTIF(Scorecards!$G$23:$X$23, BettingScoreboard!$A20)*Scorecards!$AB$23,COUNTIF(Scorecards!$G$35:$X$35,BettingScoreboard!$A20)*Scorecards!$AB$35,COUNTIF(Scorecards!$G$47:$X$47, BettingScoreboard!$A20)*Scorecards!$AB$47) -> 0

Sheet BettingPayouts
A1: Name | B1: Skins Buyin | C1: Skins | D1: CTP Buyin | E1: CTP | F1: Per Round Low Buyin | G1: Per Round Low | H1: Total
A2: Aaron Jensen | B2: =-1*SUM(IF(Scorecards!C4="Y",Scorecards!$C$2, 0),IF(Scorecards!C16="Y",Scorecards!$C$14,0),IF(Scorecards!C28="Y",Scorecards!$C$26,0),IF(Scorecards!C40="Y",Scorecards!$C$38,0)) -> -20 | C2: =BettingScoreboard!C13 -> 40.166667 | D2: =-1*SUM(IF(Scorecards!D4="Y",Scorecards!$D$2, 0),IF(Scorecards!D16="Y",Scorecards!$D$14,0),IF(Scorecards!D28="Y",Scorecards!$D$26,0),IF(Scorecards!D40="Y",Scorecards!$D$38,0)) -> -25 | E2: =BettingScoreboard!C23 -> 30 | F2: =-1*SUM(IF(Scorecards!E4="Y",Scorecards!$E$2, 0),IF(Scorecards!E16="Y",Scorecards!$E$14,0),IF(Scorecards!E28="Y",Scorecards!$E$26,0),IF(Scorecards!E40="Y",Scorecards!$E$38,0)) -> -20 | G2: =SUM(IF(BettingScoreboard!$B2=MIN(BettingScoreboard!$B$2:$B$9),Scorecards!$E$10/BettingScoreboard!$B$10),IF(BettingScoreboard!$C2=MIN(BettingScoreboard!$C$2:$C$9),Scorecards!$E$22/BettingScoreboard!$C$10), IF(BettingScoreboard!$D2=MIN(BettingScoreboard!$D$2:$D$9),Scorecards!$E$34/BettingScoreboard!$D$10),IF(BettingScoreboard!$E2=MIN(BettingScoreboard!$E$2:$E$9),Scorecards!$E$46/BettingScoreboard!$E$10)) -> #REF! | H2: =SUM(B2:G2) -> #REF!
A3: Bob Bergeron | B3: =-1*SUM(IF(Scorecards!C5="Y",Scorecards!$C$2, 0),IF(Scorecards!C17="Y",Scorecards!$C$14,0),IF(Scorecards!C29="Y",Scorecards!$C$26,0),IF(Scorecards!C41="Y",Scorecards!$C$38,0)) -> -20 | C3: =BettingScoreboard!C14 -> 11.75 | D3: =-1*SUM(IF(Scorecards!D5="Y",Scorecards!$D$2, 0),IF(Scorecards!D17="Y",Scorecards!$D$14,0),IF(Scorecards!D29="Y",Scorecards!$D$26,0),IF(Scorecards!D41="Y",Scorecards!$D$38,0)) -> -25 | E3: =BettingScoreboard!C24 -> 0 | F3: =-1*SUM(IF(Scorecards!E5="Y",Scorecards!$E$2, 0),IF(Scorecards!E17="Y",Scorecards!$E$14,0),IF(Scorecards!E29="Y",Scorecards!$E$26,0),IF(Scorecards!E41="Y",Scorecards!$E$38,0)) -> -20 | G3: =SUM(IF(BettingScoreboard!$B3=MIN(BettingScoreboard!$B$2:$B$9),Scorecards!$E$10/BettingScoreboard!$B$10),IF(BettingScoreboard!$C3=MIN(BettingScoreboard!$C$2:$C$9),Scorecards!$E$22/BettingScoreboard!$C$10), IF(BettingScoreboard!$D3=MIN(BettingScoreboard!$D$2:$D$9),Scorecards!$E$34/BettingScoreboard!$D$10),IF(BettingScoreboard!$E3=MIN(BettingScoreboard!$E$2:$E$9),Scorecards!$E$46/BettingScoreboard!$E$10)) -> #REF! | H3: =SUM(B3:G3) -> #REF!
A4: Brian Kelley | B4: =-1*SUM(IF(Scorecards!C6="Y",Scorecards!$C$2, 0),IF(Scorecards!C18="Y",Scorecards!$C$14,0),IF(Scorecards!C30="Y",Scorecards!$C$26,0),IF(Scorecards!C42="Y",Scorecards!$C$38,0)) -> -20 | C4: =BettingScoreboard!C15 -> 13.083333 | D4: =-1*SUM(IF(Scorecards!D6="Y",Scorecards!$D$2, 0),IF(Scorecards!D18="Y",Scorecards!$D$14,0),IF(Scorecards!D30="Y",Scorecards!$D$26,0),IF(Scorecards!D42="Y",Scorecards!$D$38,0)) -> -25 | E4: =BettingScoreboard!C25 -> 30 | F4: =-1*SUM(IF(Scorecards!E6="Y",Scorecards!$E$2, 0),IF(Scorecards!E18="Y",Scorecards!$E$14,0),IF(Scorecards!E30="Y",Scorecards!$E$26,0),IF(Scorecards!E42="Y",Scorecards!$E$38,0)) -> -20 | G4: =SUM(IF(BettingScoreboard!$B4=MIN(BettingScoreboard!$B$2:$B$9),Scorecards!$E$10/BettingScoreboard!$B$10),IF(BettingScoreboard!$C4=MIN(BettingScoreboard!$C$2:$C$9),Scorecards!$E$22/BettingScoreboard!$C$10), IF(BettingScoreboard!$D4=MIN(BettingScoreboard!$D$2:$D$9),Scorecards!$E$34/BettingScoreboard!$D$10),IF(BettingScoreboard!$E4=MIN(BettingScoreboard!$E$2:$E$9),Scorecards!$E$46/BettingScoreboard!$E$10)) -> #REF! | H4: =SUM(B4:G4) -> #REF!
A5: Eric Olson | B5: =-1*SUM(IF(Scorecards!C7="Y",Scorecards!$C$2, 0),IF(Scorecards!C19="Y",Scorecards!$C$14,0),IF(Scorecards!C31="Y",Scorecards!$C$26,0),IF(Scorecards!C43="Y",Scorecards!$C$38,0)) -> -20 | C5: =BettingScoreboard!C16 -> 0 | D5: =-1*SUM(IF(Scorecards!D7="Y",Scorecards!$D$2, 0),IF(Scorecards!D19="Y",Scorecards!$D$14,0),IF(Scorecards!D31="Y",Scorecards!$D$26,0),IF(Scorecards!D43="Y",Scorecards!$D$38,0)) -> -25 | E5: =BettingScoreboard!C26 -> 30 | F5: =-1*SUM(IF(Scorecards!E7="Y",Scorecards!$E$2, 0),IF(Scorecards!E19="Y",Scorecards!$E$14,0),IF(Scorecards!E31="Y",Scorecards!$E$26,0),IF(Scorecards!E43="Y",Scorecards!$E$38,0)) -> -20 | G5: =SUM(IF(BettingScoreboard!$B5=MIN(BettingScoreboard!$B$2:$B$9),Scorecards!$E$10/BettingScoreboard!$B$10),IF(BettingScoreboard!$C5=MIN(BettingScoreboard!$C$2:$C$9),Scorecards!$E$22/BettingScoreboard!$C$10), IF(BettingScoreboard!$D5=MIN(BettingScoreboard!$D$2:$D$9),Scorecards!$E$34/BettingScoreboard!$D$10),IF(BettingScoreboard!$E5=MIN(BettingScoreboard!$E$2:$E$9),Scorecards!$E$46/BettingScoreboard!$E$10)) -> #REF! | H5: =SUM(B5:G5) -> #REF!
A6: Scott Rhoades | B6: =-1*SUM(IF(Scorecards!C8="Y",Scorecards!$C$2, 0),IF(Scorecards!C20="Y",Scorecards!$C$14,0),IF(Scorecards!C32="Y",Scorecards!$C$26,0),IF(Scorecards!C44="Y",Scorecards!$C$38,0)) -> -20 | C6: =BettingScoreboard!C17 -> 48.666667 | D6: =-1*SUM(IF(Scorecards!D8="Y",Scorecards!$D$2, 0),IF(Scorecards!D20="Y",Scorecards!$D$14,0),IF(Scorecards!D32="Y",Scorecards!$D$26,0),IF(Scorecards!D44="Y",Scorecards!$D$38,0)) -> -25 | E6: =BettingScoreboard!C27 -> 30 | F6: =-1*SUM(IF(Scorecards!E8="Y",Scorecards!$E$2, 0),IF(Scorecards!E20="Y",Scorecards!$E$14,0),IF(Scorecards!E32="Y",Scorecards!$E$26,0),IF(Scorecards!E44="Y",Scorecards!$E$38,0)) -> -20 | G6: =SUM(IF(BettingScoreboard!$B6=MIN(BettingScoreboard!$B$2:$B$9),Scorecards!$E$10/BettingScoreboard!$B$10),IF(BettingScoreboard!$C6=MIN(BettingScoreboard!$C$2:$C$9),Scorecards!$E$22/BettingScoreboard!$C$10), IF(BettingScoreboard!$D6=MIN(BettingScoreboard!$D$2:$D$9),Scorecards!$E$34/BettingScoreboard!$D$10),IF(BettingScoreboard!$E6=MIN(BettingScoreboard!$E$2:$E$9),Scorecards!$E$46/BettingScoreboard!$E$10)) -> #REF! | H6: =SUM(B6:G6) -> #REF!
A7: Steve Vigo | B7: =-1*SUM(IF(#REF!="Y",Scorecards!$C$2, 0),IF(#REF!="Y",Scorecards!$C$14,0),IF(#REF!="Y",Scorecards!$C$26,0),IF(#REF!="Y",Scorecards!$C$38,0)) -> #REF! | C7: =BettingScoreboard!C18 -> 0 | D7: =-1*SUM(IF(#REF!="Y",Scorecards!$D$2, 0),IF(#REF!="Y",Scorecards!$D$14,0),IF(#REF!="Y",Scorecards!$D$26,0),IF(#REF!="Y",Scorecards!$D$38,0)) -> #REF! | E7: =BettingScoreboard!C28 -> 0 | F7: =-1*SUM(IF(#REF!="Y",Scorecards!$E$2, 0),IF(#REF!="Y",Scorecards!$E$14,0),IF(#REF!="Y",Scorecards!$E$26,0),IF(#REF!="Y",Scorecards!$E$38,0)) -> #REF! | G7: =SUM(IF(BettingScoreboard!$B7=MIN(BettingScoreboard!$B$2:$B$9),Scorecards!$E$10/BettingScoreboard!$B$10),IF(BettingScoreboard!$C7=MIN(BettingScoreboard!$C$2:$C$9),Scorecards!$E$22/BettingScoreboard!$C$10), IF(BettingScoreboard!$D7=MIN(BettingScoreboard!$D$2:$D$9),Scorecards!$E$34/BettingScoreboard!$D$10),IF(BettingScoreboard!$E7=MIN(BettingScoreboard!$E$2:$E$9),Scorecards!$E$46/BettingScoreboard!$E$10)) -> #REF! | H7: =SUM(B7:G7) -> #REF!
A8: Dave Kelley | B8: =-1*SUM(IF(#REF!="Y",Scorecards!$C$2, 0),IF(#REF!="Y",Scorecards!$C$14,0),IF(#REF!="Y",Scorecards!$C$26,0),IF(#REF!="Y",Scorecards!$C$38,0)) -> #REF! | C8: =BettingScoreboard!C19 -> 0 | D8: =-1*SUM(IF(#REF!="Y",Scorecards!$D$2, 0),IF(#REF!="Y",Scorecards!$D$14,0),IF(#REF!="Y",Scorecards!$D$26,0),IF(#REF!="Y",Scorecards!$D$38,0)) -> #REF! | E8: =BettingScoreboard!C29 -> 0 | F8: =-1*SUM(IF(#REF!="Y",Scorecards!$E$2, 0),IF(#REF!="Y",Scorecards!$E$14,0),IF(#REF!="Y",Scorecards!$E$26,0),IF(#REF!="Y",Scorecards!$E$38,0)) -> #REF! | G8: =SUM(IF(BettingScoreboard!$B8=MIN(BettingScoreboard!$B$2:$B$9),Scorecards!$E$10/BettingScoreboard!$B$10),IF(BettingScoreboard!$C8=MIN(BettingScoreboard!$C$2:$C$9),Scorecards!$E$22/BettingScoreboard!$C$10), IF(BettingScoreboard!$D8=MIN(BettingScoreboard!$D$2:$D$9),Scorecards!$E$34/BettingScoreboard!$D$10),IF(BettingScoreboard!$E8=MIN(BettingScoreboard!$E$2:$E$9),Scorecards!$E$46/BettingScoreboard!$E$10)) -> #REF! | H8: =SUM(B8:G8) -> #REF!
A9: Jeff Blanton | B9: =-1*SUM(IF(Scorecards!C9="Y",Scorecards!$C$2, 0),IF(Scorecards!C21="Y",Scorecards!$C$14,0),IF(Scorecards!C33="Y",Scorecards!$C$26,0),IF(Scorecards!C45="Y",Scorecards!$C$38,0)) -> -20 | C9: =BettingScoreboard!C20 -> 6.3333333 | D9: =-1*SUM(IF(Scorecards!D9="Y",Scorecards!$D$2, 0),IF(Scorecards!D21="Y",Scorecards!$D$14,0),IF(Scorecards!D33="Y",Scorecards!$D$26,0),IF(Scorecards!D45="Y",Scorecards!$D$38,0)) -> -25 | E9: =BettingScoreboard!C30 -> 0 | F9: =-1*SUM(IF(Scorecards!E9="Y",Scorecards!$E$2, 0),IF(Scorecards!E21="Y",Scorecards!$E$14,0),IF(Scorecards!E33="Y",Scorecards!$E$26,0),IF(Scorecards!E45="Y",Scorecards!$E$38,0)) -> -20 | G9: =SUM(IF(BettingScoreboard!$B9=MIN(BettingScoreboard!$B$2:$B$9),Scorecards!$E$10/BettingScoreboard!$B$10),IF(BettingScoreboard!$C9=MIN(BettingScoreboard!$C$2:$C$9),Scorecards!$E$22/BettingScoreboard!$C$10), IF(BettingScoreboard!$D9=MIN(BettingScoreboard!$D$2:$D$9),Scorecards!$E$34/BettingScoreboard!$D$10),IF(BettingScoreboard!$E9=MIN(BettingScoreboard!$E$2:$E$9),Scorecards!$E$46/BettingScoreboard!$E$10)) -> #REF! | H9: =SUM(B9:G9) -> #REF!
