Workbook
Name Players: Shares!$A$3:$A$8

Sheet LEADERBOARD
A1: 2016 WANNABE CUP
A2: POS | B2: SCORE | C2: TO PAR | D2: PLAYER | E2: =Scorecards!F1 -> THE GRANDE | F2: =Scorecards!F15 -> CASCADES | G2: =Scorecards!F29 -> CALDERONE | H2: =Scorecards!F43 -> CALDERONE
A3: =VLOOKUP(D3,Scores!$O$3:$P$8,2,FALSE) -> 1 | B3: =VLOOKUP(D3,Scores!$B$3:$L$8,11,FALSE) -> 284 | C3: =SUM((IF(E3="",0,Scorecards!$AA$3-E3)),(IF(F3="",0,Scorecards!$AA$17-F3)),(IF(G3="",0,Scorecards!$AA$31-G3)),(IF(H3="",0,Scorecards!$AA$45-H3)))*-1 -> -4 | D3: =VLOOKUP(1,Scores!$N$3:$O$8,2,FALSE) -> Brian Kelley | E3: =VLOOKUP(D3,Scores!$B$3:$J$8,3,FALSE) -> 69 | F3: =VLOOKUP(D3,Scores!$B$3:$J$8,5,FALSE) -> 71 | G3: =VLOOKUP(D3,Scores!$B$3:$J$8,7,FALSE) -> 74 | H3: =VLOOKUP(D3,Scores!$B$3:$J$8,9,FALSE) -> 70
A4: =VLOOKUP(D4,Scores!$O$3:$P$8,2,FALSE) -> 2 | B4: =VLOOKUP(D4,Scores!$B$3:$L$8,11,FALSE) -> 290 | C4: =SUM((IF(E4="",0,Scorecards!$AA$3-E4)),(IF(F4="",0,Scorecards!$AA$17-F4)),(IF(G4="",0,Scorecards!$AA$31-G4)),(IF(H4="",0,Scorecards!$AA$45-H4)))*-1 -> 2 | D4: =VLOOKUP(2,Scores!$N$3:$O$8,2,FALSE) -> Bob Bergeron | E4: =VLOOKUP(D4,Scores!$B$3:$J$8,3,FALSE) -> 70 | F4: =VLOOKUP(D4,Scores!$B$3:$J$8,5,FALSE) -> 78 | G4: =VLOOKUP(D4,Scores!$B$3:$J$8,7,FALSE) -> 68 | H4: =VLOOKUP(D4,Scores!$B$3:$J$8,9,FALSE) -> 74
A5: =VLOOKUP(D5,Scores!$O$3:$P$8,2,FALSE) -> 3 | B5: =VLOOKUP(D5,Scores!$B$3:$L$8,11,FALSE) -> 291 | C5: =SUM((IF(E5="",0,Scorecards!$AA$3-E5)),(IF(F5="",0,Scorecards!$AA$17-F5)),(IF(G5="",0,Scorecards!$AA$31-G5)),(IF(H5="",0,Scorecards!$AA$45-H5)))*-1 -> 3 | D5: =VLOOKUP(3,Scores!$N$3:$O$8,2,FALSE) -> Scott Rhoades | E5: =VLOOKUP(D5,Scores!$B$3:$J$8,3,FALSE) -> 65 | F5: =VLOOKUP(D5,Scores!$B$3:$J$8,5,FALSE) -> 78 | G5: =VLOOKUP(D5,Scores!$B$3:$J$8,7,FALSE) -> 76 | H5: =VLOOKUP(D5,Scores!$B$3:$J$8,9,FALSE) -> 72
A6: =VLOOKUP(D6,Scores!$O$3:$P$8,2,FALSE) -> 4 | B6: =VLOOKUP(D6,Scores!$B$3:$L$8,11,FALSE) -> 311 | C6: =SUM((IF(E6="",0,Scorecards!$AA$3-E6)),(IF(F6="",0,Scorecards!$AA$17-F6)),(IF(G6="",0,Scorecards!$AA$31-G6)),(IF(H6="",0,Scorecards!$AA$45-H6)))*-1 -> 23 | D6: =VLOOKUP(4,Scores!$N$3:$O$8,2,FALSE) -> Eric Olson | E6: =VLOOKUP(D6,Scores!$B$3:$J$8,3,FALSE) -> 78 | F6: =VLOOKUP(D6,Scores!$B$3:$J$8,5,FALSE) -> 69 | G6: =VLOOKUP(D6,Scores!$B$3:$J$8,7,FALSE) -> 88 | H6: =VLOOKUP(D6,Scores!$B$3:$J$8,9,FALSE) -> 76
A7: =VLOOKUP(D7,Scores!$O$3:$P$8,2,FALSE) -> 5 | B7: WD | C7: WD | D7: =VLOOKUP(5,Scores!$N$3:$O$8,2,FALSE) -> Aaron Jensen | E7: =VLOOKUP(D7,Scores!$B$3:$J$8,3,FALSE) -> 75 | F7: WD | G7: WD | H7: WD
A8: =VLOOKUP(D8,Scores!$O$3:$P$8,2,FALSE) -> 5 | B8: WD | C8: WD | D8: =VLOOKUP(6,Scores!$N$3:$O$8,2,FALSE) -> Matt Vigo | E8: WD | F8: WD | G8: WD | H8: WD

Sheet Scorecards
F1: THE GRANDE | AA1: 70.8 | AB1: 120
C2: 5 | D2: 0 | E2: 0 | F2: Hole | G2: 1 | H2: 2 | I2: 3 | J2: 4 | K2: 5 | L2: 6 | M2: 7 | N2: 8 | O2: 9 | P2: 10 | Q2: 11 | R2: 12 | S2: 13 | T2: 14 | U2: 15 | V2: 16 | W2: 17 | X2: 18 | Y2: OUT | Z2: IN | AA2: TOTAL | AB2: NET
A3: Player | B3: Handi | C3: SK | D3: CTP | E3: LO | F3: Par | G3: 4 | H3: 3 | I3: 4 | J3: 5 | K3: 3 | L3: 4 | M3: 4 | N3: 5 | O3: 4 | P3: 4 | Q3: 5 | R3: 3 | S3: 4 | T3: 5 | U3: 4 | V3: 4 | W3: 3 | X3: 4 | Y3: =SUM(G3:O3) -> 36 | Z3: =SUM(P3:X3) -> 36 | AA3: =Y3+Z3 -> 72
A4: AJ | B4: 8 | C4: Y | D4: N | E4: Y | G4: 5 | H4: 4 | I4: 5 | J4: 6 | K4: 3 | L4: 5 | M4: 4 | N4: 5 | O4: 5 | P4: 4 | Q4: 5 | R4: 3 | S4: 3 | T4: 6 | U4: 6 | V4: 5 | W4: 3 | X4: 6 | Y4: =SUM(G4:O4) -> 42 | Z4: =SUM(P4:X4) -> 41 | AA4: =IF(Z4>0,Y4+Z4,"") -> 83 | AB4: =IF(Z4=0,"",AA4-B4) -> 75
A5: BB | B5: 18 | C5: Y | D5: N | E5: Y | G5: 4 | H5: 3 | I5: 5 | J5: 8 | K5: 3 | L5: 7 | M5: 6 | N5: 5 | O5: 5 | P5: 5 | Q5: 7 | R5: 3 | S5: 3 | T5: 7 | U5: 4 | V5: 5 | W5: 4 | X5: 4 | Y5: =SUM(G5:O5) -> 46 | Z5: =SUM(P5:X5) -> 42 | AA5: =IF(Z5>0,Y5+Z5,"") -> 88 | AB5: =IF(Z5=0,"",AA5-B5) -> 70
A6: BK | B6: 15 | C6: Y | D6: N | E6: Y | G6: 8 | H6: 3 | I6: 5 | J6: 4 | K6: 3 | L6: 4 | M6: 4 | N6: 6 | O6: 5 | P6: 4 | Q6: 6 | R6: 4 | S6: 5 | T6: 8 | U6: 4 | V6: 4 | W6: 3 | X6: 4 | Y6: =SUM(G6:O6) -> 42 | Z6: =SUM(P6:X6) -> 42 | AA6: =IF(Z6>0,Y6+Z6,"") -> 84 | AB6: =IF(Z6=0,"",AA6-B6) -> 69
A7: EO | B7: 18 | C7: Y | D7: N | E7: Y | G7: 5 | H7: 4 | I7: 5 | J7: 7 | K7: 2 | L7: 5 | M7: 6 | N7: 8 | O7: 6 | P7: 7 | Q7: 8 | R7: 3 | S7: 5 | T7: 5 | U7: 3 | V7: 7 | W7: 6 | X7: 4 | Y7: =SUM(G7:O7) -> 48 | Z7: =SUM(P7:X7) -> 48 | AA7: =IF(Z7>0,Y7+Z7,"") -> 96 | AB7: =IF(Z7=0,"",AA7-B7) -> 78
A8: SR | B8: 8 | C8: Y | D8: N | E8: Y | G8: 5 | H8: 3 | I8: 5 | J8: 5 | K8: 3 | L8: 4 | M8: 3 | N8: 3 | O8: 3 | P8: 4 | Q8: 6 | R8: 3 | S8: 4 | T8: 4 | U8: 3 | V8: 6 | W8: 3 | X8: 6 | Y8: =SUM(G8:O8) -> 34 | Z8: =SUM(P8:X8) -> 39 | AA8: =IF(Z8>0,Y8+Z8,"") -> 73 | AB8: =IF(Z8=0,"",AA8-B8) -> 65
A9: MV | B9: - | C9: N | D9: N | E9: N | Y9: =SUM(G9:O9) -> 0 | Z9: =SUM(P9:X9) -> 0 | AA9: =IF(Z9>0,Y9+Z9,"") | AB9: =IF(Z9=0,"",AA9-B9)
AA10: =IF(Z10>0,Y10+Z10,"") | AB10: =IF(Z10=0,"",AA10-B10)
AA11: =IF(Z11>0,Y11+Z11,"") | AB11: =IF(Z11=0,"",AA11-B11)
C12: =COUNTIF(Scorecards!$C$4:$C$11, "Y")*C2 -> 25 | D12: =COUNTIF(Scorecards!$D$4:$D$11, "Y")*D2 -> 0 | E12: =COUNTIF(Scorecards!$E$4:$E$11, "Y")*E2 -> 0 | F12: SKIN | G12: {=IF(OR(SUM(IF(IF(Scorecards!$C$4:$C$11="Y", G4:G11, 10)=MIN(IF(Scorecards!$C$4:$C$11="Y", G4:G11, 10)), 1, 0)) > 1, MIN(IF(Scorecards!$C$4:$C$11="Y", G4:G11, 10)) > G3), "", INDEX(Scorecards!$A$4:$A$11,MATCH(MIN(IF(Scorecards!$C$4:$C$11="Y",G4:G11,10)),IF(Scorecards!$C$4:$C$11="Y",G4:G11,10),0)))} -> BB | H12: {=IF(OR(SUM(IF(IF(Scorecards!$C$4:$C$11="Y", H4:H11, 10)=MIN(IF(Scorecards!$C$4:$C$11="Y", H4:H11, 10)), 1, 0)) > 1, MIN(IF(Scorecards!$C$4:$C$11="Y", H4:H11, 10)) > H3), "", INDEX(Scorecards!$A$4:$A$11,MATCH(MIN(IF(Scorecards!$C$4:$C$11="Y",H4:H11,10)),IF(Scorecards!$C$4:$C$11="Y",H4:H11,10),0)))} | I12: {=IF(OR(SUM(IF(IF(Scorecards!$C$4:$C$11="Y", I4:I11, 10)=MIN(IF(Scorecards!$C$4:$C$11="Y", I4:I11, 10)), 1, 0)) > 1, MIN(IF(Scorecards!$C$4:$C$11="Y", I4:I11, 10)) > I3), "", INDEX(Scorecards!$A$4:$A$11,MATCH(MIN(IF(Scorecards!$C$4:$C$11="Y",I4:I11,10)),IF(Scorecards!$C$4:$C$11="Y",I4:I11,10),0)))} | J12: {=IF(OR(SUM(IF(IF(Scorecards!$C$4:$C$11="Y", J4:J11, 10)=MIN(IF(Scorecards!$C$4:$C$11="Y", J4:J11, 10)), 1, 0)) > 1, MIN(IF(Scorecards!$C$4:$C$11="Y", J4:J11, 10)) > J3), "", INDEX(Scorecards!$A$4:$A$11,MATCH(MIN(IF(Scorecards!$C$4:$C$11="Y",J4:J11,10)),IF(Scorecards!$C$4:$C$11="Y",J4:J11,10),0)))} -> BK | K12: {=IF(OR(SUM(IF(IF(Scorecards!$C$4:$C$11="Y", K4:K11, 10)=MIN(IF(Scorecards!$C$4:$C$11="Y", K4:K11, 10)), 1, 0)) > 1, MIN(IF(Scorecards!$C$4:$C$11="Y", K4:K11, 10)) > K3), "", INDEX(Scorecards!$A$4:$A$11,MATCH(MIN(IF(Scorecards!$C$4:$C$11="Y",K4:K11,10)),IF(Scorecards!$C$4:$C$11="Y",K4:K11,10),0)))} -> EO | L12: {=IF(OR(SUM(IF(IF(Scorecards!$C$4:$C$11="Y", L4:L11, 10)=MIN(IF(Scorecards!$C$4:$C$11="Y", L4:L11, 10)), 1, 0)) > 1, MIN(IF(Scorecards!$C$4:$C$11="Y", L4:L11, 10)) > L3), "", INDEX(Scorecards!$A$4:$A$11,MATCH(MIN(IF(Scorecards!$C$4:$C$11="Y",L4:L11,10)),IF(Scorecards!$C$4:$C$11="Y",L4:L11,10),0)))} | M12: {=IF(OR(SUM(IF(IF(Scorecards!$C$4:$C$11="Y", M4:M11, 10)=MIN(IF(Scorecards!$C$4:$C$11="Y", M4:M11, 10)), 1, 0)) > 1, MIN(IF(Scorecards!$C$4:$C$11="Y", M4:M11, 10)) > M3), "", INDEX(Scorecards!$A$4:$A$11,MATCH(MIN(IF(Scorecards!$C$4:$C$11="Y",M4:M11,10)),IF(Scorecards!$C$4:$C$11="Y",M4:M11,10),0)))} -> SR | N12: {=IF(OR(SUM(IF(IF(Scorecards!$C$4:$C$11="Y", N4:N11, 10)=MIN(IF(Scorecards!$C$4:$C$11="Y", N4:N11, 10)), 1, 0)) > 1, MIN(IF(Scorecards!$C$4:$C$11="Y", N4:N11, 10)) > N3), "", INDEX(Scorecards!$A$4:$A$11,MATCH(MIN(IF(Scorecards!$C$4:$C$11="Y",N4:N11,10)),IF(Scorecards!$C$4:$C$11="Y",N4:N11,10),0)))} -> SR | ... X12: {=IF(OR(SUM(IF(IF(Scorecards!$C$4:$C$11="Y", X4:X11, 10)=MIN(IF(Scorecards!$C$4:$C$11="Y", X4:X11, 10)), 1, 0)) > 1, MIN(IF(Scorecards!$C$4:$C$11="Y", X4:X11, 10)) > X3), "", INDEX(Scorecards!$A$4:$A$11,MATCH(MIN(IF(Scorecards!$C$4:$C$11="Y",X4:X11,10)),IF(Scorecards!$C$4:$C$11="Y",X4:X11,10),0)))} | AA12: =18-COUNTBLANK(G12:X12) -> 9 | AB12: =IF(AA12 = 0, 0, C12/AA12) -> 2.7777778
F13: CTP | AA13: =COUNTA(H13,K13,T13,W13) -> 0 | AB13: =IF(AA13 = 0, 0, D12/AA13) -> 0
F15: CASCADES | AA15: 71.2 | AB15: 132
C16: 5 | D16: 0 | E16: 0 | F16: Hole | G16: 1 | H16: 2 | I16: 3 | J16: 4 | K16: 5 | L16: 6 | M16: 7 | N16: 8 | O16: 9 | P16: 10 | Q16: 11 | R16: 12 | S16: 13 | T16: 14 | U16: 15 | V16: 16 | W16: 17 | X16: 18 | Y16: OUT | Z16: IN | AA16: TOTAL | AB16: NET
A17: Player | B17: Handi | C17: SK | D17: CTP | E17: LO | F17: Par | G17: 5 | H17: 5 | I17: 4 | J17: 3 | K17: 4 | L17: 5 | M17: 4 | N17: 4 | O17: 3 | P17: 5 | Q17: 3 | R17: 4 | S17: 4 | T17: 4 | U17: 4 | V17: 3 | W17: 4 | X17: 4 | Y17: =SUM(G17:O17) -> 37 | Z17: =SUM(P17:X17) -> 35 | AA17: =Y17+Z17 -> 72
A18: AJ | B18: 8 | C18: Y | D18: N | E18: Y | Y18: =SUM(G18:O18) -> 0 | Z18: =SUM(P18:X18) -> 0 | AA18: =IF(Z18>0,Y18+Z18,"") | AB18: =IF(Z18=0,"",AA18-B18)
A19: BB | B19: 18 | C19: Y | D19: N | E19: Y | G19: 7 | H19: 8 | I19: 5 | J19: 5 | K19: 5 | L19: 6 | M19: 4 | N19: 5 | O19: 4 | P19: 8 | Q19: 4 | R19: 5 | S19: 4 | T19: 5 | U19: 5 | V19: 4 | W19: 7 | X19: 5 | Y19: =SUM(G19:O19) -> 49 | Z19: =SUM(P19:X19) -> 47 | AA19: =IF(Z19>0,Y19+Z19,"") -> 96 | AB19: =IF(Z19=0,"",AA19-B19) -> 78
A20: BK | B20: 15 | C20: Y | D20: N | E20: Y | G20: 6 | H20: 6 | I20: 4 | J20: 4 | K20: 3 | L20: 6 | M20: 4 | N20: 4 | O20: 5 | P20: 6 | Q20: 6 | R20: 6 | S20: 4 | T20: 4 | U20: 5 | V20: 2 | W20: 6 | X20: 5 | Y20: =SUM(G20:O20) -> 42 | Z20: =SUM(P20:X20) -> 44 | AA20: =IF(Z20>0,Y20+Z20,"") -> 86 | AB20: =IF(Z20=0,"",AA20-B20) -> 71
A21: EO | B21: 18 | C21: Y | D21: N | E21: Y | G21: 7 | H21: 6 | I21: 4 | J21: 4 | K21: 4 | L21: 8 | M21: 5 | N21: 5 | O21: 3 | P21: 5 | Q21: 3 | R21: 5 | S21: 3 | T21: 4 | U21: 4 | V21: 3 | W21: 8 | X21: 6 | Y21: =SUM(G21:O21) -> 46 | Z21: =SUM(P21:X21) -> 41 | AA21: =IF(Z21>0,Y21+Z21,"") -> 87 | AB21: =IF(Z21=0,"",AA21-B21) -> 69
A22: SR | B22: 8 | C22: Y | D22: N | E22: Y | G22: 6 | H22: 6 | I22: 4 | J22: 3 | K22: 4 | L22: 6 | M22: 4 | N22: 4 | O22: 4 | P22: 6 | Q22: 5 | R22: 4 | S22: 5 | T22: 5 | U22: 5 | V22: 4 | W22: 5 | X22: 6 | Y22: =SUM(G22:O22) -> 41 | Z22: =SUM(P22:X22) -> 45 | AA22: =IF(Z22>0,Y22+Z22,"") -> 86 | AB22: =IF(Z22=0,"",AA22-B22) -> 78
A23: MV | B23: - | C23: N | D23: N | E23: N | Y23: =SUM(G23:O23) -> 0 | Z23: =SUM(P23:X23) -> 0 | AA23: =IF(Z23>0,Y23+Z23,"") | AB23: =IF(Z23=0,"",AA23-B23)
AA24: =IF(Z24>0,Y24+Z24,"") | AB24: =IF(Z24=0,"",AA24-B24)
AA25: =IF(Z25>0,Y25+Z25,"") | AB25: =IF(Z25=0,"",AA25-B25)
C26: =COUNTIF(Scorecards!$C$4:$C$11, "Y")*C16 -> 25 | D26: =COUNTIF(Scorecards!$D$4:$D$11, "Y")*D16 -> 0 | E26: =COUNTIF(Scorecards!$E$18:$E$25, "Y")*E16 -> 0 | F26: SKIN | G26: {=IF(OR(SUM(IF(IF(Scorecards!$C$18:$C$25="Y", G18:G25, 10)=MIN(IF(Scorecards!$C$18:$C$25="Y", G18:G25, 10)), 1, 0)) > 1, MIN(IF(Scorecards!$C$18:$C$25="Y", G18:G25, 10)) > G17), "", INDEX(Scorecards!$A$18:$A$25,MATCH(MIN(IF(Scorecards!$C$18:$C$25="Y",G18:G25,10)),IF(Scorecards!$C$18:$C$25="Y",G18:G25,10),0)))} | H26: {=IF(OR(SUM(IF(IF(Scorecards!$C$18:$C$25="Y", H18:H25, 10)=MIN(IF(Scorecards!$C$18:$C$25="Y", H18:H25, 10)), 1, 0)) > 1, MIN(IF(Scorecards!$C$18:$C$25="Y", H18:H25, 10)) > H17), "", INDEX(Scorecards!$A$18:$A$25,MATCH(MIN(IF(Scorecards!$C$18:$C$25="Y",H18:H25,10)),IF(Scorecards!$C$18:$C$25="Y",H18:H25,10),0)))} | I26: {=IF(OR(SUM(IF(IF(Scorecards!$C$18:$C$25="Y", I18:I25, 10)=MIN(IF(Scorecards!$C$18:$C$25="Y", I18:I25, 10)), 1, 0)) > 1, MIN(IF(Scorecards!$C$18:$C$25="Y", I18:I25, 10)) > I17), "", INDEX(Scorecards!$A$18:$A$25,MATCH(MIN(IF(Scorecards!$C$18:$C$25="Y",I18:I25,10)),IF(Scorecards!$C$18:$C$25="Y",I18:I25,10),0)))} | J26: {=IF(OR(SUM(IF(IF(Scorecards!$C$18:$C$25="Y", J18:J25, 10)=MIN(IF(Scorecards!$C$18:$C$25="Y", J18:J25, 10)), 1, 0)) > 1, MIN(IF(Scorecards!$C$18:$C$25="Y", J18:J25, 10)) > J17), "", INDEX(Scorecards!$A$18:$A$25,MATCH(MIN(IF(Scorecards!$C$18:$C$25="Y",J18:J25,10)),IF(Scorecards!$C$18:$C$25="Y",J18:J25,10),0)))} -> SR | K26: {=IF(OR(SUM(IF(IF(Scorecards!$C$18:$C$25="Y", K18:K25, 10)=MIN(IF(Scorecards!$C$18:$C$25="Y", K18:K25, 10)), 1, 0)) > 1, MIN(IF(Scorecards!$C$18:$C$25="Y", K18:K25, 10)) > K17), "", INDEX(Scorecards!$A$18:$A$25,MATCH(MIN(IF(Scorecards!$C$18:$C$25="Y",K18:K25,10)),IF(Scorecards!$C$18:$C$25="Y",K18:K25,10),0)))} -> BK | L26: {=IF(OR(SUM(IF(IF(Scorecards!$C$18:$C$25="Y", L18:L25, 10)=MIN(IF(Scorecards!$C$18:$C$25="Y", L18:L25, 10)), 1, 0)) > 1, MIN(IF(Scorecards!$C$18:$C$25="Y", L18:L25, 10)) > L17), "", INDEX(Scorecards!$A$18:$A$25,MATCH(MIN(IF(Scorecards!$C$18:$C$25="Y",L18:L25,10)),IF(Scorecards!$C$18:$C$25="Y",L18:L25,10),0)))} | M26: {=IF(OR(SUM(IF(IF(Scorecards!$C$18:$C$25="Y", M18:M25, 10)=MIN(IF(Scorecards!$C$18:$C$25="Y", M18:M25, 10)), 1, 0)) > 1, MIN(IF(Scorecards!$C$18:$C$25="Y", M18:M25, 10)) > M17), "", INDEX(Scorecards!$A$18:$A$25,MATCH(MIN(IF(Scorecards!$C$18:$C$25="Y",M18:M25,10)),IF(Scorecards!$C$18:$C$25="Y",M18:M25,10),0)))} | N26: {=IF(OR(SUM(IF(IF(Scorecards!$C$18:$C$25="Y", N18:N25, 10)=MIN(IF(Scorecards!$C$18:$C$25="Y", N18:N25, 10)), 1, 0)) > 1, MIN(IF(Scorecards!$C$18:$C$25="Y", N18:N25, 10)) > N17), "", INDEX(Scorecards!$A$18:$A$25,MATCH(MIN(IF(Scorecards!$C$18:$C$25="Y",N18:N25,10)),IF(Scorecards!$C$18:$C$25="Y",N18:N25,10),0)))} | ... V26: {=IF(OR(SUM(IF(IF(Scorecards!$C$18:$C$25="Y", V18:V25, 10)=MIN(IF(Scorecards!$C$18:$C$25="Y", V18:V25, 10)), 1, 0)) > 1, MIN(IF(Scorecards!$C$18:$C$25="Y", V18:V25, 10)) > V17), "", INDEX(Scorecards!$A$18:$A$25,MATCH(MIN(IF(Scorecards!$C$18:$C$25="Y",V18:V25,10)),IF(Scorecards!$C$18:$C$25="Y",V18:V25,10),0)))} -> BK | W26: SR | X26: {=IF(OR(SUM(IF(IF(Scorecards!$C$18:$C$25="Y", X18:X25, 10)=MIN(IF(Scorecards!$C$18:$C$25="Y", X18:X25, 10)), 1, 0)) > 1, MIN(IF(Scorecards!$C$18:$C$25="Y", X18:X25, 10)) > X17), "", INDEX(Scorecards!$A$18:$A$25,MATCH(MIN(IF(Scorecards!$C$18:$C$25="Y",X18:X25,10)),IF(Scorecards!$C$18:$C$25="Y",X18:X25,10),0)))} | AA26: =18-COUNTBLANK(G26:X26) -> 10 | AB26: =IF(AA26 = 0, 0, C26/AA26) -> 2.5
F27: CTP | AA27: =COUNTA(I27,N27,R27,W27) -> 0 | AB27: =IF(AA27 = 0, 0, D26/AA27) -> 0
F29: CALDERONE | AA29: 69.3 | AB29: 127
C30: 5 | D30: 0 | E30: 0 | F30: Hole | G30: 1 | H30: 2 | I30: 3 | J30: 4 | K30: 5 | L30: 6 | M30: 7 | N30: 8 | O30: 9 | P30: 10 | Q30: 11 | R30: 12 | S30: 13 | T30: 14 | U30: 15 | V30: 16 | W30: 17 | X30: 18 | Y30: OUT | Z30: IN | AA30: TOTAL | AB30: NET
A31: Player | B31: Handi | C31: SK | D31: CTP | E31: LO | F31: Par | G31: 5 | H31: 3 | I31: 4 | J31: 4 | K31: 4 | L31: 5 | M31: 4 | N31: 3 | O31: 4 | P31: 5 | Q31: 4 | R31: 4 | S31: 5 | T31: 4 | U31: 3 | V31: 4 | W31: 3 | X31: 4 | Y31: =SUM(G31:O31) -> 36 | Z31: =SUM(P31:X31) -> 36 | AA31: =Y31+Z31 -> 72
A32: AJ | B32: 8 | C32: Y | D32: N | E32: Y | Y32: =SUM(G32:O32) -> 0 | Z32: =SUM(P32:X32) -> 0 | AA32: =IF(Z32>0,Y32+Z32,"") | AB32: =IF(Z32=0,"",AA32-B32)
A33: BB | B33: 18 | C33: Y | D33: N | E33: Y | G33: 5 | H33: 5 | I33: 4 | J33: 5 | K33: 4 | L33: 4 | M33: 5 | N33: 2 | O33: 5 | P33: 5 | Q33: 6 | R33: 5 | S33: 8 | T33: 4 | U33: 4 | V33: 5 | W33: 4 | X33: 6 | Y33: =SUM(G33:O33) -> 39 | Z33: =SUM(P33:X33) -> 47 | AA33: =IF(Z33>0,Y33+Z33,"") -> 86 | AB33: =IF(Z33=0,"",AA33-B33) -> 68
A34: BK | B34: 15 | C34: Y | D34: N | E34: Y | G34: 6 | H34: 4 | I34: 5 | J34: 5 | K34: 5 | L34: 5 | M34: 4 | N34: 4 | O34: 7 | P34: 5 | Q34: 5 | R34: 5 | S34: 6 | T34: 6 | U34: 2 | V34: 5 | W34: 4 | X34: 6 | Y34: =SUM(G34:O34) -> 45 | Z34: =SUM(P34:X34) -> 44 | AA34: =IF(Z34>0,Y34+Z34,"") -> 89 | AB34: =IF(Z34=0,"",AA34-B34) -> 74
A35: EO | B35: 18 | C35: Y | D35: N | E35: Y | G35: 5 | H35: 7 | I35: 6 | J35: 6 | K35: 8 | L35: 7 | M35: 5 | N35: 3 | O35: 8 | P35: 5 | Q35: 6 | R35: 5 | S35: 8 | T35: 4 | U35: 3 | V35: 7 | W35: 7 | X35: 6 | Y35: =SUM(G35:O35) -> 55 | Z35: =SUM(P35:X35) -> 51 | AA35: =IF(Z35>0,Y35+Z35,"") -> 106 | AB35: =IF(Z35=0,"",AA35-B35) -> 88
A36: SR | B36: 8 | C36: Y | D36: N | E36: Y | G36: 8 | H36: 3 | I36: 4 | J36: 7 | K36: 3 | L36: 5 | M36: 4 | N36: 3 | O36: 6 | P36: 6 | Q36: 5 | R36: 4 | S36: 6 | T36: 4 | U36: 4 | V36: 4 | W36: 4 | X36: 4 | Y36: =SUM(G36:O36) -> 43 | Z36: =SUM(P36:X36) -> 41 | AA36: =IF(Z36>0,Y36+Z36,"") -> 84 | AB36: =IF(Z36=0,"",AA36-B36) -> 76
A37: MV | B37: - | C37: N | D37: N | E37: N | Y37: =SUM(G37:O37) -> 0 | Z37: =SUM(P37:X37) -> 0 | AA37: =IF(Z37>0,Y37+Z37,"") | AB37: =IF(Z37=0,"",AA37-B37)
AA38: =IF(Z38>0,Y38+Z38,"") | AB38: =IF(Z38=0,"",AA38-B38)
AA39: =IF(Z39>0,Y39+Z39,"") | AB39: =IF(Z39=0,"",AA39-B39)
C40: =COUNTIF(Scorecards!$C$4:$C$11, "Y")*C30 -> 25 | D40: =COUNTIF(Scorecards!$D$4:$D$11, "Y")*D30 -> 0 | E40: =COUNTIF(Scorecards!$E$4:$E$11, "Y")*E30 -> 0 | F40: SKIN | G40: {=IF(OR(SUM(IF(IF(Scorecards!$C$32:$C$39="Y", G32:G39, 10)=MIN(IF(Scorecards!$C$32:$C$39="Y", G32:G39, 10)), 1, 0)) > 1, MIN(IF(Scorecards!$C$32:$C$39="Y", G32:G39, 10)) > G31), "", INDEX(Scorecards!$A$32:$A$39,MATCH(MIN(IF(Scorecards!$C$32:$C$39="Y",G32:G39,10)),IF(Scorecards!$C$32:$C$39="Y",G32:G39,10),0)))} | H40: {=IF(OR(SUM(IF(IF(Scorecards!$C$32:$C$39="Y", H32:H39, 10)=MIN(IF(Scorecards!$C$32:$C$39="Y", H32:H39, 10)), 1, 0)) > 1, MIN(IF(Scorecards!$C$32:$C$39="Y", H32:H39, 10)) > H31), "", INDEX(Scorecards!$A$32:$A$39,MATCH(MIN(IF(Scorecards!$C$32:$C$39="Y",H32:H39,10)),IF(Scorecards!$C$32:$C$39="Y",H32:H39,10),0)))} -> SR | I40: {=IF(OR(SUM(IF(IF(Scorecards!$C$32:$C$39="Y", I32:I39, 10)=MIN(IF(Scorecards!$C$32:$C$39="Y", I32:I39, 10)), 1, 0)) > 1, MIN(IF(Scorecards!$C$32:$C$39="Y", I32:I39, 10)) > I31), "", INDEX(Scorecards!$A$32:$A$39,MATCH(MIN(IF(Scorecards!$C$32:$C$39="Y",I32:I39,10)),IF(Scorecards!$C$32:$C$39="Y",I32:I39,10),0)))} | J40: {=IF(OR(SUM(IF(IF(Scorecards!$C$32:$C$39="Y", J32:J39, 10)=MIN(IF(Scorecards!$C$32:$C$39="Y", J32:J39, 10)), 1, 0)) > 1, MIN(IF(Scorecards!$C$32:$C$39="Y", J32:J39, 10)) > J31), "", INDEX(Scorecards!$A$32:$A$39,MATCH(MIN(IF(Scorecards!$C$32:$C$39="Y",J32:J39,10)),IF(Scorecards!$C$32:$C$39="Y",J32:J39,10),0)))} | K40: {=IF(OR(SUM(IF(IF(Scorecards!$C$32:$C$39="Y", K32:K39, 10)=MIN(IF(Scorecards!$C$32:$C$39="Y", K32:K39, 10)), 1, 0)) > 1, MIN(IF(Scorecards!$C$32:$C$39="Y", K32:K39, 10)) > K31), "", INDEX(Scorecards!$A$32:$A$39,MATCH(MIN(IF(Scorecards!$C$32:$C$39="Y",K32:K39,10)),IF(Scorecards!$C$32:$C$39="Y",K32:K39,10),0)))} -> SR | L40: {=IF(OR(SUM(IF(IF(Scorecards!$C$32:$C$39="Y", L32:L39, 10)=MIN(IF(Scorecards!$C$32:$C$39="Y", L32:L39, 10)), 1, 0)) > 1, MIN(IF(Scorecards!$C$32:$C$39="Y", L32:L39, 10)) > L31), "", INDEX(Scorecards!$A$32:$A$39,MATCH(MIN(IF(Scorecards!$C$32:$C$39="Y",L32:L39,10)),IF(Scorecards!$C$32:$C$39="Y",L32:L39,10),0)))} -> BB | M40: {=IF(OR(SUM(IF(IF(Scorecards!$C$32:$C$39="Y", M32:M39, 10)=MIN(IF(Scorecards!$C$32:$C$39="Y", M32:M39, 10)), 1, 0)) > 1, MIN(IF(Scorecards!$C$32:$C$39="Y", M32:M39, 10)) > M31), "", INDEX(Scorecards!$A$32:$A$39,MATCH(MIN(IF(Scorecards!$C$32:$C$39="Y",M32:M39,10)),IF(Scorecards!$C$32:$C$39="Y",M32:M39,10),0)))} | N40: {=IF(OR(SUM(IF(IF(Scorecards!$C$32:$C$39="Y", N32:N39, 10)=MIN(IF(Scorecards!$C$32:$C$39="Y", N32:N39, 10)), 1, 0)) > 1, MIN(IF(Scorecards!$C$32:$C$39="Y", N32:N39, 10)) > N31), "", INDEX(Scorecards!$A$32:$A$39,MATCH(MIN(IF(Scorecards!$C$32:$C$39="Y",N32:N39,10)),IF(Scorecards!$C$32:$C$39="Y",N32:N39,10),0)))} -> BB | O40: BB | P40: {=IF(OR(SUM(IF(IF(Scorecards!$C$32:$C$39="Y", P32:P39, 10)=MIN(IF(Scorecards!$C$32:$C$39="Y", P32:P39, 10)), 1, 0)) > 1, MIN(IF(Scorecards!$C$32:$C$39="Y", P32:P39, 10)) > P31), "", INDEX(Scorecards!$A$32:$A$39,MATCH(MIN(IF(Scorecards!$C$32:$C$39="Y",P32:P39,10)),IF(Scorecards!$C$32:$C$39="Y",P32:P39,10),0)))} | Q40: {=IF(OR(SUM(IF(IF(Scorecards!$C$32:$C$39="Y", Q32:Q39, 10)=MIN(IF(Scorecards!$C$32:$C$39="Y", Q32:Q39, 10)), 1, 0)) > 1, MIN(IF(Scorecards!$C$32:$C$39="Y", Q32:Q39, 10)) > Q31), "", INDEX(Scorecards!$A$32:$A$39,MATCH(MIN(IF(Scorecards!$C$32:$C$39="Y",Q32:Q39,10)),IF(Scorecards!$C$32:$C$39="Y",Q32:Q39,10),0)))} | R40: {=IF(OR(SUM(IF(IF(Scorecards!$C$32:$C$39="Y", R32:R39, 10)=MIN(IF(Scorecards!$C$32:$C$39="Y", R32:R39, 10)), 1, 0)) > 1, MIN(IF(Scorecards!$C$32:$C$39="Y", R32:R39, 10)) > R31), "", INDEX(Scorecards!$A$32:$A$39,MATCH(MIN(IF(Scorecards!$C$32:$C$39="Y",R32:R39,10)),IF(Scorecards!$C$32:$C$39="Y",R32:R39,10),0)))} -> SR | S40: {=IF(OR(SUM(IF(IF(Scorecards!$C$32:$C$39="Y", S32:S39, 10)=MIN(IF(Scorecards!$C$32:$C$39="Y", S32:S39, 10)), 1, 0)) > 1, MIN(IF(Scorecards!$C$32:$C$39="Y", S32:S39, 10)) > S31), "", INDEX(Scorecards!$A$32:$A$39,MATCH(MIN(IF(Scorecards!$C$32:$C$39="Y",S32:S39,10)),IF(Scorecards!$C$32:$C$39="Y",S32:S39,10),0)))} | T40: {=IF(OR(SUM(IF(IF(Scorecards!$C$32:$C$39="Y", T32:T39, 10)=MIN(IF(Scorecards!$C$32:$C$39="Y", T32:T39, 10)), 1, 0)) > 1, MIN(IF(Scorecards!$C$32:$C$39="Y", T32:T39, 10)) > T31), "", INDEX(Scorecards!$A$32:$A$39,MATCH(MIN(IF(Scorecards!$C$32:$C$39="Y",T32:T39,10)),IF(Scorecards!$C$32:$C$39="Y",T32:T39,10),0)))} | U40: {=IF(OR(SUM(IF(IF(Scorecards!$C$32:$C$39="Y", U32:U39, 10)=MIN(IF(Scorecards!$C$32:$C$39="Y", U32:U39, 10)), 1, 0)) > 1, MIN(IF(Scorecards!$C$32:$C$39="Y", U32:U39, 10)) > U31), "", INDEX(Scorecards!$A$32:$A$39,MATCH(MIN(IF(Scorecards!$C$32:$C$39="Y",U32:U39,10)),IF(Scorecards!$C$32:$C$39="Y",U32:U39,10),0)))} -> BK | V40: {=IF(OR(SUM(IF(IF(Scorecards!$C$32:$C$39="Y", V32:V39, 10)=MIN(IF(Scorecards!$C$32:$C$39="Y", V32:V39, 10)), 1, 0)) > 1, MIN(IF(Scorecards!$C$32:$C$39="Y", V32:V39, 10)) > V31), "", INDEX(Scorecards!$A$32:$A$39,MATCH(MIN(IF(Scorecards!$C$32:$C$39="Y",V32:V39,10)),IF(Scorecards!$C$32:$C$39="Y",V32:V39,10),0)))} -> SR | W40: {=IF(OR(SUM(IF(IF(Scorecards!$C$32:$C$39="Y", W32:W39, 10)=MIN(IF(Scorecards!$C$32:$C$39="Y", W32:W39, 10)), 1, 0)) > 1, MIN(IF(Scorecards!$C$32:$C$39="Y", W32:W39, 10)) > W31), "", INDEX(Scorecards!$A$32:$A$39,MATCH(MIN(IF(Scorecards!$C$32:$C$39="Y",W32:W39,10)),IF(Scorecards!$C$32:$C$39="Y",W32:W39,10),0)))} | X40: {=IF(OR(SUM(IF(IF(Scorecards!$C$32:$C$39="Y", X32:X39, 10)=MIN(IF(Scorecards!$C$32:$C$39="Y", X32:X39, 10)), 1, 0)) > 1, MIN(IF(Scorecards!$C$32:$C$39="Y", X32:X39, 10)) > X31), "", INDEX(Scorecards!$A$32:$A$39,MATCH(MIN(IF(Scorecards!$C$32:$C$39="Y",X32:X39,10)),IF(Scorecards!$C$32:$C$39="Y",X32:X39,10),0)))} -> SR | AA40: =18-COUNTBLANK(G40:X40) -> 9 | AB40: =IF(AA40 = 0, 0, C40/AA40) -> 2.7777778
F41: CTP | AA41: =COUNTA(H41,N41,R41,U41) -> 0 | AB41: =IF(AA41 = 0, 0, D40/AA41) -> 0
F43: CALDERONE | AA43: 69.1 | AB43: 124
...

Sheet Scores
B1: Player | C1: =Scorecards!F1 -> THE GRANDE | E1: =Scorecards!F15 -> CASCADES | G1: =Scorecards!F29 -> CALDERONE | I1: =Scorecards!F43 -> CALDERONE | K1: TOTAL
C2: GROSS | D2: NET | E2: GROSS | F2: NET | G2: GROSS | H2: NET | I2: GROSS | J2: NET | K2: GROSS | L2: NET
A3: =RANK(L3,L$3:L$8,1)+COUNTIF($L$3:L3,L3)-1 -> 5 | B3: Aaron Jensen | C3: =Scorecards!AA4 -> 83 | D3: =Scorecards!AB4 -> 75 | E3: =Scorecards!AA18 | F3: =Scorecards!AB18 | G3: =Scorecards!AA32 | H3: =Scorecards!AB32 | I3: =Scorecards!AA46 | J3: =Scorecards!AB46 | K3: 9999 | L3: 9999 | N3: =RANK(L3,$L$3:$L$8,1)+COUNTIF($L$3:L3,L3)-1 -> 5 | O3: =INDEX($B$3:$N$8,MATCH(N3,$N$3:$N$8,0),1) -> Aaron Jensen | P3: =RANK(L3,$L$3:$L$8,1) -> 5
A4: =RANK(L4,L$3:L$8,1)+COUNTIF($L$3:L4,L4)-1 -> 2 | B4: Bob Bergeron | C4: =Scorecards!AA5 -> 88 | D4: =Scorecards!AB5 -> 70 | E4: =Scorecards!AA19 -> 96 | F4: =Scorecards!AB19 -> 78 | G4: =Scorecards!AA33 -> 86 | H4: =Scorecards!AB33 -> 68 | I4: =Scorecards!AA47 -> 92 | J4: =Scorecards!AB47 -> 74 | K4: =SUM(C4,E4,G4,I4) -> 362 | L4: =SUM(D4,F4,H4,J4) -> 290 | N4: =RANK(L4,$L$3:$L$8,1)+COUNTIF($L$3:L4,L4)-1 -> 2 | O4: =INDEX($B$3:$N$8,MATCH(N4,$N$3:$N$8,0),1) -> Bob Bergeron | P4: =RANK(L4,$L$3:$L$8,1) -> 2
A5: =RANK(L5,L$3:L$8,1)+COUNTIF($L$3:L5,L5)-1 -> 1 | B5: Brian Kelley | C5: =Scorecards!AA6 -> 84 | D5: =Scorecards!AB6 -> 69 | E5: =Scorecards!AA20 -> 86 | F5: =Scorecards!AB20 -> 71 | G5: =Scorecards!AA34 -> 89 | H5: =Scorecards!AB34 -> 74 | I5: =Scorecards!AA48 -> 85 | J5: =Scorecards!AB48 -> 70 | K5: =SUM(C5,E5,G5,I5) -> 344 | L5: =SUM(D5,F5,H5,J5) -> 284 | N5: =RANK(L5,$L$3:$L$8,1)+COUNTIF($L$3:L5,L5)-1 -> 1 | O5: =INDEX($B$3:$N$8,MATCH(N5,$N$3:$N$8,0),1) -> Brian Kelley | P5: =RANK(L5,$L$3:$L$8,1) -> 1
A6: =RANK(L6,L$3:L$8,1)+COUNTIF($L$3:L6,L6)-1 -> 4 | B6: Eric Olson | C6: =Scorecards!AA7 -> 96 | D6: =Scorecards!AB7 -> 78 | E6: =Scorecards!AA21 -> 87 | F6: =Scorecards!AB21 -> 69 | G6: =Scorecards!AA35 -> 106 | H6: =Scorecards!AB35 -> 88 | I6: =Scorecards!AA49 -> 94 | J6: =Scorecards!AB49 -> 76 | K6: =SUM(C6,E6,G6,I6) -> 383 | L6: =SUM(D6,F6,H6,J6) -> 311 | N6: =RANK(L6,$L$3:$L$8,1)+COUNTIF($L$3:L6,L6)-1 -> 4 | O6: =INDEX($B$3:$N$8,MATCH(N6,$N$3:$N$8,0),1) -> Eric Olson | P6: =RANK(L6,$L$3:$L$8,1) -> 4
A7: =RANK(L7,L$3:L$8,1)+COUNTIF($L$3:L7,L7)-1 -> 3 | B7: Scott Rhoades | C7: =Scorecards!AA8 -> 73 | D7: =Scorecards!AB8 -> 65 | E7: =Scorecards!AA22 -> 86 | F7: =Scorecards!AB22 -> 78 | G7: =Scorecards!AA36 -> 84 | H7: =Scorecards!AB36 -> 76 | I7: =Scorecards!AA50 -> 80 | J7: =Scorecards!AB50 -> 72 | K7: =SUM(C7,E7,G7,I7) -> 323 | L7: =SUM(D7,F7,H7,J7) -> 291 | N7: =RANK(L7,$L$3:$L$8,1)+COUNTIF($L$3:L7,L7)-1 -> 3 | O7: =INDEX($B$3:$N$8,MATCH(N7,$N$3:$N$8,0),1) -> Scott Rhoades | P7: =RANK(L7,$L$3:$L$8,1) -> 3
A8: =RANK(L8,L$3:L$8,1)+COUNTIF($L$3:L8,L8)-1 -> 6 | B8: Matt Vigo | C8: =Scorecards!AA9 | D8: =Scorecards!AB9 | E8: =Scorecards!AA23 | F8: =Scorecards!AB23 | G8: =Scorecards!AA37 | H8: =Scorecards!AB37 | I8: =Scorecards!AA51 | J8: =Scorecards!AB51 | K8: 9999 | L8: 9999 | N8: =RANK(L8,$L$3:$L$8,1)+COUNTIF($L$3:L8,L8)-1 -> 6 | O8: =INDEX($B$3:$N$8,MATCH(N8,$N$3:$N$8,0),1) -> Matt Vigo | P8: =RANK(L8,$L$3:$L$8,1) -> 5

Sheet Shares
B1: $1 Shares | I1: $0.50 Shares | P1: Invested
B2: AJ | C2: BB | D2: BK | E2: EO | F2: SR | G2: MV | H2: TOTAL $1 | I2: AJ | J2: BB | K2: BK | L2: EO | M2: SR | N2: MV | O2: TOTAL $0.50 | P2: =sum(P3:P8) -> 190
A3: Aaron Jensen | B3: 9 | C3: 1 | D3: 3 | E3: 1 | F3: 6 | H3: =sum(B3:F3) -> 20 | K3: 8 | L3: 4 | M3: 8 | O3: =sum(I3:N3) -> 20 | P3: =H3+O3 -> 40
A4: Bob Bergeron | B4: 9 | C4: 1 | D4: 4 | E4: 2 | F4: 4 | H4: =sum(B4:F4) -> 20 | K4: 10 | M4: 10 | O4: =sum(I4:N4) -> 20 | P4: =H4+O4 -> 40
A5: Brian Kelley | B5: 5 | D5: 10 | F5: 5 | H5: =sum(B5:F5) -> 20 | K5: 10 | M5: 10 | O5: =sum(I5:N5) -> 20 | P5: =H5+O5 -> 40
A6: Eric Olson | B6: 5 | D6: 5 | E6: 3 | F6: 7 | H6: =sum(B6:F6) -> 20 | I6: 0.5 | J6: 5 | K6: 2 | M6: 2 | N6: 0.5 | O6: =sum(I6:N6) -> 10 | P6: =H6+O6 -> 30
A7: Scott Rhoades | F7: 20 | H7: =sum(B7:F7) -> 20 | O7: =sum(I7:N7) -> 0 | P7: =H7+O7 -> 20
A8: Matt Vigo | H8: =sum(B8:F8) -> 0 | K8: 15 | L8: 5 | O8: =sum(I8:N8) -> 20 | P8: =H8+O8 -> 20
B9: =if($A$13=B2,(sum(B3:B8)+(sum(I3:I8)/2)),"") | C9: =if($A$13=C2,(sum(C3:C8)+(sum(J3:J8)/2)),"") | D9: =if($A$13=D2,(sum(D3:D8)+(sum(K3:K8)/2)),"") -> 44.5 | E9: =if($A$13=E2,(sum(E3:E8)+(sum(L3:L8)/2)),"") | F9: =if($A$13=F2,(sum(F3:F8)+(sum(M3:M8)/2)),"") | G9: =if($A$13=G2,(sum(G3:G8)+(sum(N3:N8)/2)),"")
A12: Winner
A13: BK
A15: Total $1 share | B15: 100 | D15: Total $.50 share | E15: 90
A16: Total BK $1 share | B16: 22 | D16: Total BK .50 share | E16: =sum(K3:K8) -> 45
A17: per | B17: =B15/B16 -> 4.5454545 | D17: per | E17: =E15/E16 -> 2
A18: Aaron Jensen | B18: 3 | C18: =B18*$B$17 -> 13.636364 | D18: 8 | E18: =D18*$E$17 -> 16
A19: Bob Bergeron | B19: 4 | C19: =B19*$B$17 -> 18.181818 | D19: 10 | E19: =D19*$E$17 -> 20
A20: Brian Kelley | B20: 10 | C20: =B20*$B$17 -> 45.454545 | D20: 10 | E20: =D20*$E$17 -> 20
A21: Eric Olson | B21: 5 | C21: =B21*$B$17 -> 22.727273 | D21: 2 | E21: =D21*$E$17 -> 4
A22: Scott Rhoades | C22: =B22*$B$17 -> 0 | E22: =D22*$E$17 -> 0
A23: Matt Vigo | C23: =B23*$B$17 -> 0 | D23: 15 | E23: =D23*$E$17 -> 30
A25: Aaron Jensen | B25: =C18+E18 -> 29.636364
A26: Bob Bergeron | B26: =C19+E19 -> 38.181818
A27: Brian Kelley | B27: =C20+E20 -> 65.454545
A28: Eric Olson | B28: =C21+E21 -> 26.727273
A29: Scott Rhoades | B29: =C22+E22 -> 0
A30: Matt Vigo | B30: =C23+E23 -> 30

Sheet WeekendLongBets
B1: 10 | C1: 0
A2: Player | B2: Single Round Low | C2: Low Cumulative
A3: AJ | B3: Y | C3: Y
A4: BB | B4: Y | C4: Y
A5: BK | B5: Y | C5: Y
A6: EO | B6: Y | C6: Y
A7: MV | B7: Y | C7: Y
A8: SR | B8: Y | C8: Y
A11: Totals | B11: =COUNTIF(B3:B10,"Y") *B1 -> 60 | C11: =COUNTIF(C3:C10,"Y") *C1 -> 0

Sheet BettingScoreboard
A1: Low Per Round | B1: Yarrow | C1: Bedford Valley | D1: Stonehedge N | E1: Gull Lake West
A2: AJ | B2: =IF(Scorecards!E4="Y",Scores!D3, "") -> 75 | C2: =IF(Scorecards!E18="Y",Scores!F3, "") | D2: =IF(Scorecards!E32="Y",Scores!H3, "") | E2: =IF(Scorecards!E46="Y",Scores!J3, "")
A3: BB | B3: =IF(Scorecards!E5="Y",Scores!D4, "") -> 70 | C3: =IF(Scorecards!E19="Y",Scores!F4, "") -> 78 | D3: =IF(Scorecards!E33="Y",Scores!H4, "") -> 68 | E3: =IF(Scorecards!E47="Y",Scores!J4, "") -> 74
A4: BK | B4: =IF(Scorecards!E6="Y",Scores!D5, "") -> 69 | C4: =IF(Scorecards!E20="Y",Scores!F5, "") -> 71 | D4: =IF(Scorecards!E34="Y",Scores!H5, "") -> 74 | E4: =IF(Scorecards!E48="Y",Scores!J5, "") -> 70
A5: EO | B5: =IF(Scorecards!E7="Y",Scores!D6, "") -> 78 | C5: =IF(Scorecards!E21="Y",Scores!F6, "") -> 69 | D5: =IF(Scorecards!E35="Y",Scores!H6, "") -> 88 | E5: =IF(Scorecards!E49="Y",Scores!J6, "") -> 76
A6: MV | B6: =IF(Scorecards!E8="Y",Scores!D7, "") -> 65 | C6: =IF(Scorecards!E22="Y",Scores!F7, "") -> 78 | D6: =IF(Scorecards!E36="Y",Scores!H7, "") -> 76 | E6: =IF(Scorecards!E50="Y",Scores!J7, "") -> 72
A7: SR | B7: =IF(Scorecards!E9="Y",Scores!D8, "") | C7: =IF(Scorecards!E23="Y",Scores!F8, "") | D7: =IF(Scorecards!E37="Y",Scores!H8, "") | E7: =IF(Scorecards!E51="Y",Scores!J8, "")
B8: =IF(Scorecards!F10="Y",Scores!#REF!, "") -> #ERROR! | C8: =IF(Scorecards!F24="Y",Scores!#REF!, "") -> #ERROR! | D8: =IF(Scorecards!F38="Y",Scores!#REF!, "") -> #ERROR! | E8: =IF(Scorecards!F52="Y",Scores!#REF!, "") -> #ERROR!
B9: =IF(Scorecards!F11="Y",Scores!#REF!, "") -> #ERROR! | C9: =IF(Scorecards!F25="Y",Scores!#REF!, "") -> #ERROR! | D9: =IF(Scorecards!F39="Y",Scores!#REF!, "") -> #ERROR! | E9: =IF(Scorecards!F53="Y",Scores!#REF!, "") -> #ERROR!
A10: # of Winners | B10: =COUNTIF(BettingScoreboard!$B$2:$B$9,MIN(BettingScoreboard!$B$2:$B$9)) -> 2 | C10: =COUNTIF(BettingScoreboard!$C$2:$C$9,MIN(BettingScoreboard!$C$2:$C$9)) -> 2 | D10: =COUNTIF(BettingScoreboard!$D$2:$D$9,MIN(BettingScoreboard!$D$2:$D$9)) -> 2 | E10: =COUNTIF(BettingScoreboard!$E$2:$E$9,MIN(BettingScoreboard!$E$2:$E$9)) -> 2
A12: Single Round Low | D12: Cumulative Low
A13: Player | B13: Score | D13: Player | E13: Score
A14: AJ | B14: =IF(WeekendLongBets!B3="Y",MIN(Scores!D3:J3), "") -> 75 | D14: AJ | E14: =IF(WeekendLongBets!C3="Y",SUM(Scores!D3:J3),"") -> 75
A15: BB | B15: =IF(WeekendLongBets!B4="Y",MIN(Scores!D4:J4), "") -> 68 | D15: BB | E15: =IF(WeekendLongBets!C4="Y",SUM(Scores!D4:J4),"") -> 564
A16: BK | B16: =IF(WeekendLongBets!B5="Y",MIN(Scores!D5:J5), "") -> 69 | D16: BK | E16: =IF(WeekendLongBets!C5="Y",SUM(Scores!D5:J5),"") -> 544
A17: EO | B17: =IF(WeekendLongBets!B6="Y",MIN(Scores!D6:J6), "") -> 69 | D17: EO | E17: =IF(WeekendLongBets!C6="Y",SUM(Scores!D6:J6),"") -> 598
A18: MV | B18: =IF(WeekendLongBets!B7="Y",MIN(Scores!D7:J7), "") -> 65 | D18: MV | E18: =IF(WeekendLongBets!C7="Y",SUM(Scores!D7:J7),"") -> 541
A19: SR | B19: =IF(WeekendLongBets!B8="Y",MIN(Scores!D8:J8), "") -> 0 | D19: SR | E19: =IF(WeekendLongBets!C8="Y",SUM(Scores!D8:J8),"") -> 0
B20: =IF(WeekendLongBets!B9="Y",MIN(Scores!#REF!), "") -> #ERROR! | E20: =IF(WeekendLongBets!C9="Y",SUM(Scores!#REF!),"") -> #ERROR!
B21: =IF(WeekendLongBets!B10="Y",MIN(Scores!#REF!), "") -> #ERROR! | E21: =IF(WeekendLongBets!C10="Y",SUM(Scores!#REF!),"") -> #ERROR!
A22: # of Winners | B22: =COUNTIF(BettingScoreboard!$B$14:$B$21,MIN(BettingScoreboard!$B$14:$B$21)) -> 2 | D22: # of Winners | E22: =COUNTIF(BettingScoreboard!$E$14:$E$21,MIN(BettingScoreboard!$E$14:$E$21)) -> 2
A24: Player | B24: Skins | C24: Skin $ | D24: CTP | E24: CTP $
A25: =Scorecards!A32 -> AJ | B25: =SUM(COUNTIF(Scorecards!$G$12:$X$12,BettingScoreboard!$A25),COUNTIF(Scorecards!$G$26:$X$26,BettingScoreboard!$A25),COUNTIF(Scorecards!$G$40:$X$40,BettingScoreboard!$A25),COUNTIF(Scorecards!$G$54:$X$54,BettingScoreboard!$A25)) -> 1 | C25: =SUM(COUNTIF(Scorecards!$G$12:$X$12,BettingScoreboard!$A25)*Scorecards!$AB$12,COUNTIF(Scorecards!$G$26:$X$26, BettingScoreboard!$A25)*Scorecards!$AB$26,COUNTIF(Scorecards!$G$40:$X$40,BettingScoreboard!$A25)*Scorecards!$AB$40,COUNTIF(Scorecards!$G$54:$X$54, BettingScoreboard!$A25)*Scorecards!$AB$54) -> 2.7777778 | D25: =SUM(COUNTIF(Scorecards!$G$13:$X$13,BettingScoreboard!$A25),COUNTIF(Scorecards!$G$27:$X$27,BettingScoreboard!$A25),COUNTIF(Scorecards!$G$41:$X$41,BettingScoreboard!$A25),COUNTIF(Scorecards!$G$55:$X$55,BettingScoreboard!$A25)) -> 0 | E25: =SUM(COUNTIF(Scorecards!$G$13:$X$13,BettingScoreboard!$A25)*Scorecards!$AB$13,COUNTIF(Scorecards!$G$27:$X$27, BettingScoreboard!$A25)*Scorecards!$AB$27,COUNTIF(Scorecards!$G$41:$X$41,BettingScoreboard!$A25)*Scorecards!$AB$41,COUNTIF(Scorecards!$G$55:$X$55, BettingScoreboard!$A25)*Scorecards!$AB$55) -> 0
A26: =Scorecards!A33 -> BB | B26: =SUM(COUNTIF(Scorecards!$G$12:$X$12,BettingScoreboard!$A26),COUNTIF(Scorecards!$G$26:$X$26,BettingScoreboard!$A26),COUNTIF(Scorecards!$G$40:$X$40,BettingScoreboard!$A26),COUNTIF(Scorecards!$G$54:$X$54,BettingScoreboard!$A26)) -> 5 | C26: =SUM(COUNTIF(Scorecards!$G$12:$X$12,BettingScoreboard!$A26)*Scorecards!$AB$12,COUNTIF(Scorecards!$G$26:$X$26, BettingScoreboard!$A26)*Scorecards!$AB$26,COUNTIF(Scorecards!$G$40:$X$40,BettingScoreboard!$A26)*Scorecards!$AB$40,COUNTIF(Scorecards!$G$54:$X$54, BettingScoreboard!$A26)*Scorecards!$AB$54) -> 13.194444 | D26: =SUM(COUNTIF(Scorecards!$G$13:$X$13,BettingScoreboard!$A26),COUNTIF(Scorecards!$G$27:$X$27,BettingScoreboard!$A26),COUNTIF(Scorecards!$G$41:$X$41,BettingScoreboard!$A26),COUNTIF(Scorecards!$G$55:$X$55,BettingScoreboard!$A26)) -> 0 | E26: =SUM(COUNTIF(Scorecards!$G$13:$X$13,BettingScoreboard!$A26)*Scorecards!$AB$13,COUNTIF(Scorecards!$G$27:$X$27, BettingScoreboard!$A26)*Scorecards!$AB$27,COUNTIF(Scorecards!$G$41:$X$41,BettingScoreboard!$A26)*Scorecards!$AB$41,COUNTIF(Scorecards!$G$55:$X$55, BettingScoreboard!$A26)*Scorecards!$AB$55) -> 0
A27: =Scorecards!A34 -> BK | B27: =SUM(COUNTIF(Scorecards!$G$12:$X$12,BettingScoreboard!$A27),COUNTIF(Scorecards!$G$26:$X$26,BettingScoreboard!$A27),COUNTIF(Scorecards!$G$40:$X$40,BettingScoreboard!$A27),COUNTIF(Scorecards!$G$54:$X$54,BettingScoreboard!$A27)) -> 7 | C27: =SUM(COUNTIF(Scorecards!$G$12:$X$12,BettingScoreboard!$A27)*Scorecards!$AB$12,COUNTIF(Scorecards!$G$26:$X$26, BettingScoreboard!$A27)*Scorecards!$AB$26,COUNTIF(Scorecards!$G$40:$X$40,BettingScoreboard!$A27)*Scorecards!$AB$40,COUNTIF(Scorecards!$G$54:$X$54, BettingScoreboard!$A27)*Scorecards!$AB$54) -> 17.5 | D27: =SUM(COUNTIF(Scorecards!$G$13:$X$13,BettingScoreboard!$A27),COUNTIF(Scorecards!$G$27:$X$27,BettingScoreboard!$A27),COUNTIF(Scorecards!$G$41:$X$41,BettingScoreboard!$A27),COUNTIF(Scorecards!$G$55:$X$55,BettingScoreboard!$A27)) -> 0 | E27: =SUM(COUNTIF(Scorecards!$G$13:$X$13,BettingScoreboard!$A27)*Scorecards!$AB$13,COUNTIF(Scorecards!$G$27:$X$27, BettingScoreboard!$A27)*Scorecards!$AB$27,COUNTIF(Scorecards!$G$41:$X$41,BettingScoreboard!$A27)*Scorecards!$AB$41,COUNTIF(Scorecards!$G$55:$X$55, BettingScoreboard!$A27)*Scorecards!$AB$55) -> 0
A28: =Scorecards!A35 -> EO | B28: =SUM(COUNTIF(Scorecards!$G$12:$X$12,BettingScoreboard!$A28),COUNTIF(Scorecards!$G$26:$X$26,BettingScoreboard!$A28),COUNTIF(Scorecards!$G$40:$X$40,BettingScoreboard!$A28),COUNTIF(Scorecards!$G$54:$X$54,BettingScoreboard!$A28)) -> 7 | C28: =SUM(COUNTIF(Scorecards!$G$12:$X$12,BettingScoreboard!$A28)*Scorecards!$AB$12,COUNTIF(Scorecards!$G$26:$X$26, BettingScoreboard!$A28)*Scorecards!$AB$26,COUNTIF(Scorecards!$G$40:$X$40,BettingScoreboard!$A28)*Scorecards!$AB$40,COUNTIF(Scorecards!$G$54:$X$54, BettingScoreboard!$A28)*Scorecards!$AB$54) -> 17.361111 | D28: =SUM(COUNTIF(Scorecards!$G$13:$X$13,BettingScoreboard!$A28),COUNTIF(Scorecards!$G$27:$X$27,BettingScoreboard!$A28),COUNTIF(Scorecards!$G$41:$X$41,BettingScoreboard!$A28),COUNTIF(Scorecards!$G$55:$X$55,BettingScoreboard!$A28)) -> 0 | E28: =SUM(COUNTIF(Scorecards!$G$13:$X$13,BettingScoreboard!$A28)*Scorecards!$AB$13,COUNTIF(Scorecards!$G$27:$X$27, BettingScoreboard!$A28)*Scorecards!$AB$27,COUNTIF(Scorecards!$G$41:$X$41,BettingScoreboard!$A28)*Scorecards!$AB$41,COUNTIF(Scorecards!$G$55:$X$55, BettingScoreboard!$A28)*Scorecards!$AB$55) -> 0
A29: =Scorecards!A36 -> SR | B29: =SUM(COUNTIF(Scorecards!$G$12:$X$12,BettingScoreboard!$A29),COUNTIF(Scorecards!$G$26:$X$26,BettingScoreboard!$A29),COUNTIF(Scorecards!$G$40:$X$40,BettingScoreboard!$A29),COUNTIF(Scorecards!$G$54:$X$54,BettingScoreboard!$A29)) -> 20 | C29: =SUM(COUNTIF(Scorecards!$G$12:$X$12,BettingScoreboard!$A29)*Scorecards!$AB$12,COUNTIF(Scorecards!$G$26:$X$26, BettingScoreboard!$A29)*Scorecards!$AB$26,COUNTIF(Scorecards!$G$40:$X$40,BettingScoreboard!$A29)*Scorecards!$AB$40,COUNTIF(Scorecards!$G$54:$X$54, BettingScoreboard!$A29)*Scorecards!$AB$54) -> 49.166667 | D29: =SUM(COUNTIF(Scorecards!$G$13:$X$13,BettingScoreboard!$A29),COUNTIF(Scorecards!$G$27:$X$27,BettingScoreboard!$A29),COUNTIF(Scorecards!$G$41:$X$41,BettingScoreboard!$A29),COUNTIF(Scorecards!$G$55:$X$55,BettingScoreboard!$A29)) -> 0 | E29: =SUM(COUNTIF(Scorecards!$G$13:$X$13,BettingScoreboard!$A29)*Scorecards!$AB$13,COUNTIF(Scorecards!$G$27:$X$27, BettingScoreboard!$A29)*Scorecards!$AB$27,COUNTIF(Scorecards!$G$41:$X$41,BettingScoreboard!$A29)*Scorecards!$AB$41,COUNTIF(Scorecards!$G$55:$X$55, BettingScoreboard!$A29)*Scorecards!$AB$55) -> 0
A30: =Scorecards!A37 -> MV | B30: =SUM(COUNTIF(Scorecards!$G$12:$X$12,BettingScoreboard!$A30),COUNTIF(Scorecards!$G$26:$X$26,BettingScoreboard!$A30),COUNTIF(Scorecards!$G$40:$X$40,BettingScoreboard!$A30),COUNTIF(Scorecards!$G$54:$X$54,BettingScoreboard!$A30)) -> 0 | C30: =SUM(COUNTIF(Scorecards!$G$12:$X$12,BettingScoreboard!$A30)*Scorecards!$AB$12,COUNTIF(Scorecards!$G$26:$X$26, BettingScoreboard!$A30)*Scorecards!$AB$26,COUNTIF(Scorecards!$G$40:$X$40,BettingScoreboard!$A30)*Scorecards!$AB$40,COUNTIF(Scorecards!$G$54:$X$54, BettingScoreboard!$A30)*Scorecards!$AB$54) -> 0 | D30: =SUM(COUNTIF(Scorecards!$G$13:$X$13,BettingScoreboard!$A30),COUNTIF(Scorecards!$G$27:$X$27,BettingScoreboard!$A30),COUNTIF(Scorecards!$G$41:$X$41,BettingScoreboard!$A30),COUNTIF(Scorecards!$G$55:$X$55,BettingScoreboard!$A30)) -> 0 | E30: =SUM(COUNTIF(Scorecards!$G$13:$X$13,BettingScoreboard!$A30)*Scorecards!$AB$13,COUNTIF(Scorecards!$G$27:$X$27, BettingScoreboard!$A30)*Scorecards!$AB$27,COUNTIF(Scorecards!$G$41:$X$41,BettingScoreboard!$A30)*Scorecards!$AB$41,COUNTIF(Scorecards!$G$55:$X$55, BettingScoreboard!$A30)*Scorecards!$AB$55) -> 0

Sheet BettingPayouts
A1: Name | B1: Skins Buyin | C1: Skins | D1: CTP Buyin | E1: CTP | F1: Per Round Low Buyin | G1: Per Round Low | H1: Single Round Low Buyin | I1: Single Round Low | J1: Cumulative Buyin | K1: Cumulative Low | L1: Total
A2: Aaron Jensen | B2: =-1*SUM(IF(Scorecards!C4="Y",Scorecards!$C$2, 0),IF(Scorecards!C18="Y",Scorecards!$C$16,0),IF(Scorecards!C32="Y",Scorecards!$C$30,0),IF(Scorecards!C46="Y",Scorecards!$C$44,0)) -> -20 | C2: =BettingScoreboard!C25 -> 2.7777778 | D2: =-1*SUM(IF(Scorecards!D4="Y",Scorecards!$D$2, 0),IF(Scorecards!D18="Y",Scorecards!$D$16,0),IF(Scorecards!D32="Y",Scorecards!$D$30,0),IF(Scorecards!D46="Y",Scorecards!$D$44,0)) -> 0 | E2: =BettingScoreboard!E25 -> 0 | F2: =-1*SUM(IF(Scorecards!E4="Y",Scorecards!$E$2, 0),IF(Scorecards!E18="Y",Scorecards!$E$16,0),IF(Scorecards!E32="Y",Scorecards!$E$30,0),IF(Scorecards!E46="Y",Scorecards!$E$44,0)) -> 0 | G2: =SUM(IF(BettingScoreboard!$B2=MIN(BettingScoreboard!$B$2:$B$9),Scorecards!$E$12/BettingScoreboard!$B$10),IF(BettingScoreboard!$C2=MIN(BettingScoreboard!$C$2:$C$9),Scorecards!$E$26/BettingScoreboard!$C$10), IF(BettingScoreboard!$D2=MIN(BettingScoreboard!$D$2:$D$9),Scorecards!$E$40/BettingScoreboard!$D$10),IF(BettingScoreboard!$E2=MIN(BettingScoreboard!$E$2:$E$9),Scorecards!$E$54/BettingScoreboard!$E$10)) -> #ERROR! | H2: =-1*IF(WeekendLongBets!B3="Y",WeekendLongBets!$B$1,0) -> -10 | I2: =IF(BettingScoreboard!B14=MIN(BettingScoreboard!$B$14:$B$21),WeekendLongBets!$B$11/BettingScoreboard!$B$22, 0) -> #ERROR! | J2: =-1*IF(WeekendLongBets!C3="Y",WeekendLongBets!$C$1,0) -> 0 | K2: =IF(BettingScoreboard!E14=MIN(BettingScoreboard!$E$14:$E$21),WeekendLongBets!$C$11/BettingScoreboard!$E$22, 0) -> #ERROR! | L2: =SUM(B2:K2) -> #ERROR!
A3: Bob Bergeron | B3: =-1*SUM(IF(Scorecards!C5="Y",Scorecards!$C$2, 0),IF(Scorecards!C19="Y",Scorecards!$C$16,0),IF(Scorecards!C33="Y",Scorecards!$C$30,0),IF(Scorecards!C47="Y",Scorecards!$C$44,0)) -> -20 | C3: =BettingScoreboard!C26 -> 13.194444 | D3: =-1*SUM(IF(Scorecards!D5="Y",Scorecards!$D$2, 0),IF(Scorecards!D19="Y",Scorecards!$D$16,0),IF(Scorecards!D33="Y",Scorecards!$D$30,0),IF(Scorecards!D47="Y",Scorecards!$D$44,0)) -> 0 | E3: =BettingScoreboard!E26 -> 0 | F3: =-1*SUM(IF(Scorecards!E5="Y",Scorecards!$E$2, 0),IF(Scorecards!E19="Y",Scorecards!$E$16,0),IF(Scorecards!E33="Y",Scorecards!$E$30,0),IF(Scorecards!E47="Y",Scorecards!$E$44,0)) -> 0 | G3: =SUM(IF(BettingScoreboard!$B3=MIN(BettingScoreboard!$B$2:$B$9),Scorecards!$E$12/BettingScoreboard!$B$10),IF(BettingScoreboard!$C3=MIN(BettingScoreboard!$C$2:$C$9),Scorecards!$E$26/BettingScoreboard!$C$10), IF(BettingScoreboard!$D3=MIN(BettingScoreboard!$D$2:$D$9),Scorecards!$E$40/BettingScoreboard!$D$10),IF(BettingScoreboard!$E3=MIN(BettingScoreboard!$E$2:$E$9),Scorecards!$E$54/BettingScoreboard!$E$10)) -> #ERROR! | H3: =-1*IF(WeekendLongBets!B4="Y",WeekendLongBets!$B$1,0) -> -10 | I3: =IF(BettingScoreboard!B15=MIN(BettingScoreboard!$B$14:$B$21),WeekendLongBets!$B$11/BettingScoreboard!$B$22, 0) -> #ERROR! | J3: =-1*IF(WeekendLongBets!C4="Y",WeekendLongBets!$C$1,0) -> 0 | K3: =IF(BettingScoreboard!E15=MIN(BettingScoreboard!$E$14:$E$21),WeekendLongBets!$C$11/BettingScoreboard!$E$22, 0) -> #ERROR! | L3: =SUM(B3:K3) -> #ERROR!
A4: Brian Kelly | B4: =-1*SUM(IF(Scorecards!C6="Y",Scorecards!$C$2, 0),IF(Scorecards!C20="Y",Scorecards!$C$16,0),IF(Scorecards!C34="Y",Scorecards!$C$30,0),IF(Scorecards!C48="Y",Scorecards!$C$44,0)) -> -20 | C4: =BettingScoreboard!C27 -> 17.5 | D4: =-1*SUM(IF(Scorecards!D6="Y",Scorecards!$D$2, 0),IF(Scorecards!D20="Y",Scorecards!$D$16,0),IF(Scorecards!D34="Y",Scorecards!$D$30,0),IF(Scorecards!D48="Y",Scorecards!$D$44,0)) -> 0 | E4: =BettingScoreboard!E27 -> 0 | F4: =-1*SUM(IF(Scorecards!E6="Y",Scorecards!$E$2, 0),IF(Scorecards!E20="Y",Scorecards!$E$16,0),IF(Scorecards!E34="Y",Scorecards!$E$30,0),IF(Scorecards!E48="Y",Scorecards!$E$44,0)) -> 0 | G4: =SUM(IF(BettingScoreboard!$B4=MIN(BettingScoreboard!$B$2:$B$9),Scorecards!$E$12/BettingScoreboard!$B$10),IF(BettingScoreboard!$C4=MIN(BettingScoreboard!$C$2:$C$9),Scorecards!$E$26/BettingScoreboard!$C$10), IF(BettingScoreboard!$D4=MIN(BettingScoreboard!$D$2:$D$9),Scorecards!$E$40/BettingScoreboard!$D$10),IF(BettingScoreboard!$E4=MIN(BettingScoreboard!$E$2:$E$9),Scorecards!$E$54/BettingScoreboard!$E$10)) -> #ERROR! | H4: =-1*IF(WeekendLongBets!B5="Y",WeekendLongBets!$B$1,0) -> -10 | I4: =IF(BettingScoreboard!B16=MIN(BettingScoreboard!$B$14:$B$21),WeekendLongBets!$B$11/BettingScoreboard!$B$22, 0) -> #ERROR! | J4: =-1*IF(WeekendLongBets!C5="Y",WeekendLongBets!$C$1,0) -> 0 | K4: =IF(BettingScoreboard!E16=MIN(BettingScoreboard!$E$14:$E$21),WeekendLongBets!$C$11/BettingScoreboard!$E$22, 0) -> #ERROR! | L4: =SUM(B4:K4) -> #ERROR!
A5: Eric Olson | B5: =-1*SUM(IF(Scorecards!C7="Y",Scorecards!$C$2, 0),IF(Scorecards!C21="Y",Scorecards!$C$16,0),IF(Scorecards!C35="Y",Scorecards!$C$30,0),IF(Scorecards!C49="Y",Scorecards!$C$44,0)) -> -20 | C5: =BettingScoreboard!C28 -> 17.361111 | D5: =-1*SUM(IF(Scorecards!D7="Y",Scorecards!$D$2, 0),IF(Scorecards!D21="Y",Scorecards!$D$16,0),IF(Scorecards!D35="Y",Scorecards!$D$30,0),IF(Scorecards!D49="Y",Scorecards!$D$44,0)) -> 0 | E5: =BettingScoreboard!E28 -> 0 | F5: =-1*SUM(IF(Scorecards!E7="Y",Scorecards!$E$2, 0),IF(Scorecards!E21="Y",Scorecards!$E$16,0),IF(Scorecards!E35="Y",Scorecards!$E$30,0),IF(Scorecards!E49="Y",Scorecards!$E$44,0)) -> 0 | G5: =SUM(IF(BettingScoreboard!$B5=MIN(BettingScoreboard!$B$2:$B$9),Scorecards!$E$12/BettingScoreboard!$B$10),IF(BettingScoreboard!$C5=MIN(BettingScoreboard!$C$2:$C$9),Scorecards!$E$26/BettingScoreboard!$C$10), IF(BettingScoreboard!$D5=MIN(BettingScoreboard!$D$2:$D$9),Scorecards!$E$40/BettingScoreboard!$D$10),IF(BettingScoreboard!$E5=MIN(BettingScoreboard!$E$2:$E$9),Scorecards!$E$54/BettingScoreboard!$E$10)) -> #ERROR! | H5: =-1*IF(WeekendLongBets!B6="Y",WeekendLongBets!$B$1,0) -> -10 | I5: =IF(BettingScoreboard!B17=MIN(BettingScoreboard!$B$14:$B$21),WeekendLongBets!$B$11/BettingScoreboard!$B$22, 0) -> #ERROR! | J5: =-1*IF(WeekendLongBets!C6="Y",WeekendLongBets!$C$1,0) -> 0 | K5: =IF(BettingScoreboard!E17=MIN(BettingScoreboard!$E$14:$E$21),WeekendLongBets!$C$11/BettingScoreboard!$E$22, 0) -> #ERROR! | L5: =SUM(B5:K5) -> #ERROR!
A6: Matt Vigo | B6: =-1*SUM(IF(Scorecards!C8="Y",Scorecards!$C$2, 0),IF(Scorecards!C22="Y",Scorecards!$C$16,0),IF(Scorecards!C36="Y",Scorecards!$C$30,0),IF(Scorecards!C50="Y",Scorecards!$C$44,0)) -> -20 | C6: =BettingScoreboard!C29 -> 49.166667 | D6: =-1*SUM(IF(Scorecards!D8="Y",Scorecards!$D$2, 0),IF(Scorecards!D22="Y",Scorecards!$D$16,0),IF(Scorecards!D36="Y",Scorecards!$D$30,0),IF(Scorecards!D50="Y",Scorecards!$D$44,0)) -> 0 | E6: =BettingScoreboard!E29 -> 0 | F6: =-1*SUM(IF(Scorecards!E8="Y",Scorecards!$E$2, 0),IF(Scorecards!E22="Y",Scorecards!$E$16,0),IF(Scorecards!E36="Y",Scorecards!$E$30,0),IF(Scorecards!E50="Y",Scorecards!$E$44,0)) -> 0 | G6: =SUM(IF(BettingScoreboard!$B6=MIN(BettingScoreboard!$B$2:$B$9),Scorecards!$E$12/BettingScoreboard!$B$10),IF(BettingScoreboard!$C6=MIN(BettingScoreboard!$C$2:$C$9),Scorecards!$E$26/BettingScoreboard!$C$10), IF(BettingScoreboard!$D6=MIN(BettingScoreboard!$D$2:$D$9),Scorecards!$E$40/BettingScoreboard!$D$10),IF(BettingScoreboard!$E6=MIN(BettingScoreboard!$E$2:$E$9),Scorecards!$E$54/BettingScoreboard!$E$10)) -> #ERROR! | H6: =-1*IF(WeekendLongBets!B7="Y",WeekendLongBets!$B$1,0) -> -10 | I6: =IF(BettingScoreboard!B18=MIN(BettingScoreboard!$B$14:$B$21),WeekendLongBets!$B$11/BettingScoreboard!$B$22, 0) -> #ERROR! | J6: =-1*IF(WeekendLongBets!C7="Y",WeekendLongBets!$C$1,0) -> 0 | K6: =IF(BettingScoreboard!E18=MIN(BettingScoreboard!$E$14:$E$21),WeekendLongBets!$C$11/BettingScoreboard!$E$22, 0) -> #ERROR! | L6: =SUM(B6:K6) -> #ERROR!
A7: Scott Rhoades | B7: =-1*SUM(IF(Scorecards!C9="Y",Scorecards!$C$2, 0),IF(Scorecards!C23="Y",Scorecards!$C$16,0),IF(Scorecards!C37="Y",Scorecards!$C$30,0),IF(Scorecards!C51="Y",Scorecards!$C$44,0)) -> 0 | C7: =BettingScoreboard!C30 -> 0 | D7: =-1*SUM(IF(Scorecards!D9="Y",Scorecards!$D$2, 0),IF(Scorecards!D23="Y",Scorecards!$D$16,0),IF(Scorecards!D37="Y",Scorecards!$D$30,0),IF(Scorecards!D51="Y",Scorecards!$D$44,0)) -> 0 | E7: =BettingScoreboard!E30 -> 0 | F7: =-1*SUM(IF(Scorecards!E9="Y",Scorecards!$E$2, 0),IF(Scorecards!E23="Y",Scorecards!$E$16,0),IF(Scorecards!E37="Y",Scorecards!$E$30,0),IF(Scorecards!E51="Y",Scorecards!$E$44,0)) -> 0 | G7: =SUM(IF(BettingScoreboard!$B7=MIN(BettingScoreboard!$B$2:$B$9),Scorecards!$E$12/BettingScoreboard!$B$10),IF(BettingScoreboard!$C7=MIN(BettingScoreboard!$C$2:$C$9),Scorecards!$E$26/BettingScoreboard!$C$10), IF(BettingScoreboard!$D7=MIN(BettingScoreboard!$D$2:$D$9),Scorecards!$E$40/BettingScoreboard!$D$10),IF(BettingScoreboard!$E7=MIN(BettingScoreboard!$E$2:$E$9),Scorecards!$E$54/BettingScoreboard!$E$10)) -> #ERROR! | H7: =-1*IF(WeekendLongBets!B8="Y",WeekendLongBets!$B$1,0) -> -10 | I7: =IF(BettingScoreboard!B19=MIN(BettingScoreboard!$B$14:$B$21),WeekendLongBets!$B$11/BettingScoreboard!$B$22, 0) -> #ERROR! | J7: =-1*IF(WeekendLongBets!C8="Y",WeekendLongBets!$C$1,0) -> 0 | K7: =IF(BettingScoreboard!E19=MIN(BettingScoreboard!$E$14:$E$21),WeekendLongBets!$C$11/BettingScoreboard!$E$22, 0) -> #ERROR! | L7: =SUM(B7:K7) -> #ERROR!
A13: skins | B13: 40
A14: skins buy in | B14: 100
A15: skins per | B15: =B14/B13 -> 2.5
A16: AJ | B16: 1 | C16: =B16*2.5 -> 2.5 | D16: =20-C16 -> 17.5
A17: BB | B17: 5 | C17: =B17*2.5 -> 12.5 | D17: =20-C17 -> 7.5
A18: BK | B18: 7 | C18: =B18*2.5 -> 17.5 | D18: =20-C18 -> 2.5
A19: EO | B19: 7 | C19: =B19*2.5 -> 17.5 | D19: =20-C19 -> 2.5
A20: SR | B20: 20 | C20: =B20*2.5 -> 50
