Workbook
Name SkinsGrossPerRound: 'Betting SETUP'!$J$6:$J$13
Name SkinsNetCumulative: 'Betting SETUP'!$I$6:$I$13
Name Round4Scores: Scorecards!$A$46:$Y$53
Name Round2Scores: Scorecards!$A$18:$Y$25
Name SkinsGrossCumulative: 'Betting SETUP'!$H$6:$H$13
Name ScoresRankFirst: 'Score Calcuations'!$A$3:$N$10
Name CTP: 'Betting SETUP'!$L$6:$L$13
Name ScoresFullNameFirst: 'Score Calcuations'!$B$3:$N$10
Name Round1Scores: Scorecards!$A$4:$Y$11
Name PlayersInitials: 'Players and Handis SETUP'!$A$3:$A$10
Name SkinsNetPerRound: 'Betting SETUP'!$K$6:$K$13
Name HandiFromTracker: 'Handis From Tracker'!$A$1:$B$9
Name ScoresInitialsFirst: 'Score Calcuations'!$D$3:$N$10
Name PlayersNames: 'Players and Handis SETUP'!$C$3:$C$10
Name BettingSetup: 'Betting SETUP'!$A$6:$L$13
Name CumulativeNetScores: 'Score Calcuations'!$N$3:$N$10
Name PlayersAndHandis: 'Players and Handis SETUP'!$A$3:$G$10
Name CumulativeGrossScores: 'Score Calcuations'!$M$3:$M$10
Name Round3Scores: Scorecards!$A$32:$Y$39

Sheet LEADERBOARD
A1: 2019 WANNABE CUP
A2: POS | B2: SCORE | C2: TO PAR | D2: PLAYER | E2: =Scorecards!C1 -> TULLYMORE | F2: =Scorecards!C15 -> ST IVES | G2: =Scorecards!C29 -> TULLYMORE | H2: =Scorecards!C43 -> ST IVES
A3: =VLOOKUP(D3,ScoresFullNameFirst,2,FALSE) -> 1 | B3: =VLOOKUP(D3,ScoresFullNameFirst,12,FALSE) -> 328 | C3: =SUM((IF(E3="",0,Scorecards!$X$3-E3)),(IF(F3="",0,Scorecards!$X$17-F3)),(IF(G3="",0,Scorecards!$X$31-G3)),(IF(H3="",0,Scorecards!$X$45-H3)))*-1 -> 12 | D3: =VLOOKUP((ROW()-2),ScoresRankFirst,2,FALSE) -> Scott R | E3: =VLOOKUP(D3,ScoresFullNameFirst,5,FALSE) -> 73 | F3: =VLOOKUP(D3,ScoresFullNameFirst,7,FALSE) -> 76 | G3: =VLOOKUP(D3,ScoresFullNameFirst,9,FALSE) -> 74 | H3: =VLOOKUP(D3,ScoresFullNameFirst,11,FALSE) -> 77
A4: =VLOOKUP(D4,ScoresFullNameFirst,2,FALSE) -> 2 | B4: =VLOOKUP(D4,ScoresFullNameFirst,12,FALSE) -> 365 | C4: =SUM((IF(E4="",0,Scorecards!$X$3-E4)),(IF(F4="",0,Scorecards!$X$17-F4)),(IF(G4="",0,Scorecards!$X$31-G4)),(IF(H4="",0,Scorecards!$X$45-H4)))*-1 -> 17 | D4: =VLOOKUP((ROW()-2),ScoresRankFirst,2,FALSE) -> Brian K | E4: =VLOOKUP(D4,ScoresFullNameFirst,5,FALSE) -> 84 | F4: =VLOOKUP(D4,ScoresFullNameFirst,7,FALSE) -> 71 | G4: =VLOOKUP(D4,ScoresFullNameFirst,9,FALSE) -> 78 | H4: =VLOOKUP(D4,ScoresFullNameFirst,11,FALSE) -> 72
A5: =VLOOKUP(D5,ScoresFullNameFirst,2,FALSE) -> 3 | B5: =VLOOKUP(D5,ScoresFullNameFirst,12,FALSE) -> 344 | C5: =SUM((IF(E5="",0,Scorecards!$X$3-E5)),(IF(F5="",0,Scorecards!$X$17-F5)),(IF(G5="",0,Scorecards!$X$31-G5)),(IF(H5="",0,Scorecards!$X$45-H5)))*-1 -> 28 | D5: =VLOOKUP((ROW()-2),ScoresRankFirst,2,FALSE) -> Aaron J | E5: =VLOOKUP(D5,ScoresFullNameFirst,5,FALSE) -> 84 | F5: =VLOOKUP(D5,ScoresFullNameFirst,7,FALSE) -> 74 | G5: =VLOOKUP(D5,ScoresFullNameFirst,9,FALSE) -> 73 | H5: =VLOOKUP(D5,ScoresFullNameFirst,11,FALSE) -> 85
A6: =VLOOKUP(D6,ScoresFullNameFirst,2,FALSE) -> 4 | B6: =VLOOKUP(D6,ScoresFullNameFirst,12,FALSE) -> 373 | C6: =SUM((IF(E6="",0,Scorecards!$X$3-E6)),(IF(F6="",0,Scorecards!$X$17-F6)),(IF(G6="",0,Scorecards!$X$31-G6)),(IF(H6="",0,Scorecards!$X$45-H6)))*-1 -> 37 | D6: =VLOOKUP((ROW()-2),ScoresRankFirst,2,FALSE) -> John C | E6: =VLOOKUP(D6,ScoresFullNameFirst,5,FALSE) -> 79 | F6: =VLOOKUP(D6,ScoresFullNameFirst,7,FALSE) -> 81 | G6: =VLOOKUP(D6,ScoresFullNameFirst,9,FALSE) -> 91 | H6: =VLOOKUP(D6,ScoresFullNameFirst,11,FALSE) -> 74
A7: =VLOOKUP(D7,ScoresFullNameFirst,2,FALSE) -> 5 | B7: =VLOOKUP(D7,ScoresFullNameFirst,12,FALSE) -> 399 | C7: =SUM((IF(E7="",0,Scorecards!$X$3-E7)),(IF(F7="",0,Scorecards!$X$17-F7)),(IF(G7="",0,Scorecards!$X$31-G7)),(IF(H7="",0,Scorecards!$X$45-H7)))*-1 -> 43 | D7: =VLOOKUP((ROW()-2),ScoresRankFirst,2,FALSE) -> Eric O | E7: =VLOOKUP(D7,ScoresFullNameFirst,5,FALSE) -> 84 | F7: =VLOOKUP(D7,ScoresFullNameFirst,7,FALSE) -> 84 | G7: =VLOOKUP(D7,ScoresFullNameFirst,9,FALSE) -> 77 | H7: =VLOOKUP(D7,ScoresFullNameFirst,11,FALSE) -> 86
A8: =VLOOKUP(D8,ScoresFullNameFirst,2,FALSE) -> 6 | B8: =VLOOKUP(D8,ScoresFullNameFirst,12,FALSE) -> 396 | C8: =SUM((IF(E8="",0,Scorecards!$X$3-E8)),(IF(F8="",0,Scorecards!$X$17-F8)),(IF(G8="",0,Scorecards!$X$31-G8)),(IF(H8="",0,Scorecards!$X$45-H8)))*-1 -> 48 | D8: =VLOOKUP((ROW()-2),ScoresRankFirst,2,FALSE) -> Bob B | E8: =VLOOKUP(D8,ScoresFullNameFirst,5,FALSE) -> 76 | F8: =VLOOKUP(D8,ScoresFullNameFirst,7,FALSE) -> 80 | G8: =VLOOKUP(D8,ScoresFullNameFirst,9,FALSE) -> 94 | H8: =VLOOKUP(D8,ScoresFullNameFirst,11,FALSE) -> 86
A9: =VLOOKUP(D9,ScoresFullNameFirst,2,FALSE) -> 6 | B9: =VLOOKUP(D9,ScoresFullNameFirst,12,FALSE) -> 396 | C9: =SUM((IF(E9="",0,Scorecards!$X$3-E9)),(IF(F9="",0,Scorecards!$X$17-F9)),(IF(G9="",0,Scorecards!$X$31-G9)),(IF(H9="",0,Scorecards!$X$45-H9)))*-1 -> 48 | D9: =VLOOKUP((ROW()-2),ScoresRankFirst,2,FALSE) -> Jeff B | E9: =VLOOKUP(D9,ScoresFullNameFirst,5,FALSE) -> 77 | F9: =VLOOKUP(D9,ScoresFullNameFirst,7,FALSE) -> 84 | G9: =VLOOKUP(D9,ScoresFullNameFirst,9,FALSE) -> 89 | H9: =VLOOKUP(D9,ScoresFullNameFirst,11,FALSE) -> 86
A10: =VLOOKUP(D10,ScoresFullNameFirst,2,FALSE) -> 8 | B10: =VLOOKUP(D10,ScoresFullNameFirst,12,FALSE) -> 402 | C10: =SUM((IF(E10="",0,Scorecards!$X$3-E10)),(IF(F10="",0,Scorecards!$X$17-F10)),(IF(G10="",0,Scorecards!$X$31-G10)),(IF(H10="",0,Scorecards!$X$45-H10)))*-1 -> 50 | D10: =VLOOKUP((ROW()-2),ScoresRankFirst,2,FALSE) -> Andy V | E10: =VLOOKUP(D10,ScoresFullNameFirst,5,FALSE) -> 82 | F10: =VLOOKUP(D10,ScoresFullNameFirst,7,FALSE) -> 84 | G10: =VLOOKUP(D10,ScoresFullNameFirst,9,FALSE) -> 95 | H10: =VLOOKUP(D10,ScoresFullNameFirst,11,FALSE) -> 77

Sheet Scorecards
C1: ='Players and Handis SETUP'!D1 -> TULLYMORE | X1: 71.2 | Y1: 141
C2: Hole | D2: 1 | E2: 2 | F2: 3 | G2: 4 | H2: 5 | I2: 6 | J2: 7 | K2: 8 | L2: 9 | M2: 10 | N2: 11 | O2: 12 | P2: 13 | Q2: 14 | R2: 15 | S2: 16 | T2: 17 | U2: 18 | V2: OUT | W2: IN | X2: TOTAL | Y2: NET
A3: Player | B3: Handi | C3: Par | D3: 5 | E3: 4 | F3: 4 | G3: 3 | H3: 3 | I3: 4 | J3: 3 | K3: 5 | L3: 4 | M3: 4 | N3: 4 | O3: 3 | P3: 5 | Q3: 4 | R3: 3 | S3: 5 | T3: 4 | U3: 5 | V3: =SUM(D3:L3) -> 35 | W3: =SUM(M3:U3) -> 37 | X3: =V3+W3 -> 72
A4: AJ | B4: 7 | D4: 5 | E4: 5 | F4: 5 | G4: 5 | H4: 3 | I4: 4 | J4: 3 | K4: 6 | L4: 4 | M4: 7 | N4: 5 | O4: 5 | P4: 7 | Q4: 4 | R4: 4 | S4: 6 | T4: 6 | U4: 7 | V4: =SUM(D4:L4) -> 40 | W4: =SUM(M4:U4) -> 51 | X4: =IF(W4>0,V4+W4,"") -> 91 | Y4: =IF(W4=0,"",X4-B4) -> 84
A5: AV | B5: 16 | D5: 6 | E5: 6 | F5: 4 | G5: 6 | H5: 4 | I5: 7 | J5: 3 | K5: 6 | L5: 7 | M5: 5 | N5: 5 | O5: 4 | P5: 8 | Q5: 4 | R5: 4 | S5: 8 | T5: 4 | U5: 7 | V5: =SUM(D5:L5) -> 49 | W5: =SUM(M5:U5) -> 49 | X5: =IF(W5>0,V5+W5,"") -> 98 | Y5: =IF(W5=0,"",X5-B5) -> 82
A6: BB | B6: 15 | D6: 6 | E6: 6 | F6: 6 | G6: 4 | H6: 4 | I6: 5 | J6: 3 | K6: 6 | L6: 7 | M6: 5 | N6: 5 | O6: 3 | P6: 7 | Q6: 4 | R6: 3 | S6: 6 | T6: 4 | U6: 7 | V6: =SUM(D6:L6) -> 47 | W6: =SUM(M6:U6) -> 44 | X6: =IF(W6>0,V6+W6,"") -> 91 | Y6: =IF(W6=0,"",X6-B6) -> 76
A7: BK | B7: 15 | D7: 8 | E7: 7 | F7: 8 | G7: 4 | H7: 4 | I7: 5 | J7: 3 | K7: 8 | L7: 5 | M7: 10 | N7: 5 | O7: 2 | P7: 6 | Q7: 5 | R7: 4 | S7: 4 | T7: 6 | U7: 5 | V7: =SUM(D7:L7) -> 52 | W7: =SUM(M7:U7) -> 47 | X7: =IF(W7>0,V7+W7,"") -> 99 | Y7: =IF(W7=0,"",X7-B7) -> 84
A8: EO | B8: 17 | D8: 7 | E8: 6 | F8: 8 | G8: 4 | H8: 4 | I8: 7 | J8: 7 | K8: 6 | L8: 3 | M8: 4 | N8: 5 | O8: 4 | P8: 5 | Q8: 6 | R8: 5 | S8: 7 | T8: 7 | U8: 6 | V8: =SUM(D8:L8) -> 52 | W8: =SUM(M8:U8) -> 49 | X8: =IF(W8>0,V8+W8,"") -> 101 | Y8: =IF(W8=0,"",X8-B8) -> 84
A9: JB | B9: 15 | D9: 5 | E9: 5 | F9: 5 | G9: 3 | H9: 4 | I9: 4 | J9: 3 | K9: 6 | L9: 4 | M9: 9 | N9: 4 | O9: 4 | P9: 7 | Q9: 7 | R9: 5 | S9: 5 | T9: 6 | U9: 6 | V9: =SUM(D9:L9) -> 39 | W9: =SUM(M9:U9) -> 53 | X9: =IF(W9>0,V9+W9,"") -> 92 | Y9: =IF(W9=0,"",X9-B9) -> 77
A10: JC | B10: 12 | D10: 7 | E10: 5 | F10: 5 | G10: 3 | H10: 3 | I10: 4 | J10: 4 | K10: 7 | L10: 4 | M10: 6 | N10: 5 | O10: 4 | P10: 7 | Q10: 5 | R10: 4 | S10: 6 | T10: 5 | U10: 7 | V10: =SUM(D10:L10) -> 42 | W10: =SUM(M10:U10) -> 49 | X10: =IF(W10>0,V10+W10,"") -> 91 | Y10: =IF(W10=0,"",X10-B10) -> 79
A11: SR | B11: 7 | D11: 6 | E11: 4 | F11: 5 | G11: 4 | H11: 4 | I11: 4 | J11: 3 | K11: 5 | L11: 7 | M11: 5 | N11: 4 | O11: 3 | P11: 6 | Q11: 4 | R11: 3 | S11: 4 | T11: 4 | U11: 5 | V11: =SUM(D11:L11) -> 42 | W11: =SUM(M11:U11) -> 38 | X11: =IF(W11>0,V11+W11,"") -> 80 | Y11: =IF(W11=0,"",X11-B11) -> 73
C12: SKIN | D12: {=IF(OR(SUM(IF(IF(SkinsGrossCumulative="Y", D4:D11, 10)=MIN(IF(SkinsGrossCumulative="Y", D4:D11, 10)), 1, 0)) > 1, MIN(IF(SkinsGrossCumulative="Y", D4:D11, 10)) > D3), "", INDEX(PlayersInitials,MATCH(MIN(IF(SkinsGrossCumulative="Y",D4:D11,10)),IF(SkinsGrossCumulative="Y",D4:D11,10),0)))} | E12: {=IF(OR(SUM(IF(IF(SkinsGrossCumulative="Y", E4:E11, 10)=MIN(IF(SkinsGrossCumulative="Y", E4:E11, 10)), 1, 0)) > 1, MIN(IF(SkinsGrossCumulative="Y", E4:E11, 10)) > E3), "", INDEX(PlayersInitials,MATCH(MIN(IF(SkinsGrossCumulative="Y",E4:E11,10)),IF(SkinsGrossCumulative="Y",E4:E11,10),0)))} -> SR | F12: {=IF(OR(SUM(IF(IF(SkinsGrossCumulative="Y", F4:F11, 10)=MIN(IF(SkinsGrossCumulative="Y", F4:F11, 10)), 1, 0)) > 1, MIN(IF(SkinsGrossCumulative="Y", F4:F11, 10)) > F3), "", INDEX(PlayersInitials,MATCH(MIN(IF(SkinsGrossCumulative="Y",F4:F11,10)),IF(SkinsGrossCumulative="Y",F4:F11,10),0)))} -> AV | G12: {=IF(OR(SUM(IF(IF(SkinsGrossCumulative="Y", G4:G11, 10)=MIN(IF(SkinsGrossCumulative="Y", G4:G11, 10)), 1, 0)) > 1, MIN(IF(SkinsGrossCumulative="Y", G4:G11, 10)) > G3), "", INDEX(PlayersInitials,MATCH(MIN(IF(SkinsGrossCumulative="Y",G4:G11,10)),IF(SkinsGrossCumulative="Y",G4:G11,10),0)))} | H12: {=IF(OR(SUM(IF(IF(SkinsGrossCumulative="Y", H4:H11, 10)=MIN(IF(SkinsGrossCumulative="Y", H4:H11, 10)), 1, 0)) > 1, MIN(IF(SkinsGrossCumulative="Y", H4:H11, 10)) > H3), "", INDEX(PlayersInitials,MATCH(MIN(IF(SkinsGrossCumulative="Y",H4:H11,10)),IF(SkinsGrossCumulative="Y",H4:H11,10),0)))} | I12: {=IF(OR(SUM(IF(IF(SkinsGrossCumulative="Y", I4:I11, 10)=MIN(IF(SkinsGrossCumulative="Y", I4:I11, 10)), 1, 0)) > 1, MIN(IF(SkinsGrossCumulative="Y", I4:I11, 10)) > I3), "", INDEX(PlayersInitials,MATCH(MIN(IF(SkinsGrossCumulative="Y",I4:I11,10)),IF(SkinsGrossCumulative="Y",I4:I11,10),0)))} | J12: {=IF(OR(SUM(IF(IF(SkinsGrossCumulative="Y", J4:J11, 10)=MIN(IF(SkinsGrossCumulative="Y", J4:J11, 10)), 1, 0)) > 1, MIN(IF(SkinsGrossCumulative="Y", J4:J11, 10)) > J3), "", INDEX(PlayersInitials,MATCH(MIN(IF(SkinsGrossCumulative="Y",J4:J11,10)),IF(SkinsGrossCumulative="Y",J4:J11,10),0)))} | K12: {=IF(OR(SUM(IF(IF(SkinsGrossCumulative="Y", K4:K11, 10)=MIN(IF(SkinsGrossCumulative="Y", K4:K11, 10)), 1, 0)) > 1, MIN(IF(SkinsGrossCumulative="Y", K4:K11, 10)) > K3), "", INDEX(PlayersInitials,MATCH(MIN(IF(SkinsGrossCumulative="Y",K4:K11,10)),IF(SkinsGrossCumulative="Y",K4:K11,10),0)))} -> SR | ... U12: {=IF(OR(SUM(IF(IF(SkinsGrossCumulative="Y", U4:U11, 10)=MIN(IF(SkinsGrossCumulative="Y", U4:U11, 10)), 1, 0)) > 1, MIN(IF(SkinsGrossCumulative="Y", U4:U11, 10)) > U3), "", INDEX(PlayersInitials,MATCH(MIN(IF(SkinsGrossCumulative="Y",U4:U11,10)),IF(SkinsGrossCumulative="Y",U4:U11,10),0)))} | X12: =18-COUNTBLANK(D12:U12) -> 7
C13: CTP | V13: =countif(D3:L3,3) -> 3 | W13: =countif(M3:U3,3) -> 2 | X13: =COUNTA(D13:U13) -> 0
C15: ='Players and Handis SETUP'!E1 -> ST IVES | X15: 70.5 | Y15: 141
C16: Hole | D16: 1 | E16: 2 | F16: 3 | G16: 4 | H16: 5 | I16: 6 | J16: 7 | K16: 8 | L16: 9 | M16: 10 | N16: 11 | O16: 12 | P16: 13 | Q16: 14 | R16: 15 | S16: 16 | T16: 17 | U16: 18 | V16: OUT | W16: IN | X16: TOTAL | Y16: NET
A17: Player | B17: Handi | C17: Par | D17: 4 | E17: 3 | F17: 4 | G17: 5 | H17: 4 | I17: 4 | J17: 5 | K17: 3 | L17: 4 | M17: 4 | N17: 5 | O17: 4 | P17: 3 | Q17: 4 | R17: 4 | S17: 3 | T17: 5 | U17: 4 | V17: =SUM(D17:L17) -> 36 | W17: =SUM(M17:U17) -> 36 | X17: =V17+W17 -> 72
A18: AJ | B18: 7 | D18: 7 | E18: 3 | F18: 6 | G18: 6 | H18: 4 | I18: 3 | J18: 4 | K18: 3 | L18: 4 | M18: 4 | N18: 5 | O18: 5 | P18: 4 | Q18: 5 | R18: 4 | S18: 4 | T18: 5 | U18: 5 | V18: =SUM(D18:L18) -> 40 | W18: =SUM(M18:U18) -> 41 | X18: =IF(W18>0,V18+W18,"") -> 81 | Y18: =IF(W18=0,"",X18-B18) -> 74
A19: AV | B19: 16 | D19: 7 | E19: 4 | F19: 6 | G19: 7 | H19: 7 | I19: 4 | J19: 8 | K19: 4 | L19: 4 | M19: 4 | N19: 7 | O19: 5 | P19: 5 | Q19: 6 | R19: 6 | S19: 3 | T19: 6 | U19: 7 | V19: =SUM(D19:L19) -> 51 | W19: =SUM(M19:U19) -> 49 | X19: =IF(W19>0,V19+W19,"") -> 100 | Y19: =IF(W19=0,"",X19-B19) -> 84
A20: BB | B20: 15 | D20: 7 | E20: 4 | F20: 7 | G20: 5 | H20: 4 | I20: 5 | J20: 7 | K20: 4 | L20: 6 | M20: 5 | N20: 6 | O20: 5 | P20: 3 | Q20: 6 | R20: 5 | S20: 4 | T20: 6 | U20: 6 | V20: =SUM(D20:L20) -> 49 | W20: =SUM(M20:U20) -> 46 | X20: =IF(W20>0,V20+W20,"") -> 95 | Y20: =IF(W20=0,"",X20-B20) -> 80
A21: BK | B21: 15 | D21: 6 | E21: 3 | F21: 3 | G21: 5 | H21: 4 | I21: 4 | J21: 7 | K21: 5 | L21: 4 | M21: 5 | N21: 8 | O21: 5 | P21: 3 | Q21: 5 | R21: 4 | S21: 3 | T21: 7 | U21: 5 | V21: =SUM(D21:L21) -> 41 | W21: =SUM(M21:U21) -> 45 | X21: =IF(W21>0,V21+W21,"") -> 86 | Y21: =IF(W21=0,"",X21-B21) -> 71
A22: EO | B22: 17 | D22: 9 | E22: 6 | F22: 5 | G22: 7 | H22: 5 | I22: 5 | J22: 5 | K22: 3 | L22: 5 | M22: 4 | N22: 8 | O22: 6 | P22: 4 | Q22: 8 | R22: 5 | S22: 4 | T22: 7 | U22: 5 | V22: =SUM(D22:L22) -> 50 | W22: =SUM(M22:U22) -> 51 | X22: =IF(W22>0,V22+W22,"") -> 101 | Y22: =IF(W22=0,"",X22-B22) -> 84
A23: JB | B23: 15 | D23: 5 | E23: 6 | F23: 6 | G23: 7 | H23: 7 | I23: 6 | J23: 5 | K23: 4 | L23: 4 | M23: 5 | N23: 6 | O23: 5 | P23: 5 | Q23: 6 | R23: 7 | S23: 4 | T23: 5 | U23: 6 | V23: =SUM(D23:L23) -> 50 | W23: =SUM(M23:U23) -> 49 | X23: =IF(W23>0,V23+W23,"") -> 99 | Y23: =IF(W23=0,"",X23-B23) -> 84
A24: JC | B24: 12 | D24: 5 | E24: 6 | F24: 8 | G24: 6 | H24: 6 | I24: 5 | J24: 6 | K24: 4 | L24: 6 | M24: 6 | N24: 5 | O24: 4 | P24: 5 | Q24: 5 | R24: 5 | S24: 3 | T24: 5 | U24: 3 | V24: =SUM(D24:L24) -> 52 | W24: =SUM(M24:U24) -> 41 | X24: =IF(W24>0,V24+W24,"") -> 93 | Y24: =IF(W24=0,"",X24-B24) -> 81
A25: SR | B25: 7 | D25: 5 | E25: 3 | F25: 6 | G25: 5 | H25: 5 | I25: 5 | J25: 7 | K25: 3 | L25: 4 | M25: 4 | N25: 5 | O25: 5 | P25: 4 | Q25: 5 | R25: 4 | S25: 3 | T25: 5 | U25: 5 | V25: =SUM(D25:L25) -> 43 | W25: =SUM(M25:U25) -> 40 | X25: =IF(W25>0,V25+W25,"") -> 83 | Y25: =IF(W25=0,"",X25-B25) -> 76
C26: SKIN | D26: {=IF(OR(SUM(IF(IF(SkinsGrossCumulative="Y", D18:D25, 10)=MIN(IF(SkinsGrossCumulative="Y", D18:D25, 10)), 1, 0)) > 1, MIN(IF(SkinsGrossCumulative="Y", D18:D25, 10)) > D17), "", INDEX(PlayersInitials,MATCH(MIN(IF(SkinsGrossCumulative="Y",D18:D25,10)),IF(SkinsGrossCumulative="Y",D18:D25,10),0)))} | E26: {=IF(OR(SUM(IF(IF(SkinsGrossCumulative="Y", E18:E25, 10)=MIN(IF(SkinsGrossCumulative="Y", E18:E25, 10)), 1, 0)) > 1, MIN(IF(SkinsGrossCumulative="Y", E18:E25, 10)) > E17), "", INDEX(PlayersInitials,MATCH(MIN(IF(SkinsGrossCumulative="Y",E18:E25,10)),IF(SkinsGrossCumulative="Y",E18:E25,10),0)))} | F26: {=IF(OR(SUM(IF(IF(SkinsGrossCumulative="Y", F18:F25, 10)=MIN(IF(SkinsGrossCumulative="Y", F18:F25, 10)), 1, 0)) > 1, MIN(IF(SkinsGrossCumulative="Y", F18:F25, 10)) > F17), "", INDEX(PlayersInitials,MATCH(MIN(IF(SkinsGrossCumulative="Y",F18:F25,10)),IF(SkinsGrossCumulative="Y",F18:F25,10),0)))} -> BK | G26: {=IF(OR(SUM(IF(IF(SkinsGrossCumulative="Y", G18:G25, 10)=MIN(IF(SkinsGrossCumulative="Y", G18:G25, 10)), 1, 0)) > 1, MIN(IF(SkinsGrossCumulative="Y", G18:G25, 10)) > G17), "", INDEX(PlayersInitials,MATCH(MIN(IF(SkinsGrossCumulative="Y",G18:G25,10)),IF(SkinsGrossCumulative="Y",G18:G25,10),0)))} | H26: {=IF(OR(SUM(IF(IF(SkinsGrossCumulative="Y", H18:H25, 10)=MIN(IF(SkinsGrossCumulative="Y", H18:H25, 10)), 1, 0)) > 1, MIN(IF(SkinsGrossCumulative="Y", H18:H25, 10)) > H17), "", INDEX(PlayersInitials,MATCH(MIN(IF(SkinsGrossCumulative="Y",H18:H25,10)),IF(SkinsGrossCumulative="Y",H18:H25,10),0)))} | I26: {=IF(OR(SUM(IF(IF(SkinsGrossCumulative="Y", I18:I25, 10)=MIN(IF(SkinsGrossCumulative="Y", I18:I25, 10)), 1, 0)) > 1, MIN(IF(SkinsGrossCumulative="Y", I18:I25, 10)) > I17), "", INDEX(PlayersInitials,MATCH(MIN(IF(SkinsGrossCumulative="Y",I18:I25,10)),IF(SkinsGrossCumulative="Y",I18:I25,10),0)))} -> AJ | J26: {=IF(OR(SUM(IF(IF(SkinsGrossCumulative="Y", J18:J25, 10)=MIN(IF(SkinsGrossCumulative="Y", J18:J25, 10)), 1, 0)) > 1, MIN(IF(SkinsGrossCumulative="Y", J18:J25, 10)) > J17), "", INDEX(PlayersInitials,MATCH(MIN(IF(SkinsGrossCumulative="Y",J18:J25,10)),IF(SkinsGrossCumulative="Y",J18:J25,10),0)))} -> AJ | K26: {=IF(OR(SUM(IF(IF(SkinsGrossCumulative="Y", K18:K25, 10)=MIN(IF(SkinsGrossCumulative="Y", K18:K25, 10)), 1, 0)) > 1, MIN(IF(SkinsGrossCumulative="Y", K18:K25, 10)) > K17), "", INDEX(PlayersInitials,MATCH(MIN(IF(SkinsGrossCumulative="Y",K18:K25,10)),IF(SkinsGrossCumulative="Y",K18:K25,10),0)))} | ... U26: {=IF(OR(SUM(IF(IF(SkinsGrossCumulative="Y", U18:U25, 10)=MIN(IF(SkinsGrossCumulative="Y", U18:U25, 10)), 1, 0)) > 1, MIN(IF(SkinsGrossCumulative="Y", U18:U25, 10)) > U17), "", INDEX(PlayersInitials,MATCH(MIN(IF(SkinsGrossCumulative="Y",U18:U25,10)),IF(SkinsGrossCumulative="Y",U18:U25,10),0)))} -> JC | X26: =18-COUNTBLANK(D26:U26) -> 5
C27: CTP | V27: =countif(D17:L17,3) -> 2 | W27: =countif(M17:U17,3) -> 2 | X27: =COUNTA(D27:U27) -> 0
C29: ='Players and Handis SETUP'!F1 -> TULLYMORE | X29: 71.2 | Y29: 141
C30: Hole | D30: 1 | E30: 2 | F30: 3 | G30: 4 | H30: 5 | I30: 6 | J30: 7 | K30: 8 | L30: 9 | M30: 10 | N30: 11 | O30: 12 | P30: 13 | Q30: 14 | R30: 15 | S30: 16 | T30: 17 | U30: 18 | V30: OUT | W30: IN | X30: TOTAL | Y30: NET
A31: Player | B31: Handi | C31: Par | D31: 5 | E31: 4 | F31: 4 | G31: 3 | H31: 3 | I31: 4 | J31: 3 | K31: 5 | L31: 4 | M31: 4 | N31: 4 | O31: 3 | P31: 5 | Q31: 4 | R31: 3 | S31: 5 | T31: 4 | U31: 5 | V31: =SUM(D31:L31) -> 35 | W31: =SUM(M31:U31) -> 37 | X31: =V31+W31 -> 72
A32: AJ | B32: 7 | D32: 6 | E32: 5 | F32: 4 | G32: 3 | H32: 4 | I32: 4 | J32: 4 | K32: 5 | L32: 3 | M32: 4 | N32: 5 | O32: 3 | P32: 5 | Q32: 6 | R32: 3 | S32: 5 | T32: 4 | U32: 7 | V32: =SUM(D32:L32) -> 38 | W32: =SUM(M32:U32) -> 42 | X32: =IF(W32>0,V32+W32,"") -> 80 | Y32: =IF(W32=0,"",X32-B32) -> 73
A33: AV | B33: 16 | D33: 7 | E33: 7 | F33: 7 | G33: 5 | H33: 3 | I33: 16 | J33: 5 | K33: 6 | L33: 5 | M33: 8 | N33: 7 | O33: 3 | P33: 8 | Q33: 3 | R33: 4 | S33: 6 | T33: 4 | U33: 7 | V33: =SUM(D33:L33) -> 61 | W33: =SUM(M33:U33) -> 50 | X33: =IF(W33>0,V33+W33,"") -> 111 | Y33: =IF(W33=0,"",X33-B33) -> 95
A34: BB | B34: 15 | D34: 5 | E34: 6 | F34: 7 | G34: 6 | H34: 7 | I34: 7 | J34: 2 | K34: 7 | L34: 5 | M34: 7 | N34: 5 | O34: 4 | P34: 8 | Q34: 7 | R34: 5 | S34: 8 | T34: 6 | U34: 7 | V34: =SUM(D34:L34) -> 52 | W34: =SUM(M34:U34) -> 57 | X34: =IF(W34>0,V34+W34,"") -> 109 | Y34: =IF(W34=0,"",X34-B34) -> 94
A35: BK | B35: 15 | D35: 7 | E35: 7 | F35: 7 | G35: 3 | H35: 4 | I35: 5 | J35: 4 | K35: 5 | L35: 5 | M35: 4 | N35: 6 | O35: 3 | P35: 6 | Q35: 5 | R35: 3 | S35: 7 | T35: 7 | U35: 5 | V35: =SUM(D35:L35) -> 47 | W35: =SUM(M35:U35) -> 46 | X35: =IF(W35>0,V35+W35,"") -> 93 | Y35: =IF(W35=0,"",X35-B35) -> 78
A36: EO | B36: 17 | D36: 7 | E36: 4 | F36: 4 | G36: 3 | H36: 3 | I36: 5 | J36: 5 | K36: 9 | L36: 4 | M36: 4 | N36: 5 | O36: 5 | P36: 6 | Q36: 7 | R36: 4 | S36: 5 | T36: 6 | U36: 8 | V36: =SUM(D36:L36) -> 44 | W36: =SUM(M36:U36) -> 50 | X36: =IF(W36>0,V36+W36,"") -> 94 | Y36: =IF(W36=0,"",X36-B36) -> 77
A37: JB | B37: 15 | D37: 8 | E37: 7 | F37: 4 | G37: 4 | H37: 3 | I37: 8 | J37: 5 | K37: 5 | L37: 5 | M37: 6 | N37: 6 | O37: 3 | P37: 6 | Q37: 4 | R37: 5 | S37: 5 | T37: 9 | U37: 11 | V37: =SUM(D37:L37) -> 49 | W37: =SUM(M37:U37) -> 55 | X37: =IF(W37>0,V37+W37,"") -> 104 | Y37: =IF(W37=0,"",X37-B37) -> 89
A38: JC | B38: 12 | D38: 7 | E38: 6 | F38: 8 | G38: 5 | H38: 6 | I38: 4 | J38: 4 | K38: 7 | L38: 5 | M38: 9 | N38: 6 | O38: 5 | P38: 5 | Q38: 4 | R38: 3 | S38: 8 | T38: 7 | U38: 4 | V38: =SUM(D38:L38) -> 52 | W38: =SUM(M38:U38) -> 51 | X38: =IF(W38>0,V38+W38,"") -> 103 | Y38: =IF(W38=0,"",X38-B38) -> 91
A39: SR | B39: 7 | D39: 7 | E39: 5 | F39: 4 | G39: 4 | H39: 4 | I39: 4 | J39: 3 | K39: 6 | L39: 4 | M39: 5 | N39: 7 | O39: 3 | P39: 6 | Q39: 3 | R39: 2 | S39: 5 | T39: 4 | U39: 5 | V39: =SUM(D39:L39) -> 41 | W39: =SUM(M39:U39) -> 40 | X39: =IF(W39>0,V39+W39,"") -> 81 | Y39: =IF(W39=0,"",X39-B39) -> 74
C40: SKIN | D40: {=IF(OR(SUM(IF(IF(SkinsGrossCumulative="Y", D32:D39, 10)=MIN(IF(SkinsGrossCumulative="Y", D32:D39, 10)), 1, 0)) > 1, MIN(IF(SkinsGrossCumulative="Y", D32:D39, 10)) > D31), "", INDEX(PlayersInitials,MATCH(MIN(IF(SkinsGrossCumulative="Y",D32:D39,10)),IF(SkinsGrossCumulative="Y",D32:D39,10),0)))} -> BB | E40: {=IF(OR(SUM(IF(IF(SkinsGrossCumulative="Y", E32:E39, 10)=MIN(IF(SkinsGrossCumulative="Y", E32:E39, 10)), 1, 0)) > 1, MIN(IF(SkinsGrossCumulative="Y", E32:E39, 10)) > E31), "", INDEX(PlayersInitials,MATCH(MIN(IF(SkinsGrossCumulative="Y",E32:E39,10)),IF(SkinsGrossCumulative="Y",E32:E39,10),0)))} -> EO | F40: {=IF(OR(SUM(IF(IF(SkinsGrossCumulative="Y", F32:F39, 10)=MIN(IF(SkinsGrossCumulative="Y", F32:F39, 10)), 1, 0)) > 1, MIN(IF(SkinsGrossCumulative="Y", F32:F39, 10)) > F31), "", INDEX(PlayersInitials,MATCH(MIN(IF(SkinsGrossCumulative="Y",F32:F39,10)),IF(SkinsGrossCumulative="Y",F32:F39,10),0)))} | G40: {=IF(OR(SUM(IF(IF(SkinsGrossCumulative="Y", G32:G39, 10)=MIN(IF(SkinsGrossCumulative="Y", G32:G39, 10)), 1, 0)) > 1, MIN(IF(SkinsGrossCumulative="Y", G32:G39, 10)) > G31), "", INDEX(PlayersInitials,MATCH(MIN(IF(SkinsGrossCumulative="Y",G32:G39,10)),IF(SkinsGrossCumulative="Y",G32:G39,10),0)))} | H40: {=IF(OR(SUM(IF(IF(SkinsGrossCumulative="Y", H32:H39, 10)=MIN(IF(SkinsGrossCumulative="Y", H32:H39, 10)), 1, 0)) > 1, MIN(IF(SkinsGrossCumulative="Y", H32:H39, 10)) > H31), "", INDEX(PlayersInitials,MATCH(MIN(IF(SkinsGrossCumulative="Y",H32:H39,10)),IF(SkinsGrossCumulative="Y",H32:H39,10),0)))} | I40: {=IF(OR(SUM(IF(IF(SkinsGrossCumulative="Y", I32:I39, 10)=MIN(IF(SkinsGrossCumulative="Y", I32:I39, 10)), 1, 0)) > 1, MIN(IF(SkinsGrossCumulative="Y", I32:I39, 10)) > I31), "", INDEX(PlayersInitials,MATCH(MIN(IF(SkinsGrossCumulative="Y",I32:I39,10)),IF(SkinsGrossCumulative="Y",I32:I39,10),0)))} | J40: {=IF(OR(SUM(IF(IF(SkinsGrossCumulative="Y", J32:J39, 10)=MIN(IF(SkinsGrossCumulative="Y", J32:J39, 10)), 1, 0)) > 1, MIN(IF(SkinsGrossCumulative="Y", J32:J39, 10)) > J31), "", INDEX(PlayersInitials,MATCH(MIN(IF(SkinsGrossCumulative="Y",J32:J39,10)),IF(SkinsGrossCumulative="Y",J32:J39,10),0)))} -> BB | K40: {=IF(OR(SUM(IF(IF(SkinsGrossCumulative="Y", K32:K39, 10)=MIN(IF(SkinsGrossCumulative="Y", K32:K39, 10)), 1, 0)) > 1, MIN(IF(SkinsGrossCumulative="Y", K32:K39, 10)) > K31), "", INDEX(PlayersInitials,MATCH(MIN(IF(SkinsGrossCumulative="Y",K32:K39,10)),IF(SkinsGrossCumulative="Y",K32:K39,10),0)))} | ... U40: {=IF(OR(SUM(IF(IF(SkinsGrossCumulative="Y", U32:U39, 10)=MIN(IF(SkinsGrossCumulative="Y", U32:U39, 10)), 1, 0)) > 1, MIN(IF(SkinsGrossCumulative="Y", U32:U39, 10)) > U31), "", INDEX(PlayersInitials,MATCH(MIN(IF(SkinsGrossCumulative="Y",U32:U39,10)),IF(SkinsGrossCumulative="Y",U32:U39,10),0)))} -> JC | X40: =18-COUNTBLANK(D40:U40) -> 6
C41: CTP | V41: =countif(D31:L31,3) -> 3 | W41: =countif(M31:U31,3) -> 2 | X41: =COUNTA(D41:U41) -> 0
C43: ='Players and Handis SETUP'!G1 -> ST IVES | X43: 70.5 | Y43: 141
...

Sheet Stock Market
B1: $1 Shares | J1: =sum(J3:J10) -> 160
B2: AJ | C2: AV | D2: BB | E2: BK | F2: EO | G2: JB | H2: JC | I2: SR | J2: TOTAL $1 | L2: FINAL | M2: PAYOUT
A3: Aaron J | B3: 12 | C3: 1 | D3: 1 | E3: 1 | F3: 1 | G3: 1 | H3: 1 | I3: 2 | J3: =sum(B3:I3) -> 20 | L3: Aaron J | M3: =if($A$13="","",if($M$14=0,(($J$1+$J$13)*(N15/$N$23)),if($N$14=0,(($J$1+$J$13)*(M15/$M$23)),(($M$14*M15)+($N$14*N15))))) -> 24.761905
A4: Andy V | B4: 3 | C4: 10 | H4: 5 | I4: 2 | J4: =sum(B4:I4) -> 20 | L4: Andy V | M4: =if($A$13="","",if($M$14=0,(($J$1+$J$13)*(N16/$N$23)),if($N$14=0,(($J$1+$J$13)*(M16/$M$23)),(($M$14*M16)+($N$14*N16))))) -> 11.428571
A5: Bob B | B5: 2 | C5: 2 | D5: 6 | E5: 2 | F5: 2 | G5: 2 | H5: 2 | I5: 2 | J5: =sum(B5:I5) -> 20 | L5: Bob B | M5: =if($A$13="","",if($M$14=0,(($J$1+$J$13)*(N17/$N$23)),if($N$14=0,(($J$1+$J$13)*(M17/$M$23)),(($M$14*M17)+($N$14*N17))))) -> 19.761905
A6: Brian K | B6: 5 | D6: 5 | E6: 10 | J6: =sum(B6:I6) -> 20 | L6: Brian K | M6: =if($A$13="","",if($M$14=0,(($J$1+$J$13)*(N18/$N$23)),if($N$14=0,(($J$1+$J$13)*(M18/$M$23)),(($M$14*M18)+($N$14*N18))))) -> 0
A7: Eric O | B7: 2 | D7: 1 | E7: 4 | F7: 8 | H7: 3 | I7: 2 | J7: =sum(B7:I7) -> 20 | L7: Eric O | M7: =if($A$13="","",if($M$14=0,(($J$1+$J$13)*(N19/$N$23)),if($N$14=0,(($J$1+$J$13)*(M19/$M$23)),(($M$14*M19)+($N$14*N19))))) -> 11.428571
A8: Jeff B | G8: 20 | J8: =sum(B8:I8) -> 20 | L8: Jeff B | M8: =if($A$13="","",if($M$14=0,(($J$1+$J$13)*(N20/$N$23)),if($N$14=0,(($J$1+$J$13)*(M20/$M$23)),(($M$14*M20)+($N$14*N20))))) -> 8.3333333
A9: John C | B9: 5 | E9: 5 | H9: 10 | J9: =sum(B9:I9) -> 20 | L9: John C | M9: =if($A$13="","",if($M$14=0,(($J$1+$J$13)*(N21/$N$23)),if($N$14=0,(($J$1+$J$13)*(M21/$M$23)),(($M$14*M21)+($N$14*N21))))) -> 8.3333333
A10: Scott R | I10: 20 | J10: =sum(B10:I10) -> 20 | L10: Scott R | M10: =if($A$13="","",if($M$14=0,(($J$1+$J$13)*(N22/$N$23)),if($N$14=0,(($J$1+$J$13)*(M22/$M$23)),(($M$14*M22)+($N$14*N22))))) -> 130.95238
B11: =SUM(B3:B10) -> 29 | C11: =SUM(C3:C10) -> 13 | D11: =SUM(D3:D10) -> 13 | E11: =SUM(E3:E10) -> 22 | F11: =SUM(F3:F10) -> 11 | G11: =SUM(G3:G10) -> 23 | H11: =SUM(H3:H10) -> 21 | I11: =SUM(I3:I10) -> 28 | J11: =sum(B11:I11) -> 160
A12: WBC Winner
A13: SR | B13: $2 Shares | J13: =sum(J15:J22) -> 55 | M13: $1 winners | N13: $2 winners
B14: AJ | C14: AV | D14: BB | E14: BK | F14: EO | G14: JB | H14: JC | I14: SR | J14: TOTAL $2 | M14: =if(M23="TBD","TBD",if(M23=0,0,J11/M23)) -> 5.7142857 | N14: =if(N23="TBD","TBD",if($N$23=0,0,(J23/N23))) -> 1.6666667
A15: Aaron J | D15: 2 | I15: 8 | J15: =sum(B15:I15) -> 10 | L15: Aaron J | M15: =if($A$13="","",if($A$13=B$2,(vlookup(L15,$A$3:$I$10,2,FALSE)),if($A$13=C$2,(vlookup(L15,$A$3:$I$10,3,FALSE)),if($A$13=D$2,(vlookup(L15,$A$3:$I$10,4,FALSE)),if($A$13=E$2,(vlookup(L15,$A$3:$I$10,5,FALSE)),if($A$13=F$2,(vlookup(L15,$A$3:$I$10,6,FALSE)),if($A$13=G$2,(vlookup(L15,$A$3:$I$10,7,FALSE)),if($A$13=H$2,(vlookup(L15,$A$3:$I$10,8,FALSE)),if($A$13=I$2,(vlookup(L15,$A$3:$I$10,9,FALSE)),0))))))))) -> 2 | N15: =if($A$13="","",if($A$13=B$14,(vlookup($L15,$A$15:$I$22,2,FALSE)),if($A$13=C$14,(vlookup($L15,$A$15:$I$22,3,FALSE)),if($A$13=D$14,(vlookup($L15,$A$15:$I$22,4,FALSE)),if($A$13=E$14,(vlookup($L15,$A$15:$I$22,5,FALSE)),if($A$13=F$14,(vlookup($L15,$A$15:$I$22,6,FALSE)),if($A$13=G$14,(vlookup($L15,$A$15:$I$22,7,FALSE)),if($A$13=H$14,(vlookup($L15,$A$15:$I$22,8,FALSE)), if($A$13=I$14,(vlookup($L15,$A$15:$I$22,9,FALSE))))))))))) -> 8
A16: Andy V | J16: =sum(B16:I16) -> 0 | L16: Andy V | M16: =if($A$13="","",if($A$13=B$2,(vlookup(L16,$A$3:$I$10,2,FALSE)),if($A$13=C$2,(vlookup(L16,$A$3:$I$10,3,FALSE)),if($A$13=D$2,(vlookup(L16,$A$3:$I$10,4,FALSE)),if($A$13=E$2,(vlookup(L16,$A$3:$I$10,5,FALSE)),if($A$13=F$2,(vlookup(L16,$A$3:$I$10,6,FALSE)),if($A$13=G$2,(vlookup(L16,$A$3:$I$10,7,FALSE)),if($A$13=H$2,(vlookup(L16,$A$3:$I$10,8,FALSE)),if($A$13=I$2,(vlookup(L16,$A$3:$I$10,9,FALSE)),0))))))))) -> 2 | N16: =if($A$13="","",if($A$13=B$14,(vlookup($L16,$A$15:$I$22,2,FALSE)),if($A$13=C$14,(vlookup($L16,$A$15:$I$22,3,FALSE)),if($A$13=D$14,(vlookup($L16,$A$15:$I$22,4,FALSE)),if($A$13=E$14,(vlookup($L16,$A$15:$I$22,5,FALSE)),if($A$13=F$14,(vlookup($L16,$A$15:$I$22,6,FALSE)),if($A$13=G$14,(vlookup($L16,$A$15:$I$22,7,FALSE)),if($A$13=H$14,(vlookup($L16,$A$15:$I$22,8,FALSE)), if($A$13=I$14,(vlookup($L16,$A$15:$I$22,9,FALSE)))))))))))
A17: Bob B | I17: 5 | J17: =sum(B17:I17) -> 5 | L17: Bob B | M17: =if($A$13="","",if($A$13=B$2,(vlookup(L17,$A$3:$I$10,2,FALSE)),if($A$13=C$2,(vlookup(L17,$A$3:$I$10,3,FALSE)),if($A$13=D$2,(vlookup(L17,$A$3:$I$10,4,FALSE)),if($A$13=E$2,(vlookup(L17,$A$3:$I$10,5,FALSE)),if($A$13=F$2,(vlookup(L17,$A$3:$I$10,6,FALSE)),if($A$13=G$2,(vlookup(L17,$A$3:$I$10,7,FALSE)),if($A$13=H$2,(vlookup(L17,$A$3:$I$10,8,FALSE)),if($A$13=I$2,(vlookup(L17,$A$3:$I$10,9,FALSE)),0))))))))) -> 2 | N17: =if($A$13="","",if($A$13=B$14,(vlookup($L17,$A$15:$I$22,2,FALSE)),if($A$13=C$14,(vlookup($L17,$A$15:$I$22,3,FALSE)),if($A$13=D$14,(vlookup($L17,$A$15:$I$22,4,FALSE)),if($A$13=E$14,(vlookup($L17,$A$15:$I$22,5,FALSE)),if($A$13=F$14,(vlookup($L17,$A$15:$I$22,6,FALSE)),if($A$13=G$14,(vlookup($L17,$A$15:$I$22,7,FALSE)),if($A$13=H$14,(vlookup($L17,$A$15:$I$22,8,FALSE)), if($A$13=I$14,(vlookup($L17,$A$15:$I$22,9,FALSE))))))))))) -> 5
A18: Brian K | J18: =sum(B18:I18) -> 0 | L18: Brian K | M18: =if($A$13="","",if($A$13=B$2,(vlookup(L18,$A$3:$I$10,2,FALSE)),if($A$13=C$2,(vlookup(L18,$A$3:$I$10,3,FALSE)),if($A$13=D$2,(vlookup(L18,$A$3:$I$10,4,FALSE)),if($A$13=E$2,(vlookup(L18,$A$3:$I$10,5,FALSE)),if($A$13=F$2,(vlookup(L18,$A$3:$I$10,6,FALSE)),if($A$13=G$2,(vlookup(L18,$A$3:$I$10,7,FALSE)),if($A$13=H$2,(vlookup(L18,$A$3:$I$10,8,FALSE)),if($A$13=I$2,(vlookup(L18,$A$3:$I$10,9,FALSE)),0))))))))) | N18: =if($A$13="","",if($A$13=B$14,(vlookup($L18,$A$15:$I$22,2,FALSE)),if($A$13=C$14,(vlookup($L18,$A$15:$I$22,3,FALSE)),if($A$13=D$14,(vlookup($L18,$A$15:$I$22,4,FALSE)),if($A$13=E$14,(vlookup($L18,$A$15:$I$22,5,FALSE)),if($A$13=F$14,(vlookup($L18,$A$15:$I$22,6,FALSE)),if($A$13=G$14,(vlookup($L18,$A$15:$I$22,7,FALSE)),if($A$13=H$14,(vlookup($L18,$A$15:$I$22,8,FALSE)), if($A$13=I$14,(vlookup($L18,$A$15:$I$22,9,FALSE)))))))))))
A19: Eric O | B19: 5 | E19: 5 | J19: =sum(B19:I19) -> 10 | L19: Eric O | M19: =if($A$13="","",if($A$13=B$2,(vlookup(L19,$A$3:$I$10,2,FALSE)),if($A$13=C$2,(vlookup(L19,$A$3:$I$10,3,FALSE)),if($A$13=D$2,(vlookup(L19,$A$3:$I$10,4,FALSE)),if($A$13=E$2,(vlookup(L19,$A$3:$I$10,5,FALSE)),if($A$13=F$2,(vlookup(L19,$A$3:$I$10,6,FALSE)),if($A$13=G$2,(vlookup(L19,$A$3:$I$10,7,FALSE)),if($A$13=H$2,(vlookup(L19,$A$3:$I$10,8,FALSE)),if($A$13=I$2,(vlookup(L19,$A$3:$I$10,9,FALSE)),0))))))))) -> 2 | N19: =if($A$13="","",if($A$13=B$14,(vlookup($L19,$A$15:$I$22,2,FALSE)),if($A$13=C$14,(vlookup($L19,$A$15:$I$22,3,FALSE)),if($A$13=D$14,(vlookup($L19,$A$15:$I$22,4,FALSE)),if($A$13=E$14,(vlookup($L19,$A$15:$I$22,5,FALSE)),if($A$13=F$14,(vlookup($L19,$A$15:$I$22,6,FALSE)),if($A$13=G$14,(vlookup($L19,$A$15:$I$22,7,FALSE)),if($A$13=H$14,(vlookup($L19,$A$15:$I$22,8,FALSE)), if($A$13=I$14,(vlookup($L19,$A$15:$I$22,9,FALSE)))))))))))
A20: Jeff B | G20: 5 | I20: 5 | J20: =sum(B20:I20) -> 10 | L20: Jeff B | M20: =if($A$13="","",if($A$13=B$2,(vlookup(L20,$A$3:$I$10,2,FALSE)),if($A$13=C$2,(vlookup(L20,$A$3:$I$10,3,FALSE)),if($A$13=D$2,(vlookup(L20,$A$3:$I$10,4,FALSE)),if($A$13=E$2,(vlookup(L20,$A$3:$I$10,5,FALSE)),if($A$13=F$2,(vlookup(L20,$A$3:$I$10,6,FALSE)),if($A$13=G$2,(vlookup(L20,$A$3:$I$10,7,FALSE)),if($A$13=H$2,(vlookup(L20,$A$3:$I$10,8,FALSE)),if($A$13=I$2,(vlookup(L20,$A$3:$I$10,9,FALSE)),0))))))))) | N20: =if($A$13="","",if($A$13=B$14,(vlookup($L20,$A$15:$I$22,2,FALSE)),if($A$13=C$14,(vlookup($L20,$A$15:$I$22,3,FALSE)),if($A$13=D$14,(vlookup($L20,$A$15:$I$22,4,FALSE)),if($A$13=E$14,(vlookup($L20,$A$15:$I$22,5,FALSE)),if($A$13=F$14,(vlookup($L20,$A$15:$I$22,6,FALSE)),if($A$13=G$14,(vlookup($L20,$A$15:$I$22,7,FALSE)),if($A$13=H$14,(vlookup($L20,$A$15:$I$22,8,FALSE)), if($A$13=I$14,(vlookup($L20,$A$15:$I$22,9,FALSE))))))))))) -> 5
A21: John C | E21: 5 | I21: 5 | J21: =sum(B21:I21) -> 10 | L21: John C | M21: =if($A$13="","",if($A$13=B$2,(vlookup(L21,$A$3:$I$10,2,FALSE)),if($A$13=C$2,(vlookup(L21,$A$3:$I$10,3,FALSE)),if($A$13=D$2,(vlookup(L21,$A$3:$I$10,4,FALSE)),if($A$13=E$2,(vlookup(L21,$A$3:$I$10,5,FALSE)),if($A$13=F$2,(vlookup(L21,$A$3:$I$10,6,FALSE)),if($A$13=G$2,(vlookup(L21,$A$3:$I$10,7,FALSE)),if($A$13=H$2,(vlookup(L21,$A$3:$I$10,8,FALSE)),if($A$13=I$2,(vlookup(L21,$A$3:$I$10,9,FALSE)),0))))))))) | N21: =if($A$13="","",if($A$13=B$14,(vlookup($L21,$A$15:$I$22,2,FALSE)),if($A$13=C$14,(vlookup($L21,$A$15:$I$22,3,FALSE)),if($A$13=D$14,(vlookup($L21,$A$15:$I$22,4,FALSE)),if($A$13=E$14,(vlookup($L21,$A$15:$I$22,5,FALSE)),if($A$13=F$14,(vlookup($L21,$A$15:$I$22,6,FALSE)),if($A$13=G$14,(vlookup($L21,$A$15:$I$22,7,FALSE)),if($A$13=H$14,(vlookup($L21,$A$15:$I$22,8,FALSE)), if($A$13=I$14,(vlookup($L21,$A$15:$I$22,9,FALSE))))))))))) -> 5
A22: Scott R | I22: 10 | J22: =sum(B22:I22) -> 10 | L22: Scott R | M22: =if($A$13="","",if($A$13=B$2,(vlookup(L22,$A$3:$I$10,2,FALSE)),if($A$13=C$2,(vlookup(L22,$A$3:$I$10,3,FALSE)),if($A$13=D$2,(vlookup(L22,$A$3:$I$10,4,FALSE)),if($A$13=E$2,(vlookup(L22,$A$3:$I$10,5,FALSE)),if($A$13=F$2,(vlookup(L22,$A$3:$I$10,6,FALSE)),if($A$13=G$2,(vlookup(L22,$A$3:$I$10,7,FALSE)),if($A$13=H$2,(vlookup(L22,$A$3:$I$10,8,FALSE)),if($A$13=I$2,(vlookup(L22,$A$3:$I$10,9,FALSE)),0))))))))) -> 20 | N22: =if($A$13="","",if($A$13=B$14,(vlookup($L22,$A$15:$I$22,2,FALSE)),if($A$13=C$14,(vlookup($L22,$A$15:$I$22,3,FALSE)),if($A$13=D$14,(vlookup($L22,$A$15:$I$22,4,FALSE)),if($A$13=E$14,(vlookup($L22,$A$15:$I$22,5,FALSE)),if($A$13=F$14,(vlookup($L22,$A$15:$I$22,6,FALSE)),if($A$13=G$14,(vlookup($L22,$A$15:$I$22,7,FALSE)),if($A$13=H$14,(vlookup($L22,$A$15:$I$22,8,FALSE)), if($A$13=I$14,(vlookup($L22,$A$15:$I$22,9,FALSE))))))))))) -> 10
B23: =SUM(B15:B22) -> 5 | C23: =SUM(C15:C22) -> 0 | D23: =SUM(D15:D22) -> 2 | E23: =SUM(E15:E22) -> 10 | F23: =SUM(F15:F22) -> 0 | G23: =SUM(G15:G22) -> 5 | H23: =SUM(H15:H22) -> 0 | I23: =SUM(I15:I22) -> 33 | J23: =sum(B23:I23) -> 55 | M23: =if(A13="","TBD",if($A$13=B2,B11,if($A$13=C2,C11,if($A$13=D2,D11,if($A$13=E2,E11,if($A$13=F2,F11,if($A$13=G2,G11,if($A$13=H2,H11,if($A$13=I2,I11,"TBD"))))))))) -> 28 | N23: =if(A13="","TBD",if($A$13=B14,B23,if($A$13=C14,C23,if($A$13=D14,D23,if($A$13=E14,E23,if($A$13=F14,F23,if($A$13=G14,G23,if($A$13=H14,H23,if($A$13=I14,I23,"TBD"))))))))) -> 33

Sheet BettingScoreboard
A1: Low Net Per Round | B1: =Scorecards!C1 -> TULLYMORE | C1: =Scorecards!C15 -> ST IVES | D1: =Scorecards!C29 -> TULLYMORE | E1: =Scorecards!C43 -> ST IVES
A2: ='Betting SETUP'!A6 -> AJ | B2: =IF(vlookup($A2,BettingSetup,3,false)="Y",(vlookup($A2,ScoresInitialsFirst,3,false)), "out") -> 84 | C2: =IF(vlookup($A2,BettingSetup,3,false)="Y",(vlookup($A2,ScoresInitialsFirst,5,false)), "out") -> 74 | D2: =IF(vlookup($A2,BettingSetup,3,false)="Y",(vlookup($A2,ScoresInitialsFirst,7,false)), "out") -> 73 | E2: =IF(vlookup($A2,BettingSetup,3,false)="Y",(vlookup($A2,ScoresInitialsFirst,9,false)), "out") -> 85
A3: ='Betting SETUP'!A7 -> AV | B3: =IF(vlookup($A3,BettingSetup,3,false)="Y",(vlookup($A3,ScoresInitialsFirst,3,false)), "out") -> 82 | C3: =IF(vlookup($A3,BettingSetup,3,false)="Y",(vlookup($A3,ScoresInitialsFirst,5,false)), "out") -> 84 | D3: =IF(vlookup($A3,BettingSetup,3,false)="Y",(vlookup($A3,ScoresInitialsFirst,7,false)), "out") -> 95 | E3: =IF(vlookup($A3,BettingSetup,3,false)="Y",(vlookup($A3,ScoresInitialsFirst,9,false)), "out") -> 77
A4: ='Betting SETUP'!A8 -> BB | B4: =IF(vlookup($A4,BettingSetup,3,false)="Y",(vlookup($A4,ScoresInitialsFirst,3,false)), "out") -> 76 | C4: =IF(vlookup($A4,BettingSetup,3,false)="Y",(vlookup($A4,ScoresInitialsFirst,5,false)), "out") -> 80 | D4: =IF(vlookup($A4,BettingSetup,3,false)="Y",(vlookup($A4,ScoresInitialsFirst,7,false)), "out") -> 94 | E4: =IF(vlookup($A4,BettingSetup,3,false)="Y",(vlookup($A4,ScoresInitialsFirst,9,false)), "out") -> 86
A5: ='Betting SETUP'!A9 -> BK | B5: =IF(vlookup($A5,BettingSetup,3,false)="Y",(vlookup($A5,ScoresInitialsFirst,3,false)), "out") -> 84 | C5: =IF(vlookup($A5,BettingSetup,3,false)="Y",(vlookup($A5,ScoresInitialsFirst,5,false)), "out") -> 71 | D5: =IF(vlookup($A5,BettingSetup,3,false)="Y",(vlookup($A5,ScoresInitialsFirst,7,false)), "out") -> 78 | E5: =IF(vlookup($A5,BettingSetup,3,false)="Y",(vlookup($A5,ScoresInitialsFirst,9,false)), "out") -> 72
A6: ='Betting SETUP'!A10 -> EO | B6: =IF(vlookup($A6,BettingSetup,3,false)="Y",(vlookup($A6,ScoresInitialsFirst,3,false)), "out") -> 84 | C6: =IF(vlookup($A6,BettingSetup,3,false)="Y",(vlookup($A6,ScoresInitialsFirst,5,false)), "out") -> 84 | D6: =IF(vlookup($A6,BettingSetup,3,false)="Y",(vlookup($A6,ScoresInitialsFirst,7,false)), "out") -> 77 | E6: =IF(vlookup($A6,BettingSetup,3,false)="Y",(vlookup($A6,ScoresInitialsFirst,9,false)), "out") -> 86
A7: ='Betting SETUP'!A11 -> JB | B7: =IF(vlookup($A7,BettingSetup,3,false)="Y",(vlookup($A7,ScoresInitialsFirst,3,false)), "out") -> 77 | C7: =IF(vlookup($A7,BettingSetup,3,false)="Y",(vlookup($A7,ScoresInitialsFirst,5,false)), "out") -> 84 | D7: =IF(vlookup($A7,BettingSetup,3,false)="Y",(vlookup($A7,ScoresInitialsFirst,7,false)), "out") -> 89 | E7: =IF(vlookup($A7,BettingSetup,3,false)="Y",(vlookup($A7,ScoresInitialsFirst,9,false)), "out") -> 86
A8: ='Betting SETUP'!A12 -> JC | B8: =IF(vlookup($A8,BettingSetup,3,false)="Y",(vlookup($A8,ScoresInitialsFirst,3,false)), "out") -> 79 | C8: =IF(vlookup($A8,BettingSetup,3,false)="Y",(vlookup($A8,ScoresInitialsFirst,5,false)), "out") -> 81 | D8: =IF(vlookup($A8,BettingSetup,3,false)="Y",(vlookup($A8,ScoresInitialsFirst,7,false)), "out") -> 91 | E8: =IF(vlookup($A8,BettingSetup,3,false)="Y",(vlookup($A8,ScoresInitialsFirst,9,false)), "out") -> 74
A9: ='Betting SETUP'!A13 -> SR | B9: =IF(vlookup($A9,BettingSetup,3,false)="Y",(vlookup($A9,ScoresInitialsFirst,3,false)), "out") -> 73 | C9: =IF(vlookup($A9,BettingSetup,3,false)="Y",(vlookup($A9,ScoresInitialsFirst,5,false)), "out") -> 76 | D9: =IF(vlookup($A9,BettingSetup,3,false)="Y",(vlookup($A9,ScoresInitialsFirst,7,false)), "out") -> 74 | E9: =IF(vlookup($A9,BettingSetup,3,false)="Y",(vlookup($A9,ScoresInitialsFirst,9,false)), "out") -> 77
A10: # of Winners | B10: =COUNTIF(BettingScoreboard!$B$2:$B$9,MIN(BettingScoreboard!$B$2:$B$9)) -> 1 | C10: =COUNTIF(BettingScoreboard!$C$2:$C$9,MIN(BettingScoreboard!$C$2:$C$9)) -> 1 | D10: =COUNTIF(BettingScoreboard!$D$2:$D$9,MIN(BettingScoreboard!$D$2:$D$9)) -> 1 | E10: =COUNTIF(BettingScoreboard!$E$2:$E$9,MIN(BettingScoreboard!$E$2:$E$9)) -> 1
A11: $ | B11: =if(B10=0,"",('Betting SETUP'!$C$14/'Betting SETUP'!$B$1)/B10) -> 15 | C11: =if(C10=0,"",('Betting SETUP'!$C$14/'Betting SETUP'!$B$1)/C10) -> 15 | D11: =if(D10=0,"",('Betting SETUP'!$C$14/'Betting SETUP'!$B$1)/D10) -> 15 | E11: =if(E10=0,"",('Betting SETUP'!$C$14/'Betting SETUP'!$B$1)/E10) -> 15
A13: Player | B13: Skins | C13: Skin $
A14: AJ | B14: =SUM(COUNTIF(Scorecards!$D$12:$U$12,BettingScoreboard!$A14),COUNTIF(Scorecards!$D$26:$U$26,BettingScoreboard!$A14),COUNTIF(Scorecards!$D$40:$U$40,BettingScoreboard!$A14),COUNTIF(Scorecards!$D$54:$U$54,BettingScoreboard!$A14)) -> 4 | C14: =B14*'Betting SETUP'!$H$14/(sum($B$14:$B$21)) -> 33.684211
A15: BB | B15: =SUM(COUNTIF(Scorecards!$D$12:$U$12,BettingScoreboard!$A15),COUNTIF(Scorecards!$D$26:$U$26,BettingScoreboard!$A15),COUNTIF(Scorecards!$D$40:$U$40,BettingScoreboard!$A15),COUNTIF(Scorecards!$D$54:$U$54,BettingScoreboard!$A15)) -> 2 | C15: =B15*'Betting SETUP'!$H$14/(sum($B$14:$B$21)) -> 16.842105
A16: BK | B16: =SUM(COUNTIF(Scorecards!$D$12:$U$12,BettingScoreboard!$A16),COUNTIF(Scorecards!$D$26:$U$26,BettingScoreboard!$A16),COUNTIF(Scorecards!$D$40:$U$40,BettingScoreboard!$A16),COUNTIF(Scorecards!$D$54:$U$54,BettingScoreboard!$A16)) -> 4 | C16: =B16*'Betting SETUP'!$H$14/(sum($B$14:$B$21)) -> 33.684211
A17: EO | B17: =SUM(COUNTIF(Scorecards!$D$12:$U$12,BettingScoreboard!$A17),COUNTIF(Scorecards!$D$26:$U$26,BettingScoreboard!$A17),COUNTIF(Scorecards!$D$40:$U$40,BettingScoreboard!$A17),COUNTIF(Scorecards!$D$54:$U$54,BettingScoreboard!$A17)) -> 5 | C17: =B17*'Betting SETUP'!$H$14/(sum($B$14:$B$21)) -> 42.105263
A18: SR | B18: =SUM(COUNTIF(Scorecards!$D$12:$U$12,BettingScoreboard!$A18),COUNTIF(Scorecards!$D$26:$U$26,BettingScoreboard!$A18),COUNTIF(Scorecards!$D$40:$U$40,BettingScoreboard!$A18),COUNTIF(Scorecards!$D$54:$U$54,BettingScoreboard!$A18)) -> 4 | C18: =B18*'Betting SETUP'!$H$14/(sum($B$14:$B$21)) -> 33.684211
A19: SV | B19: =SUM(COUNTIF(Scorecards!$D$12:$U$12,BettingScoreboard!$A19),COUNTIF(Scorecards!$D$26:$U$26,BettingScoreboard!$A19),COUNTIF(Scorecards!$D$40:$U$40,BettingScoreboard!$A19),COUNTIF(Scorecards!$D$54:$U$54,BettingScoreboard!$A19)) -> 0 | C19: =B19*'Betting SETUP'!$H$14/(sum($B$14:$B$21)) -> 0
A20: DK | B20: =SUM(COUNTIF(Scorecards!$D$12:$U$12,BettingScoreboard!$A20),COUNTIF(Scorecards!$D$26:$U$26,BettingScoreboard!$A20),COUNTIF(Scorecards!$D$40:$U$40,BettingScoreboard!$A20),COUNTIF(Scorecards!$D$54:$U$54,BettingScoreboard!$A20)) -> 0 | C20: =B20*'Betting SETUP'!$H$14/(sum($B$14:$B$21)) -> 0
A21: JB | B21: =SUM(COUNTIF(Scorecards!$D$12:$U$12,BettingScoreboard!$A21),COUNTIF(Scorecards!$D$26:$U$26,BettingScoreboard!$A21),COUNTIF(Scorecards!$D$40:$U$40,BettingScoreboard!$A21),COUNTIF(Scorecards!$D$54:$U$54,BettingScoreboard!$A21)) -> 0 | C21: =B21*'Betting SETUP'!$H$14/(sum($B$14:$B$21)) -> 0
A23: Player | B23: CTP | C23: CTP $
A24: AJ | B24: =SUM(COUNTIF(Scorecards!$D$13:$U$13,BettingScoreboard!$A24),COUNTIF(Scorecards!$D$27:$U$27,BettingScoreboard!$A24),COUNTIF(Scorecards!$D$41:$U$41,BettingScoreboard!$A24),COUNTIF(Scorecards!$D$55:$U$55,BettingScoreboard!$A24)) -> 0 | C24: =B24*('Betting SETUP'!$L$14/(sum($B$24:$B$31))) -> #DIV/0!
A25: AV | B25: =SUM(COUNTIF(Scorecards!$D$13:$U$13,BettingScoreboard!$A25),COUNTIF(Scorecards!$D$27:$U$27,BettingScoreboard!$A25),COUNTIF(Scorecards!$D$41:$U$41,BettingScoreboard!$A25),COUNTIF(Scorecards!$D$55:$U$55,BettingScoreboard!$A25)) -> 0 | C25: =B25*('Betting SETUP'!$L$14/(sum($B$24:$B$31))) -> #DIV/0!
A26: BB | B26: =SUM(COUNTIF(Scorecards!$D$13:$U$13,BettingScoreboard!$A26),COUNTIF(Scorecards!$D$27:$U$27,BettingScoreboard!$A26),COUNTIF(Scorecards!$D$41:$U$41,BettingScoreboard!$A26),COUNTIF(Scorecards!$D$55:$U$55,BettingScoreboard!$A26)) -> 0 | C26: =B26*('Betting SETUP'!$L$14/(sum($B$24:$B$31))) -> #DIV/0!
A27: BK | B27: =SUM(COUNTIF(Scorecards!$D$13:$U$13,BettingScoreboard!$A27),COUNTIF(Scorecards!$D$27:$U$27,BettingScoreboard!$A27),COUNTIF(Scorecards!$D$41:$U$41,BettingScoreboard!$A27),COUNTIF(Scorecards!$D$55:$U$55,BettingScoreboard!$A27)) -> 0 | C27: =B27*('Betting SETUP'!$L$14/(sum($B$24:$B$31))) -> #DIV/0!
A28: EO | B28: =SUM(COUNTIF(Scorecards!$D$13:$U$13,BettingScoreboard!$A28),COUNTIF(Scorecards!$D$27:$U$27,BettingScoreboard!$A28),COUNTIF(Scorecards!$D$41:$U$41,BettingScoreboard!$A28),COUNTIF(Scorecards!$D$55:$U$55,BettingScoreboard!$A28)) -> 0 | C28: =B28*('Betting SETUP'!$L$14/(sum($B$24:$B$31))) -> #DIV/0!
A29: JB | B29: =SUM(COUNTIF(Scorecards!$D$13:$U$13,BettingScoreboard!$A29),COUNTIF(Scorecards!$D$27:$U$27,BettingScoreboard!$A29),COUNTIF(Scorecards!$D$41:$U$41,BettingScoreboard!$A29),COUNTIF(Scorecards!$D$55:$U$55,BettingScoreboard!$A29)) -> 0 | C29: =B29*('Betting SETUP'!$L$14/(sum($B$24:$B$31))) -> #DIV/0!
A30: JC | B30: =SUM(COUNTIF(Scorecards!$D$13:$U$13,BettingScoreboard!$A30),COUNTIF(Scorecards!$D$27:$U$27,BettingScoreboard!$A30),COUNTIF(Scorecards!$D$41:$U$41,BettingScoreboard!$A30),COUNTIF(Scorecards!$D$55:$U$55,BettingScoreboard!$A30)) -> 0 | C30: =B30*('Betting SETUP'!$L$14/(sum($B$24:$B$31))) -> #DIV/0!
A31: SR | B31: =SUM(COUNTIF(Scorecards!$D$13:$U$13,BettingScoreboard!$A31),COUNTIF(Scorecards!$D$27:$U$27,BettingScoreboard!$A31),COUNTIF(Scorecards!$D$41:$U$41,BettingScoreboard!$A31),COUNTIF(Scorecards!$D$55:$U$55,BettingScoreboard!$A31)) -> 0 | C31: =B31*('Betting SETUP'!$L$14/(sum($B$24:$B$31))) -> #DIV/0!

Sheet Score Calcuations
A1: RANK | B1: Player | C1: RANK | E1: =Scorecards!C1 -> TULLYMORE | G1: =Scorecards!C15 -> ST IVES | I1: =Scorecards!C29 -> TULLYMORE | K1: =Scorecards!C43 -> ST IVES | M1: TOTAL
A2: w/o TIES | C2: w/ TIES | E2: GROSS | F2: NET | G2: GROSS | H2: NET | I2: GROSS | J2: NET | K2: GROSS | L2: NET | M2: GROSS | N2: NET
A3: =RANK(N3,$N$3:$N$10,1)+COUNTIF($N$3:N3,N3)-1 -> 3 | B3: =vlookup(D3,PlayersAndHandis,3,false) -> Aaron J | C3: =RANK(N3,$N$3:$N$10,1) -> 3 | D3: ='Players and Handis SETUP'!A3 -> AJ | E3: =vlookup($D3,Round1Scores,24,false) -> 91 | F3: =vlookup($D3,Round1Scores,25,false) -> 84 | G3: =vlookup($D3,Round2Scores,24,false) -> 81 | H3: =vlookup($D3,Round2Scores,25,false) -> 74 | I3: =vlookup($D3,Scorecards!$A$32:$Y$39,24,false) -> 80 | J3: =vlookup($D3,Scorecards!$A$32:$Y$39,25,false) -> 73 | K3: =vlookup($D3,Scorecards!$A$46:$Y$53,24,false) -> 92 | L3: =vlookup($D3,Scorecards!$A$46:$Y$53,25,false) -> 85 | M3: =SUM(E3,G3,I3,K3) -> 344 | N3: =SUM(F3,H3,J3,L3) -> 316
A4: =RANK(N4,$N$3:$N$10,1)+COUNTIF($N$3:N4,N4)-1 -> 8 | B4: =vlookup(D4,PlayersAndHandis,3,false) -> Andy V | C4: =RANK(N4,$N$3:$N$10,1) -> 8 | D4: ='Players and Handis SETUP'!A4 -> AV | E4: =vlookup($D4,Round1Scores,24,false) -> 98 | F4: =vlookup($D4,Round1Scores,25,false) -> 82 | G4: =vlookup($D4,Round2Scores,24,false) -> 100 | H4: =vlookup($D4,Round2Scores,25,false) -> 84 | I4: =vlookup($D4,Scorecards!$A$32:$Y$39,24,false) -> 111 | J4: =vlookup($D4,Scorecards!$A$32:$Y$39,25,false) -> 95 | K4: =vlookup($D4,Scorecards!$A$46:$Y$53,24,false) -> 93 | L4: =vlookup($D4,Scorecards!$A$46:$Y$53,25,false) -> 77 | M4: =SUM(E4,G4,I4,K4) -> 402 | N4: =SUM(F4,H4,J4,L4) -> 338
A5: =RANK(N5,$N$3:$N$10,1)+COUNTIF($N$3:N5,N5)-1 -> 6 | B5: =vlookup(D5,PlayersAndHandis,3,false) -> Bob B | C5: =RANK(N5,$N$3:$N$10,1) -> 6 | D5: ='Players and Handis SETUP'!A5 -> BB | E5: =vlookup($D5,Round1Scores,24,false) -> 91 | F5: =vlookup($D5,Round1Scores,25,false) -> 76 | G5: =vlookup($D5,Round2Scores,24,false) -> 95 | H5: =vlookup($D5,Round2Scores,25,false) -> 80 | I5: =vlookup($D5,Scorecards!$A$32:$Y$39,24,false) -> 109 | J5: =vlookup($D5,Scorecards!$A$32:$Y$39,25,false) -> 94 | K5: =vlookup($D5,Scorecards!$A$46:$Y$53,24,false) -> 101 | L5: =vlookup($D5,Scorecards!$A$46:$Y$53,25,false) -> 86 | M5: =SUM(E5,G5,I5,K5) -> 396 | N5: =SUM(F5,H5,J5,L5) -> 336
A6: =RANK(N6,$N$3:$N$10,1)+COUNTIF($N$3:N6,N6)-1 -> 2 | B6: =vlookup(D6,PlayersAndHandis,3,false) -> Brian K | C6: =RANK(N6,$N$3:$N$10,1) -> 2 | D6: ='Players and Handis SETUP'!A6 -> BK | E6: =vlookup($D6,Round1Scores,24,false) -> 99 | F6: =vlookup($D6,Round1Scores,25,false) -> 84 | G6: =vlookup($D6,Round2Scores,24,false) -> 86 | H6: =vlookup($D6,Round2Scores,25,false) -> 71 | I6: =vlookup($D6,Scorecards!$A$32:$Y$39,24,false) -> 93 | J6: =vlookup($D6,Scorecards!$A$32:$Y$39,25,false) -> 78 | K6: =vlookup($D6,Scorecards!$A$46:$Y$53,24,false) -> 87 | L6: =vlookup($D6,Scorecards!$A$46:$Y$53,25,false) -> 72 | M6: =SUM(E6,G6,I6,K6) -> 365 | N6: =SUM(F6,H6,J6,L6) -> 305
A7: =RANK(N7,$N$3:$N$10,1)+COUNTIF($N$3:N7,N7)-1 -> 5 | B7: =vlookup(D7,PlayersAndHandis,3,false) -> Eric O | C7: =RANK(N7,$N$3:$N$10,1) -> 5 | D7: ='Players and Handis SETUP'!A7 -> EO | E7: =vlookup($D7,Round1Scores,24,false) -> 101 | F7: =vlookup($D7,Round1Scores,25,false) -> 84 | G7: =vlookup($D7,Round2Scores,24,false) -> 101 | H7: =vlookup($D7,Round2Scores,25,false) -> 84 | I7: =vlookup($D7,Scorecards!$A$32:$Y$39,24,false) -> 94 | J7: =vlookup($D7,Scorecards!$A$32:$Y$39,25,false) -> 77 | K7: =vlookup($D7,Scorecards!$A$46:$Y$53,24,false) -> 103 | L7: =vlookup($D7,Scorecards!$A$46:$Y$53,25,false) -> 86 | M7: =SUM(E7,G7,I7,K7) -> 399 | N7: =SUM(F7,H7,J7,L7) -> 331
A8: =RANK(N8,$N$3:$N$10,1)+COUNTIF($N$3:N8,N8)-1 -> 7 | B8: =vlookup(D8,PlayersAndHandis,3,false) -> Jeff B | C8: =RANK(N8,$N$3:$N$10,1) -> 6 | D8: ='Players and Handis SETUP'!A8 -> JB | E8: =vlookup($D8,Round1Scores,24,false) -> 92 | F8: =vlookup($D8,Round1Scores,25,false) -> 77 | G8: =vlookup($D8,Round2Scores,24,false) -> 99 | H8: =vlookup($D8,Round2Scores,25,false) -> 84 | I8: =vlookup($D8,Scorecards!$A$32:$Y$39,24,false) -> 104 | J8: =vlookup($D8,Scorecards!$A$32:$Y$39,25,false) -> 89 | K8: =vlookup($D8,Scorecards!$A$46:$Y$53,24,false) -> 101 | L8: =vlookup($D8,Scorecards!$A$46:$Y$53,25,false) -> 86 | M8: =SUM(E8,G8,I8,K8) -> 396 | N8: =SUM(F8,H8,J8,L8) -> 336
A9: =RANK(N9,$N$3:$N$10,1)+COUNTIF($N$3:N9,N9)-1 -> 4 | B9: =vlookup(D9,PlayersAndHandis,3,false) -> John C | C9: =RANK(N9,$N$3:$N$10,1) -> 4 | D9: ='Players and Handis SETUP'!A9 -> JC | E9: =vlookup($D9,Round1Scores,24,false) -> 91 | F9: =vlookup($D9,Round1Scores,25,false) -> 79 | G9: =vlookup($D9,Round2Scores,24,false) -> 93 | H9: =vlookup($D9,Round2Scores,25,false) -> 81 | I9: =vlookup($D9,Scorecards!$A$32:$Y$39,24,false) -> 103 | J9: =vlookup($D9,Scorecards!$A$32:$Y$39,25,false) -> 91 | K9: =vlookup($D9,Scorecards!$A$46:$Y$53,24,false) -> 86 | L9: =vlookup($D9,Scorecards!$A$46:$Y$53,25,false) -> 74 | M9: =SUM(E9,G9,I9,K9) -> 373 | N9: =SUM(F9,H9,J9,L9) -> 325
A10: =RANK(N10,$N$3:$N$10,1)+COUNTIF($N$3:N10,N10)-1 -> 1 | B10: =vlookup(D10,PlayersAndHandis,3,false) -> Scott R | C10: =RANK(N10,$N$3:$N$10,1) -> 1 | D10: ='Players and Handis SETUP'!A10 -> SR | E10: =vlookup($D10,Round1Scores,24,false) -> 80 | F10: =vlookup($D10,Round1Scores,25,false) -> 73 | G10: =vlookup($D10,Round2Scores,24,false) -> 83 | H10: =vlookup($D10,Round2Scores,25,false) -> 76 | I10: =vlookup($D10,Scorecards!$A$32:$Y$39,24,false) -> 81 | J10: =vlookup($D10,Scorecards!$A$32:$Y$39,25,false) -> 74 | K10: =vlookup($D10,Scorecards!$A$46:$Y$53,24,false) -> 84 | L10: =vlookup($D10,Scorecards!$A$46:$Y$53,25,false) -> 77 | M10: =SUM(E10,G10,I10,K10) -> 328 | N10: =SUM(F10,H10,J10,L10) -> 300

Sheet Betting SETUP
A1: Number of Individual Rounds | B1: 4
A2: ACTIVE | B2: NO | C2: YES | D2: NO | E2: NO | F2: NO | G2: NO | H2: YES | I2: NO | J2: NO | K2: NO | L2: YES
A3: TOTAL | C3: 7.5 | G3: 0 | H3: 20 | I3: 0 | L3: 22.5
A4: PER ROUND | D4: N/A | E4: N/A | F4: N/A | G4: N/A | H4: N/A | I4: N/A | J4: 5
A5: Player | B5: Low Score - Gross - Per Round | C5: Low Score - Net - Per Round | D5: Low Round - Gross | E5: Low Round - Net | F5: Low Cumulative - Gross | G5: Low Cumulative - Net | H5: Skins - Gross - Cumulative | I5: Skins - Net - Cumulative | J5: Skins - Gross - Per Round | K5: Skins - Net - Per Round | L5: CTP
A6: AJ | C6: Y | H6: Y | L6: Y
A7: AV | C7: Y | H7: Y | L7: Y
A8: BB | C8: Y | H8: Y | L8: Y
A9: BK | C9: Y | H9: Y | L9: Y
A10: EO | C10: Y | H10: Y | L10: Y
A11: JB | C11: Y | H11: Y | L11: Y
A12: JC | C12: Y | H12: Y | L12: Y
A13: SR | C13: Y | H13: Y | L13: Y
A14: =sum(B14:L14) -> 400 | B14: =COUNTIF(B6:B13,"Y") *B3 -> 0 | C14: =COUNTIF(C6:C13,"Y") *C3 -> 60 | D14: =COUNTIF(D6:D13,"Y") *D3 -> 0 | E14: =COUNTIF(E6:E13,"Y") *E3 -> 0 | F14: =COUNTIF(F6:F13,"Y") *F3 -> 0 | G14: =COUNTIF(G6:G13,"Y") *G3 -> 0 | H14: =COUNTIF(H6:H13,"Y") *H3 -> 160 | I14: =COUNTIF(I6:I13,"Y") *I3 -> 0 | ... L14: =COUNTIF(L6:L13,"Y") *L3 -> 180

Sheet Players and Handis SETUP
D1: TULLYMORE | E1: ST IVES | F1: TULLYMORE | G1: ST IVES | H1: 4.5 to 5.2 | I1: 6
A2: Player | B2: Index | C2: Player | D2: 141 | E2: 141 | F2: 141 | G2: 141 | H2: 5.3 to 6.0 | I2: 7
A3: AJ | B3: =vlookup(C3,HandiFromTracker,2,false) -> #N/A | C3: Aaron J | D3: 8 | E3: 8 | F3: 8 | G3: 8 | H3: 6.1 to 6.8 | I3: 8
A4: AV | B4: =vlookup(C4,HandiFromTracker,2,false) -> #N/A | C4: Andy V | D4: 20 | E4: 20 | F4: 20 | G4: 20 | H4: 6.9 to 7.6 | I4: 9
A5: BB | B5: =vlookup(C5,HandiFromTracker,2,false) -> #N/A | C5: Bob B | D5: 19 | E5: 19 | F5: 19 | G5: 19 | H5: 7.7 to 8.4 | I5: 10
A6: BK | B6: =vlookup(C6,HandiFromTracker,2,false) -> #N/A | C6: Brian K | D6: 15 | E6: 15 | F6: 15 | G6: 15 | H6: 8.5 to 9.2 | I6: 11
A7: EO | B7: =vlookup(C7,HandiFromTracker,2,false) -> #N/A | C7: Eric O | D7: 22 | E7: 22 | F7: 22 | G7: 22 | H7: 9.3 to 10.0 | I7: 12
A8: JB | B8: =vlookup(C8,HandiFromTracker,2,false) -> #N/A | C8: Jeff B | D8: 19 | E8: 19 | F8: 19 | G8: 19 | H8: 10.1 to 10.8 | I8: 13
A9: JC | B9: =vlookup(C9,HandiFromTracker,2,false) -> #N/A | C9: John C | D9: 12 | E9: 12 | F9: 12 | G9: 12 | H9: 10.9 to 11.6 | I9: 14
A10: SR | B10: =vlookup(C10,HandiFromTracker,2,false) -> #N/A | C10: Scott R | D10: 7 | E10: 7 | F10: 7 | G10: 7 | H10: 11.7 to 12.4 | I10: 15
H11: 12.5 to 13.2 | I11: 16
H12: 13.3 to 14.0 | I12: 17
H13: 14.1 to 14.8 | I13: 18
H14: 14.9 to 15.6 | I14: 19
H15: 15.7 to 16.4 | I15: 20
H16: 16.5 to 17.2 | I16: 21
H17: 17.3 to 18.0 | I17: 22
H18: 18.1 to 18.8 | I18: 23

Sheet Stock Market Print Sheet
A1: YOUR NAME | D1: YOUR NAME | G1: YOUR NAME | J1: YOUR NAME
A3: Aaron J | D3: Aaron J | G3: Aaron J | J3: Aaron J
A4: Andy V | D4: Andy V | G4: Andy V | J4: Andy V
A5: Bob B | D5: Bob B | G5: Bob B | J5: Bob B
A6: Brian K | D6: Brian K | G6: Brian K | J6: Brian K
A7: Eric O | D7: Eric O | G7: Eric O | J7: Eric O
A8: Jeff B | D8: Jeff B | G8: Jeff B | J8: Jeff B
A9: John C | D9: John C | G9: John C | J9: John C
A10: Scott R | D10: Scott R | G10: Scott R | J10: Scott R
A11: TOTAL $1 SHARES | D11: TOTAL $1 SHARES | G11: TOTAL $1 SHARES | J11: TOTAL $1 SHARES
A13: YOUR NAME | D13: YOUR NAME | G13: YOUR NAME | J13: YOUR NAME
A15: Aaron J | D15: Aaron J | G15: Aaron J | J15: Aaron J
... A47: TOTAL $2 SHARES | D47: TOTAL $2 SHARES | G47: TOTAL $2 SHARES | J47: TOTAL $2 SHARES

Sheet Handis From Tracker
A1: =IFERROR(__xludf.DUMMYFUNCTION("importrange(""http://docs.google.com/spreadsheets/d/13LTrqSwjK4rQqgADHR7ZLpHud1vsKbCqd2KBSWs2SjE/edit"",""MASTER!A:B"")"),"#REF!") -> #REF!
